.-.-.-.-.-.-.-.-.-.-.-.-.-.-.-.-.-.-.-.-.-.-.-.-.-.-.-.-.-.-.-.-.-.-.-.-.-.-.-.- 
 ERROR 2016-10-24 07:52:29,162 base 6796 140448339203840 Internal Server Error: /cartera/ 
Traceback (most recent call last):
  File "/home/midas/Documentos/infa_web_folder/dev_env/local/lib/python2.7/site-packages/django/core/handlers/base.py", line 149, in get_response
    response = self.process_exception_by_middleware(e, request)
  File "/home/midas/Documentos/infa_web_folder/dev_env/local/lib/python2.7/site-packages/django/core/handlers/base.py", line 147, in get_response
    response = wrapped_callback(request, *callback_args, **callback_kwargs)
  File "/home/midas/Documentos/infa_web_folder/dev_env/local/lib/python2.7/site-packages/django/views/generic/base.py", line 68, in view
    return self.dispatch(request, *args, **kwargs)
  File "/home/midas/Documentos/infa_web_folder/dev_env/local/lib/python2.7/site-packages/django/views/generic/base.py", line 88, in dispatch
    return handler(request, *args, **kwargs)
  File "/home/midas/Documentos/infa_web_folder/dev_env/local/lib/python2.7/site-packages/django/views/generic/list.py", line 159, in get
    self.object_list = self.get_queryset()
  File "/home/midas/Documentos/infa_web_folder/InfaWeb/infa_web/apps/movimientos/views.py", line 58, in get_queryset
    queryset = super(CarteraList, self).get_queryset().order_by('fmovi').filter(ctimo = ctimo_billing('ctimo_cxc_billing', self.request.db).pk)
  File "/home/midas/Documentos/infa_web_folder/InfaWeb/infa_web/apps/facturacion/views.py", line 176, in ctimo_billing
    return Timo.objects.using(request_db).get(pk = ctimo_billing)
  File "/home/midas/Documentos/infa_web_folder/dev_env/local/lib/python2.7/site-packages/django/db/models/query.py", line 381, in get
    num = len(clone)
  File "/home/midas/Documentos/infa_web_folder/dev_env/local/lib/python2.7/site-packages/django/db/models/query.py", line 240, in __len__
    self._fetch_all()
  File "/home/midas/Documentos/infa_web_folder/dev_env/local/lib/python2.7/site-packages/django/db/models/query.py", line 1074, in _fetch_all
    self._result_cache = list(self.iterator())
  File "/home/midas/Documentos/infa_web_folder/dev_env/local/lib/python2.7/site-packages/django/db/models/query.py", line 52, in __iter__
    results = compiler.execute_sql()
  File "/home/midas/Documentos/infa_web_folder/dev_env/local/lib/python2.7/site-packages/django/db/models/sql/compiler.py", line 846, in execute_sql
    cursor = self.connection.cursor()
  File "/home/midas/Documentos/infa_web_folder/dev_env/local/lib/python2.7/site-packages/django/db/backends/base/base.py", line 231, in cursor
    cursor = self.make_debug_cursor(self._cursor())
  File "/home/midas/Documentos/infa_web_folder/dev_env/local/lib/python2.7/site-packages/django/db/backends/base/base.py", line 204, in _cursor
    self.ensure_connection()
  File "/home/midas/Documentos/infa_web_folder/dev_env/local/lib/python2.7/site-packages/django/db/backends/base/base.py", line 199, in ensure_connection
    self.connect()
  File "/home/midas/Documentos/infa_web_folder/dev_env/local/lib/python2.7/site-packages/django/db/utils.py", line 95, in __exit__
    six.reraise(dj_exc_type, dj_exc_value, traceback)
  File "/home/midas/Documentos/infa_web_folder/dev_env/local/lib/python2.7/site-packages/django/db/backends/base/base.py", line 199, in ensure_connection
    self.connect()
  File "/home/midas/Documentos/infa_web_folder/dev_env/local/lib/python2.7/site-packages/django/db/backends/base/base.py", line 171, in connect
    self.connection = self.get_new_connection(conn_params)
  File "/home/midas/Documentos/infa_web_folder/dev_env/local/lib/python2.7/site-packages/django/db/backends/postgresql/base.py", line 175, in get_new_connection
    connection = Database.connect(**conn_params)
  File "/home/midas/Documentos/infa_web_folder/dev_env/local/lib/python2.7/site-packages/psycopg2/__init__.py", line 164, in connect
    conn = _connect(dsn, connection_factory=connection_factory, async=async)
OperationalError: FATAL:  database "stzef" does not exist

.-.-.-.-.-.-.-.-.-.-.-.-.-.-.-.-.-.-.-.-.-.-.-.-.-.-.-.-.-.-.-.-.-.-.-.-.-.-.-.- 
 ERROR 2016-10-24 07:55:40,311 base 6987 140543220799232 Internal Server Error: /cartera/ 
Traceback (most recent call last):
  File "/home/midas/Documentos/infa_web_folder/dev_env/local/lib/python2.7/site-packages/django/core/handlers/base.py", line 149, in get_response
    response = self.process_exception_by_middleware(e, request)
  File "/home/midas/Documentos/infa_web_folder/dev_env/local/lib/python2.7/site-packages/django/core/handlers/base.py", line 147, in get_response
    response = wrapped_callback(request, *callback_args, **callback_kwargs)
  File "/home/midas/Documentos/infa_web_folder/dev_env/local/lib/python2.7/site-packages/django/views/generic/base.py", line 68, in view
    return self.dispatch(request, *args, **kwargs)
  File "/home/midas/Documentos/infa_web_folder/dev_env/local/lib/python2.7/site-packages/django/views/generic/base.py", line 88, in dispatch
    return handler(request, *args, **kwargs)
  File "/home/midas/Documentos/infa_web_folder/dev_env/local/lib/python2.7/site-packages/django/views/generic/list.py", line 159, in get
    self.object_list = self.get_queryset()
  File "/home/midas/Documentos/infa_web_folder/InfaWeb/infa_web/apps/movimientos/views.py", line 58, in get_queryset
    queryset = super(CarteraList, self).get_queryset().order_by('fmovi').filter(ctimo = ctimo_billing('ctimo_cxc_billing', self.request.db).pk)
  File "/home/midas/Documentos/infa_web_folder/InfaWeb/infa_web/apps/facturacion/views.py", line 176, in ctimo_billing
    return Timo.objects.using(request_db).get(pk = ctimo_billing)
  File "/home/midas/Documentos/infa_web_folder/dev_env/local/lib/python2.7/site-packages/django/db/models/query.py", line 381, in get
    num = len(clone)
  File "/home/midas/Documentos/infa_web_folder/dev_env/local/lib/python2.7/site-packages/django/db/models/query.py", line 240, in __len__
    self._fetch_all()
  File "/home/midas/Documentos/infa_web_folder/dev_env/local/lib/python2.7/site-packages/django/db/models/query.py", line 1074, in _fetch_all
    self._result_cache = list(self.iterator())
  File "/home/midas/Documentos/infa_web_folder/dev_env/local/lib/python2.7/site-packages/django/db/models/query.py", line 49, in __iter__
    compiler = queryset.query.get_compiler(using=db)
  File "/home/midas/Documentos/infa_web_folder/dev_env/local/lib/python2.7/site-packages/django/db/models/sql/query.py", line 254, in get_compiler
    connection = connections[using]
  File "/home/midas/Documentos/infa_web_folder/dev_env/local/lib/python2.7/site-packages/django/db/utils.py", line 209, in __getitem__
    self.ensure_defaults(alias)
  File "/home/midas/Documentos/infa_web_folder/dev_env/local/lib/python2.7/site-packages/django/db/utils.py", line 179, in ensure_defaults
    raise ConnectionDoesNotExist("The connection %s doesn't exist" % alias)
ConnectionDoesNotExist: The connection db_1 doesn't exist
.-.-.-.-.-.-.-.-.-.-.-.-.-.-.-.-.-.-.-.-.-.-.-.-.-.-.-.-.-.-.-.-.-.-.-.-.-.-.-.- 
 ERROR 2016-10-24 07:56:47,753 base 7027 140495190472448 Internal Server Error: /cartera/detalle/1/ 
Traceback (most recent call last):
  File "/home/midas/Documentos/infa_web_folder/dev_env/local/lib/python2.7/site-packages/django/core/handlers/base.py", line 174, in get_response
    response = self.process_exception_by_middleware(e, request)
  File "/home/midas/Documentos/infa_web_folder/dev_env/local/lib/python2.7/site-packages/django/core/handlers/base.py", line 172, in get_response
    response = response.render()
  File "/home/midas/Documentos/infa_web_folder/dev_env/local/lib/python2.7/site-packages/django/template/response.py", line 160, in render
    self.content = self.rendered_content
  File "/home/midas/Documentos/infa_web_folder/dev_env/local/lib/python2.7/site-packages/django/template/response.py", line 137, in rendered_content
    content = template.render(context, self._request)
  File "/home/midas/Documentos/infa_web_folder/dev_env/local/lib/python2.7/site-packages/django/template/backends/django.py", line 95, in render
    return self.template.render(context)
  File "/home/midas/Documentos/infa_web_folder/dev_env/local/lib/python2.7/site-packages/django/template/base.py", line 206, in render
    return self._render(context)
  File "/home/midas/Documentos/infa_web_folder/dev_env/local/lib/python2.7/site-packages/django/template/base.py", line 197, in _render
    return self.nodelist.render(context)
  File "/home/midas/Documentos/infa_web_folder/dev_env/local/lib/python2.7/site-packages/django/template/base.py", line 992, in render
    bit = node.render_annotated(context)
  File "/home/midas/Documentos/infa_web_folder/dev_env/local/lib/python2.7/site-packages/django/template/base.py", line 959, in render_annotated
    return self.render(context)
  File "/home/midas/Documentos/infa_web_folder/dev_env/local/lib/python2.7/site-packages/django/template/loader_tags.py", line 173, in render
    return compiled_parent._render(context)
  File "/home/midas/Documentos/infa_web_folder/dev_env/local/lib/python2.7/site-packages/django/template/base.py", line 197, in _render
    return self.nodelist.render(context)
  File "/home/midas/Documentos/infa_web_folder/dev_env/local/lib/python2.7/site-packages/django/template/base.py", line 992, in render
    bit = node.render_annotated(context)
  File "/home/midas/Documentos/infa_web_folder/dev_env/local/lib/python2.7/site-packages/django/template/base.py", line 959, in render_annotated
    return self.render(context)
  File "/home/midas/Documentos/infa_web_folder/dev_env/local/lib/python2.7/site-packages/django/template/loader_tags.py", line 69, in render
    result = block.nodelist.render(context)
  File "/home/midas/Documentos/infa_web_folder/dev_env/local/lib/python2.7/site-packages/django/template/base.py", line 992, in render
    bit = node.render_annotated(context)
  File "/home/midas/Documentos/infa_web_folder/dev_env/local/lib/python2.7/site-packages/django/template/base.py", line 959, in render_annotated
    return self.render(context)
  File "/home/midas/Documentos/infa_web_folder/dev_env/local/lib/python2.7/site-packages/django/template/base.py", line 1043, in render
    output = self.filter_expression.resolve(context)
  File "/home/midas/Documentos/infa_web_folder/dev_env/local/lib/python2.7/site-packages/django/template/base.py", line 736, in resolve
    new_obj = func(obj, *arg_vals)
  File "/home/midas/Documentos/infa_web_folder/InfaWeb/infa_web/apps/base/templatetags/date_appen.py", line 113, in get_total_saldo
    value = movi_cartera - movi_abono
TypeError: unsupported operand type(s) for -: 'Decimal' and 'NoneType'
.-.-.-.-.-.-.-.-.-.-.-.-.-.-.-.-.-.-.-.-.-.-.-.-.-.-.-.-.-.-.-.-.-.-.-.-.-.-.-.- 
 ERROR 2016-10-24 11:09:41,693 base 15687 140067859322624 Internal Server Error: /bill/proccess/fn/annulment 
Traceback (most recent call last):
  File "/home/midas/Documentos/infa_web_folder/dev_env/local/lib/python2.7/site-packages/django/core/handlers/base.py", line 149, in get_response
    response = self.process_exception_by_middleware(e, request)
  File "/home/midas/Documentos/infa_web_folder/dev_env/local/lib/python2.7/site-packages/django/core/handlers/base.py", line 147, in get_response
    response = wrapped_callback(request, *callback_args, **callback_kwargs)
  File "/home/midas/Documentos/infa_web_folder/dev_env/local/lib/python2.7/site-packages/django/views/decorators/csrf.py", line 58, in wrapped_view
    return view_func(*args, **kwargs)
  File "/home/midas/Documentos/infa_web_folder/InfaWeb/infa_web/apps/facturacion/views.py", line 944, in bill_proccess_fn_annulment
    return HttpResponse(json.dumps(response), content_type="application/json",status=200)
  File "/usr/lib/python2.7/json/__init__.py", line 243, in dumps
    return _default_encoder.encode(obj)
  File "/usr/lib/python2.7/json/encoder.py", line 207, in encode
    chunks = self.iterencode(o, _one_shot=True)
  File "/usr/lib/python2.7/json/encoder.py", line 270, in iterencode
    return _iterencode(o, 0)
  File "/usr/lib/python2.7/json/encoder.py", line 184, in default
    raise TypeError(repr(o) + " is not JSON serializable")
TypeError: Decimal('4000.00') is not JSON serializable
