.-.-.-.-.-.-.-.-.-.-.-.-.-.-.-.-.-.-.-.-.-.-.-.-.-.-.-.-.-.-.-.-.-.-.-.-.-.-.-.- 
 ERROR 2016-10-25 09:46:59,739 base 11772 140296150144768 Internal Server Error: /bill/billing/ 
Traceback (most recent call last):
  File "/home/midas/Documentos/infa_web_folder/dev_env/local/lib/python2.7/site-packages/django/core/handlers/base.py", line 174, in get_response
    response = self.process_exception_by_middleware(e, request)
  File "/home/midas/Documentos/infa_web_folder/dev_env/local/lib/python2.7/site-packages/django/core/handlers/base.py", line 172, in get_response
    response = response.render()
  File "/home/midas/Documentos/infa_web_folder/dev_env/local/lib/python2.7/site-packages/django/template/response.py", line 160, in render
    self.content = self.rendered_content
  File "/home/midas/Documentos/infa_web_folder/dev_env/local/lib/python2.7/site-packages/django/template/response.py", line 135, in rendered_content
    template = self._resolve_template(self.template_name)
  File "/home/midas/Documentos/infa_web_folder/dev_env/local/lib/python2.7/site-packages/django/template/response.py", line 90, in _resolve_template
    new_template = self.resolve_template(template)
  File "/home/midas/Documentos/infa_web_folder/dev_env/local/lib/python2.7/site-packages/django/template/response.py", line 80, in resolve_template
    return select_template(template, using=self.using)
  File "/home/midas/Documentos/infa_web_folder/dev_env/local/lib/python2.7/site-packages/django/template/loader.py", line 55, in select_template
    engines = _engine_list(using)
  File "/home/midas/Documentos/infa_web_folder/dev_env/local/lib/python2.7/site-packages/django/template/loader.py", line 143, in _engine_list
    return engines.all() if using is None else [engines[using]]
  File "/home/midas/Documentos/infa_web_folder/dev_env/local/lib/python2.7/site-packages/django/template/utils.py", line 110, in all
    return [self[alias] for alias in self]
  File "/home/midas/Documentos/infa_web_folder/dev_env/local/lib/python2.7/site-packages/django/template/utils.py", line 101, in __getitem__
    engine = engine_cls(params)
  File "/home/midas/Documentos/infa_web_folder/dev_env/local/lib/python2.7/site-packages/django/template/backends/django.py", line 31, in __init__
    options['libraries'] = self.get_templatetag_libraries(libraries)
  File "/home/midas/Documentos/infa_web_folder/dev_env/local/lib/python2.7/site-packages/django/template/backends/django.py", line 49, in get_templatetag_libraries
    libraries = get_installed_libraries()
  File "/home/midas/Documentos/infa_web_folder/dev_env/local/lib/python2.7/site-packages/django/template/backends/django.py", line 142, in get_installed_libraries
    for name in get_package_libraries(pkg):
  File "/home/midas/Documentos/infa_web_folder/dev_env/local/lib/python2.7/site-packages/django/template/backends/django.py", line 155, in get_package_libraries
    module = import_module(entry[1])
  File "/usr/lib/python2.7/importlib/__init__.py", line 37, in import_module
    __import__(name)
  File "/home/midas/Documentos/infa_web_folder/InfaWeb/infa_web/apps/base/templatetags/tags_appem.py", line 3, in <module>
    register = template.Library()
NameError: name 'template' is not defined
.-.-.-.-.-.-.-.-.-.-.-.-.-.-.-.-.-.-.-.-.-.-.-.-.-.-.-.-.-.-.-.-.-.-.-.-.-.-.-.- 
 ERROR 2016-10-25 09:47:08,699 base 11772 140296150144768 Internal Server Error: /bill/billing/ 
Traceback (most recent call last):
  File "/home/midas/Documentos/infa_web_folder/dev_env/local/lib/python2.7/site-packages/django/core/handlers/base.py", line 174, in get_response
    response = self.process_exception_by_middleware(e, request)
  File "/home/midas/Documentos/infa_web_folder/dev_env/local/lib/python2.7/site-packages/django/core/handlers/base.py", line 172, in get_response
    response = response.render()
  File "/home/midas/Documentos/infa_web_folder/dev_env/local/lib/python2.7/site-packages/django/template/response.py", line 160, in render
    self.content = self.rendered_content
  File "/home/midas/Documentos/infa_web_folder/dev_env/local/lib/python2.7/site-packages/django/template/response.py", line 135, in rendered_content
    template = self._resolve_template(self.template_name)
  File "/home/midas/Documentos/infa_web_folder/dev_env/local/lib/python2.7/site-packages/django/template/response.py", line 90, in _resolve_template
    new_template = self.resolve_template(template)
  File "/home/midas/Documentos/infa_web_folder/dev_env/local/lib/python2.7/site-packages/django/template/response.py", line 80, in resolve_template
    return select_template(template, using=self.using)
  File "/home/midas/Documentos/infa_web_folder/dev_env/local/lib/python2.7/site-packages/django/template/loader.py", line 55, in select_template
    engines = _engine_list(using)
  File "/home/midas/Documentos/infa_web_folder/dev_env/local/lib/python2.7/site-packages/django/template/loader.py", line 143, in _engine_list
    return engines.all() if using is None else [engines[using]]
  File "/home/midas/Documentos/infa_web_folder/dev_env/local/lib/python2.7/site-packages/django/template/utils.py", line 110, in all
    return [self[alias] for alias in self]
  File "/home/midas/Documentos/infa_web_folder/dev_env/local/lib/python2.7/site-packages/django/template/utils.py", line 101, in __getitem__
    engine = engine_cls(params)
  File "/home/midas/Documentos/infa_web_folder/dev_env/local/lib/python2.7/site-packages/django/template/backends/django.py", line 31, in __init__
    options['libraries'] = self.get_templatetag_libraries(libraries)
  File "/home/midas/Documentos/infa_web_folder/dev_env/local/lib/python2.7/site-packages/django/template/backends/django.py", line 49, in get_templatetag_libraries
    libraries = get_installed_libraries()
  File "/home/midas/Documentos/infa_web_folder/dev_env/local/lib/python2.7/site-packages/django/template/backends/django.py", line 142, in get_installed_libraries
    for name in get_package_libraries(pkg):
  File "/home/midas/Documentos/infa_web_folder/dev_env/local/lib/python2.7/site-packages/django/template/backends/django.py", line 155, in get_package_libraries
    module = import_module(entry[1])
  File "/usr/lib/python2.7/importlib/__init__.py", line 37, in import_module
    __import__(name)
  File "/home/midas/Documentos/infa_web_folder/InfaWeb/infa_web/apps/base/templatetags/tags_appem.py", line 3, in <module>
    register = template.Library()
NameError: name 'template' is not defined
.-.-.-.-.-.-.-.-.-.-.-.-.-.-.-.-.-.-.-.-.-.-.-.-.-.-.-.-.-.-.-.-.-.-.-.-.-.-.-.- 
 ERROR 2016-10-25 09:47:18,377 base 11772 140296139917056 Internal Server Error: / 
Traceback (most recent call last):
  File "/home/midas/Documentos/infa_web_folder/dev_env/local/lib/python2.7/site-packages/django/core/handlers/base.py", line 174, in get_response
    response = self.process_exception_by_middleware(e, request)
  File "/home/midas/Documentos/infa_web_folder/dev_env/local/lib/python2.7/site-packages/django/core/handlers/base.py", line 172, in get_response
    response = response.render()
  File "/home/midas/Documentos/infa_web_folder/dev_env/local/lib/python2.7/site-packages/django/template/response.py", line 160, in render
    self.content = self.rendered_content
  File "/home/midas/Documentos/infa_web_folder/dev_env/local/lib/python2.7/site-packages/django/template/response.py", line 135, in rendered_content
    template = self._resolve_template(self.template_name)
  File "/home/midas/Documentos/infa_web_folder/dev_env/local/lib/python2.7/site-packages/django/template/response.py", line 90, in _resolve_template
    new_template = self.resolve_template(template)
  File "/home/midas/Documentos/infa_web_folder/dev_env/local/lib/python2.7/site-packages/django/template/response.py", line 80, in resolve_template
    return select_template(template, using=self.using)
  File "/home/midas/Documentos/infa_web_folder/dev_env/local/lib/python2.7/site-packages/django/template/loader.py", line 55, in select_template
    engines = _engine_list(using)
  File "/home/midas/Documentos/infa_web_folder/dev_env/local/lib/python2.7/site-packages/django/template/loader.py", line 143, in _engine_list
    return engines.all() if using is None else [engines[using]]
  File "/home/midas/Documentos/infa_web_folder/dev_env/local/lib/python2.7/site-packages/django/template/utils.py", line 110, in all
    return [self[alias] for alias in self]
  File "/home/midas/Documentos/infa_web_folder/dev_env/local/lib/python2.7/site-packages/django/template/utils.py", line 101, in __getitem__
    engine = engine_cls(params)
  File "/home/midas/Documentos/infa_web_folder/dev_env/local/lib/python2.7/site-packages/django/template/backends/django.py", line 31, in __init__
    options['libraries'] = self.get_templatetag_libraries(libraries)
  File "/home/midas/Documentos/infa_web_folder/dev_env/local/lib/python2.7/site-packages/django/template/backends/django.py", line 49, in get_templatetag_libraries
    libraries = get_installed_libraries()
  File "/home/midas/Documentos/infa_web_folder/dev_env/local/lib/python2.7/site-packages/django/template/backends/django.py", line 142, in get_installed_libraries
    for name in get_package_libraries(pkg):
  File "/home/midas/Documentos/infa_web_folder/dev_env/local/lib/python2.7/site-packages/django/template/backends/django.py", line 155, in get_package_libraries
    module = import_module(entry[1])
  File "/usr/lib/python2.7/importlib/__init__.py", line 37, in import_module
    __import__(name)
  File "/home/midas/Documentos/infa_web_folder/InfaWeb/infa_web/apps/base/templatetags/tags_appem.py", line 3, in <module>
    register = template.Library()
NameError: name 'template' is not defined
.-.-.-.-.-.-.-.-.-.-.-.-.-.-.-.-.-.-.-.-.-.-.-.-.-.-.-.-.-.-.-.-.-.-.-.-.-.-.-.- 
 ERROR 2016-10-25 09:47:25,689 base 11772 140296150144768 Internal Server Error: / 
Traceback (most recent call last):
  File "/home/midas/Documentos/infa_web_folder/dev_env/local/lib/python2.7/site-packages/django/core/handlers/base.py", line 174, in get_response
    response = self.process_exception_by_middleware(e, request)
  File "/home/midas/Documentos/infa_web_folder/dev_env/local/lib/python2.7/site-packages/django/core/handlers/base.py", line 172, in get_response
    response = response.render()
  File "/home/midas/Documentos/infa_web_folder/dev_env/local/lib/python2.7/site-packages/django/template/response.py", line 160, in render
    self.content = self.rendered_content
  File "/home/midas/Documentos/infa_web_folder/dev_env/local/lib/python2.7/site-packages/django/template/response.py", line 135, in rendered_content
    template = self._resolve_template(self.template_name)
  File "/home/midas/Documentos/infa_web_folder/dev_env/local/lib/python2.7/site-packages/django/template/response.py", line 90, in _resolve_template
    new_template = self.resolve_template(template)
  File "/home/midas/Documentos/infa_web_folder/dev_env/local/lib/python2.7/site-packages/django/template/response.py", line 80, in resolve_template
    return select_template(template, using=self.using)
  File "/home/midas/Documentos/infa_web_folder/dev_env/local/lib/python2.7/site-packages/django/template/loader.py", line 55, in select_template
    engines = _engine_list(using)
  File "/home/midas/Documentos/infa_web_folder/dev_env/local/lib/python2.7/site-packages/django/template/loader.py", line 143, in _engine_list
    return engines.all() if using is None else [engines[using]]
  File "/home/midas/Documentos/infa_web_folder/dev_env/local/lib/python2.7/site-packages/django/template/utils.py", line 110, in all
    return [self[alias] for alias in self]
  File "/home/midas/Documentos/infa_web_folder/dev_env/local/lib/python2.7/site-packages/django/template/utils.py", line 101, in __getitem__
    engine = engine_cls(params)
  File "/home/midas/Documentos/infa_web_folder/dev_env/local/lib/python2.7/site-packages/django/template/backends/django.py", line 31, in __init__
    options['libraries'] = self.get_templatetag_libraries(libraries)
  File "/home/midas/Documentos/infa_web_folder/dev_env/local/lib/python2.7/site-packages/django/template/backends/django.py", line 49, in get_templatetag_libraries
    libraries = get_installed_libraries()
  File "/home/midas/Documentos/infa_web_folder/dev_env/local/lib/python2.7/site-packages/django/template/backends/django.py", line 142, in get_installed_libraries
    for name in get_package_libraries(pkg):
  File "/home/midas/Documentos/infa_web_folder/dev_env/local/lib/python2.7/site-packages/django/template/backends/django.py", line 155, in get_package_libraries
    module = import_module(entry[1])
  File "/usr/lib/python2.7/importlib/__init__.py", line 37, in import_module
    __import__(name)
  File "/home/midas/Documentos/infa_web_folder/InfaWeb/infa_web/apps/base/templatetags/tags_appem.py", line 3, in <module>
    register = template.Library()
NameError: name 'template' is not defined
.-.-.-.-.-.-.-.-.-.-.-.-.-.-.-.-.-.-.-.-.-.-.-.-.-.-.-.-.-.-.-.-.-.-.-.-.-.-.-.- 
 ERROR 2016-10-25 09:47:51,451 base 11891 139779509319424 Internal Server Error: / 
Traceback (most recent call last):
  File "/home/midas/Documentos/infa_web_folder/dev_env/local/lib/python2.7/site-packages/django/core/handlers/base.py", line 174, in get_response
    response = self.process_exception_by_middleware(e, request)
  File "/home/midas/Documentos/infa_web_folder/dev_env/local/lib/python2.7/site-packages/django/core/handlers/base.py", line 172, in get_response
    response = response.render()
  File "/home/midas/Documentos/infa_web_folder/dev_env/local/lib/python2.7/site-packages/django/template/response.py", line 160, in render
    self.content = self.rendered_content
  File "/home/midas/Documentos/infa_web_folder/dev_env/local/lib/python2.7/site-packages/django/template/response.py", line 135, in rendered_content
    template = self._resolve_template(self.template_name)
  File "/home/midas/Documentos/infa_web_folder/dev_env/local/lib/python2.7/site-packages/django/template/response.py", line 90, in _resolve_template
    new_template = self.resolve_template(template)
  File "/home/midas/Documentos/infa_web_folder/dev_env/local/lib/python2.7/site-packages/django/template/response.py", line 80, in resolve_template
    return select_template(template, using=self.using)
  File "/home/midas/Documentos/infa_web_folder/dev_env/local/lib/python2.7/site-packages/django/template/loader.py", line 55, in select_template
    engines = _engine_list(using)
  File "/home/midas/Documentos/infa_web_folder/dev_env/local/lib/python2.7/site-packages/django/template/loader.py", line 143, in _engine_list
    return engines.all() if using is None else [engines[using]]
  File "/home/midas/Documentos/infa_web_folder/dev_env/local/lib/python2.7/site-packages/django/template/utils.py", line 110, in all
    return [self[alias] for alias in self]
  File "/home/midas/Documentos/infa_web_folder/dev_env/local/lib/python2.7/site-packages/django/template/utils.py", line 101, in __getitem__
    engine = engine_cls(params)
  File "/home/midas/Documentos/infa_web_folder/dev_env/local/lib/python2.7/site-packages/django/template/backends/django.py", line 31, in __init__
    options['libraries'] = self.get_templatetag_libraries(libraries)
  File "/home/midas/Documentos/infa_web_folder/dev_env/local/lib/python2.7/site-packages/django/template/backends/django.py", line 49, in get_templatetag_libraries
    libraries = get_installed_libraries()
  File "/home/midas/Documentos/infa_web_folder/dev_env/local/lib/python2.7/site-packages/django/template/backends/django.py", line 142, in get_installed_libraries
    for name in get_package_libraries(pkg):
  File "/home/midas/Documentos/infa_web_folder/dev_env/local/lib/python2.7/site-packages/django/template/backends/django.py", line 155, in get_package_libraries
    module = import_module(entry[1])
  File "/usr/lib/python2.7/importlib/__init__.py", line 37, in import_module
    __import__(name)
  File "/home/midas/Documentos/infa_web_folder/InfaWeb/infa_web/apps/base/templatetags/tags_appem.py", line 3, in <module>
    register = template.Library()
NameError: name 'template' is not defined
.-.-.-.-.-.-.-.-.-.-.-.-.-.-.-.-.-.-.-.-.-.-.-.-.-.-.-.-.-.-.-.-.-.-.-.-.-.-.-.- 
 ERROR 2016-10-25 09:47:58,594 base 11891 139779500926720 Internal Server Error: /parameters/ 
Traceback (most recent call last):
  File "/home/midas/Documentos/infa_web_folder/dev_env/local/lib/python2.7/site-packages/django/core/handlers/base.py", line 149, in get_response
    response = self.process_exception_by_middleware(e, request)
  File "/home/midas/Documentos/infa_web_folder/dev_env/local/lib/python2.7/site-packages/django/core/handlers/base.py", line 147, in get_response
    response = wrapped_callback(request, *callback_args, **callback_kwargs)
<<<<<<< HEAD
  File "/home/jsandoval86/ProjectsDev/Appem/env/local/lib/python2.7/site-packages/django/views/decorators/csrf.py", line 58, in wrapped_view
    return view_func(*args, **kwargs)
  File "/home/jsandoval86/ProjectsDev/Appem/appem/infa_web/apps/facturacion/views.py", line 298, in BillSave
    data['femi'] = data['femi'] + " " + today.strftime("%H:%M:%S")
KeyError: 'femi'
=======
TypeError: int() argument must be a string or a number, not 'Esdo'
>>>>>>> 80aaf54b7872818c3b8df1785cc846c7b7e2e0fc
.-.-.-.-.-.-.-.-.-.-.-.-.-.-.-.-.-.-.-.-.-.-.-.-.-.-.-.-.-.-.-.-.-.-.-.-.-.-.-.- 
 ERROR 2016-10-25 09:43:46,884 base 9789 140232789120768 Internal Server Error: /m/search-client 
Traceback (most recent call last):
  File "/home/jsandoval86/ProjectsDev/Appem/env/local/lib/python2.7/site-packages/django/core/handlers/base.py", line 149, in get_response
    response = self.process_exception_by_middleware(e, request)
  File "/home/jsandoval86/ProjectsDev/Appem/env/local/lib/python2.7/site-packages/django/core/handlers/base.py", line 147, in get_response
    response = wrapped_callback(request, *callback_args, **callback_kwargs)
  File "/home/jsandoval86/ProjectsDev/Appem/appem/infa_web/apps/m/views.py", line 88, in mFacSearchClient
    return render(request, 'm/m_fac_search_client.html', context)
  File "/home/jsandoval86/ProjectsDev/Appem/env/local/lib/python2.7/site-packages/django/shortcuts.py", line 67, in render
    template_name, context, request=request, using=using)
  File "/home/jsandoval86/ProjectsDev/Appem/env/local/lib/python2.7/site-packages/django/template/loader.py", line 97, in render_to_string
    return template.render(context, request)
  File "/home/jsandoval86/ProjectsDev/Appem/env/local/lib/python2.7/site-packages/django/template/backends/django.py", line 95, in render
    return self.template.render(context)
  File "/home/jsandoval86/ProjectsDev/Appem/env/local/lib/python2.7/site-packages/django/template/base.py", line 206, in render
    return self._render(context)
  File "/home/jsandoval86/ProjectsDev/Appem/env/local/lib/python2.7/site-packages/django/template/base.py", line 197, in _render
    return self.nodelist.render(context)
  File "/home/jsandoval86/ProjectsDev/Appem/env/local/lib/python2.7/site-packages/django/template/base.py", line 992, in render
    bit = node.render_annotated(context)
  File "/home/jsandoval86/ProjectsDev/Appem/env/local/lib/python2.7/site-packages/django/template/base.py", line 959, in render_annotated
    return self.render(context)
  File "/home/jsandoval86/ProjectsDev/Appem/env/local/lib/python2.7/site-packages/django/template/loader_tags.py", line 173, in render
    return compiled_parent._render(context)
  File "/home/jsandoval86/ProjectsDev/Appem/env/local/lib/python2.7/site-packages/django/template/base.py", line 197, in _render
    return self.nodelist.render(context)
  File "/home/jsandoval86/ProjectsDev/Appem/env/local/lib/python2.7/site-packages/django/template/base.py", line 992, in render
    bit = node.render_annotated(context)
  File "/home/jsandoval86/ProjectsDev/Appem/env/local/lib/python2.7/site-packages/django/template/base.py", line 959, in render_annotated
    return self.render(context)
  File "/home/jsandoval86/ProjectsDev/Appem/env/local/lib/python2.7/site-packages/django/template/loader_tags.py", line 69, in render
    result = block.nodelist.render(context)
  File "/home/jsandoval86/ProjectsDev/Appem/env/local/lib/python2.7/site-packages/django/template/base.py", line 992, in render
    bit = node.render_annotated(context)
  File "/home/jsandoval86/ProjectsDev/Appem/env/local/lib/python2.7/site-packages/django/template/base.py", line 959, in render_annotated
    return self.render(context)
  File "/home/jsandoval86/ProjectsDev/Appem/env/local/lib/python2.7/site-packages/django/template/defaulttags.py", line 168, in render
    len_values = len(values)
  File "/home/jsandoval86/ProjectsDev/Appem/env/local/lib/python2.7/site-packages/django/db/models/query.py", line 240, in __len__
    self._fetch_all()
  File "/home/jsandoval86/ProjectsDev/Appem/env/local/lib/python2.7/site-packages/django/db/models/query.py", line 1074, in _fetch_all
    self._result_cache = list(self.iterator())
  File "/home/jsandoval86/ProjectsDev/Appem/env/local/lib/python2.7/site-packages/django/db/models/query.py", line 52, in __iter__
    results = compiler.execute_sql()
  File "/home/jsandoval86/ProjectsDev/Appem/env/local/lib/python2.7/site-packages/django/db/models/sql/compiler.py", line 846, in execute_sql
    cursor = self.connection.cursor()
  File "/home/jsandoval86/ProjectsDev/Appem/env/local/lib/python2.7/site-packages/django/db/backends/base/base.py", line 231, in cursor
    cursor = self.make_debug_cursor(self._cursor())
  File "/home/jsandoval86/ProjectsDev/Appem/env/local/lib/python2.7/site-packages/django/db/backends/base/base.py", line 204, in _cursor
    self.ensure_connection()
  File "/home/jsandoval86/ProjectsDev/Appem/env/local/lib/python2.7/site-packages/django/db/backends/base/base.py", line 199, in ensure_connection
    self.connect()
  File "/home/jsandoval86/ProjectsDev/Appem/env/local/lib/python2.7/site-packages/django/db/utils.py", line 95, in __exit__
    six.reraise(dj_exc_type, dj_exc_value, traceback)
  File "/home/jsandoval86/ProjectsDev/Appem/env/local/lib/python2.7/site-packages/django/db/backends/base/base.py", line 199, in ensure_connection
    self.connect()
  File "/home/jsandoval86/ProjectsDev/Appem/env/local/lib/python2.7/site-packages/django/db/backends/base/base.py", line 171, in connect
    self.connection = self.get_new_connection(conn_params)
  File "/home/jsandoval86/ProjectsDev/Appem/env/local/lib/python2.7/site-packages/django/db/backends/postgresql/base.py", line 175, in get_new_connection
    connection = Database.connect(**conn_params)
  File "/home/jsandoval86/ProjectsDev/Appem/env/local/lib/python2.7/site-packages/psycopg2/__init__.py", line 164, in connect
    conn = _connect(dsn, connection_factory=connection_factory, async=async)
OperationalError: FATAL:  password authentication failed for user "root"
FATAL:  password authentication failed for user "root"

.-.-.-.-.-.-.-.-.-.-.-.-.-.-.-.-.-.-.-.-.-.-.-.-.-.-.-.-.-.-.-.-.-.-.-.-.-.-.-.- 
 ERROR 2016-10-25 09:45:54,053 base 10239 139738790016768 Internal Server Error: /m/search-client 
Traceback (most recent call last):
  File "/home/jsandoval86/ProjectsDev/Appem/env/local/lib/python2.7/site-packages/django/core/handlers/base.py", line 149, in get_response
    response = self.process_exception_by_middleware(e, request)
  File "/home/jsandoval86/ProjectsDev/Appem/env/local/lib/python2.7/site-packages/django/core/handlers/base.py", line 147, in get_response
    response = wrapped_callback(request, *callback_args, **callback_kwargs)
  File "/home/jsandoval86/ProjectsDev/Appem/appem/infa_web/apps/m/views.py", line 88, in mFacSearchClient
    return render(request, 'm/m_fac_search_client.html', context)
  File "/home/jsandoval86/ProjectsDev/Appem/env/local/lib/python2.7/site-packages/django/shortcuts.py", line 67, in render
    template_name, context, request=request, using=using)
  File "/home/jsandoval86/ProjectsDev/Appem/env/local/lib/python2.7/site-packages/django/template/loader.py", line 97, in render_to_string
    return template.render(context, request)
  File "/home/jsandoval86/ProjectsDev/Appem/env/local/lib/python2.7/site-packages/django/template/backends/django.py", line 95, in render
    return self.template.render(context)
  File "/home/jsandoval86/ProjectsDev/Appem/env/local/lib/python2.7/site-packages/django/template/base.py", line 206, in render
    return self._render(context)
  File "/home/jsandoval86/ProjectsDev/Appem/env/local/lib/python2.7/site-packages/django/template/base.py", line 197, in _render
    return self.nodelist.render(context)
  File "/home/jsandoval86/ProjectsDev/Appem/env/local/lib/python2.7/site-packages/django/template/base.py", line 992, in render
    bit = node.render_annotated(context)
  File "/home/jsandoval86/ProjectsDev/Appem/env/local/lib/python2.7/site-packages/django/template/base.py", line 959, in render_annotated
    return self.render(context)
  File "/home/jsandoval86/ProjectsDev/Appem/env/local/lib/python2.7/site-packages/django/template/loader_tags.py", line 173, in render
    return compiled_parent._render(context)
  File "/home/jsandoval86/ProjectsDev/Appem/env/local/lib/python2.7/site-packages/django/template/base.py", line 197, in _render
    return self.nodelist.render(context)
  File "/home/jsandoval86/ProjectsDev/Appem/env/local/lib/python2.7/site-packages/django/template/base.py", line 992, in render
    bit = node.render_annotated(context)
  File "/home/jsandoval86/ProjectsDev/Appem/env/local/lib/python2.7/site-packages/django/template/base.py", line 959, in render_annotated
    return self.render(context)
  File "/home/jsandoval86/ProjectsDev/Appem/env/local/lib/python2.7/site-packages/django/template/loader_tags.py", line 69, in render
    result = block.nodelist.render(context)
  File "/home/jsandoval86/ProjectsDev/Appem/env/local/lib/python2.7/site-packages/django/template/base.py", line 992, in render
    bit = node.render_annotated(context)
  File "/home/jsandoval86/ProjectsDev/Appem/env/local/lib/python2.7/site-packages/django/template/base.py", line 959, in render_annotated
    return self.render(context)
  File "/home/jsandoval86/ProjectsDev/Appem/env/local/lib/python2.7/site-packages/django/template/defaulttags.py", line 168, in render
    len_values = len(values)
  File "/home/jsandoval86/ProjectsDev/Appem/env/local/lib/python2.7/site-packages/django/db/models/query.py", line 240, in __len__
    self._fetch_all()
  File "/home/jsandoval86/ProjectsDev/Appem/env/local/lib/python2.7/site-packages/django/db/models/query.py", line 1074, in _fetch_all
    self._result_cache = list(self.iterator())
  File "/home/jsandoval86/ProjectsDev/Appem/env/local/lib/python2.7/site-packages/django/db/models/query.py", line 52, in __iter__
    results = compiler.execute_sql()
  File "/home/jsandoval86/ProjectsDev/Appem/env/local/lib/python2.7/site-packages/django/db/models/sql/compiler.py", line 846, in execute_sql
    cursor = self.connection.cursor()
  File "/home/jsandoval86/ProjectsDev/Appem/env/local/lib/python2.7/site-packages/django/db/backends/base/base.py", line 231, in cursor
    cursor = self.make_debug_cursor(self._cursor())
  File "/home/jsandoval86/ProjectsDev/Appem/env/local/lib/python2.7/site-packages/django/db/backends/base/base.py", line 204, in _cursor
    self.ensure_connection()
  File "/home/jsandoval86/ProjectsDev/Appem/env/local/lib/python2.7/site-packages/django/db/backends/base/base.py", line 199, in ensure_connection
    self.connect()
  File "/home/jsandoval86/ProjectsDev/Appem/env/local/lib/python2.7/site-packages/django/db/utils.py", line 95, in __exit__
    six.reraise(dj_exc_type, dj_exc_value, traceback)
  File "/home/jsandoval86/ProjectsDev/Appem/env/local/lib/python2.7/site-packages/django/db/backends/base/base.py", line 199, in ensure_connection
    self.connect()
  File "/home/jsandoval86/ProjectsDev/Appem/env/local/lib/python2.7/site-packages/django/db/backends/base/base.py", line 171, in connect
    self.connection = self.get_new_connection(conn_params)
  File "/home/jsandoval86/ProjectsDev/Appem/env/local/lib/python2.7/site-packages/django/db/backends/postgresql/base.py", line 175, in get_new_connection
    connection = Database.connect(**conn_params)
  File "/home/jsandoval86/ProjectsDev/Appem/env/local/lib/python2.7/site-packages/psycopg2/__init__.py", line 164, in connect
    conn = _connect(dsn, connection_factory=connection_factory, async=async)
OperationalError: FATAL:  password authentication failed for user "postgres"
FATAL:  password authentication failed for user "postgres"

.-.-.-.-.-.-.-.-.-.-.-.-.-.-.-.-.-.-.-.-.-.-.-.-.-.-.-.-.-.-.-.-.-.-.-.-.-.-.-.- 
 ERROR 2016-10-25 09:51:32,776 base 10369 140519889377024 Internal Server Error: /m/articles/list 
Traceback (most recent call last):
  File "/home/jsandoval86/ProjectsDev/Appem/env/local/lib/python2.7/site-packages/django/core/handlers/base.py", line 149, in get_response
    response = self.process_exception_by_middleware(e, request)
  File "/home/jsandoval86/ProjectsDev/Appem/env/local/lib/python2.7/site-packages/django/core/handlers/base.py", line 147, in get_response
    response = wrapped_callback(request, *callback_args, **callback_kwargs)
  File "/home/jsandoval86/ProjectsDev/Appem/env/local/lib/python2.7/site-packages/django/views/decorators/csrf.py", line 58, in wrapped_view
    return view_func(*args, **kwargs)
  File "/home/jsandoval86/ProjectsDev/Appem/appem/infa_web/apps/m/views.py", line 157, in mArticlesList
    Q(carlos=query) | Q(ncorto__contains=query)
  File "/home/jsandoval86/ProjectsDev/Appem/env/local/lib/python2.7/site-packages/django/db/models/query.py", line 790, in filter
    return self._filter_or_exclude(False, *args, **kwargs)
  File "/home/jsandoval86/ProjectsDev/Appem/env/local/lib/python2.7/site-packages/django/db/models/query.py", line 808, in _filter_or_exclude
    clone.query.add_q(Q(*args, **kwargs))
  File "/home/jsandoval86/ProjectsDev/Appem/env/local/lib/python2.7/site-packages/django/db/models/sql/query.py", line 1243, in add_q
    clause, _ = self._add_q(q_object, self.used_aliases)
  File "/home/jsandoval86/ProjectsDev/Appem/env/local/lib/python2.7/site-packages/django/db/models/sql/query.py", line 1263, in _add_q
    current_negated, allow_joins, split_subq)
  File "/home/jsandoval86/ProjectsDev/Appem/env/local/lib/python2.7/site-packages/django/db/models/sql/query.py", line 1269, in _add_q
    allow_joins=allow_joins, split_subq=split_subq,
  File "/home/jsandoval86/ProjectsDev/Appem/env/local/lib/python2.7/site-packages/django/db/models/sql/query.py", line 1203, in build_filter
    condition = self.build_lookup(lookups, col, value)
  File "/home/jsandoval86/ProjectsDev/Appem/env/local/lib/python2.7/site-packages/django/db/models/sql/query.py", line 1099, in build_lookup
    return final_lookup(lhs, rhs)
  File "/home/jsandoval86/ProjectsDev/Appem/env/local/lib/python2.7/site-packages/django/db/models/lookups.py", line 19, in __init__
    self.rhs = self.get_prep_lookup()
  File "/home/jsandoval86/ProjectsDev/Appem/env/local/lib/python2.7/site-packages/django/db/models/lookups.py", line 57, in get_prep_lookup
    return self.lhs.output_field.get_prep_lookup(self.lookup_name, self.rhs)
  File "/home/jsandoval86/ProjectsDev/Appem/env/local/lib/python2.7/site-packages/django/db/models/fields/__init__.py", line 1860, in get_prep_lookup
    return super(IntegerField, self).get_prep_lookup(lookup_type, value)
  File "/home/jsandoval86/ProjectsDev/Appem/env/local/lib/python2.7/site-packages/django/db/models/fields/__init__.py", line 744, in get_prep_lookup
    return self.get_prep_value(value)
  File "/home/jsandoval86/ProjectsDev/Appem/env/local/lib/python2.7/site-packages/django/db/models/fields/__init__.py", line 1854, in get_prep_value
    return int(value)
ValueError: invalid literal for int() with base 10: 'moto'
.-.-.-.-.-.-.-.-.-.-.-.-.-.-.-.-.-.-.-.-.-.-.-.-.-.-.-.-.-.-.-.-.-.-.-.-.-.-.-.- 
 ERROR 2016-10-25 09:51:34,638 base 10369 140519889377024 Internal Server Error: /m/articles/list 
Traceback (most recent call last):
  File "/home/jsandoval86/ProjectsDev/Appem/env/local/lib/python2.7/site-packages/django/core/handlers/base.py", line 149, in get_response
    response = self.process_exception_by_middleware(e, request)
  File "/home/jsandoval86/ProjectsDev/Appem/env/local/lib/python2.7/site-packages/django/core/handlers/base.py", line 147, in get_response
    response = wrapped_callback(request, *callback_args, **callback_kwargs)
  File "/home/jsandoval86/ProjectsDev/Appem/env/local/lib/python2.7/site-packages/django/views/decorators/csrf.py", line 58, in wrapped_view
    return view_func(*args, **kwargs)
  File "/home/jsandoval86/ProjectsDev/Appem/appem/infa_web/apps/m/views.py", line 157, in mArticlesList
    Q(carlos=query) | Q(ncorto__contains=query)
  File "/home/jsandoval86/ProjectsDev/Appem/env/local/lib/python2.7/site-packages/django/db/models/query.py", line 790, in filter
    return self._filter_or_exclude(False, *args, **kwargs)
  File "/home/jsandoval86/ProjectsDev/Appem/env/local/lib/python2.7/site-packages/django/db/models/query.py", line 808, in _filter_or_exclude
    clone.query.add_q(Q(*args, **kwargs))
  File "/home/jsandoval86/ProjectsDev/Appem/env/local/lib/python2.7/site-packages/django/db/models/sql/query.py", line 1243, in add_q
    clause, _ = self._add_q(q_object, self.used_aliases)
  File "/home/jsandoval86/ProjectsDev/Appem/env/local/lib/python2.7/site-packages/django/db/models/sql/query.py", line 1263, in _add_q
    current_negated, allow_joins, split_subq)
  File "/home/jsandoval86/ProjectsDev/Appem/env/local/lib/python2.7/site-packages/django/db/models/sql/query.py", line 1269, in _add_q
    allow_joins=allow_joins, split_subq=split_subq,
  File "/home/jsandoval86/ProjectsDev/Appem/env/local/lib/python2.7/site-packages/django/db/models/sql/query.py", line 1203, in build_filter
    condition = self.build_lookup(lookups, col, value)
  File "/home/jsandoval86/ProjectsDev/Appem/env/local/lib/python2.7/site-packages/django/db/models/sql/query.py", line 1099, in build_lookup
    return final_lookup(lhs, rhs)
  File "/home/jsandoval86/ProjectsDev/Appem/env/local/lib/python2.7/site-packages/django/db/models/lookups.py", line 19, in __init__
    self.rhs = self.get_prep_lookup()
  File "/home/jsandoval86/ProjectsDev/Appem/env/local/lib/python2.7/site-packages/django/db/models/lookups.py", line 57, in get_prep_lookup
    return self.lhs.output_field.get_prep_lookup(self.lookup_name, self.rhs)
  File "/home/jsandoval86/ProjectsDev/Appem/env/local/lib/python2.7/site-packages/django/db/models/fields/__init__.py", line 1860, in get_prep_lookup
    return super(IntegerField, self).get_prep_lookup(lookup_type, value)
  File "/home/jsandoval86/ProjectsDev/Appem/env/local/lib/python2.7/site-packages/django/db/models/fields/__init__.py", line 744, in get_prep_lookup
    return self.get_prep_value(value)
  File "/home/jsandoval86/ProjectsDev/Appem/env/local/lib/python2.7/site-packages/django/db/models/fields/__init__.py", line 1854, in get_prep_value
    return int(value)
ValueError: invalid literal for int() with base 10: 'motoro'
.-.-.-.-.-.-.-.-.-.-.-.-.-.-.-.-.-.-.-.-.-.-.-.-.-.-.-.-.-.-.-.-.-.-.-.-.-.-.-.- 
 ERROR 2016-10-25 09:51:42,702 base 10369 140519889377024 Internal Server Error: /m/articles/list 
Traceback (most recent call last):
  File "/home/jsandoval86/ProjectsDev/Appem/env/local/lib/python2.7/site-packages/django/core/handlers/base.py", line 149, in get_response
    response = self.process_exception_by_middleware(e, request)
  File "/home/jsandoval86/ProjectsDev/Appem/env/local/lib/python2.7/site-packages/django/core/handlers/base.py", line 147, in get_response
    response = wrapped_callback(request, *callback_args, **callback_kwargs)
  File "/home/jsandoval86/ProjectsDev/Appem/env/local/lib/python2.7/site-packages/django/views/decorators/csrf.py", line 58, in wrapped_view
    return view_func(*args, **kwargs)
  File "/home/jsandoval86/ProjectsDev/Appem/appem/infa_web/apps/m/views.py", line 157, in mArticlesList
    Q(carlos=query) | Q(ncorto__contains=query)
  File "/home/jsandoval86/ProjectsDev/Appem/env/local/lib/python2.7/site-packages/django/db/models/query.py", line 790, in filter
    return self._filter_or_exclude(False, *args, **kwargs)
  File "/home/jsandoval86/ProjectsDev/Appem/env/local/lib/python2.7/site-packages/django/db/models/query.py", line 808, in _filter_or_exclude
    clone.query.add_q(Q(*args, **kwargs))
  File "/home/jsandoval86/ProjectsDev/Appem/env/local/lib/python2.7/site-packages/django/db/models/sql/query.py", line 1243, in add_q
    clause, _ = self._add_q(q_object, self.used_aliases)
  File "/home/jsandoval86/ProjectsDev/Appem/env/local/lib/python2.7/site-packages/django/db/models/sql/query.py", line 1263, in _add_q
    current_negated, allow_joins, split_subq)
  File "/home/jsandoval86/ProjectsDev/Appem/env/local/lib/python2.7/site-packages/django/db/models/sql/query.py", line 1269, in _add_q
    allow_joins=allow_joins, split_subq=split_subq,
  File "/home/jsandoval86/ProjectsDev/Appem/env/local/lib/python2.7/site-packages/django/db/models/sql/query.py", line 1203, in build_filter
    condition = self.build_lookup(lookups, col, value)
  File "/home/jsandoval86/ProjectsDev/Appem/env/local/lib/python2.7/site-packages/django/db/models/sql/query.py", line 1099, in build_lookup
    return final_lookup(lhs, rhs)
  File "/home/jsandoval86/ProjectsDev/Appem/env/local/lib/python2.7/site-packages/django/db/models/lookups.py", line 19, in __init__
    self.rhs = self.get_prep_lookup()
  File "/home/jsandoval86/ProjectsDev/Appem/env/local/lib/python2.7/site-packages/django/db/models/lookups.py", line 57, in get_prep_lookup
    return self.lhs.output_field.get_prep_lookup(self.lookup_name, self.rhs)
  File "/home/jsandoval86/ProjectsDev/Appem/env/local/lib/python2.7/site-packages/django/db/models/fields/__init__.py", line 1860, in get_prep_lookup
    return super(IntegerField, self).get_prep_lookup(lookup_type, value)
  File "/home/jsandoval86/ProjectsDev/Appem/env/local/lib/python2.7/site-packages/django/db/models/fields/__init__.py", line 744, in get_prep_lookup
    return self.get_prep_value(value)
  File "/home/jsandoval86/ProjectsDev/Appem/env/local/lib/python2.7/site-packages/django/db/models/fields/__init__.py", line 1854, in get_prep_value
    return int(value)
ValueError: invalid literal for int() with base 10: 'motor'
.-.-.-.-.-.-.-.-.-.-.-.-.-.-.-.-.-.-.-.-.-.-.-.-.-.-.-.-.-.-.-.-.-.-.-.-.-.-.-.- 
 ERROR 2016-10-25 10:03:06,872 base 10899 139857132615424 Internal Server Error: /bill/save/ 
Traceback (most recent call last):
  File "/home/jsandoval86/ProjectsDev/Appem/env/local/lib/python2.7/site-packages/django/core/handlers/base.py", line 149, in get_response
    response = self.process_exception_by_middleware(e, request)
  File "/home/jsandoval86/ProjectsDev/Appem/env/local/lib/python2.7/site-packages/django/core/handlers/base.py", line 147, in get_response
    response = wrapped_callback(request, *callback_args, **callback_kwargs)
  File "/home/jsandoval86/ProjectsDev/Appem/env/local/lib/python2.7/site-packages/django/views/decorators/csrf.py", line 58, in wrapped_view
    return view_func(*args, **kwargs)
  File "/home/jsandoval86/ProjectsDev/Appem/appem/infa_web/apps/facturacion/views.py", line 299, in BillSave
    data['femi'] = data['femi'] + " " + today.strftime("%H:%M:%S")
KeyError: 'femi'
=======
  File "/home/midas/Documentos/infa_web_folder/InfaWeb/infa_web/apps/base/views.py", line 158, in ParametersList
    return render_to_response("parametros/parameters.html",context)
  File "/home/midas/Documentos/infa_web_folder/dev_env/local/lib/python2.7/site-packages/django/shortcuts.py", line 39, in render_to_response
    content = loader.render_to_string(template_name, context, using=using)
  File "/home/midas/Documentos/infa_web_folder/dev_env/local/lib/python2.7/site-packages/django/template/loader.py", line 96, in render_to_string
    template = get_template(template_name, using=using)
  File "/home/midas/Documentos/infa_web_folder/dev_env/local/lib/python2.7/site-packages/django/template/loader.py", line 26, in get_template
    engines = _engine_list(using)
  File "/home/midas/Documentos/infa_web_folder/dev_env/local/lib/python2.7/site-packages/django/template/loader.py", line 143, in _engine_list
    return engines.all() if using is None else [engines[using]]
  File "/home/midas/Documentos/infa_web_folder/dev_env/local/lib/python2.7/site-packages/django/template/utils.py", line 110, in all
    return [self[alias] for alias in self]
  File "/home/midas/Documentos/infa_web_folder/dev_env/local/lib/python2.7/site-packages/django/template/utils.py", line 101, in __getitem__
    engine = engine_cls(params)
  File "/home/midas/Documentos/infa_web_folder/dev_env/local/lib/python2.7/site-packages/django/template/backends/django.py", line 31, in __init__
    options['libraries'] = self.get_templatetag_libraries(libraries)
  File "/home/midas/Documentos/infa_web_folder/dev_env/local/lib/python2.7/site-packages/django/template/backends/django.py", line 49, in get_templatetag_libraries
    libraries = get_installed_libraries()
  File "/home/midas/Documentos/infa_web_folder/dev_env/local/lib/python2.7/site-packages/django/template/backends/django.py", line 142, in get_installed_libraries
    for name in get_package_libraries(pkg):
  File "/home/midas/Documentos/infa_web_folder/dev_env/local/lib/python2.7/site-packages/django/template/backends/django.py", line 155, in get_package_libraries
    module = import_module(entry[1])
  File "/usr/lib/python2.7/importlib/__init__.py", line 37, in import_module
    __import__(name)
  File "/home/midas/Documentos/infa_web_folder/InfaWeb/infa_web/apps/base/templatetags/tags_appem.py", line 3, in <module>
    register = template.Library()
NameError: name 'template' is not defined
>>>>>>> efae654f4b16b2de233d66921eb420a6663121af
