.-.-.-.-.-.-.-.-.-.-.-.-.-.-.-.-.-.-.-.-.-.-.-.-.-.-.-.-.-.-.-.-.-.-.-.-.-.-.-.- 
 ERROR 2016-10-18 09:26:48,123 base 10579 139886465967872 Internal Server Error: /bill/reports/fn/ventas_formas_pago 
Traceback (most recent call last):
  File "/home/midas/Documentos/infa_web_folder/dev_env/local/lib/python2.7/site-packages/django/core/handlers/base.py", line 149, in get_response
    response = self.process_exception_by_middleware(e, request)
  File "/home/midas/Documentos/infa_web_folder/dev_env/local/lib/python2.7/site-packages/django/core/handlers/base.py", line 147, in get_response
    response = wrapped_callback(request, *callback_args, **callback_kwargs)
  File "/home/midas/Documentos/infa_web_folder/dev_env/local/lib/python2.7/site-packages/django/views/generic/base.py", line 68, in view
    return self.dispatch(request, *args, **kwargs)
  File "/home/midas/Documentos/infa_web_folder/dev_env/local/lib/python2.7/site-packages/django/views/generic/base.py", line 88, in dispatch
    return handler(request, *args, **kwargs)
  File "/home/midas/Documentos/infa_web_folder/dev_env/local/lib/python2.7/site-packages/easy_pdf/views.py", line 80, in get
    context = self.get_context_data(**kwargs)
  File "/home/midas/Documentos/infa_web_folder/InfaWeb/infa_web/apps/facturacion/views.py", line 1010, in get_context_data
    context = super(report_fn_bill, self).get_context_data(**kwargs)
TypeError: super(type, obj): obj must be an instance or subtype of type
.-.-.-.-.-.-.-.-.-.-.-.-.-.-.-.-.-.-.-.-.-.-.-.-.-.-.-.-.-.-.-.-.-.-.-.-.-.-.-.- 
 ERROR 2016-10-18 14:54:55,084 base 5295 139898638747456 Internal Server Error: /bill/save/ 
Traceback (most recent call last):
  File "/home/midas/Documentos/infa_web_folder/dev_env/local/lib/python2.7/site-packages/django/core/handlers/base.py", line 149, in get_response
    response = self.process_exception_by_middleware(e, request)
  File "/home/midas/Documentos/infa_web_folder/dev_env/local/lib/python2.7/site-packages/django/core/handlers/base.py", line 147, in get_response
    response = wrapped_callback(request, *callback_args, **callback_kwargs)
  File "/home/midas/Documentos/infa_web_folder/dev_env/local/lib/python2.7/site-packages/django/views/decorators/csrf.py", line 58, in wrapped_view
    return view_func(*args, **kwargs)
  File "/home/midas/Documentos/infa_web_folder/InfaWeb/infa_web/apps/facturacion/views.py", line 384, in BillSave
    'descri': '-'
  File "/home/midas/Documentos/infa_web_folder/InfaWeb/infa_web/apps/facturacion/views.py", line 126, in save_mvsa
    mvsa.save(using = request_db)
  File "/home/midas/Documentos/infa_web_folder/dev_env/local/lib/python2.7/site-packages/django/db/models/base.py", line 708, in save
    force_update=force_update, update_fields=update_fields)
  File "/home/midas/Documentos/infa_web_folder/dev_env/local/lib/python2.7/site-packages/django/db/models/base.py", line 736, in save_base
    updated = self._save_table(raw, cls, force_insert, force_update, using, update_fields)
  File "/home/midas/Documentos/infa_web_folder/dev_env/local/lib/python2.7/site-packages/django/db/models/base.py", line 820, in _save_table
    result = self._do_insert(cls._base_manager, using, fields, update_pk, raw)
  File "/home/midas/Documentos/infa_web_folder/dev_env/local/lib/python2.7/site-packages/django/db/models/base.py", line 859, in _do_insert
    using=using, raw=raw)
  File "/home/midas/Documentos/infa_web_folder/dev_env/local/lib/python2.7/site-packages/django/db/models/manager.py", line 122, in manager_method
    return getattr(self.get_queryset(), name)(*args, **kwargs)
  File "/home/midas/Documentos/infa_web_folder/dev_env/local/lib/python2.7/site-packages/django/db/models/query.py", line 1039, in _insert
    return query.get_compiler(using=using).execute_sql(return_id)
  File "/home/midas/Documentos/infa_web_folder/dev_env/local/lib/python2.7/site-packages/django/db/models/sql/compiler.py", line 1060, in execute_sql
    cursor.execute(sql, params)
  File "/home/midas/Documentos/infa_web_folder/dev_env/local/lib/python2.7/site-packages/django/db/backends/utils.py", line 64, in execute
    return self.cursor.execute(sql, params)
  File "/home/midas/Documentos/infa_web_folder/dev_env/local/lib/python2.7/site-packages/django/db/utils.py", line 95, in __exit__
    six.reraise(dj_exc_type, dj_exc_value, traceback)
  File "/home/midas/Documentos/infa_web_folder/dev_env/local/lib/python2.7/site-packages/django/db/backends/utils.py", line 64, in execute
    return self.cursor.execute(sql, params)
IntegrityError: duplicate key value violates unique constraint "movimientos_mvsa_pkey"
DETAIL:  Key (cmvsa)=(1) already exists.

.-.-.-.-.-.-.-.-.-.-.-.-.-.-.-.-.-.-.-.-.-.-.-.-.-.-.-.-.-.-.-.-.-.-.-.-.-.-.-.- 
 ERROR 2016-10-19 09:35:14,075 base 8745 140019904677632 Internal Server Error: /bill/save/ 
Traceback (most recent call last):
  File "/home/midas/Documentos/infa_web_folder/dev_env/local/lib/python2.7/site-packages/django/core/handlers/base.py", line 149, in get_response
    response = self.process_exception_by_middleware(e, request)
  File "/home/midas/Documentos/infa_web_folder/dev_env/local/lib/python2.7/site-packages/django/core/handlers/base.py", line 147, in get_response
    response = wrapped_callback(request, *callback_args, **callback_kwargs)
  File "/home/midas/Documentos/infa_web_folder/dev_env/local/lib/python2.7/site-packages/django/views/decorators/csrf.py", line 58, in wrapped_view
    return view_func(*args, **kwargs)
  File "/home/midas/Documentos/infa_web_folder/InfaWeb/infa_web/apps/facturacion/views.py", line 325, in BillSave
    value_vttotal = float(data['vttotal'])
ValueError: could not convert string to float: %24+11%2C000
.-.-.-.-.-.-.-.-.-.-.-.-.-.-.-.-.-.-.-.-.-.-.-.-.-.-.-.-.-.-.-.-.-.-.-.-.-.-.-.- 
 ERROR 2016-10-19 10:31:41,572 base 11482 140653840799552 Internal Server Error: /bill/save/ 
Traceback (most recent call last):
  File "/home/midas/Documentos/infa_web_folder/dev_env/local/lib/python2.7/site-packages/django/core/handlers/base.py", line 149, in get_response
    response = self.process_exception_by_middleware(e, request)
  File "/home/midas/Documentos/infa_web_folder/dev_env/local/lib/python2.7/site-packages/django/core/handlers/base.py", line 147, in get_response
    response = wrapped_callback(request, *callback_args, **callback_kwargs)
  File "/home/midas/Documentos/infa_web_folder/dev_env/local/lib/python2.7/site-packages/django/views/decorators/csrf.py", line 58, in wrapped_view
    return view_func(*args, **kwargs)
  File "/home/midas/Documentos/infa_web_folder/InfaWeb/infa_web/apps/facturacion/views.py", line 429, in BillSave
    banmpago = Banfopa.objects.using(request.db).get(pk = data_facpago['banmpago'])
  File "/home/midas/Documentos/infa_web_folder/dev_env/local/lib/python2.7/site-packages/django/db/models/query.py", line 387, in get
    self.model._meta.object_name
DoesNotExist: Banfopa matching query does not exist.
.-.-.-.-.-.-.-.-.-.-.-.-.-.-.-.-.-.-.-.-.-.-.-.-.-.-.-.-.-.-.-.-.-.-.-.-.-.-.-.- 
 ERROR 2016-10-19 10:33:22,156 base 11508 140661877729088 Internal Server Error: /bill/save/ 
Traceback (most recent call last):
  File "/home/midas/Documentos/infa_web_folder/dev_env/local/lib/python2.7/site-packages/django/core/handlers/base.py", line 149, in get_response
    response = self.process_exception_by_middleware(e, request)
  File "/home/midas/Documentos/infa_web_folder/dev_env/local/lib/python2.7/site-packages/django/core/handlers/base.py", line 147, in get_response
    response = wrapped_callback(request, *callback_args, **callback_kwargs)
  File "/home/midas/Documentos/infa_web_folder/dev_env/local/lib/python2.7/site-packages/django/views/decorators/csrf.py", line 58, in wrapped_view
    return view_func(*args, **kwargs)
  File "/home/midas/Documentos/infa_web_folder/InfaWeb/infa_web/apps/facturacion/views.py", line 429, in BillSave
    banmpago = Banfopa.objects.using(request.db).get(pk = data_facpago['banmpago'])
  File "/home/midas/Documentos/infa_web_folder/dev_env/local/lib/python2.7/site-packages/django/db/models/query.py", line 387, in get
    self.model._meta.object_name
DoesNotExist: Banfopa matching query does not exist.
.-.-.-.-.-.-.-.-.-.-.-.-.-.-.-.-.-.-.-.-.-.-.-.-.-.-.-.-.-.-.-.-.-.-.-.-.-.-.-.- 
 ERROR 2016-10-19 10:34:31,676 base 11553 140600498034496 Internal Server Error: /bill/save/ 
Traceback (most recent call last):
  File "/home/midas/Documentos/infa_web_folder/dev_env/local/lib/python2.7/site-packages/django/core/handlers/base.py", line 149, in get_response
    response = self.process_exception_by_middleware(e, request)
  File "/home/midas/Documentos/infa_web_folder/dev_env/local/lib/python2.7/site-packages/django/core/handlers/base.py", line 147, in get_response
    response = wrapped_callback(request, *callback_args, **callback_kwargs)
  File "/home/midas/Documentos/infa_web_folder/dev_env/local/lib/python2.7/site-packages/django/views/decorators/csrf.py", line 58, in wrapped_view
    return view_func(*args, **kwargs)
  File "/home/midas/Documentos/infa_web_folder/InfaWeb/infa_web/apps/facturacion/views.py", line 486, in BillSave
    carlos = Arlo.objects.using(request.db).get(pk = data_deta['carlos'])
TypeError: list indices must be integers, not str
.-.-.-.-.-.-.-.-.-.-.-.-.-.-.-.-.-.-.-.-.-.-.-.-.-.-.-.-.-.-.-.-.-.-.-.-.-.-.-.- 
 ERROR 2016-10-19 10:37:09,835 base 11707 140434302318400 Internal Server Error: /bill/save/ 
Traceback (most recent call last):
  File "/home/midas/Documentos/infa_web_folder/dev_env/local/lib/python2.7/site-packages/django/core/handlers/base.py", line 149, in get_response
    response = self.process_exception_by_middleware(e, request)
  File "/home/midas/Documentos/infa_web_folder/dev_env/local/lib/python2.7/site-packages/django/core/handlers/base.py", line 147, in get_response
    response = wrapped_callback(request, *callback_args, **callback_kwargs)
  File "/home/midas/Documentos/infa_web_folder/dev_env/local/lib/python2.7/site-packages/django/views/decorators/csrf.py", line 58, in wrapped_view
    return view_func(*args, **kwargs)
  File "/home/midas/Documentos/infa_web_folder/InfaWeb/infa_web/apps/facturacion/views.py", line 487, in BillSave
    civa = Iva.objects.using(request.db).get(pk = data_deta['civa'])
  File "/home/midas/Documentos/infa_web_folder/dev_env/local/lib/python2.7/site-packages/django/db/models/query.py", line 387, in get
    self.model._meta.object_name
DoesNotExist: Iva matching query does not exist.
.-.-.-.-.-.-.-.-.-.-.-.-.-.-.-.-.-.-.-.-.-.-.-.-.-.-.-.-.-.-.-.-.-.-.-.-.-.-.-.- 
 ERROR 2016-10-19 11:14:05,032 base 12924 139722871375680 Internal Server Error: /bill/save/ 
Traceback (most recent call last):
  File "/home/midas/Documentos/infa_web_folder/dev_env/local/lib/python2.7/site-packages/django/core/handlers/base.py", line 149, in get_response
    response = self.process_exception_by_middleware(e, request)
  File "/home/midas/Documentos/infa_web_folder/dev_env/local/lib/python2.7/site-packages/django/core/handlers/base.py", line 147, in get_response
    response = wrapped_callback(request, *callback_args, **callback_kwargs)
  File "/home/midas/Documentos/infa_web_folder/dev_env/local/lib/python2.7/site-packages/django/views/decorators/csrf.py", line 58, in wrapped_view
    return view_func(*args, **kwargs)
  File "/home/midas/Documentos/infa_web_folder/InfaWeb/infa_web/apps/facturacion/views.py", line 528, in BillSave
    response["fac"] = json.dumps(fac)
  File "/usr/lib/python2.7/json/__init__.py", line 243, in dumps
    return _default_encoder.encode(obj)
  File "/usr/lib/python2.7/json/encoder.py", line 207, in encode
    chunks = self.iterencode(o, _one_shot=True)
  File "/usr/lib/python2.7/json/encoder.py", line 270, in iterencode
    return _iterencode(o, 0)
  File "/usr/lib/python2.7/json/encoder.py", line 184, in default
    raise TypeError(repr(o) + " is not JSON serializable")
TypeError: <Fac: IA00001000> is not JSON serializable
.-.-.-.-.-.-.-.-.-.-.-.-.-.-.-.-.-.-.-.-.-.-.-.-.-.-.-.-.-.-.-.-.-.-.-.-.-.-.-.- 
 ERROR 2016-10-19 11:15:38,051 base 12973 140487374022464 Internal Server Error: /bill/save/ 
Traceback (most recent call last):
  File "/home/midas/Documentos/infa_web_folder/dev_env/local/lib/python2.7/site-packages/django/core/handlers/base.py", line 149, in get_response
    response = self.process_exception_by_middleware(e, request)
  File "/home/midas/Documentos/infa_web_folder/dev_env/local/lib/python2.7/site-packages/django/core/handlers/base.py", line 147, in get_response
    response = wrapped_callback(request, *callback_args, **callback_kwargs)
  File "/home/midas/Documentos/infa_web_folder/dev_env/local/lib/python2.7/site-packages/django/views/decorators/csrf.py", line 58, in wrapped_view
    return view_func(*args, **kwargs)
  File "/home/midas/Documentos/infa_web_folder/InfaWeb/infa_web/apps/facturacion/views.py", line 528, in BillSave
    response["fac"] = serializers.serialize("json", [fac],use_natural_foreign_keys=True, use_natural_primary_keys=True)
  File "/home/midas/Documentos/infa_web_folder/dev_env/local/lib/python2.7/site-packages/django/core/serializers/__init__.py", line 129, in serialize
    s.serialize(queryset, **options)
  File "/home/midas/Documentos/infa_web_folder/dev_env/local/lib/python2.7/site-packages/django/core/serializers/base.py", line 88, in serialize
    self.handle_field(obj, field)
  File "/home/midas/Documentos/infa_web_folder/dev_env/local/lib/python2.7/site-packages/django/core/serializers/python.py", line 55, in handle_field
    self._current[field.name] = field.value_to_string(obj)
  File "/home/midas/Documentos/infa_web_folder/dev_env/local/lib/python2.7/site-packages/django/db/models/fields/__init__.py", line 1466, in value_to_string
    return '' if val is None else val.isoformat()
AttributeError: 'unicode' object has no attribute 'isoformat'
.-.-.-.-.-.-.-.-.-.-.-.-.-.-.-.-.-.-.-.-.-.-.-.-.-.-.-.-.-.-.-.-.-.-.-.-.-.-.-.- 
 ERROR 2016-10-19 11:17:33,365 base 13029 139824955221824 Internal Server Error: /bill/save/ 
Traceback (most recent call last):
  File "/home/midas/Documentos/infa_web_folder/dev_env/local/lib/python2.7/site-packages/django/core/handlers/base.py", line 149, in get_response
    response = self.process_exception_by_middleware(e, request)
  File "/home/midas/Documentos/infa_web_folder/dev_env/local/lib/python2.7/site-packages/django/core/handlers/base.py", line 147, in get_response
    response = wrapped_callback(request, *callback_args, **callback_kwargs)
  File "/home/midas/Documentos/infa_web_folder/dev_env/local/lib/python2.7/site-packages/django/views/decorators/csrf.py", line 58, in wrapped_view
    return view_func(*args, **kwargs)
  File "/home/midas/Documentos/infa_web_folder/InfaWeb/infa_web/apps/facturacion/views.py", line 528, in BillSave
    response["fac"] = serializers.serialize("json", list([fac]),use_natural_foreign_keys=True, use_natural_primary_keys=True)
  File "/home/midas/Documentos/infa_web_folder/dev_env/local/lib/python2.7/site-packages/django/core/serializers/__init__.py", line 129, in serialize
    s.serialize(queryset, **options)
  File "/home/midas/Documentos/infa_web_folder/dev_env/local/lib/python2.7/site-packages/django/core/serializers/base.py", line 88, in serialize
    self.handle_field(obj, field)
  File "/home/midas/Documentos/infa_web_folder/dev_env/local/lib/python2.7/site-packages/django/core/serializers/python.py", line 55, in handle_field
    self._current[field.name] = field.value_to_string(obj)
  File "/home/midas/Documentos/infa_web_folder/dev_env/local/lib/python2.7/site-packages/django/db/models/fields/__init__.py", line 1466, in value_to_string
    return '' if val is None else val.isoformat()
AttributeError: 'unicode' object has no attribute 'isoformat'
