.-.-.-.-.-.-.-.-.-.-.-.-.-.-.-.-.-.-.-.-.-.-.-.-.-.-.-.-.-.-.-.-.-.-.-.-.-.-.-.- 
 ERROR 2016-10-06 11:37:23,851 base 8584 139849447732992 Internal Server Error: /articles/add/ 
Traceback (most recent call last):
  File "/home/midas/Documentos/infa_web_folder/dev_env/local/lib/python2.7/site-packages/django/core/handlers/base.py", line 123, in get_response
    response = middleware_method(request)
  File "/home/midas/Documentos/infa_web_folder/InfaWeb/infa_web/apps/base/middleware.py", line 10, in process_request
    manageParameters = ManageParameters(request.db)
AttributeError: 'WSGIRequest' object has no attribute 'db'
.-.-.-.-.-.-.-.-.-.-.-.-.-.-.-.-.-.-.-.-.-.-.-.-.-.-.-.-.-.-.-.-.-.-.-.-.-.-.-.- 
 ERROR 2016-10-06 11:38:03,888 base 8622 139640124208896 Internal Server Error: /articles/add/ 
Traceback (most recent call last):
  File "/home/midas/Documentos/infa_web_folder/dev_env/local/lib/python2.7/site-packages/django/core/handlers/base.py", line 123, in get_response
    response = middleware_method(request)
  File "/home/midas/Documentos/infa_web_folder/InfaWeb/infa_web/apps/base/middleware.py", line 45, in process_request
    manageParameters = ManageParameters(request.db)
AttributeError: 'WSGIRequest' object has no attribute 'db'
.-.-.-.-.-.-.-.-.-.-.-.-.-.-.-.-.-.-.-.-.-.-.-.-.-.-.-.-.-.-.-.-.-.-.-.-.-.-.-.- 
 ERROR 2016-10-06 11:38:06,159 base 8622 139640124208896 Internal Server Error: /articles/add/ 
Traceback (most recent call last):
  File "/home/midas/Documentos/infa_web_folder/dev_env/local/lib/python2.7/site-packages/django/core/handlers/base.py", line 123, in get_response
    response = middleware_method(request)
  File "/home/midas/Documentos/infa_web_folder/InfaWeb/infa_web/apps/base/middleware.py", line 45, in process_request
    manageParameters = ManageParameters(request.db)
AttributeError: 'WSGIRequest' object has no attribute 'db'
.-.-.-.-.-.-.-.-.-.-.-.-.-.-.-.-.-.-.-.-.-.-.-.-.-.-.-.-.-.-.-.-.-.-.-.-.-.-.-.- 
 ERROR 2016-10-06 11:46:32,059 base 9326 139629493577472 Internal Server Error: /parameters/ 
Traceback (most recent call last):
  File "/home/midas/Documentos/infa_web_folder/dev_env/local/lib/python2.7/site-packages/django/core/handlers/base.py", line 123, in get_response
    response = middleware_method(request)
  File "/home/midas/Documentos/infa_web_folder/InfaWeb/infa_web/apps/base/middleware.py", line 9, in process_request
    manageParameters = ManageParameters(request.db)
  File "/home/midas/Documentos/infa_web_folder/InfaWeb/infa_web/parameters.py", line 21, in __init__
    "Missing file params"
ImproperlyConfigured: Missing file params
.-.-.-.-.-.-.-.-.-.-.-.-.-.-.-.-.-.-.-.-.-.-.-.-.-.-.-.-.-.-.-.-.-.-.-.-.-.-.-.- 
 ERROR 2016-10-06 11:48:48,260 base 9427 140580614842112 Internal Server Error: /parameters/ 
Traceback (most recent call last):
  File "/home/midas/Documentos/infa_web_folder/dev_env/local/lib/python2.7/site-packages/django/core/handlers/base.py", line 123, in get_response
    response = middleware_method(request)
  File "/home/midas/Documentos/infa_web_folder/InfaWeb/infa_web/apps/base/middleware.py", line 9, in process_request
    manageParameters = ManageParameters(request.db)
  File "/home/midas/Documentos/infa_web_folder/InfaWeb/infa_web/parameters.py", line 22, in __init__
    "Missing file params. subdomain: %s - db: %s. path %s " % (subdomain,name_db,self.path_file)
ImproperlyConfigured: Missing file params. subdomain: stzef - db: db_1. path /home/midas/Documentos/infa_web_folder/InfaWeb/infa_web/params/db_1_params.json 
.-.-.-.-.-.-.-.-.-.-.-.-.-.-.-.-.-.-.-.-.-.-.-.-.-.-.-.-.-.-.-.-.-.-.-.-.-.-.-.- 
 ERROR 2016-10-06 11:51:18,700 base 9668 140713614382848 Internal Server Error: /parameters/ 
Traceback (most recent call last):
  File "/home/midas/Documentos/infa_web_folder/dev_env/local/lib/python2.7/site-packages/django/core/handlers/base.py", line 123, in get_response
    response = middleware_method(request)
  File "/home/midas/Documentos/infa_web_folder/InfaWeb/infa_web/apps/base/middleware.py", line 9, in process_request
    manageParameters = ManageParameters(request.db)
  File "/home/midas/Documentos/infa_web_folder/InfaWeb/infa_web/parameters.py", line 22, in __init__
    "Missing file params. \n Subdomain: %s \n db: %s \n path %s " % (subdomain,name_db,self.path_file)
ImproperlyConfigured: Missing file params. 
 Subdomain: stzef 
 db: db_1 path /home/midas/Documentos/infa_web_folder/InfaWeb/infa_web/params/db_1_params.json 
.-.-.-.-.-.-.-.-.-.-.-.-.-.-.-.-.-.-.-.-.-.-.-.-.-.-.-.-.-.-.-.-.-.-.-.-.-.-.-.- 
 ERROR 2016-10-06 11:51:37,800 base 9690 139644185958144 Internal Server Error: /parameters/ 
Traceback (most recent call last):
  File "/home/midas/Documentos/infa_web_folder/dev_env/local/lib/python2.7/site-packages/django/core/handlers/base.py", line 123, in get_response
    response = middleware_method(request)
  File "/home/midas/Documentos/infa_web_folder/InfaWeb/infa_web/apps/base/middleware.py", line 9, in process_request
    manageParameters = ManageParameters(request.db)
  File "/home/midas/Documentos/infa_web_folder/InfaWeb/infa_web/parameters.py", line 22, in __init__
    "Missing file params. \nSubdomain: %s \ndb: %s \npath %s " % (subdomain,name_db,self.path_file)
ImproperlyConfigured: Missing file params. 
Subdomain: stzef 
db: db_1 
path /home/midas/Documentos/infa_web_folder/InfaWeb/infa_web/params/db_1_params.json 
.-.-.-.-.-.-.-.-.-.-.-.-.-.-.-.-.-.-.-.-.-.-.-.-.-.-.-.-.-.-.-.-.-.-.-.-.-.-.-.- 
 ERROR 2016-10-06 11:52:00,525 base 9709 140229931800320 Internal Server Error: /parameters/ 
Traceback (most recent call last):
  File "/home/midas/Documentos/infa_web_folder/dev_env/local/lib/python2.7/site-packages/django/core/handlers/base.py", line 123, in get_response
    response = middleware_method(request)
  File "/home/midas/Documentos/infa_web_folder/InfaWeb/infa_web/apps/base/middleware.py", line 9, in process_request
    manageParameters = ManageParameters(request.db)
  File "/home/midas/Documentos/infa_web_folder/InfaWeb/infa_web/parameters.py", line 22, in __init__
    "Missing file params. \nSubdomain : %s \ndb : %s \npath : %s " % (subdomain,name_db,self.path_file)
ImproperlyConfigured: Missing file params. 
Subdomain : stzef 
db : db_1 
path : /home/midas/Documentos/infa_web_folder/InfaWeb/infa_web/params/db_1_params.json 
.-.-.-.-.-.-.-.-.-.-.-.-.-.-.-.-.-.-.-.-.-.-.-.-.-.-.-.-.-.-.-.-.-.-.-.-.-.-.-.- 
 ERROR 2016-10-06 11:52:18,007 base 9751 139920889849600 Internal Server Error: /parameters/ 
Traceback (most recent call last):
  File "/home/midas/Documentos/infa_web_folder/dev_env/local/lib/python2.7/site-packages/django/core/handlers/base.py", line 123, in get_response
    response = middleware_method(request)
  File "/home/midas/Documentos/infa_web_folder/InfaWeb/infa_web/apps/base/middleware.py", line 9, in process_request
    manageParameters = ManageParameters(request.db)
  File "/home/midas/Documentos/infa_web_folder/InfaWeb/infa_web/parameters.py", line 22, in __init__
    "Missing File Parameters. \nSubdomain : %s \ndb : %s \npath : %s " % (subdomain,name_db,self.path_file)
ImproperlyConfigured: Missing File Parameters. 
Subdomain : stzef 
db : db_1 
path : /home/midas/Documentos/infa_web_folder/InfaWeb/infa_web/params/db_1_params.json 
.-.-.-.-.-.-.-.-.-.-.-.-.-.-.-.-.-.-.-.-.-.-.-.-.-.-.-.-.-.-.-.-.-.-.-.-.-.-.-.- 
 ERROR 2016-10-06 11:52:29,539 base 9770 140221410457344 Internal Server Error: /parameters/ 
Traceback (most recent call last):
  File "/home/midas/Documentos/infa_web_folder/dev_env/local/lib/python2.7/site-packages/django/core/handlers/base.py", line 123, in get_response
    response = middleware_method(request)
  File "/home/midas/Documentos/infa_web_folder/InfaWeb/infa_web/apps/base/middleware.py", line 9, in process_request
    manageParameters = ManageParameters(request.db)
  File "/home/midas/Documentos/infa_web_folder/InfaWeb/infa_web/parameters.py", line 22, in __init__
    "Missing File Parameters. \nSubdomain : %s \Database : %s \npath : %s " % (subdomain,name_db,self.path_file)
ImproperlyConfigured: Missing File Parameters. 
Subdomain : stzef \Database : db_1 
path : /home/midas/Documentos/infa_web_folder/InfaWeb/infa_web/params/db_1_params.json 
.-.-.-.-.-.-.-.-.-.-.-.-.-.-.-.-.-.-.-.-.-.-.-.-.-.-.-.-.-.-.-.-.-.-.-.-.-.-.-.- 
 ERROR 2016-10-06 11:52:37,606 base 9791 140343526082304 Internal Server Error: /parameters/ 
Traceback (most recent call last):
  File "/home/midas/Documentos/infa_web_folder/dev_env/local/lib/python2.7/site-packages/django/core/handlers/base.py", line 123, in get_response
    response = middleware_method(request)
  File "/home/midas/Documentos/infa_web_folder/InfaWeb/infa_web/apps/base/middleware.py", line 9, in process_request
    manageParameters = ManageParameters(request.db)
  File "/home/midas/Documentos/infa_web_folder/InfaWeb/infa_web/parameters.py", line 22, in __init__
    "Missing File Parameters. \nSubdomain : %s \nDatabase : %s \npath : %s " % (subdomain,name_db,self.path_file)
ImproperlyConfigured: Missing File Parameters. 
Subdomain : stzef 
Database : db_1 
path : /home/midas/Documentos/infa_web_folder/InfaWeb/infa_web/params/db_1_params.json 
.-.-.-.-.-.-.-.-.-.-.-.-.-.-.-.-.-.-.-.-.-.-.-.-.-.-.-.-.-.-.-.-.-.-.-.-.-.-.-.- 
 ERROR 2016-10-06 11:52:46,282 base 9814 140208442271488 Internal Server Error: /parameters/ 
Traceback (most recent call last):
  File "/home/midas/Documentos/infa_web_folder/dev_env/local/lib/python2.7/site-packages/django/core/handlers/base.py", line 123, in get_response
    response = middleware_method(request)
  File "/home/midas/Documentos/infa_web_folder/InfaWeb/infa_web/apps/base/middleware.py", line 9, in process_request
    manageParameters = ManageParameters(request.db)
  File "/home/midas/Documentos/infa_web_folder/InfaWeb/infa_web/parameters.py", line 22, in __init__
    "Missing File Parameters. \nSubdomain : %s \nDatabase : %s \nPath : %s " % (subdomain,name_db,self.path_file)
ImproperlyConfigured: Missing File Parameters. 
Subdomain : stzef 
Database : db_1 
Path : /home/midas/Documentos/infa_web_folder/InfaWeb/infa_web/params/db_1_params.json 
.-.-.-.-.-.-.-.-.-.-.-.-.-.-.-.-.-.-.-.-.-.-.-.-.-.-.-.-.-.-.-.-.-.-.-.-.-.-.-.- 
 ERROR 2016-10-06 14:41:00,291 base 4440 139931032741632 Internal Server Error: /inventory/stocks/report/ 
Traceback (most recent call last):
  File "/home/midas/Documentos/infa_web_folder/dev_env/local/lib/python2.7/site-packages/django/core/handlers/base.py", line 149, in get_response
    response = self.process_exception_by_middleware(e, request)
  File "/home/midas/Documentos/infa_web_folder/dev_env/local/lib/python2.7/site-packages/django/core/handlers/base.py", line 147, in get_response
    response = wrapped_callback(request, *callback_args, **callback_kwargs)
  File "/home/midas/Documentos/infa_web_folder/dev_env/local/lib/python2.7/site-packages/django/contrib/auth/decorators.py", line 23, in _wrapped_view
    return view_func(request, *args, **kwargs)
  File "/home/midas/Documentos/infa_web_folder/dev_env/local/lib/python2.7/site-packages/django/views/generic/base.py", line 68, in view
    return self.dispatch(request, *args, **kwargs)
  File "/home/midas/Documentos/infa_web_folder/dev_env/local/lib/python2.7/site-packages/django/views/generic/base.py", line 88, in dispatch
    return handler(request, *args, **kwargs)
  File "/home/midas/Documentos/infa_web_folder/dev_env/local/lib/python2.7/site-packages/django/views/generic/edit.py", line 213, in get
    return self.render_to_response(self.get_context_data())
  File "/home/midas/Documentos/infa_web_folder/InfaWeb/infa_web/apps/inventarios/views.py", line 309, in get_context_data
    context = super(InventoryReportStocks, self).get_context_data(**kwargs)
  File "/home/midas/Documentos/infa_web_folder/dev_env/local/lib/python2.7/site-packages/django/views/generic/edit.py", line 122, in get_context_data
    kwargs['form'] = self.get_form()
  File "/home/midas/Documentos/infa_web_folder/dev_env/local/lib/python2.7/site-packages/django/views/generic/edit.py", line 74, in get_form
    return form_class(**self.get_form_kwargs())
  File "/home/midas/Documentos/infa_web_folder/InfaWeb/infa_web/apps/inventarios/forms.py", line 29, in __init__
    manageParameters = ManageParameters(name_db)
  File "/home/midas/Documentos/infa_web_folder/InfaWeb/infa_web/parameters.py", line 21, in __init__
    "Missing File Parameters. \nSubdomain : %s \nDatabase : %s \nPath : %s " % (subdomain,name_db,self.path_file)
ImproperlyConfigured: Missing File Parameters. 
Subdomain :  
Database :  
Path : /home/midas/Documentos/infa_web_folder/InfaWeb/infa_web/params/_params.json 
.-.-.-.-.-.-.-.-.-.-.-.-.-.-.-.-.-.-.-.-.-.-.-.-.-.-.-.-.-.-.-.-.-.-.-.-.-.-.-.- 
 ERROR 2016-10-06 15:01:27,875 base 5887 139680884434688 Internal Server Error: /third-parties/add/ 
Traceback (most recent call last):
  File "/home/midas/Documentos/infa_web_folder/dev_env/local/lib/python2.7/site-packages/django/core/handlers/base.py", line 149, in get_response
    response = self.process_exception_by_middleware(e, request)
  File "/home/midas/Documentos/infa_web_folder/dev_env/local/lib/python2.7/site-packages/django/core/handlers/base.py", line 147, in get_response
    response = wrapped_callback(request, *callback_args, **callback_kwargs)
  File "/home/midas/Documentos/infa_web_folder/dev_env/local/lib/python2.7/site-packages/django/contrib/auth/decorators.py", line 23, in _wrapped_view
    return view_func(request, *args, **kwargs)
  File "/home/midas/Documentos/infa_web_folder/dev_env/local/lib/python2.7/site-packages/django/views/generic/base.py", line 68, in view
    return self.dispatch(request, *args, **kwargs)
  File "/home/midas/Documentos/infa_web_folder/dev_env/local/lib/python2.7/site-packages/django/views/generic/base.py", line 88, in dispatch
    return handler(request, *args, **kwargs)
  File "/home/midas/Documentos/infa_web_folder/dev_env/local/lib/python2.7/site-packages/django/views/generic/edit.py", line 256, in post
    return super(BaseCreateView, self).post(request, *args, **kwargs)
  File "/home/midas/Documentos/infa_web_folder/dev_env/local/lib/python2.7/site-packages/django/views/generic/edit.py", line 222, in post
    return self.form_valid(form)
  File "/home/midas/Documentos/infa_web_folder/InfaWeb/infa_web/apps/base/views.py", line 101, in form_valid
    response = super(AjaxableResponseMixin, self).form_valid(form)
  File "/home/midas/Documentos/infa_web_folder/InfaWeb/infa_web/custom/generic_views.py", line 32, in form_valid
    self.object = obj.save(using=usingAlias)
  File "/home/midas/Documentos/infa_web_folder/dev_env/local/lib/python2.7/site-packages/django/db/models/base.py", line 708, in save
    force_update=force_update, update_fields=update_fields)
  File "/home/midas/Documentos/infa_web_folder/dev_env/local/lib/python2.7/site-packages/django/db/models/base.py", line 736, in save_base
    updated = self._save_table(raw, cls, force_insert, force_update, using, update_fields)
  File "/home/midas/Documentos/infa_web_folder/dev_env/local/lib/python2.7/site-packages/django/db/models/base.py", line 820, in _save_table
    result = self._do_insert(cls._base_manager, using, fields, update_pk, raw)
  File "/home/midas/Documentos/infa_web_folder/dev_env/local/lib/python2.7/site-packages/django/db/models/base.py", line 859, in _do_insert
    using=using, raw=raw)
  File "/home/midas/Documentos/infa_web_folder/dev_env/local/lib/python2.7/site-packages/django/db/models/manager.py", line 122, in manager_method
    return getattr(self.get_queryset(), name)(*args, **kwargs)
  File "/home/midas/Documentos/infa_web_folder/dev_env/local/lib/python2.7/site-packages/django/db/models/query.py", line 1039, in _insert
    return query.get_compiler(using=using).execute_sql(return_id)
  File "/home/midas/Documentos/infa_web_folder/dev_env/local/lib/python2.7/site-packages/django/db/models/sql/compiler.py", line 1060, in execute_sql
    cursor.execute(sql, params)
  File "/home/midas/Documentos/infa_web_folder/dev_env/local/lib/python2.7/site-packages/django/db/backends/utils.py", line 79, in execute
    return super(CursorDebugWrapper, self).execute(sql, params)
  File "/home/midas/Documentos/infa_web_folder/dev_env/local/lib/python2.7/site-packages/django/db/backends/utils.py", line 64, in execute
    return self.cursor.execute(sql, params)
  File "/home/midas/Documentos/infa_web_folder/dev_env/local/lib/python2.7/site-packages/django/db/utils.py", line 95, in __exit__
    six.reraise(dj_exc_type, dj_exc_value, traceback)
  File "/home/midas/Documentos/infa_web_folder/dev_env/local/lib/python2.7/site-packages/django/db/backends/utils.py", line 64, in execute
    return self.cursor.execute(sql, params)
IntegrityError: duplicate key value violates unique constraint "terceros_tercero_pkey"
DETAIL:  Key (citerce)=(1) already exists.

.-.-.-.-.-.-.-.-.-.-.-.-.-.-.-.-.-.-.-.-.-.-.-.-.-.-.-.-.-.-.-.-.-.-.-.-.-.-.-.- 
 ERROR 2016-10-06 15:33:57,152 base 7304 139789760190208 Internal Server Error: /bill/save/ 
Traceback (most recent call last):
  File "/home/midas/Documentos/infa_web_folder/dev_env/local/lib/python2.7/site-packages/django/core/handlers/base.py", line 149, in get_response
    response = self.process_exception_by_middleware(e, request)
  File "/home/midas/Documentos/infa_web_folder/dev_env/local/lib/python2.7/site-packages/django/core/handlers/base.py", line 147, in get_response
    response = wrapped_callback(request, *callback_args, **callback_kwargs)
  File "/home/midas/Documentos/infa_web_folder/dev_env/local/lib/python2.7/site-packages/django/contrib/auth/decorators.py", line 23, in _wrapped_view
    return view_func(request, *args, **kwargs)
  File "/home/midas/Documentos/infa_web_folder/dev_env/local/lib/python2.7/site-packages/django/views/decorators/csrf.py", line 58, in wrapped_view
    return view_func(*args, **kwargs)
  File "/home/midas/Documentos/infa_web_folder/InfaWeb/infa_web/apps/facturacion/views.py", line 123, in BillSave
    mvsa.save(using=request.db)
  File "/home/midas/Documentos/infa_web_folder/dev_env/local/lib/python2.7/site-packages/django/db/models/base.py", line 708, in save
    force_update=force_update, update_fields=update_fields)
  File "/home/midas/Documentos/infa_web_folder/dev_env/local/lib/python2.7/site-packages/django/db/models/base.py", line 736, in save_base
    updated = self._save_table(raw, cls, force_insert, force_update, using, update_fields)
  File "/home/midas/Documentos/infa_web_folder/dev_env/local/lib/python2.7/site-packages/django/db/models/base.py", line 820, in _save_table
    result = self._do_insert(cls._base_manager, using, fields, update_pk, raw)
  File "/home/midas/Documentos/infa_web_folder/dev_env/local/lib/python2.7/site-packages/django/db/models/base.py", line 859, in _do_insert
    using=using, raw=raw)
  File "/home/midas/Documentos/infa_web_folder/dev_env/local/lib/python2.7/site-packages/django/db/models/manager.py", line 122, in manager_method
    return getattr(self.get_queryset(), name)(*args, **kwargs)
  File "/home/midas/Documentos/infa_web_folder/dev_env/local/lib/python2.7/site-packages/django/db/models/query.py", line 1039, in _insert
    return query.get_compiler(using=using).execute_sql(return_id)
  File "/home/midas/Documentos/infa_web_folder/dev_env/local/lib/python2.7/site-packages/django/db/models/sql/compiler.py", line 1060, in execute_sql
    cursor.execute(sql, params)
  File "/home/midas/Documentos/infa_web_folder/dev_env/local/lib/python2.7/site-packages/django/db/backends/utils.py", line 79, in execute
    return super(CursorDebugWrapper, self).execute(sql, params)
  File "/home/midas/Documentos/infa_web_folder/dev_env/local/lib/python2.7/site-packages/django/db/backends/utils.py", line 64, in execute
    return self.cursor.execute(sql, params)
  File "/home/midas/Documentos/infa_web_folder/dev_env/local/lib/python2.7/site-packages/django/db/utils.py", line 95, in __exit__
    six.reraise(dj_exc_type, dj_exc_value, traceback)
  File "/home/midas/Documentos/infa_web_folder/dev_env/local/lib/python2.7/site-packages/django/db/backends/utils.py", line 64, in execute
    return self.cursor.execute(sql, params)
IntegrityError: duplicate key value violates unique constraint "movimientos_mvsa_pkey"
DETAIL:  Key (cmvsa)=(1) already exists.

.-.-.-.-.-.-.-.-.-.-.-.-.-.-.-.-.-.-.-.-.-.-.-.-.-.-.-.-.-.-.-.-.-.-.-.-.-.-.-.- 
 ERROR 2016-10-06 15:34:05,164 base 7304 139789760190208 Internal Server Error: /bill/save/ 
Traceback (most recent call last):
  File "/home/midas/Documentos/infa_web_folder/dev_env/local/lib/python2.7/site-packages/django/core/handlers/base.py", line 149, in get_response
    response = self.process_exception_by_middleware(e, request)
  File "/home/midas/Documentos/infa_web_folder/dev_env/local/lib/python2.7/site-packages/django/core/handlers/base.py", line 147, in get_response
    response = wrapped_callback(request, *callback_args, **callback_kwargs)
  File "/home/midas/Documentos/infa_web_folder/dev_env/local/lib/python2.7/site-packages/django/contrib/auth/decorators.py", line 23, in _wrapped_view
    return view_func(request, *args, **kwargs)
  File "/home/midas/Documentos/infa_web_folder/dev_env/local/lib/python2.7/site-packages/django/views/decorators/csrf.py", line 58, in wrapped_view
    return view_func(*args, **kwargs)
  File "/home/midas/Documentos/infa_web_folder/InfaWeb/infa_web/apps/facturacion/views.py", line 50, in BillSave
    data = json.loads(request.body)
  File "/usr/lib/python2.7/json/__init__.py", line 338, in loads
    return _default_decoder.decode(s)
  File "/usr/lib/python2.7/json/decoder.py", line 366, in decode
    obj, end = self.raw_decode(s, idx=_w(s, 0).end())
  File "/usr/lib/python2.7/json/decoder.py", line 384, in raw_decode
    raise ValueError("No JSON object could be decoded")
ValueError: No JSON object could be decoded
.-.-.-.-.-.-.-.-.-.-.-.-.-.-.-.-.-.-.-.-.-.-.-.-.-.-.-.-.-.-.-.-.-.-.-.-.-.-.-.- 
 ERROR 2016-10-06 15:38:38,116 base 7304 139789735012096 Internal Server Error: /bill/proccess/fn/annulment 
Traceback (most recent call last):
  File "/home/midas/Documentos/infa_web_folder/dev_env/local/lib/python2.7/site-packages/django/core/handlers/base.py", line 149, in get_response
    response = self.process_exception_by_middleware(e, request)
  File "/home/midas/Documentos/infa_web_folder/dev_env/local/lib/python2.7/site-packages/django/core/handlers/base.py", line 147, in get_response
    response = wrapped_callback(request, *callback_args, **callback_kwargs)
  File "/home/midas/Documentos/infa_web_folder/dev_env/local/lib/python2.7/site-packages/django/contrib/auth/decorators.py", line 23, in _wrapped_view
    return view_func(request, *args, **kwargs)
  File "/home/midas/Documentos/infa_web_folder/dev_env/local/lib/python2.7/site-packages/django/views/decorators/csrf.py", line 58, in wrapped_view
    return view_func(*args, **kwargs)
  File "/home/midas/Documentos/infa_web_folder/InfaWeb/infa_web/apps/facturacion/views.py", line 635, in bill_proccess_fn_annulment
    movideta = Movideta.objects.using(request.db).get(docrefe = factura.cfac)
  File "/home/midas/Documentos/infa_web_folder/dev_env/local/lib/python2.7/site-packages/django/db/models/query.py", line 391, in get
    (self.model._meta.object_name, num)
MultipleObjectsReturned: get() returned more than one Movideta -- it returned 2!
.-.-.-.-.-.-.-.-.-.-.-.-.-.-.-.-.-.-.-.-.-.-.-.-.-.-.-.-.-.-.-.-.-.-.-.-.-.-.-.- 
 ERROR 2016-10-06 15:40:00,906 base 8575 139772894160640 Internal Server Error: /bill/proccess/fn/annulment 
Traceback (most recent call last):
  File "/home/midas/Documentos/infa_web_folder/dev_env/local/lib/python2.7/site-packages/django/core/handlers/base.py", line 149, in get_response
    response = self.process_exception_by_middleware(e, request)
  File "/home/midas/Documentos/infa_web_folder/dev_env/local/lib/python2.7/site-packages/django/core/handlers/base.py", line 147, in get_response
    response = wrapped_callback(request, *callback_args, **callback_kwargs)
  File "/home/midas/Documentos/infa_web_folder/dev_env/local/lib/python2.7/site-packages/django/contrib/auth/decorators.py", line 23, in _wrapped_view
    return view_func(request, *args, **kwargs)
  File "/home/midas/Documentos/infa_web_folder/dev_env/local/lib/python2.7/site-packages/django/views/decorators/csrf.py", line 58, in wrapped_view
    return view_func(*args, **kwargs)
  File "/home/midas/Documentos/infa_web_folder/InfaWeb/infa_web/apps/facturacion/views.py", line 635, in bill_proccess_fn_annulment
    movideta = Movideta.objects.using(request.db).get(docrefe = factura.cfac)
  File "/home/midas/Documentos/infa_web_folder/dev_env/local/lib/python2.7/site-packages/django/db/models/query.py", line 391, in get
    (self.model._meta.object_name, num)
MultipleObjectsReturned: get() returned more than one Movideta -- it returned 2!
.-.-.-.-.-.-.-.-.-.-.-.-.-.-.-.-.-.-.-.-.-.-.-.-.-.-.-.-.-.-.-.-.-.-.-.-.-.-.-.- 
 ERROR 2016-10-06 15:42:52,949 base 8785 140377916913408 Internal Server Error: /bill/proccess/fn/annulment 
Traceback (most recent call last):
  File "/home/midas/Documentos/infa_web_folder/dev_env/local/lib/python2.7/site-packages/django/core/handlers/base.py", line 149, in get_response
    response = self.process_exception_by_middleware(e, request)
  File "/home/midas/Documentos/infa_web_folder/dev_env/local/lib/python2.7/site-packages/django/core/handlers/base.py", line 147, in get_response
    response = wrapped_callback(request, *callback_args, **callback_kwargs)
  File "/home/midas/Documentos/infa_web_folder/dev_env/local/lib/python2.7/site-packages/django/contrib/auth/decorators.py", line 23, in _wrapped_view
    return view_func(request, *args, **kwargs)
  File "/home/midas/Documentos/infa_web_folder/dev_env/local/lib/python2.7/site-packages/django/views/decorators/csrf.py", line 58, in wrapped_view
    return view_func(*args, **kwargs)
  File "/home/midas/Documentos/infa_web_folder/InfaWeb/infa_web/apps/facturacion/views.py", line 647, in bill_proccess_fn_annulment
    'esdo_mew' :estado.nesdo
AttributeError: 'dict' object has no attribute 'mvsa'
.-.-.-.-.-.-.-.-.-.-.-.-.-.-.-.-.-.-.-.-.-.-.-.-.-.-.-.-.-.-.-.-.-.-.-.-.-.-.-.- 
 ERROR 2016-10-06 15:43:57,453 base 8883 140081383085824 Internal Server Error: /bill/proccess/fn/annulment 
Traceback (most recent call last):
  File "/home/midas/Documentos/infa_web_folder/dev_env/local/lib/python2.7/site-packages/django/core/handlers/base.py", line 149, in get_response
    response = self.process_exception_by_middleware(e, request)
  File "/home/midas/Documentos/infa_web_folder/dev_env/local/lib/python2.7/site-packages/django/core/handlers/base.py", line 147, in get_response
    response = wrapped_callback(request, *callback_args, **callback_kwargs)
  File "/home/midas/Documentos/infa_web_folder/dev_env/local/lib/python2.7/site-packages/django/contrib/auth/decorators.py", line 23, in _wrapped_view
    return view_func(request, *args, **kwargs)
  File "/home/midas/Documentos/infa_web_folder/dev_env/local/lib/python2.7/site-packages/django/views/decorators/csrf.py", line 58, in wrapped_view
    return view_func(*args, **kwargs)
  File "/home/midas/Documentos/infa_web_folder/InfaWeb/infa_web/apps/facturacion/views.py", line 666, in bill_proccess_fn_annulment
    response.factura.cfac = factura.cfac
AttributeError: 'dict' object has no attribute 'factura'
.-.-.-.-.-.-.-.-.-.-.-.-.-.-.-.-.-.-.-.-.-.-.-.-.-.-.-.-.-.-.-.-.-.-.-.-.-.-.-.- 
 ERROR 2016-10-07 08:04:00,484 base 5226 140125117822720 Internal Server Error: / 
Traceback (most recent call last):
  File "/home/jsandoval86/ProjectsDev/Appem/env/local/lib/python2.7/site-packages/django/core/handlers/base.py", line 123, in get_response
    response = middleware_method(request)
  File "/home/jsandoval86/ProjectsDev/Appem/appem/infa_web/apps/base/middleware.py", line 9, in process_request
    manageParameters = ManageParameters(request.db)
  File "/home/jsandoval86/ProjectsDev/Appem/appem/infa_web/parameters.py", line 21, in __init__
    "Missing File Parameters. \nSubdomain : %s \nDatabase : %s \nPath : %s " % (subdomain,name_db,self.path_file)
ImproperlyConfigured: Missing File Parameters. 
Subdomain : stzef 
Database : db_1 
Path : /home/jsandoval86/ProjectsDev/Appem/appem/infa_web/params/db_1_params.json 
.-.-.-.-.-.-.-.-.-.-.-.-.-.-.-.-.-.-.-.-.-.-.-.-.-.-.-.-.-.-.-.-.-.-.-.-.-.-.-.- 
 ERROR 2016-10-07 08:04:00,863 base 5226 140125109430016 Internal Server Error: /favicon.ico 
Traceback (most recent call last):
  File "/home/jsandoval86/ProjectsDev/Appem/env/local/lib/python2.7/site-packages/django/core/handlers/base.py", line 123, in get_response
    response = middleware_method(request)
  File "/home/jsandoval86/ProjectsDev/Appem/appem/infa_web/apps/base/middleware.py", line 9, in process_request
    manageParameters = ManageParameters(request.db)
  File "/home/jsandoval86/ProjectsDev/Appem/appem/infa_web/parameters.py", line 21, in __init__
    "Missing File Parameters. \nSubdomain : %s \nDatabase : %s \nPath : %s " % (subdomain,name_db,self.path_file)
ImproperlyConfigured: Missing File Parameters. 
Subdomain : stzef 
Database : db_1 
Path : /home/jsandoval86/ProjectsDev/Appem/appem/infa_web/params/db_1_params.json 
.-.-.-.-.-.-.-.-.-.-.-.-.-.-.-.-.-.-.-.-.-.-.-.-.-.-.-.-.-.-.-.-.-.-.-.-.-.-.-.- 
 ERROR 2016-10-07 08:04:11,705 base 5226 140125109430016 Internal Server Error: / 
Traceback (most recent call last):
  File "/home/jsandoval86/ProjectsDev/Appem/env/local/lib/python2.7/site-packages/django/core/handlers/base.py", line 123, in get_response
    response = middleware_method(request)
  File "/home/jsandoval86/ProjectsDev/Appem/appem/infa_web/apps/base/middleware.py", line 9, in process_request
    manageParameters = ManageParameters(request.db)
  File "/home/jsandoval86/ProjectsDev/Appem/appem/infa_web/parameters.py", line 21, in __init__
    "Missing File Parameters. \nSubdomain : %s \nDatabase : %s \nPath : %s " % (subdomain,name_db,self.path_file)
ImproperlyConfigured: Missing File Parameters. 
Subdomain : upc 
Database : default 
Path : /home/jsandoval86/ProjectsDev/Appem/appem/infa_web/params/default_params.json 
.-.-.-.-.-.-.-.-.-.-.-.-.-.-.-.-.-.-.-.-.-.-.-.-.-.-.-.-.-.-.-.-.-.-.-.-.-.-.-.- 
 ERROR 2016-10-07 08:04:11,992 base 5226 140125117822720 Internal Server Error: /favicon.ico 
Traceback (most recent call last):
  File "/home/jsandoval86/ProjectsDev/Appem/env/local/lib/python2.7/site-packages/django/core/handlers/base.py", line 123, in get_response
    response = middleware_method(request)
  File "/home/jsandoval86/ProjectsDev/Appem/appem/infa_web/apps/base/middleware.py", line 9, in process_request
    manageParameters = ManageParameters(request.db)
  File "/home/jsandoval86/ProjectsDev/Appem/appem/infa_web/parameters.py", line 21, in __init__
    "Missing File Parameters. \nSubdomain : %s \nDatabase : %s \nPath : %s " % (subdomain,name_db,self.path_file)
ImproperlyConfigured: Missing File Parameters. 
Subdomain : upc 
Database : default 
Path : /home/jsandoval86/ProjectsDev/Appem/appem/infa_web/params/default_params.json 
.-.-.-.-.-.-.-.-.-.-.-.-.-.-.-.-.-.-.-.-.-.-.-.-.-.-.-.-.-.-.-.-.-.-.-.-.-.-.-.- 
 ERROR 2016-10-07 08:04:18,107 base 5226 140125117822720 Internal Server Error: / 
Traceback (most recent call last):
  File "/home/jsandoval86/ProjectsDev/Appem/env/local/lib/python2.7/site-packages/django/core/handlers/base.py", line 123, in get_response
    response = middleware_method(request)
  File "/home/jsandoval86/ProjectsDev/Appem/appem/infa_web/apps/base/middleware.py", line 9, in process_request
    manageParameters = ManageParameters(request.db)
  File "/home/jsandoval86/ProjectsDev/Appem/appem/infa_web/parameters.py", line 21, in __init__
    "Missing File Parameters. \nSubdomain : %s \nDatabase : %s \nPath : %s " % (subdomain,name_db,self.path_file)
ImproperlyConfigured: Missing File Parameters. 
Subdomain : stzef 
Database : db_1 
Path : /home/jsandoval86/ProjectsDev/Appem/appem/infa_web/params/db_1_params.json 
.-.-.-.-.-.-.-.-.-.-.-.-.-.-.-.-.-.-.-.-.-.-.-.-.-.-.-.-.-.-.-.-.-.-.-.-.-.-.-.- 
 ERROR 2016-10-07 08:04:18,337 base 5226 140125109430016 Internal Server Error: /favicon.ico 
Traceback (most recent call last):
  File "/home/jsandoval86/ProjectsDev/Appem/env/local/lib/python2.7/site-packages/django/core/handlers/base.py", line 123, in get_response
    response = middleware_method(request)
  File "/home/jsandoval86/ProjectsDev/Appem/appem/infa_web/apps/base/middleware.py", line 9, in process_request
    manageParameters = ManageParameters(request.db)
  File "/home/jsandoval86/ProjectsDev/Appem/appem/infa_web/parameters.py", line 21, in __init__
    "Missing File Parameters. \nSubdomain : %s \nDatabase : %s \nPath : %s " % (subdomain,name_db,self.path_file)
ImproperlyConfigured: Missing File Parameters. 
Subdomain : stzef 
Database : db_1 
Path : /home/jsandoval86/ProjectsDev/Appem/appem/infa_web/params/db_1_params.json 
.-.-.-.-.-.-.-.-.-.-.-.-.-.-.-.-.-.-.-.-.-.-.-.-.-.-.-.-.-.-.-.-.-.-.-.-.-.-.-.- 
 ERROR 2016-10-07 08:04:24,921 base 5226 140125099988736 Internal Server Error: /inicio/ 
Traceback (most recent call last):
  File "/home/jsandoval86/ProjectsDev/Appem/env/local/lib/python2.7/site-packages/django/core/handlers/base.py", line 123, in get_response
    response = middleware_method(request)
  File "/home/jsandoval86/ProjectsDev/Appem/appem/infa_web/apps/base/middleware.py", line 9, in process_request
    manageParameters = ManageParameters(request.db)
  File "/home/jsandoval86/ProjectsDev/Appem/appem/infa_web/parameters.py", line 21, in __init__
    "Missing File Parameters. \nSubdomain : %s \nDatabase : %s \nPath : %s " % (subdomain,name_db,self.path_file)
ImproperlyConfigured: Missing File Parameters. 
Subdomain : stzef 
Database : db_1 
Path : /home/jsandoval86/ProjectsDev/Appem/appem/infa_web/params/db_1_params.json 
.-.-.-.-.-.-.-.-.-.-.-.-.-.-.-.-.-.-.-.-.-.-.-.-.-.-.-.-.-.-.-.-.-.-.-.-.-.-.-.- 
 ERROR 2016-10-07 08:04:25,143 base 5226 140125091596032 Internal Server Error: /favicon.ico 
Traceback (most recent call last):
  File "/home/jsandoval86/ProjectsDev/Appem/env/local/lib/python2.7/site-packages/django/core/handlers/base.py", line 123, in get_response
    response = middleware_method(request)
  File "/home/jsandoval86/ProjectsDev/Appem/appem/infa_web/apps/base/middleware.py", line 9, in process_request
    manageParameters = ManageParameters(request.db)
  File "/home/jsandoval86/ProjectsDev/Appem/appem/infa_web/parameters.py", line 21, in __init__
    "Missing File Parameters. \nSubdomain : %s \nDatabase : %s \nPath : %s " % (subdomain,name_db,self.path_file)
ImproperlyConfigured: Missing File Parameters. 
Subdomain : stzef 
Database : db_1 
Path : /home/jsandoval86/ProjectsDev/Appem/appem/infa_web/params/db_1_params.json 
.-.-.-.-.-.-.-.-.-.-.-.-.-.-.-.-.-.-.-.-.-.-.-.-.-.-.-.-.-.-.-.-.-.-.-.-.-.-.-.- 
 ERROR 2016-10-07 08:04:29,807 base 5226 140125109430016 Internal Server Error: / 
Traceback (most recent call last):
  File "/home/jsandoval86/ProjectsDev/Appem/env/local/lib/python2.7/site-packages/django/core/handlers/base.py", line 123, in get_response
    response = middleware_method(request)
  File "/home/jsandoval86/ProjectsDev/Appem/appem/infa_web/apps/base/middleware.py", line 9, in process_request
    manageParameters = ManageParameters(request.db)
  File "/home/jsandoval86/ProjectsDev/Appem/appem/infa_web/parameters.py", line 21, in __init__
    "Missing File Parameters. \nSubdomain : %s \nDatabase : %s \nPath : %s " % (subdomain,name_db,self.path_file)
ImproperlyConfigured: Missing File Parameters. 
Subdomain : stzef 
Database : db_1 
Path : /home/jsandoval86/ProjectsDev/Appem/appem/infa_web/params/db_1_params.json 
.-.-.-.-.-.-.-.-.-.-.-.-.-.-.-.-.-.-.-.-.-.-.-.-.-.-.-.-.-.-.-.-.-.-.-.-.-.-.-.- 
 ERROR 2016-10-07 08:04:30,048 base 5226 140125091596032 Internal Server Error: /favicon.ico 
Traceback (most recent call last):
  File "/home/jsandoval86/ProjectsDev/Appem/env/local/lib/python2.7/site-packages/django/core/handlers/base.py", line 123, in get_response
    response = middleware_method(request)
  File "/home/jsandoval86/ProjectsDev/Appem/appem/infa_web/apps/base/middleware.py", line 9, in process_request
    manageParameters = ManageParameters(request.db)
  File "/home/jsandoval86/ProjectsDev/Appem/appem/infa_web/parameters.py", line 21, in __init__
    "Missing File Parameters. \nSubdomain : %s \nDatabase : %s \nPath : %s " % (subdomain,name_db,self.path_file)
ImproperlyConfigured: Missing File Parameters. 
Subdomain : stzef 
Database : db_1 
Path : /home/jsandoval86/ProjectsDev/Appem/appem/infa_web/params/db_1_params.json 
.-.-.-.-.-.-.-.-.-.-.-.-.-.-.-.-.-.-.-.-.-.-.-.-.-.-.-.-.-.-.-.-.-.-.-.-.-.-.-.- 
 ERROR 2016-10-07 08:05:47,213 base 5226 140125081630464 Internal Server Error: /parameters/ 
Traceback (most recent call last):
  File "/home/jsandoval86/ProjectsDev/Appem/env/local/lib/python2.7/site-packages/django/core/handlers/base.py", line 149, in get_response
    response = self.process_exception_by_middleware(e, request)
  File "/home/jsandoval86/ProjectsDev/Appem/env/local/lib/python2.7/site-packages/django/core/handlers/base.py", line 147, in get_response
    response = wrapped_callback(request, *callback_args, **callback_kwargs)
  File "/home/jsandoval86/ProjectsDev/Appem/env/local/lib/python2.7/site-packages/django/contrib/auth/decorators.py", line 23, in _wrapped_view
    return view_func(request, *args, **kwargs)
  File "/home/jsandoval86/ProjectsDev/Appem/appem/infa_web/apps/base/views.py", line 141, in ParametersList
    for object_db in model.objects.using(request.db).filter(**query):
  File "/home/jsandoval86/ProjectsDev/Appem/env/local/lib/python2.7/site-packages/django/db/models/query.py", line 258, in __iter__
    self._fetch_all()
  File "/home/jsandoval86/ProjectsDev/Appem/env/local/lib/python2.7/site-packages/django/db/models/query.py", line 1074, in _fetch_all
    self._result_cache = list(self.iterator())
  File "/home/jsandoval86/ProjectsDev/Appem/env/local/lib/python2.7/site-packages/django/db/models/query.py", line 52, in __iter__
    results = compiler.execute_sql()
  File "/home/jsandoval86/ProjectsDev/Appem/env/local/lib/python2.7/site-packages/django/db/models/sql/compiler.py", line 846, in execute_sql
    cursor = self.connection.cursor()
  File "/home/jsandoval86/ProjectsDev/Appem/env/local/lib/python2.7/site-packages/django/db/backends/base/base.py", line 231, in cursor
    cursor = self.make_debug_cursor(self._cursor())
  File "/home/jsandoval86/ProjectsDev/Appem/env/local/lib/python2.7/site-packages/django/db/backends/base/base.py", line 204, in _cursor
    self.ensure_connection()
  File "/home/jsandoval86/ProjectsDev/Appem/env/local/lib/python2.7/site-packages/django/db/backends/base/base.py", line 199, in ensure_connection
    self.connect()
  File "/home/jsandoval86/ProjectsDev/Appem/env/local/lib/python2.7/site-packages/django/db/utils.py", line 95, in __exit__
    six.reraise(dj_exc_type, dj_exc_value, traceback)
  File "/home/jsandoval86/ProjectsDev/Appem/env/local/lib/python2.7/site-packages/django/db/backends/base/base.py", line 199, in ensure_connection
    self.connect()
  File "/home/jsandoval86/ProjectsDev/Appem/env/local/lib/python2.7/site-packages/django/db/backends/base/base.py", line 171, in connect
    self.connection = self.get_new_connection(conn_params)
  File "/home/jsandoval86/ProjectsDev/Appem/env/local/lib/python2.7/site-packages/django/db/backends/postgresql/base.py", line 175, in get_new_connection
    connection = Database.connect(**conn_params)
  File "/home/jsandoval86/ProjectsDev/Appem/env/local/lib/python2.7/site-packages/psycopg2/__init__.py", line 164, in connect
    conn = _connect(dsn, connection_factory=connection_factory, async=async)
OperationalError: FATAL:  database "appem_stzef" does not exist

.-.-.-.-.-.-.-.-.-.-.-.-.-.-.-.-.-.-.-.-.-.-.-.-.-.-.-.-.-.-.-.-.-.-.-.-.-.-.-.- 
 ERROR 2016-10-07 08:17:48,900 base 5920 140014767818496 Internal Server Error: /bill/list/ 
Traceback (most recent call last):
  File "/home/jsandoval86/ProjectsDev/Appem/env/local/lib/python2.7/site-packages/django/core/handlers/base.py", line 174, in get_response
    response = self.process_exception_by_middleware(e, request)
  File "/home/jsandoval86/ProjectsDev/Appem/env/local/lib/python2.7/site-packages/django/core/handlers/base.py", line 172, in get_response
    response = response.render()
  File "/home/jsandoval86/ProjectsDev/Appem/env/local/lib/python2.7/site-packages/django/template/response.py", line 160, in render
    self.content = self.rendered_content
  File "/home/jsandoval86/ProjectsDev/Appem/env/local/lib/python2.7/site-packages/django/template/response.py", line 137, in rendered_content
    content = template.render(context, self._request)
  File "/home/jsandoval86/ProjectsDev/Appem/env/local/lib/python2.7/site-packages/django/template/backends/django.py", line 95, in render
    return self.template.render(context)
  File "/home/jsandoval86/ProjectsDev/Appem/env/local/lib/python2.7/site-packages/django/template/base.py", line 206, in render
    return self._render(context)
  File "/home/jsandoval86/ProjectsDev/Appem/env/local/lib/python2.7/site-packages/django/template/base.py", line 197, in _render
    return self.nodelist.render(context)
  File "/home/jsandoval86/ProjectsDev/Appem/env/local/lib/python2.7/site-packages/django/template/base.py", line 992, in render
    bit = node.render_annotated(context)
  File "/home/jsandoval86/ProjectsDev/Appem/env/local/lib/python2.7/site-packages/django/template/base.py", line 959, in render_annotated
    return self.render(context)
  File "/home/jsandoval86/ProjectsDev/Appem/env/local/lib/python2.7/site-packages/django/template/loader_tags.py", line 173, in render
    return compiled_parent._render(context)
  File "/home/jsandoval86/ProjectsDev/Appem/env/local/lib/python2.7/site-packages/django/template/base.py", line 197, in _render
    return self.nodelist.render(context)
  File "/home/jsandoval86/ProjectsDev/Appem/env/local/lib/python2.7/site-packages/django/template/base.py", line 992, in render
    bit = node.render_annotated(context)
  File "/home/jsandoval86/ProjectsDev/Appem/env/local/lib/python2.7/site-packages/django/template/base.py", line 959, in render_annotated
    return self.render(context)
  File "/home/jsandoval86/ProjectsDev/Appem/env/local/lib/python2.7/site-packages/django/template/loader_tags.py", line 69, in render
    result = block.nodelist.render(context)
  File "/home/jsandoval86/ProjectsDev/Appem/env/local/lib/python2.7/site-packages/django/template/base.py", line 992, in render
    bit = node.render_annotated(context)
  File "/home/jsandoval86/ProjectsDev/Appem/env/local/lib/python2.7/site-packages/django/template/base.py", line 959, in render_annotated
    return self.render(context)
  File "/home/jsandoval86/ProjectsDev/Appem/env/local/lib/python2.7/site-packages/django/template/defaulttags.py", line 168, in render
    len_values = len(values)
  File "/home/jsandoval86/ProjectsDev/Appem/env/local/lib/python2.7/site-packages/django/db/models/query.py", line 240, in __len__
    self._fetch_all()
  File "/home/jsandoval86/ProjectsDev/Appem/env/local/lib/python2.7/site-packages/django/db/models/query.py", line 1074, in _fetch_all
    self._result_cache = list(self.iterator())
  File "/home/jsandoval86/ProjectsDev/Appem/env/local/lib/python2.7/site-packages/django/db/models/query.py", line 52, in __iter__
    results = compiler.execute_sql()
  File "/home/jsandoval86/ProjectsDev/Appem/env/local/lib/python2.7/site-packages/django/db/models/sql/compiler.py", line 848, in execute_sql
    cursor.execute(sql, params)
  File "/home/jsandoval86/ProjectsDev/Appem/env/local/lib/python2.7/site-packages/django/db/backends/utils.py", line 79, in execute
    return super(CursorDebugWrapper, self).execute(sql, params)
  File "/home/jsandoval86/ProjectsDev/Appem/env/local/lib/python2.7/site-packages/django/db/backends/utils.py", line 64, in execute
    return self.cursor.execute(sql, params)
  File "/home/jsandoval86/ProjectsDev/Appem/env/local/lib/python2.7/site-packages/django/db/utils.py", line 95, in __exit__
    six.reraise(dj_exc_type, dj_exc_value, traceback)
  File "/home/jsandoval86/ProjectsDev/Appem/env/local/lib/python2.7/site-packages/django/db/backends/utils.py", line 64, in execute
    return self.cursor.execute(sql, params)
ProgrammingError: column facturacion_fac.vefe does not exist
LINE 1: ...acion_fac"."vdescu", "facturacion_fac"."vttotal", "facturaci...
                                                             ^

.-.-.-.-.-.-.-.-.-.-.-.-.-.-.-.-.-.-.-.-.-.-.-.-.-.-.-.-.-.-.-.-.-.-.-.-.-.-.-.- 
 ERROR 2016-10-07 08:25:47,073 base 6204 140224910849792 Internal Server Error: /bill/print/ 
Traceback (most recent call last):
  File "/home/jsandoval86/ProjectsDev/Appem/env/local/lib/python2.7/site-packages/django/core/handlers/base.py", line 149, in get_response
    response = self.process_exception_by_middleware(e, request)
  File "/home/jsandoval86/ProjectsDev/Appem/env/local/lib/python2.7/site-packages/django/core/handlers/base.py", line 147, in get_response
    response = wrapped_callback(request, *callback_args, **callback_kwargs)
  File "/home/jsandoval86/ProjectsDev/Appem/env/local/lib/python2.7/site-packages/django/contrib/auth/decorators.py", line 23, in _wrapped_view
    return view_func(request, *args, **kwargs)
  File "/home/jsandoval86/ProjectsDev/Appem/env/local/lib/python2.7/site-packages/django/views/generic/base.py", line 68, in view
    return self.dispatch(request, *args, **kwargs)
  File "/home/jsandoval86/ProjectsDev/Appem/env/local/lib/python2.7/site-packages/django/views/generic/base.py", line 88, in dispatch
    return handler(request, *args, **kwargs)
  File "/home/jsandoval86/ProjectsDev/Appem/env/local/lib/python2.7/site-packages/easy_pdf/views.py", line 80, in get
    context = self.get_context_data(**kwargs)
  File "/home/jsandoval86/ProjectsDev/Appem/appem/infa_web/apps/facturacion/views.py", line 686, in get_context_data
    usuario = Usuario.objects.using(self.request.db).filter()[0]
  File "/home/jsandoval86/ProjectsDev/Appem/env/local/lib/python2.7/site-packages/django/db/models/query.py", line 297, in __getitem__
    return list(qs)[0]
IndexError: list index out of range
.-.-.-.-.-.-.-.-.-.-.-.-.-.-.-.-.-.-.-.-.-.-.-.-.-.-.-.-.-.-.-.-.-.-.-.-.-.-.-.- 
 ERROR 2016-10-07 08:27:01,757 base 6204 140224910849792 Internal Server Error: /bill/print/ 
Traceback (most recent call last):
  File "/home/jsandoval86/ProjectsDev/Appem/env/local/lib/python2.7/site-packages/django/core/handlers/base.py", line 149, in get_response
    response = self.process_exception_by_middleware(e, request)
  File "/home/jsandoval86/ProjectsDev/Appem/env/local/lib/python2.7/site-packages/django/core/handlers/base.py", line 147, in get_response
    response = wrapped_callback(request, *callback_args, **callback_kwargs)
  File "/home/jsandoval86/ProjectsDev/Appem/env/local/lib/python2.7/site-packages/django/contrib/auth/decorators.py", line 23, in _wrapped_view
    return view_func(request, *args, **kwargs)
  File "/home/jsandoval86/ProjectsDev/Appem/env/local/lib/python2.7/site-packages/django/views/generic/base.py", line 68, in view
    return self.dispatch(request, *args, **kwargs)
  File "/home/jsandoval86/ProjectsDev/Appem/env/local/lib/python2.7/site-packages/django/views/generic/base.py", line 88, in dispatch
    return handler(request, *args, **kwargs)
  File "/home/jsandoval86/ProjectsDev/Appem/env/local/lib/python2.7/site-packages/easy_pdf/views.py", line 80, in get
    context = self.get_context_data(**kwargs)
  File "/home/jsandoval86/ProjectsDev/Appem/appem/infa_web/apps/facturacion/views.py", line 686, in get_context_data
    usuario = Usuario.objects.using(self.request.db).filter()[0]
  File "/home/jsandoval86/ProjectsDev/Appem/env/local/lib/python2.7/site-packages/django/db/models/query.py", line 297, in __getitem__
    return list(qs)[0]
IndexError: list index out of range
.-.-.-.-.-.-.-.-.-.-.-.-.-.-.-.-.-.-.-.-.-.-.-.-.-.-.-.-.-.-.-.-.-.-.-.-.-.-.-.- 
 ERROR 2016-10-07 08:36:04,482 base 6204 140224910849792 Internal Server Error: /bill/print/ 
Traceback (most recent call last):
  File "/home/jsandoval86/ProjectsDev/Appem/env/local/lib/python2.7/site-packages/django/core/handlers/base.py", line 149, in get_response
    response = self.process_exception_by_middleware(e, request)
  File "/home/jsandoval86/ProjectsDev/Appem/env/local/lib/python2.7/site-packages/django/core/handlers/base.py", line 147, in get_response
    response = wrapped_callback(request, *callback_args, **callback_kwargs)
  File "/home/jsandoval86/ProjectsDev/Appem/env/local/lib/python2.7/site-packages/django/contrib/auth/decorators.py", line 23, in _wrapped_view
    return view_func(request, *args, **kwargs)
  File "/home/jsandoval86/ProjectsDev/Appem/env/local/lib/python2.7/site-packages/django/views/generic/base.py", line 68, in view
    return self.dispatch(request, *args, **kwargs)
  File "/home/jsandoval86/ProjectsDev/Appem/env/local/lib/python2.7/site-packages/django/views/generic/base.py", line 88, in dispatch
    return handler(request, *args, **kwargs)
  File "/home/jsandoval86/ProjectsDev/Appem/env/local/lib/python2.7/site-packages/easy_pdf/views.py", line 80, in get
    context = self.get_context_data(**kwargs)
  File "/home/jsandoval86/ProjectsDev/Appem/appem/infa_web/apps/facturacion/views.py", line 686, in get_context_data
    usuario = Usuario.objects.using(self.request.db).filter()[0]
  File "/home/jsandoval86/ProjectsDev/Appem/env/local/lib/python2.7/site-packages/django/db/models/query.py", line 297, in __getitem__
    return list(qs)[0]
IndexError: list index out of range
.-.-.-.-.-.-.-.-.-.-.-.-.-.-.-.-.-.-.-.-.-.-.-.-.-.-.-.-.-.-.-.-.-.-.-.-.-.-.-.- 
 ERROR 2016-10-07 08:40:08,708 base 6204 140225150543616 Internal Server Error: /bill/save/ 
Traceback (most recent call last):
  File "/home/jsandoval86/ProjectsDev/Appem/env/local/lib/python2.7/site-packages/django/core/handlers/base.py", line 149, in get_response
    response = self.process_exception_by_middleware(e, request)
  File "/home/jsandoval86/ProjectsDev/Appem/env/local/lib/python2.7/site-packages/django/core/handlers/base.py", line 147, in get_response
    response = wrapped_callback(request, *callback_args, **callback_kwargs)
  File "/home/jsandoval86/ProjectsDev/Appem/env/local/lib/python2.7/site-packages/django/contrib/auth/decorators.py", line 23, in _wrapped_view
    return view_func(request, *args, **kwargs)
  File "/home/jsandoval86/ProjectsDev/Appem/env/local/lib/python2.7/site-packages/django/views/decorators/csrf.py", line 58, in wrapped_view
    return view_func(*args, **kwargs)
  File "/home/jsandoval86/ProjectsDev/Appem/appem/infa_web/apps/facturacion/views.py", line 98, in BillSave
    vcambio = float(data['vcambio']),
ValueError: could not convert string to float: 
.-.-.-.-.-.-.-.-.-.-.-.-.-.-.-.-.-.-.-.-.-.-.-.-.-.-.-.-.-.-.-.-.-.-.-.-.-.-.-.- 
 ERROR 2016-10-07 08:40:15,610 base 6204 140225150543616 Internal Server Error: /bill/save/ 
Traceback (most recent call last):
  File "/home/jsandoval86/ProjectsDev/Appem/env/local/lib/python2.7/site-packages/django/core/handlers/base.py", line 149, in get_response
    response = self.process_exception_by_middleware(e, request)
  File "/home/jsandoval86/ProjectsDev/Appem/env/local/lib/python2.7/site-packages/django/core/handlers/base.py", line 147, in get_response
    response = wrapped_callback(request, *callback_args, **callback_kwargs)
  File "/home/jsandoval86/ProjectsDev/Appem/env/local/lib/python2.7/site-packages/django/contrib/auth/decorators.py", line 23, in _wrapped_view
    return view_func(request, *args, **kwargs)
  File "/home/jsandoval86/ProjectsDev/Appem/env/local/lib/python2.7/site-packages/django/views/decorators/csrf.py", line 58, in wrapped_view
    return view_func(*args, **kwargs)
  File "/home/jsandoval86/ProjectsDev/Appem/appem/infa_web/apps/facturacion/views.py", line 50, in BillSave
    data = json.loads(request.body)
  File "/usr/lib/python2.7/json/__init__.py", line 338, in loads
    return _default_decoder.decode(s)
  File "/usr/lib/python2.7/json/decoder.py", line 366, in decode
    obj, end = self.raw_decode(s, idx=_w(s, 0).end())
  File "/usr/lib/python2.7/json/decoder.py", line 384, in raw_decode
    raise ValueError("No JSON object could be decoded")
ValueError: No JSON object could be decoded
.-.-.-.-.-.-.-.-.-.-.-.-.-.-.-.-.-.-.-.-.-.-.-.-.-.-.-.-.-.-.-.-.-.-.-.-.-.-.-.- 
 ERROR 2016-10-07 08:46:33,514 base 6204 140224902457088 Internal Server Error: /bill/print/ 
Traceback (most recent call last):
  File "/home/jsandoval86/ProjectsDev/Appem/env/local/lib/python2.7/site-packages/django/core/handlers/base.py", line 149, in get_response
    response = self.process_exception_by_middleware(e, request)
  File "/home/jsandoval86/ProjectsDev/Appem/env/local/lib/python2.7/site-packages/django/core/handlers/base.py", line 147, in get_response
    response = wrapped_callback(request, *callback_args, **callback_kwargs)
  File "/home/jsandoval86/ProjectsDev/Appem/env/local/lib/python2.7/site-packages/django/contrib/auth/decorators.py", line 23, in _wrapped_view
    return view_func(request, *args, **kwargs)
  File "/home/jsandoval86/ProjectsDev/Appem/env/local/lib/python2.7/site-packages/django/views/generic/base.py", line 68, in view
    return self.dispatch(request, *args, **kwargs)
  File "/home/jsandoval86/ProjectsDev/Appem/env/local/lib/python2.7/site-packages/django/views/generic/base.py", line 88, in dispatch
    return handler(request, *args, **kwargs)
  File "/home/jsandoval86/ProjectsDev/Appem/env/local/lib/python2.7/site-packages/easy_pdf/views.py", line 80, in get
    context = self.get_context_data(**kwargs)
  File "/home/jsandoval86/ProjectsDev/Appem/appem/infa_web/apps/facturacion/views.py", line 686, in get_context_data
    usuario = Usuario.objects.using(self.request.db).filter()[0]
  File "/home/jsandoval86/ProjectsDev/Appem/env/local/lib/python2.7/site-packages/django/db/models/query.py", line 297, in __getitem__
    return list(qs)[0]
IndexError: list index out of range
