.-.-.-.-.-.-.-.-.-.-.-.-.-.-.-.-.-.-.-.-.-.-.-.-.-.-.-.-.-.-.-.-.-.-.-.-.-.-.-.- 
 ERROR 2016-10-18 09:26:48,123 base 10579 139886465967872 Internal Server Error: /bill/reports/fn/ventas_formas_pago 
Traceback (most recent call last):
  File "/home/midas/Documentos/infa_web_folder/dev_env/local/lib/python2.7/site-packages/django/core/handlers/base.py", line 149, in get_response
    response = self.process_exception_by_middleware(e, request)
  File "/home/midas/Documentos/infa_web_folder/dev_env/local/lib/python2.7/site-packages/django/core/handlers/base.py", line 147, in get_response
    response = wrapped_callback(request, *callback_args, **callback_kwargs)
  File "/home/midas/Documentos/infa_web_folder/dev_env/local/lib/python2.7/site-packages/django/views/generic/base.py", line 68, in view
    return self.dispatch(request, *args, **kwargs)
  File "/home/midas/Documentos/infa_web_folder/dev_env/local/lib/python2.7/site-packages/django/views/generic/base.py", line 88, in dispatch
    return handler(request, *args, **kwargs)
  File "/home/midas/Documentos/infa_web_folder/dev_env/local/lib/python2.7/site-packages/easy_pdf/views.py", line 80, in get
    context = self.get_context_data(**kwargs)
  File "/home/midas/Documentos/infa_web_folder/InfaWeb/infa_web/apps/facturacion/views.py", line 1010, in get_context_data
    context = super(report_fn_bill, self).get_context_data(**kwargs)
TypeError: super(type, obj): obj must be an instance or subtype of type
.-.-.-.-.-.-.-.-.-.-.-.-.-.-.-.-.-.-.-.-.-.-.-.-.-.-.-.-.-.-.-.-.-.-.-.-.-.-.-.- 
 ERROR 2016-10-18 14:54:55,084 base 5295 139898638747456 Internal Server Error: /bill/save/ 
Traceback (most recent call last):
  File "/home/midas/Documentos/infa_web_folder/dev_env/local/lib/python2.7/site-packages/django/core/handlers/base.py", line 149, in get_response
    response = self.process_exception_by_middleware(e, request)
  File "/home/midas/Documentos/infa_web_folder/dev_env/local/lib/python2.7/site-packages/django/core/handlers/base.py", line 147, in get_response
    response = wrapped_callback(request, *callback_args, **callback_kwargs)
  File "/home/midas/Documentos/infa_web_folder/dev_env/local/lib/python2.7/site-packages/django/views/decorators/csrf.py", line 58, in wrapped_view
    return view_func(*args, **kwargs)
  File "/home/midas/Documentos/infa_web_folder/InfaWeb/infa_web/apps/facturacion/views.py", line 384, in BillSave
    'descri': '-'
  File "/home/midas/Documentos/infa_web_folder/InfaWeb/infa_web/apps/facturacion/views.py", line 126, in save_mvsa
    mvsa.save(using = request_db)
  File "/home/midas/Documentos/infa_web_folder/dev_env/local/lib/python2.7/site-packages/django/db/models/base.py", line 708, in save
    force_update=force_update, update_fields=update_fields)
  File "/home/midas/Documentos/infa_web_folder/dev_env/local/lib/python2.7/site-packages/django/db/models/base.py", line 736, in save_base
    updated = self._save_table(raw, cls, force_insert, force_update, using, update_fields)
  File "/home/midas/Documentos/infa_web_folder/dev_env/local/lib/python2.7/site-packages/django/db/models/base.py", line 820, in _save_table
    result = self._do_insert(cls._base_manager, using, fields, update_pk, raw)
  File "/home/midas/Documentos/infa_web_folder/dev_env/local/lib/python2.7/site-packages/django/db/models/base.py", line 859, in _do_insert
    using=using, raw=raw)
  File "/home/midas/Documentos/infa_web_folder/dev_env/local/lib/python2.7/site-packages/django/db/models/manager.py", line 122, in manager_method
    return getattr(self.get_queryset(), name)(*args, **kwargs)
  File "/home/midas/Documentos/infa_web_folder/dev_env/local/lib/python2.7/site-packages/django/db/models/query.py", line 1039, in _insert
    return query.get_compiler(using=using).execute_sql(return_id)
  File "/home/midas/Documentos/infa_web_folder/dev_env/local/lib/python2.7/site-packages/django/db/models/sql/compiler.py", line 1060, in execute_sql
    cursor.execute(sql, params)
  File "/home/midas/Documentos/infa_web_folder/dev_env/local/lib/python2.7/site-packages/django/db/backends/utils.py", line 64, in execute
    return self.cursor.execute(sql, params)
  File "/home/midas/Documentos/infa_web_folder/dev_env/local/lib/python2.7/site-packages/django/db/utils.py", line 95, in __exit__
    six.reraise(dj_exc_type, dj_exc_value, traceback)
  File "/home/midas/Documentos/infa_web_folder/dev_env/local/lib/python2.7/site-packages/django/db/backends/utils.py", line 64, in execute
    return self.cursor.execute(sql, params)
IntegrityError: duplicate key value violates unique constraint "movimientos_mvsa_pkey"
DETAIL:  Key (cmvsa)=(1) already exists.

.-.-.-.-.-.-.-.-.-.-.-.-.-.-.-.-.-.-.-.-.-.-.-.-.-.-.-.-.-.-.-.-.-.-.-.-.-.-.-.- 
 ERROR 2016-10-19 09:35:14,075 base 8745 140019904677632 Internal Server Error: /bill/save/ 
Traceback (most recent call last):
  File "/home/midas/Documentos/infa_web_folder/dev_env/local/lib/python2.7/site-packages/django/core/handlers/base.py", line 149, in get_response
    response = self.process_exception_by_middleware(e, request)
  File "/home/midas/Documentos/infa_web_folder/dev_env/local/lib/python2.7/site-packages/django/core/handlers/base.py", line 147, in get_response
    response = wrapped_callback(request, *callback_args, **callback_kwargs)
  File "/home/midas/Documentos/infa_web_folder/dev_env/local/lib/python2.7/site-packages/django/views/decorators/csrf.py", line 58, in wrapped_view
    return view_func(*args, **kwargs)
<<<<<<< HEAD
  File "/home/midas/Documentos/infa_web_folder/InfaWeb/infa_web/apps/inventarios/views.py", line 175, in inventory_save
    response_data = json.loads(request.POST.get('data_r'))
  File "/usr/lib/python2.7/json/__init__.py", line 338, in loads
    return _default_decoder.decode(s)
  File "/usr/lib/python2.7/json/decoder.py", line 366, in decode
    obj, end = self.raw_decode(s, idx=_w(s, 0).end())
  File "/usr/lib/python2.7/json/decoder.py", line 382, in raw_decode
    obj, end = self.scan_once(s, idx)
ValueError: Expecting property name enclosed in double quotes: line 1 column 2 (char 1)
.-.-.-.-.-.-.-.-.-.-.-.-.-.-.-.-.-.-.-.-.-.-.-.-.-.-.-.-.-.-.-.-.-.-.-.-.-.-.-.- 
 ERROR 2016-10-14 10:12:32,671 base 9336 140424256464640 Internal Server Error: /bill/print/ 
Traceback (most recent call last):
  File "/home/midas/Documentos/infa_web_folder/dev_env/local/lib/python2.7/site-packages/django/core/handlers/base.py", line 149, in get_response
    response = self.process_exception_by_middleware(e, request)
  File "/home/midas/Documentos/infa_web_folder/dev_env/local/lib/python2.7/site-packages/django/core/handlers/base.py", line 147, in get_response
    response = wrapped_callback(request, *callback_args, **callback_kwargs)
  File "/home/midas/Documentos/infa_web_folder/dev_env/local/lib/python2.7/site-packages/django/views/generic/base.py", line 68, in view
    return self.dispatch(request, *args, **kwargs)
  File "/home/midas/Documentos/infa_web_folder/dev_env/local/lib/python2.7/site-packages/django/views/generic/base.py", line 88, in dispatch
    return handler(request, *args, **kwargs)
  File "/home/midas/Documentos/infa_web_folder/dev_env/local/lib/python2.7/site-packages/easy_pdf/views.py", line 80, in get
    context = self.get_context_data(**kwargs)
  File "/home/midas/Documentos/infa_web_folder/InfaWeb/infa_web/apps/facturacion/views.py", line 958, in get_context_data
    factura = Fac.objects.using(self.request.db).get(cfac=cfac)
  File "/home/midas/Documentos/infa_web_folder/dev_env/local/lib/python2.7/site-packages/django/db/models/query.py", line 387, in get
    self.model._meta.object_name
DoesNotExist: Fac matching query does not exist.
.-.-.-.-.-.-.-.-.-.-.-.-.-.-.-.-.-.-.-.-.-.-.-.-.-.-.-.-.-.-.-.-.-.-.-.-.-.-.-.- 
 ERROR 2016-10-14 10:54:00,635 base 11828 139734693480192 Internal Server Error: /bill/reports/view/ventas 
Traceback (most recent call last):
  File "/home/midas/Documentos/infa_web_folder/dev_env/local/lib/python2.7/site-packages/django/core/handlers/base.py", line 149, in get_response
    response = self.process_exception_by_middleware(e, request)
  File "/home/midas/Documentos/infa_web_folder/dev_env/local/lib/python2.7/site-packages/django/core/handlers/base.py", line 147, in get_response
    response = wrapped_callback(request, *callback_args, **callback_kwargs)
  File "/home/midas/Documentos/infa_web_folder/InfaWeb/infa_web/apps/facturacion/views.py", line 1005, in report_view_bill
    return render(request,"facturacion/reportes/views/ventas.html",{"form":form,"form_common":form_common})
  File "/home/midas/Documentos/infa_web_folder/dev_env/local/lib/python2.7/site-packages/django/shortcuts.py", line 67, in render
    template_name, context, request=request, using=using)
  File "/home/midas/Documentos/infa_web_folder/dev_env/local/lib/python2.7/site-packages/django/template/loader.py", line 97, in render_to_string
    return template.render(context, request)
  File "/home/midas/Documentos/infa_web_folder/dev_env/local/lib/python2.7/site-packages/django/template/backends/django.py", line 95, in render
    return self.template.render(context)
  File "/home/midas/Documentos/infa_web_folder/dev_env/local/lib/python2.7/site-packages/django/template/base.py", line 206, in render
    return self._render(context)
  File "/home/midas/Documentos/infa_web_folder/dev_env/local/lib/python2.7/site-packages/django/template/base.py", line 197, in _render
    return self.nodelist.render(context)
  File "/home/midas/Documentos/infa_web_folder/dev_env/local/lib/python2.7/site-packages/django/template/base.py", line 992, in render
    bit = node.render_annotated(context)
  File "/home/midas/Documentos/infa_web_folder/dev_env/local/lib/python2.7/site-packages/django/template/base.py", line 959, in render_annotated
    return self.render(context)
  File "/home/midas/Documentos/infa_web_folder/dev_env/local/lib/python2.7/site-packages/django/template/loader_tags.py", line 173, in render
    return compiled_parent._render(context)
  File "/home/midas/Documentos/infa_web_folder/dev_env/local/lib/python2.7/site-packages/django/template/base.py", line 197, in _render
    return self.nodelist.render(context)
  File "/home/midas/Documentos/infa_web_folder/dev_env/local/lib/python2.7/site-packages/django/template/base.py", line 992, in render
    bit = node.render_annotated(context)
  File "/home/midas/Documentos/infa_web_folder/dev_env/local/lib/python2.7/site-packages/django/template/base.py", line 959, in render_annotated
    return self.render(context)
  File "/home/midas/Documentos/infa_web_folder/dev_env/local/lib/python2.7/site-packages/django/template/loader_tags.py", line 69, in render
    result = block.nodelist.render(context)
  File "/home/midas/Documentos/infa_web_folder/dev_env/local/lib/python2.7/site-packages/django/template/base.py", line 992, in render
    bit = node.render_annotated(context)
  File "/home/midas/Documentos/infa_web_folder/dev_env/local/lib/python2.7/site-packages/django/template/base.py", line 959, in render_annotated
    return self.render(context)
  File "/home/midas/Documentos/infa_web_folder/dev_env/local/lib/python2.7/site-packages/django/template/base.py", line 1049, in render
    return render_value_in_context(output, context)
  File "/home/midas/Documentos/infa_web_folder/dev_env/local/lib/python2.7/site-packages/django/template/base.py", line 1026, in render_value_in_context
    value = force_text(value)
  File "/home/midas/Documentos/infa_web_folder/dev_env/local/lib/python2.7/site-packages/django/utils/encoding.py", line 78, in force_text
    s = six.text_type(s)
  File "/home/midas/Documentos/infa_web_folder/dev_env/local/lib/python2.7/site-packages/django/utils/html.py", line 381, in <lambda>
    klass.__unicode__ = lambda self: mark_safe(klass_unicode(self))
  File "/home/midas/Documentos/infa_web_folder/dev_env/local/lib/python2.7/site-packages/django/forms/boundfield.py", line 43, in __str__
    return self.as_widget()
  File "/home/midas/Documentos/infa_web_folder/dev_env/local/lib/python2.7/site-packages/django/forms/boundfield.py", line 101, in as_widget
    return force_text(widget.render(name, self.value(), attrs=attrs))
  File "/home/midas/Documentos/infa_web_folder/dev_env/local/lib/python2.7/site-packages/django/forms/widgets.py", line 528, in render
    options = self.render_options(choices, [value])
  File "/home/midas/Documentos/infa_web_folder/dev_env/local/lib/python2.7/site-packages/django/forms/widgets.py", line 554, in render_options
    for option_value, option_label in chain(self.choices, choices):
  File "/home/midas/Documentos/infa_web_folder/dev_env/local/lib/python2.7/site-packages/django/forms/models.py", line 1105, in __iter__
    queryset = self.queryset.all()
AttributeError: 'list' object has no attribute 'all'
>>>>>>> 70b4eedc85959f0fe4b96e6f14b0c1f518ca3c79
.-.-.-.-.-.-.-.-.-.-.-.-.-.-.-.-.-.-.-.-.-.-.-.-.-.-.-.-.-.-.-.-.-.-.-.-.-.-.-.- 
 ERROR 2016-10-18 07:50:37,230 base 3364 632 Internal Server Error: /bill/save/ 
Traceback (most recent call last):
  File "C:\Python27\lib\site-packages\django\core\handlers\base.py", line 149, in get_response
    response = self.process_exception_by_middleware(e, request)
  File "C:\Python27\lib\site-packages\django\core\handlers\base.py", line 147, in get_response
    response = wrapped_callback(request, *callback_args, **callback_kwargs)
  File "C:\Python27\lib\site-packages\django\views\decorators\csrf.py", line 58, in wrapped_view
    return view_func(*args, **kwargs)
  File "D:\Proyectos\infa web\infa_web\infa_web\apps\facturacion\views.py", line 465, in BillSave
    'vmovi': medios_pagos_total
  File "D:\Proyectos\infa web\infa_web\infa_web\apps\facturacion\views.py", line 181, in save_movideta
    movideta = movi[0].movideta_set.using(request_db).get(itmovi = movideta_array['itmovi'])
  File "C:\Python27\lib\site-packages\django\db\models\query.py", line 387, in get
    self.model._meta.object_name
DoesNotExist: Movideta matching query does not exist.
.-.-.-.-.-.-.-.-.-.-.-.-.-.-.-.-.-.-.-.-.-.-.-.-.-.-.-.-.-.-.-.-.-.-.-.-.-.-.-.- 
 ERROR 2016-10-18 07:50:49,015 base 3364 3900 Internal Server Error: /bill/save/ 
Traceback (most recent call last):
  File "C:\Python27\lib\site-packages\django\core\handlers\base.py", line 149, in get_response
    response = self.process_exception_by_middleware(e, request)
  File "C:\Python27\lib\site-packages\django\core\handlers\base.py", line 147, in get_response
    response = wrapped_callback(request, *callback_args, **callback_kwargs)
  File "C:\Python27\lib\site-packages\django\views\decorators\csrf.py", line 58, in wrapped_view
    return view_func(*args, **kwargs)
  File "D:\Proyectos\infa web\infa_web\infa_web\apps\facturacion\views.py", line 295, in BillSave
    data = json.loads(request.body)
  File "C:\Python27\lib\json\__init__.py", line 339, in loads
    return _default_decoder.decode(s)
  File "C:\Python27\lib\json\decoder.py", line 364, in decode
    obj, end = self.raw_decode(s, idx=_w(s, 0).end())
  File "C:\Python27\lib\json\decoder.py", line 382, in raw_decode
    raise ValueError("No JSON object could be decoded")
ValueError: No JSON object could be decoded
.-.-.-.-.-.-.-.-.-.-.-.-.-.-.-.-.-.-.-.-.-.-.-.-.-.-.-.-.-.-.-.-.-.-.-.-.-.-.-.- 
 ERROR 2016-10-18 07:50:57,308 base 3364 2976 Internal Server Error: /bill/save/ 
Traceback (most recent call last):
  File "C:\Python27\lib\site-packages\django\core\handlers\base.py", line 149, in get_response
    response = self.process_exception_by_middleware(e, request)
  File "C:\Python27\lib\site-packages\django\core\handlers\base.py", line 147, in get_response
    response = wrapped_callback(request, *callback_args, **callback_kwargs)
  File "C:\Python27\lib\site-packages\django\views\decorators\csrf.py", line 58, in wrapped_view
    return view_func(*args, **kwargs)
  File "D:\Proyectos\infa web\infa_web\infa_web\apps\facturacion\views.py", line 465, in BillSave
    'vmovi': medios_pagos_total
  File "D:\Proyectos\infa web\infa_web\infa_web\apps\facturacion\views.py", line 181, in save_movideta
    movideta = movi[0].movideta_set.using(request_db).get(itmovi = movideta_array['itmovi'])
  File "C:\Python27\lib\site-packages\django\db\models\query.py", line 387, in get
    self.model._meta.object_name
DoesNotExist: Movideta matching query does not exist.
.-.-.-.-.-.-.-.-.-.-.-.-.-.-.-.-.-.-.-.-.-.-.-.-.-.-.-.-.-.-.-.-.-.-.-.-.-.-.-.- 
 ERROR 2016-10-18 07:53:31,706 base 3364 2204 Internal Server Error: /bill/save/ 
Traceback (most recent call last):
  File "C:\Python27\lib\site-packages\django\core\handlers\base.py", line 149, in get_response
    response = self.process_exception_by_middleware(e, request)
  File "C:\Python27\lib\site-packages\django\core\handlers\base.py", line 147, in get_response
    response = wrapped_callback(request, *callback_args, **callback_kwargs)
  File "C:\Python27\lib\site-packages\django\views\decorators\csrf.py", line 58, in wrapped_view
    return view_func(*args, **kwargs)
  File "D:\Proyectos\infa web\infa_web\infa_web\apps\facturacion\views.py", line 465, in BillSave
    'vmovi': medios_pagos_total
  File "D:\Proyectos\infa web\infa_web\infa_web\apps\facturacion\views.py", line 181, in save_movideta
    movideta = movi[0].movideta_set.using(request_db).get(itmovi = movideta_array['itmovi'])
  File "C:\Python27\lib\site-packages\django\db\models\query.py", line 387, in get
    self.model._meta.object_name
DoesNotExist: Movideta matching query does not exist.
.-.-.-.-.-.-.-.-.-.-.-.-.-.-.-.-.-.-.-.-.-.-.-.-.-.-.-.-.-.-.-.-.-.-.-.-.-.-.-.- 
 ERROR 2016-10-18 07:55:34,553 base 4992 5296 Internal Server Error: /bill/save/ 
Traceback (most recent call last):
  File "C:\Python27\lib\site-packages\django\core\handlers\base.py", line 149, in get_response
    response = self.process_exception_by_middleware(e, request)
  File "C:\Python27\lib\site-packages\django\core\handlers\base.py", line 147, in get_response
    response = wrapped_callback(request, *callback_args, **callback_kwargs)
  File "C:\Python27\lib\site-packages\django\views\decorators\csrf.py", line 58, in wrapped_view
    return view_func(*args, **kwargs)
  File "D:\Proyectos\infa web\infa_web\infa_web\apps\facturacion\views.py", line 466, in BillSave
    'vmovi': medios_pagos_total
  File "D:\Proyectos\infa web\infa_web\infa_web\apps\facturacion\views.py", line 182, in save_movideta
    movideta = movi[0].movideta_set.using(request_db).get(itmovi = movideta_array['itmovi'])
  File "C:\Python27\lib\site-packages\django\db\models\query.py", line 387, in get
    self.model._meta.object_name
DoesNotExist: Movideta matching query does not exist.
.-.-.-.-.-.-.-.-.-.-.-.-.-.-.-.-.-.-.-.-.-.-.-.-.-.-.-.-.-.-.-.-.-.-.-.-.-.-.-.- 
 ERROR 2016-10-18 07:56:07,706 base 3844 2968 Internal Server Error: /bill/save/ 
Traceback (most recent call last):
  File "C:\Python27\lib\site-packages\django\core\handlers\base.py", line 149, in get_response
    response = self.process_exception_by_middleware(e, request)
  File "C:\Python27\lib\site-packages\django\core\handlers\base.py", line 147, in get_response
    response = wrapped_callback(request, *callback_args, **callback_kwargs)
  File "C:\Python27\lib\site-packages\django\views\decorators\csrf.py", line 58, in wrapped_view
    return view_func(*args, **kwargs)
  File "D:\Proyectos\infa web\infa_web\infa_web\apps\facturacion\views.py", line 466, in BillSave
    'vmovi': medios_pagos_total
  File "D:\Proyectos\infa web\infa_web\infa_web\apps\facturacion\views.py", line 180, in save_movideta
    print movi[0]
  File "C:\Python27\lib\site-packages\django\db\models\query.py", line 297, in __getitem__
    return list(qs)[0]
IndexError: list index out of range
.-.-.-.-.-.-.-.-.-.-.-.-.-.-.-.-.-.-.-.-.-.-.-.-.-.-.-.-.-.-.-.-.-.-.-.-.-.-.-.- 
 ERROR 2016-10-18 07:56:55,734 base 3456 2816 Internal Server Error: /bill/save/ 
Traceback (most recent call last):
  File "C:\Python27\lib\site-packages\django\core\handlers\base.py", line 149, in get_response
    response = self.process_exception_by_middleware(e, request)
  File "C:\Python27\lib\site-packages\django\core\handlers\base.py", line 147, in get_response
    response = wrapped_callback(request, *callback_args, **callback_kwargs)
  File "C:\Python27\lib\site-packages\django\views\decorators\csrf.py", line 58, in wrapped_view
    return view_func(*args, **kwargs)
  File "D:\Proyectos\infa web\infa_web\infa_web\apps\facturacion\views.py", line 466, in BillSave
    'vmovi': medios_pagos_total
  File "D:\Proyectos\infa web\infa_web\infa_web\apps\facturacion\views.py", line 182, in save_movideta
    movideta = movi[0].movideta_set.using(request_db).get(itmovi = movideta_array['itmovi'])
  File "C:\Python27\lib\site-packages\django\db\models\query.py", line 387, in get
    self.model._meta.object_name
DoesNotExist: Movideta matching query does not exist.
.-.-.-.-.-.-.-.-.-.-.-.-.-.-.-.-.-.-.-.-.-.-.-.-.-.-.-.-.-.-.-.-.-.-.-.-.-.-.-.- 
 ERROR 2016-10-18 08:05:02,509 base 6116 1340 Internal Server Error: /bill/save/ 
Traceback (most recent call last):
  File "C:\Python27\lib\site-packages\django\core\handlers\base.py", line 149, in get_response
    response = self.process_exception_by_middleware(e, request)
  File "C:\Python27\lib\site-packages\django\core\handlers\base.py", line 147, in get_response
    response = wrapped_callback(request, *callback_args, **callback_kwargs)
  File "C:\Python27\lib\site-packages\django\views\decorators\csrf.py", line 58, in wrapped_view
    return view_func(*args, **kwargs)
  File "D:\Proyectos\infa web\infa_web\infa_web\apps\facturacion\views.py", line 466, in BillSave
    'vmovi': medios_pagos_total
  File "D:\Proyectos\infa web\infa_web\infa_web\apps\facturacion\views.py", line 180, in save_movideta
    movi = movi if not movi[0] else movi[0]
  File "C:\Python27\lib\site-packages\django\db\models\query.py", line 297, in __getitem__
    return list(qs)[0]
IndexError: list index out of range
.-.-.-.-.-.-.-.-.-.-.-.-.-.-.-.-.-.-.-.-.-.-.-.-.-.-.-.-.-.-.-.-.-.-.-.-.-.-.-.- 
 ERROR 2016-10-18 08:07:17,341 base 2692 3196 Internal Server Error: /bill/save/ 
Traceback (most recent call last):
  File "C:\Python27\lib\site-packages\django\core\handlers\base.py", line 149, in get_response
    response = self.process_exception_by_middleware(e, request)
  File "C:\Python27\lib\site-packages\django\core\handlers\base.py", line 147, in get_response
    response = wrapped_callback(request, *callback_args, **callback_kwargs)
  File "C:\Python27\lib\site-packages\django\views\decorators\csrf.py", line 58, in wrapped_view
    return view_func(*args, **kwargs)
  File "D:\Proyectos\infa web\infa_web\infa_web\apps\facturacion\views.py", line 467, in BillSave
    'vmovi': medios_pagos_total
  File "D:\Proyectos\infa web\infa_web\infa_web\apps\facturacion\views.py", line 180, in save_movideta
    movi = movi if not movi[0] else movi[0]
  File "C:\Python27\lib\site-packages\django\db\models\query.py", line 297, in __getitem__
    return list(qs)[0]
IndexError: list index out of range
.-.-.-.-.-.-.-.-.-.-.-.-.-.-.-.-.-.-.-.-.-.-.-.-.-.-.-.-.-.-.-.-.-.-.-.-.-.-.-.- 
 ERROR 2016-10-18 08:08:33,069 base 3388 2912 Internal Server Error: /bill/save/ 
Traceback (most recent call last):
  File "C:\Python27\lib\site-packages\django\core\handlers\base.py", line 149, in get_response
    response = self.process_exception_by_middleware(e, request)
  File "C:\Python27\lib\site-packages\django\core\handlers\base.py", line 147, in get_response
    response = wrapped_callback(request, *callback_args, **callback_kwargs)
  File "C:\Python27\lib\site-packages\django\views\decorators\csrf.py", line 58, in wrapped_view
    return view_func(*args, **kwargs)
  File "D:\Proyectos\infa web\infa_web\infa_web\apps\facturacion\views.py", line 467, in BillSave
    'vmovi': medios_pagos_total
  File "D:\Proyectos\infa web\infa_web\infa_web\apps\facturacion\views.py", line 181, in save_movideta
    movideta = movi.movideta_set.using(request_db).get(itmovi = movideta_array['itmovi'])
AttributeError: 'QuerySet' object has no attribute 'movideta_set'
.-.-.-.-.-.-.-.-.-.-.-.-.-.-.-.-.-.-.-.-.-.-.-.-.-.-.-.-.-.-.-.-.-.-.-.-.-.-.-.- 
 ERROR 2016-10-18 08:10:33,086 base 1304 5968 Internal Server Error: /bill/save/ 
Traceback (most recent call last):
  File "C:\Python27\lib\site-packages\django\core\handlers\base.py", line 149, in get_response
    response = self.process_exception_by_middleware(e, request)
  File "C:\Python27\lib\site-packages\django\core\handlers\base.py", line 147, in get_response
    response = wrapped_callback(request, *callback_args, **callback_kwargs)
  File "C:\Python27\lib\site-packages\django\views\decorators\csrf.py", line 58, in wrapped_view
    return view_func(*args, **kwargs)
  File "D:\Proyectos\infa web\infa_web\infa_web\apps\facturacion\views.py", line 467, in BillSave
    'vmovi': medios_pagos_total
  File "D:\Proyectos\infa web\infa_web\infa_web\apps\facturacion\views.py", line 182, in save_movideta
    movideta = movi.movideta_set.using(request_db).get(itmovi = movideta_array['itmovi'])
AttributeError: 'QuerySet' object has no attribute 'movideta_set'
.-.-.-.-.-.-.-.-.-.-.-.-.-.-.-.-.-.-.-.-.-.-.-.-.-.-.-.-.-.-.-.-.-.-.-.-.-.-.-.- 
 ERROR 2016-10-18 08:12:31,351 base 5584 5308 Internal Server Error: /bill/save/ 
Traceback (most recent call last):
  File "C:\Python27\lib\site-packages\django\core\handlers\base.py", line 149, in get_response
    response = self.process_exception_by_middleware(e, request)
  File "C:\Python27\lib\site-packages\django\core\handlers\base.py", line 147, in get_response
    response = wrapped_callback(request, *callback_args, **callback_kwargs)
  File "C:\Python27\lib\site-packages\django\views\decorators\csrf.py", line 58, in wrapped_view
    return view_func(*args, **kwargs)
  File "D:\Proyectos\infa web\infa_web\infa_web\apps\facturacion\views.py", line 467, in BillSave
    'vmovi': medios_pagos_total
  File "D:\Proyectos\infa web\infa_web\infa_web\apps\facturacion\views.py", line 182, in save_movideta
    movideta = movi.movideta_set.using(request_db).get(itmovi = movideta_array['itmovi'])
AttributeError: 'QuerySet' object has no attribute 'movideta_set'
.-.-.-.-.-.-.-.-.-.-.-.-.-.-.-.-.-.-.-.-.-.-.-.-.-.-.-.-.-.-.-.-.-.-.-.-.-.-.-.- 
 ERROR 2016-10-18 08:17:34,323 base 1996 4220 Internal Server Error: /bill/save/ 
Traceback (most recent call last):
  File "C:\Python27\lib\site-packages\django\core\handlers\base.py", line 149, in get_response
    response = self.process_exception_by_middleware(e, request)
  File "C:\Python27\lib\site-packages\django\core\handlers\base.py", line 147, in get_response
    response = wrapped_callback(request, *callback_args, **callback_kwargs)
  File "C:\Python27\lib\site-packages\django\views\decorators\csrf.py", line 58, in wrapped_view
    return view_func(*args, **kwargs)
  File "D:\Proyectos\infa web\infa_web\infa_web\apps\facturacion\views.py", line 468, in BillSave
    'vmovi': medios_pagos_total
  File "D:\Proyectos\infa web\infa_web\infa_web\apps\facturacion\views.py", line 183, in save_movideta
    movideta = movi.movideta_set.using(request_db).get(itmovi = movideta_array['itmovi'])
AttributeError: 'QuerySet' object has no attribute 'movideta_set'
.-.-.-.-.-.-.-.-.-.-.-.-.-.-.-.-.-.-.-.-.-.-.-.-.-.-.-.-.-.-.-.-.-.-.-.-.-.-.-.- 
 ERROR 2016-10-18 08:17:52,964 base 4504 3492 Internal Server Error: /bill/save/ 
Traceback (most recent call last):
  File "C:\Python27\lib\site-packages\django\core\handlers\base.py", line 149, in get_response
    response = self.process_exception_by_middleware(e, request)
  File "C:\Python27\lib\site-packages\django\core\handlers\base.py", line 147, in get_response
    response = wrapped_callback(request, *callback_args, **callback_kwargs)
  File "C:\Python27\lib\site-packages\django\views\decorators\csrf.py", line 58, in wrapped_view
    return view_func(*args, **kwargs)
  File "D:\Proyectos\infa web\infa_web\infa_web\apps\facturacion\views.py", line 468, in BillSave
    'vmovi': medios_pagos_total
  File "D:\Proyectos\infa web\infa_web\infa_web\apps\facturacion\views.py", line 183, in save_movideta
    movideta = movi.movideta_set.using(request_db).get(itmovi = movideta_array['itmovi'])
AttributeError: 'QuerySet' object has no attribute 'movideta_set'
.-.-.-.-.-.-.-.-.-.-.-.-.-.-.-.-.-.-.-.-.-.-.-.-.-.-.-.-.-.-.-.-.-.-.-.-.-.-.-.- 
 ERROR 2016-10-18 08:19:07,596 base 4504 3196 Internal Server Error: /bill/save/ 
Traceback (most recent call last):
  File "C:\Python27\lib\site-packages\django\core\handlers\base.py", line 149, in get_response
    response = self.process_exception_by_middleware(e, request)
  File "C:\Python27\lib\site-packages\django\core\handlers\base.py", line 147, in get_response
    response = wrapped_callback(request, *callback_args, **callback_kwargs)
  File "C:\Python27\lib\site-packages\django\views\decorators\csrf.py", line 58, in wrapped_view
    return view_func(*args, **kwargs)
  File "D:\Proyectos\infa web\infa_web\infa_web\apps\facturacion\views.py", line 468, in BillSave
    'vmovi': medios_pagos_total
  File "D:\Proyectos\infa web\infa_web\infa_web\apps\facturacion\views.py", line 183, in save_movideta
    movideta = movi.movideta_set.using(request_db).get(itmovi = movideta_array['itmovi'])
AttributeError: 'QuerySet' object has no attribute 'movideta_set'
.-.-.-.-.-.-.-.-.-.-.-.-.-.-.-.-.-.-.-.-.-.-.-.-.-.-.-.-.-.-.-.-.-.-.-.-.-.-.-.- 
 ERROR 2016-10-18 08:20:49,595 base 872 4892 Internal Server Error: /bill/save/ 
Traceback (most recent call last):
  File "C:\Python27\lib\site-packages\django\core\handlers\base.py", line 149, in get_response
    response = self.process_exception_by_middleware(e, request)
  File "C:\Python27\lib\site-packages\django\core\handlers\base.py", line 147, in get_response
    response = wrapped_callback(request, *callback_args, **callback_kwargs)
  File "C:\Python27\lib\site-packages\django\views\decorators\csrf.py", line 58, in wrapped_view
    return view_func(*args, **kwargs)
  File "D:\Proyectos\infa web\infa_web\infa_web\apps\facturacion\views.py", line 468, in BillSave
    'vmovi': medios_pagos_total
  File "D:\Proyectos\infa web\infa_web\infa_web\apps\facturacion\views.py", line 183, in save_movideta
    movideta = movi.movideta_set.using(request_db).get(itmovi = movideta_array['itmovi'])
AttributeError: 'QuerySet' object has no attribute 'movideta_set'
.-.-.-.-.-.-.-.-.-.-.-.-.-.-.-.-.-.-.-.-.-.-.-.-.-.-.-.-.-.-.-.-.-.-.-.-.-.-.-.- 
 ERROR 2016-10-18 08:22:30,384 base 4940 3232 Internal Server Error: /bill/save/ 
Traceback (most recent call last):
  File "C:\Python27\lib\site-packages\django\core\handlers\base.py", line 149, in get_response
    response = self.process_exception_by_middleware(e, request)
  File "C:\Python27\lib\site-packages\django\core\handlers\base.py", line 147, in get_response
    response = wrapped_callback(request, *callback_args, **callback_kwargs)
  File "C:\Python27\lib\site-packages\django\views\decorators\csrf.py", line 58, in wrapped_view
    return view_func(*args, **kwargs)
  File "D:\Proyectos\infa web\infa_web\infa_web\apps\facturacion\views.py", line 468, in BillSave
    'vmovi': medios_pagos_total
  File "D:\Proyectos\infa web\infa_web\infa_web\apps\facturacion\views.py", line 183, in save_movideta
    movideta = movi.movideta_set.using(request_db).get(itmovi = movideta_array['itmovi'])
AttributeError: 'QuerySet' object has no attribute 'movideta_set'
.-.-.-.-.-.-.-.-.-.-.-.-.-.-.-.-.-.-.-.-.-.-.-.-.-.-.-.-.-.-.-.-.-.-.-.-.-.-.-.- 
 ERROR 2016-10-18 08:23:46,905 base 1940 1952 Internal Server Error: /bill/save/ 
Traceback (most recent call last):
  File "C:\Python27\lib\site-packages\django\core\handlers\base.py", line 149, in get_response
    response = self.process_exception_by_middleware(e, request)
  File "C:\Python27\lib\site-packages\django\core\handlers\base.py", line 147, in get_response
    response = wrapped_callback(request, *callback_args, **callback_kwargs)
  File "C:\Python27\lib\site-packages\django\views\decorators\csrf.py", line 58, in wrapped_view
    return view_func(*args, **kwargs)
  File "D:\Proyectos\infa web\infa_web\infa_web\apps\facturacion\views.py", line 469, in BillSave
    'vmovi': medios_pagos_total
  File "D:\Proyectos\infa web\infa_web\infa_web\apps\facturacion\views.py", line 184, in save_movideta
    movideta = movi.movideta_set.using(request_db).get(itmovi = movideta_array['itmovi'])
AttributeError: 'QuerySet' object has no attribute 'movideta_set'
.-.-.-.-.-.-.-.-.-.-.-.-.-.-.-.-.-.-.-.-.-.-.-.-.-.-.-.-.-.-.-.-.-.-.-.-.-.-.-.- 
 ERROR 2016-10-18 08:24:13,197 base 4220 2820 Internal Server Error: /bill/save/ 
Traceback (most recent call last):
  File "C:\Python27\lib\site-packages\django\core\handlers\base.py", line 149, in get_response
    response = self.process_exception_by_middleware(e, request)
  File "C:\Python27\lib\site-packages\django\core\handlers\base.py", line 147, in get_response
    response = wrapped_callback(request, *callback_args, **callback_kwargs)
  File "C:\Python27\lib\site-packages\django\views\decorators\csrf.py", line 58, in wrapped_view
    return view_func(*args, **kwargs)
  File "D:\Proyectos\infa web\infa_web\infa_web\apps\facturacion\views.py", line 469, in BillSave
    'vmovi': medios_pagos_total
  File "D:\Proyectos\infa web\infa_web\infa_web\apps\facturacion\views.py", line 184, in save_movideta
    movideta = movi.movideta_set.using(request_db).get(itmovi = movideta_array['itmovi'])
AttributeError: 'QuerySet' object has no attribute 'movideta_set'
.-.-.-.-.-.-.-.-.-.-.-.-.-.-.-.-.-.-.-.-.-.-.-.-.-.-.-.-.-.-.-.-.-.-.-.-.-.-.-.- 
 ERROR 2016-10-18 08:24:39,286 base 2636 3256 Internal Server Error: /bill/save/ 
Traceback (most recent call last):
  File "C:\Python27\lib\site-packages\django\core\handlers\base.py", line 149, in get_response
    response = self.process_exception_by_middleware(e, request)
  File "C:\Python27\lib\site-packages\django\core\handlers\base.py", line 147, in get_response
    response = wrapped_callback(request, *callback_args, **callback_kwargs)
  File "C:\Python27\lib\site-packages\django\views\decorators\csrf.py", line 58, in wrapped_view
    return view_func(*args, **kwargs)
  File "D:\Proyectos\infa web\infa_web\infa_web\apps\facturacion\views.py", line 469, in BillSave
    'vmovi': medios_pagos_total
  File "D:\Proyectos\infa web\infa_web\infa_web\apps\facturacion\views.py", line 184, in save_movideta
    movideta = movi.movideta_set.using(request_db).get(itmovi = movideta_array['itmovi'])
AttributeError: 'QuerySet' object has no attribute 'movideta_set'
.-.-.-.-.-.-.-.-.-.-.-.-.-.-.-.-.-.-.-.-.-.-.-.-.-.-.-.-.-.-.-.-.-.-.-.-.-.-.-.- 
 ERROR 2016-10-18 08:25:06,976 base 4188 4716 Internal Server Error: /bill/save/ 
Traceback (most recent call last):
  File "C:\Python27\lib\site-packages\django\core\handlers\base.py", line 149, in get_response
    response = self.process_exception_by_middleware(e, request)
  File "C:\Python27\lib\site-packages\django\core\handlers\base.py", line 147, in get_response
    response = wrapped_callback(request, *callback_args, **callback_kwargs)
  File "C:\Python27\lib\site-packages\django\views\decorators\csrf.py", line 58, in wrapped_view
    return view_func(*args, **kwargs)
  File "D:\Proyectos\infa web\infa_web\infa_web\apps\facturacion\views.py", line 469, in BillSave
    'vmovi': medios_pagos_total
  File "D:\Proyectos\infa web\infa_web\infa_web\apps\facturacion\views.py", line 184, in save_movideta
    movideta = movi.movideta_set.using(request_db).get(itmovi = movideta_array['itmovi'])
AttributeError: 'QuerySet' object has no attribute 'movideta_set'
.-.-.-.-.-.-.-.-.-.-.-.-.-.-.-.-.-.-.-.-.-.-.-.-.-.-.-.-.-.-.-.-.-.-.-.-.-.-.-.- 
 ERROR 2016-10-18 08:28:35,688 base 4764 5896 Internal Server Error: /bill/save/ 
Traceback (most recent call last):
  File "C:\Python27\lib\site-packages\django\core\handlers\base.py", line 149, in get_response
    response = self.process_exception_by_middleware(e, request)
  File "C:\Python27\lib\site-packages\django\core\handlers\base.py", line 147, in get_response
    response = wrapped_callback(request, *callback_args, **callback_kwargs)
  File "C:\Python27\lib\site-packages\django\views\decorators\csrf.py", line 58, in wrapped_view
    return view_func(*args, **kwargs)
  File "D:\Proyectos\infa web\infa_web\infa_web\apps\facturacion\views.py", line 467, in BillSave
    'vmovi': medios_pagos_total
  File "D:\Proyectos\infa web\infa_web\infa_web\apps\facturacion\views.py", line 183, in save_movideta
    movideta = movi.movideta_set.using(request_db).get(itmovi = movideta_array['itmovi'])
  File "C:\Python27\lib\site-packages\django\db\models\query.py", line 387, in get
    self.model._meta.object_name
DoesNotExist: Movideta matching query does not exist.
.-.-.-.-.-.-.-.-.-.-.-.-.-.-.-.-.-.-.-.-.-.-.-.-.-.-.-.-.-.-.-.-.-.-.-.-.-.-.-.- 
 ERROR 2016-10-18 08:29:00,197 base 4844 3136 Internal Server Error: /bill/save/ 
Traceback (most recent call last):
  File "C:\Python27\lib\site-packages\django\core\handlers\base.py", line 149, in get_response
    response = self.process_exception_by_middleware(e, request)
  File "C:\Python27\lib\site-packages\django\core\handlers\base.py", line 147, in get_response
    response = wrapped_callback(request, *callback_args, **callback_kwargs)
  File "C:\Python27\lib\site-packages\django\views\decorators\csrf.py", line 58, in wrapped_view
    return view_func(*args, **kwargs)
  File "D:\Proyectos\infa web\infa_web\infa_web\apps\facturacion\views.py", line 467, in BillSave
    'vmovi': medios_pagos_total
  File "D:\Proyectos\infa web\infa_web\infa_web\apps\facturacion\views.py", line 183, in save_movideta
    movideta = movi.movideta_set.using(request_db).get(itmovi = movideta_array['itmovi'])
AttributeError: 'QuerySet' object has no attribute 'movideta_set'
.-.-.-.-.-.-.-.-.-.-.-.-.-.-.-.-.-.-.-.-.-.-.-.-.-.-.-.-.-.-.-.-.-.-.-.-.-.-.-.- 
 ERROR 2016-10-18 08:31:04,979 base 3960 3300 Internal Server Error: /bill/save/ 
Traceback (most recent call last):
  File "C:\Python27\lib\site-packages\django\core\handlers\base.py", line 149, in get_response
    response = self.process_exception_by_middleware(e, request)
  File "C:\Python27\lib\site-packages\django\core\handlers\base.py", line 147, in get_response
    response = wrapped_callback(request, *callback_args, **callback_kwargs)
  File "C:\Python27\lib\site-packages\django\views\decorators\csrf.py", line 58, in wrapped_view
    return view_func(*args, **kwargs)
  File "D:\Proyectos\infa web\infa_web\infa_web\apps\facturacion\views.py", line 467, in BillSave
    'vmovi': medios_pagos_total
  File "D:\Proyectos\infa web\infa_web\infa_web\apps\facturacion\views.py", line 182, in save_movideta
    if movi.movideta_set.using(request_db).count() > 0:
AttributeError: 'QuerySet' object has no attribute 'movideta_set'
.-.-.-.-.-.-.-.-.-.-.-.-.-.-.-.-.-.-.-.-.-.-.-.-.-.-.-.-.-.-.-.-.-.-.-.-.-.-.-.- 
 ERROR 2016-10-18 08:34:03,408 base 4084 5992 Internal Server Error: /bill/save/ 
Traceback (most recent call last):
  File "C:\Python27\lib\site-packages\django\core\handlers\base.py", line 149, in get_response
    response = self.process_exception_by_middleware(e, request)
  File "C:\Python27\lib\site-packages\django\core\handlers\base.py", line 147, in get_response
    response = wrapped_callback(request, *callback_args, **callback_kwargs)
  File "C:\Python27\lib\site-packages\django\views\decorators\csrf.py", line 58, in wrapped_view
    return view_func(*args, **kwargs)
  File "D:\Proyectos\infa web\infa_web\infa_web\apps\facturacion\views.py", line 465, in BillSave
    'vmovi': medios_pagos_total
  File "D:\Proyectos\infa web\infa_web\infa_web\apps\facturacion\views.py", line 180, in save_movideta
    if movi.movideta__set.using(request_db).count() > 0:
AttributeError: 'Movi' object has no attribute 'movideta__set'
.-.-.-.-.-.-.-.-.-.-.-.-.-.-.-.-.-.-.-.-.-.-.-.-.-.-.-.-.-.-.-.-.-.-.-.-.-.-.-.- 
 ERROR 2016-10-18 08:36:09,072 base 4724 4928 Internal Server Error: /bill/save/ 
Traceback (most recent call last):
  File "C:\Python27\lib\site-packages\django\core\handlers\base.py", line 149, in get_response
    response = self.process_exception_by_middleware(e, request)
  File "C:\Python27\lib\site-packages\django\core\handlers\base.py", line 147, in get_response
    response = wrapped_callback(request, *callback_args, **callback_kwargs)
  File "C:\Python27\lib\site-packages\django\views\decorators\csrf.py", line 58, in wrapped_view
    return view_func(*args, **kwargs)
  File "D:\Proyectos\infa web\infa_web\infa_web\apps\facturacion\views.py", line 465, in BillSave
    'vmovi': medios_pagos_total
  File "D:\Proyectos\infa web\infa_web\infa_web\apps\facturacion\views.py", line 180, in save_movideta
    if movi.objects.movideta_set.using(request_db).count() > 0:
  File "C:\Python27\lib\site-packages\django\db\models\manager.py", line 250, in __get__
    raise AttributeError("Manager isn't accessible via %s instances" % type.__name__)
AttributeError: Manager isn't accessible via Movi instances
.-.-.-.-.-.-.-.-.-.-.-.-.-.-.-.-.-.-.-.-.-.-.-.-.-.-.-.-.-.-.-.-.-.-.-.-.-.-.-.- 
 ERROR 2016-10-18 08:37:27,255 base 4048 2524 Internal Server Error: /bill/save/ 
Traceback (most recent call last):
  File "C:\Python27\lib\site-packages\django\core\handlers\base.py", line 149, in get_response
    response = self.process_exception_by_middleware(e, request)
  File "C:\Python27\lib\site-packages\django\core\handlers\base.py", line 147, in get_response
    response = wrapped_callback(request, *callback_args, **callback_kwargs)
  File "C:\Python27\lib\site-packages\django\views\decorators\csrf.py", line 58, in wrapped_view
    return view_func(*args, **kwargs)
  File "D:\Proyectos\infa web\infa_web\infa_web\apps\facturacion\views.py", line 465, in BillSave
    'vmovi': medios_pagos_total
  File "D:\Proyectos\infa web\infa_web\infa_web\apps\facturacion\views.py", line 180, in save_movideta
    if movi.movideta_set.using(request_db).count() > 0:
AttributeError: 'QuerySet' object has no attribute 'movideta_set'
.-.-.-.-.-.-.-.-.-.-.-.-.-.-.-.-.-.-.-.-.-.-.-.-.-.-.-.-.-.-.-.-.-.-.-.-.-.-.-.- 
 ERROR 2016-10-18 08:41:45,017 base 4416 3248 Internal Server Error: /bill/save/ 
Traceback (most recent call last):
  File "C:\Python27\lib\site-packages\django\core\handlers\base.py", line 149, in get_response
    response = self.process_exception_by_middleware(e, request)
  File "C:\Python27\lib\site-packages\django\core\handlers\base.py", line 147, in get_response
    response = wrapped_callback(request, *callback_args, **callback_kwargs)
  File "C:\Python27\lib\site-packages\django\views\decorators\csrf.py", line 58, in wrapped_view
    return view_func(*args, **kwargs)
  File "D:\Proyectos\infa web\infa_web\infa_web\apps\facturacion\views.py", line 466, in BillSave
    'vmovi': medios_pagos_total
  File "D:\Proyectos\infa web\infa_web\infa_web\apps\facturacion\views.py", line 181, in save_movideta
    if movi.movideta_set.using(request_db).count() > 0:
AttributeError: 'int' object has no attribute 'movideta_set'
.-.-.-.-.-.-.-.-.-.-.-.-.-.-.-.-.-.-.-.-.-.-.-.-.-.-.-.-.-.-.-.-.-.-.-.-.-.-.-.- 
 ERROR 2016-10-18 08:42:08,446 base 1168 3352 Internal Server Error: /bill/save/ 
Traceback (most recent call last):
  File "C:\Python27\lib\site-packages\django\core\handlers\base.py", line 149, in get_response
    response = self.process_exception_by_middleware(e, request)
  File "C:\Python27\lib\site-packages\django\core\handlers\base.py", line 147, in get_response
    response = wrapped_callback(request, *callback_args, **callback_kwargs)
  File "C:\Python27\lib\site-packages\django\views\decorators\csrf.py", line 58, in wrapped_view
    return view_func(*args, **kwargs)
  File "D:\Proyectos\infa web\infa_web\infa_web\apps\facturacion\views.py", line 466, in BillSave
    'vmovi': medios_pagos_total
  File "D:\Proyectos\infa web\infa_web\infa_web\apps\facturacion\views.py", line 181, in save_movideta
    if movi.movideta_set.using(request_db).count() > 0:
AttributeError: 'QuerySet' object has no attribute 'movideta_set'
.-.-.-.-.-.-.-.-.-.-.-.-.-.-.-.-.-.-.-.-.-.-.-.-.-.-.-.-.-.-.-.-.-.-.-.-.-.-.-.- 
 ERROR 2016-10-18 09:11:28,926 base 4612 3908 Internal Server Error: /bill/save/ 
Traceback (most recent call last):
  File "C:\Python27\lib\site-packages\django\core\handlers\base.py", line 149, in get_response
    response = self.process_exception_by_middleware(e, request)
  File "C:\Python27\lib\site-packages\django\core\handlers\base.py", line 147, in get_response
    response = wrapped_callback(request, *callback_args, **callback_kwargs)
  File "C:\Python27\lib\site-packages\django\views\decorators\csrf.py", line 58, in wrapped_view
    return view_func(*args, **kwargs)
  File "D:\Proyectos\infa web\infa_web\infa_web\apps\facturacion\views.py", line 466, in BillSave
    'vmovi': medios_pagos_total
  File "D:\Proyectos\infa web\infa_web\infa_web\apps\facturacion\views.py", line 181, in save_movideta
    if movi.movideta_set.count() > 0:
AttributeError: 'QuerySet' object has no attribute 'movideta_set'
.-.-.-.-.-.-.-.-.-.-.-.-.-.-.-.-.-.-.-.-.-.-.-.-.-.-.-.-.-.-.-.-.-.-.-.-.-.-.-.- 
 ERROR 2016-10-18 09:19:27,930 base 4612 5456 Internal Server Error: /bill/save/ 
Traceback (most recent call last):
  File "C:\Python27\lib\site-packages\django\core\handlers\base.py", line 149, in get_response
    response = self.process_exception_by_middleware(e, request)
  File "C:\Python27\lib\site-packages\django\core\handlers\base.py", line 147, in get_response
    response = wrapped_callback(request, *callback_args, **callback_kwargs)
  File "C:\Python27\lib\site-packages\django\views\decorators\csrf.py", line 58, in wrapped_view
    return view_func(*args, **kwargs)
  File "D:\Proyectos\infa web\infa_web\infa_web\apps\facturacion\views.py", line 466, in BillSave
    'vmovi': medios_pagos_total
  File "D:\Proyectos\infa web\infa_web\infa_web\apps\facturacion\views.py", line 181, in save_movideta
    if movi.movideta_set.count() > 0:
AttributeError: 'QuerySet' object has no attribute 'movideta_set'
.-.-.-.-.-.-.-.-.-.-.-.-.-.-.-.-.-.-.-.-.-.-.-.-.-.-.-.-.-.-.-.-.-.-.-.-.-.-.-.- 
 ERROR 2016-10-18 09:21:04,483 base 5352 5636 Internal Server Error: /bill/save/ 
Traceback (most recent call last):
  File "C:\Python27\lib\site-packages\django\core\handlers\base.py", line 149, in get_response
    response = self.process_exception_by_middleware(e, request)
  File "C:\Python27\lib\site-packages\django\core\handlers\base.py", line 147, in get_response
    response = wrapped_callback(request, *callback_args, **callback_kwargs)
  File "C:\Python27\lib\site-packages\django\views\decorators\csrf.py", line 58, in wrapped_view
    return view_func(*args, **kwargs)
  File "D:\Proyectos\infa web\infa_web\infa_web\apps\facturacion\views.py", line 466, in BillSave
    'vmovi': medios_pagos_total
  File "D:\Proyectos\infa web\infa_web\infa_web\apps\facturacion\views.py", line 181, in save_movideta
    if movi.movideta_set.count() > 0:
AttributeError: 'QuerySet' object has no attribute 'movideta_set'
.-.-.-.-.-.-.-.-.-.-.-.-.-.-.-.-.-.-.-.-.-.-.-.-.-.-.-.-.-.-.-.-.-.-.-.-.-.-.-.- 
 ERROR 2016-10-18 09:21:49,607 base 5268 3260 Internal Server Error: /bill/save/ 
Traceback (most recent call last):
  File "C:\Python27\lib\site-packages\django\core\handlers\base.py", line 149, in get_response
    response = self.process_exception_by_middleware(e, request)
  File "C:\Python27\lib\site-packages\django\core\handlers\base.py", line 147, in get_response
    response = wrapped_callback(request, *callback_args, **callback_kwargs)
  File "C:\Python27\lib\site-packages\django\views\decorators\csrf.py", line 58, in wrapped_view
    return view_func(*args, **kwargs)
  File "D:\Proyectos\infa web\infa_web\infa_web\apps\facturacion\views.py", line 466, in BillSave
    'vmovi': medios_pagos_total
  File "D:\Proyectos\infa web\infa_web\infa_web\apps\facturacion\views.py", line 180, in save_movideta
    movi = movideta_array['cmovi'] if movi.count() == 0 else (movi[0] if movi.count() > 1 else movi)
AttributeError: 'QuerySet' object has no attribute 'movideta_set'
.-.-.-.-.-.-.-.-.-.-.-.-.-.-.-.-.-.-.-.-.-.-.-.-.-.-.-.-.-.-.-.-.-.-.-.-.-.-.-.- 
 ERROR 2016-10-18 09:22:56,312 base 5268 3624 Internal Server Error: /bill/save/ 
Traceback (most recent call last):
  File "C:\Python27\lib\site-packages\django\core\handlers\base.py", line 149, in get_response
    response = self.process_exception_by_middleware(e, request)
  File "C:\Python27\lib\site-packages\django\core\handlers\base.py", line 147, in get_response
    response = wrapped_callback(request, *callback_args, **callback_kwargs)
  File "C:\Python27\lib\site-packages\django\views\decorators\csrf.py", line 58, in wrapped_view
    return view_func(*args, **kwargs)
  File "D:\Proyectos\infa web\infa_web\infa_web\apps\facturacion\views.py", line 466, in BillSave
    'vmovi': medios_pagos_total
  File "D:\Proyectos\infa web\infa_web\infa_web\apps\facturacion\views.py", line 180, in save_movideta
    movi = movideta_array['cmovi'] if movi.count() == 0 else (movi[0] if movi.count() > 1 else movi)
AttributeError: 'QuerySet' object has no attribute 'movideta_set'
.-.-.-.-.-.-.-.-.-.-.-.-.-.-.-.-.-.-.-.-.-.-.-.-.-.-.-.-.-.-.-.-.-.-.-.-.-.-.-.- 
 ERROR 2016-10-18 09:24:10,454 base 2440 5556 Internal Server Error: /bill/save/ 
Traceback (most recent call last):
  File "C:\Python27\lib\site-packages\django\core\handlers\base.py", line 149, in get_response
    response = self.process_exception_by_middleware(e, request)
  File "C:\Python27\lib\site-packages\django\core\handlers\base.py", line 147, in get_response
    response = wrapped_callback(request, *callback_args, **callback_kwargs)
  File "C:\Python27\lib\site-packages\django\views\decorators\csrf.py", line 58, in wrapped_view
    return view_func(*args, **kwargs)
  File "D:\Proyectos\infa web\infa_web\infa_web\apps\facturacion\views.py", line 465, in BillSave
    'vmovi': medios_pagos_total
  File "D:\Proyectos\infa web\infa_web\infa_web\apps\facturacion\views.py", line 179, in save_movideta
    movi = movideta_array['cmovi'] if movi.movideta_set.count() == 0 else (movi[0] if movi.count() > 1 else movi)
AttributeError: 'QuerySet' object has no attribute 'movideta_set'
.-.-.-.-.-.-.-.-.-.-.-.-.-.-.-.-.-.-.-.-.-.-.-.-.-.-.-.-.-.-.-.-.-.-.-.-.-.-.-.- 
 ERROR 2016-10-18 09:24:46,948 base 3360 680 Internal Server Error: /bill/save/ 
Traceback (most recent call last):
  File "C:\Python27\lib\site-packages\django\core\handlers\base.py", line 149, in get_response
    response = self.process_exception_by_middleware(e, request)
  File "C:\Python27\lib\site-packages\django\core\handlers\base.py", line 147, in get_response
    response = wrapped_callback(request, *callback_args, **callback_kwargs)
  File "C:\Python27\lib\site-packages\django\views\decorators\csrf.py", line 58, in wrapped_view
    return view_func(*args, **kwargs)
  File "D:\Proyectos\infa web\infa_web\infa_web\apps\facturacion\views.py", line 466, in BillSave
    'vmovi': medios_pagos_total
  File "D:\Proyectos\infa web\infa_web\infa_web\apps\facturacion\views.py", line 179, in save_movideta
    print movi.movideta_set.count()
AttributeError: 'QuerySet' object has no attribute 'movideta_set'
.-.-.-.-.-.-.-.-.-.-.-.-.-.-.-.-.-.-.-.-.-.-.-.-.-.-.-.-.-.-.-.-.-.-.-.-.-.-.-.- 
 ERROR 2016-10-18 09:26:11,726 base 5720 5376 Internal Server Error: /bill/save/ 
Traceback (most recent call last):
  File "C:\Python27\lib\site-packages\django\core\handlers\base.py", line 149, in get_response
    response = self.process_exception_by_middleware(e, request)
  File "C:\Python27\lib\site-packages\django\core\handlers\base.py", line 147, in get_response
    response = wrapped_callback(request, *callback_args, **callback_kwargs)
  File "C:\Python27\lib\site-packages\django\views\decorators\csrf.py", line 58, in wrapped_view
    return view_func(*args, **kwargs)
  File "D:\Proyectos\infa web\infa_web\infa_web\apps\facturacion\views.py", line 464, in BillSave
    'vmovi': medios_pagos_total
  File "D:\Proyectos\infa web\infa_web\infa_web\apps\facturacion\views.py", line 180, in save_movideta
    movideta = movi[0].movideta_set.using(request_db).get(itmovi = movideta_array['itmovi'])
  File "C:\Python27\lib\site-packages\django\db\models\query.py", line 387, in get
    self.model._meta.object_name
DoesNotExist: Movideta matching query does not exist.
.-.-.-.-.-.-.-.-.-.-.-.-.-.-.-.-.-.-.-.-.-.-.-.-.-.-.-.-.-.-.-.-.-.-.-.-.-.-.-.- 
 ERROR 2016-10-18 09:27:03,928 base 5412 4880 Internal Server Error: /bill/save/ 
Traceback (most recent call last):
  File "C:\Python27\lib\site-packages\django\core\handlers\base.py", line 149, in get_response
    response = self.process_exception_by_middleware(e, request)
  File "C:\Python27\lib\site-packages\django\core\handlers\base.py", line 147, in get_response
    response = wrapped_callback(request, *callback_args, **callback_kwargs)
  File "C:\Python27\lib\site-packages\django\views\decorators\csrf.py", line 58, in wrapped_view
    return view_func(*args, **kwargs)
  File "D:\Proyectos\infa web\infa_web\infa_web\apps\facturacion\views.py", line 464, in BillSave
    'vmovi': medios_pagos_total
  File "D:\Proyectos\infa web\infa_web\infa_web\apps\facturacion\views.py", line 180, in save_movideta
    movideta = movi[0].movideta_set.using(request_db).get(itmovi = movideta_array['itmovi'])
  File "C:\Python27\lib\site-packages\django\db\models\query.py", line 297, in __getitem__
    return list(qs)[0]
IndexError: list index out of range
.-.-.-.-.-.-.-.-.-.-.-.-.-.-.-.-.-.-.-.-.-.-.-.-.-.-.-.-.-.-.-.-.-.-.-.-.-.-.-.- 
 ERROR 2016-10-18 09:28:23,073 base 896 4432 Internal Server Error: /bill/save/ 
Traceback (most recent call last):
  File "C:\Python27\lib\site-packages\django\core\handlers\base.py", line 149, in get_response
    response = self.process_exception_by_middleware(e, request)
  File "C:\Python27\lib\site-packages\django\core\handlers\base.py", line 147, in get_response
    response = wrapped_callback(request, *callback_args, **callback_kwargs)
  File "C:\Python27\lib\site-packages\django\views\decorators\csrf.py", line 58, in wrapped_view
    return view_func(*args, **kwargs)
  File "D:\Proyectos\infa web\infa_web\infa_web\apps\facturacion\views.py", line 465, in BillSave
    'vmovi': medios_pagos_total
  File "D:\Proyectos\infa web\infa_web\infa_web\apps\facturacion\views.py", line 181, in save_movideta
    movideta = movi[0].movideta_set.using(request_db).get(itmovi = movideta_array['itmovi'])
  File "C:\Python27\lib\site-packages\django\db\models\query.py", line 297, in __getitem__
    return list(qs)[0]
IndexError: list index out of range
.-.-.-.-.-.-.-.-.-.-.-.-.-.-.-.-.-.-.-.-.-.-.-.-.-.-.-.-.-.-.-.-.-.-.-.-.-.-.-.- 
 ERROR 2016-10-18 09:30:00,618 base 5504 2860 Internal Server Error: /bill/save/ 
Traceback (most recent call last):
  File "C:\Python27\lib\site-packages\django\core\handlers\base.py", line 149, in get_response
    response = self.process_exception_by_middleware(e, request)
  File "C:\Python27\lib\site-packages\django\core\handlers\base.py", line 147, in get_response
    response = wrapped_callback(request, *callback_args, **callback_kwargs)
  File "C:\Python27\lib\site-packages\django\views\decorators\csrf.py", line 58, in wrapped_view
    return view_func(*args, **kwargs)
  File "D:\Proyectos\infa web\infa_web\infa_web\apps\facturacion\views.py", line 465, in BillSave
    'vmovi': medios_pagos_total
  File "D:\Proyectos\infa web\infa_web\infa_web\apps\facturacion\views.py", line 181, in save_movideta
    movideta = movi.movideta_set.using(request_db).get(itmovi = movideta_array['itmovi'])
AttributeError: 'QuerySet' object has no attribute 'movideta_set'
.-.-.-.-.-.-.-.-.-.-.-.-.-.-.-.-.-.-.-.-.-.-.-.-.-.-.-.-.-.-.-.-.-.-.-.-.-.-.-.- 
 ERROR 2016-10-18 09:33:36,967 base 2372 5540 Internal Server Error: /bill/save/ 
Traceback (most recent call last):
  File "C:\Python27\lib\site-packages\django\core\handlers\base.py", line 149, in get_response
    response = self.process_exception_by_middleware(e, request)
  File "C:\Python27\lib\site-packages\django\core\handlers\base.py", line 147, in get_response
    response = wrapped_callback(request, *callback_args, **callback_kwargs)
  File "C:\Python27\lib\site-packages\django\views\decorators\csrf.py", line 58, in wrapped_view
    return view_func(*args, **kwargs)
  File "D:\Proyectos\infa web\infa_web\infa_web\apps\facturacion\views.py", line 465, in BillSave
    'vmovi': medios_pagos_total
  File "D:\Proyectos\infa web\infa_web\infa_web\apps\facturacion\views.py", line 179, in save_movideta
    movi =  Movi.objects.get(cmovi = (movideta_array['cmovi'].pk if not movi else (movi[0].pk if movi.count() > 1 else movi.pk)))
AttributeError: 'QuerySet' object has no attribute 'pk'
.-.-.-.-.-.-.-.-.-.-.-.-.-.-.-.-.-.-.-.-.-.-.-.-.-.-.-.-.-.-.-.-.-.-.-.-.-.-.-.- 
 ERROR 2016-10-18 09:34:18,388 base 4892 4284 Internal Server Error: /bill/save/ 
Traceback (most recent call last):
  File "C:\Python27\lib\site-packages\django\core\handlers\base.py", line 149, in get_response
    response = self.process_exception_by_middleware(e, request)
  File "C:\Python27\lib\site-packages\django\core\handlers\base.py", line 147, in get_response
    response = wrapped_callback(request, *callback_args, **callback_kwargs)
  File "C:\Python27\lib\site-packages\django\views\decorators\csrf.py", line 58, in wrapped_view
    return view_func(*args, **kwargs)
  File "D:\Proyectos\infa web\infa_web\infa_web\apps\facturacion\views.py", line 465, in BillSave
    'vmovi': medios_pagos_total
  File "D:\Proyectos\infa web\infa_web\infa_web\apps\facturacion\views.py", line 179, in save_movideta
    movi =  Movi.objects.get(cmovi = (movideta_array['cmovi'].cmovi if not movi else (movi[0] if movi.count() > 1 else movi.cmovi)))
AttributeError: 'QuerySet' object has no attribute 'cmovi'
.-.-.-.-.-.-.-.-.-.-.-.-.-.-.-.-.-.-.-.-.-.-.-.-.-.-.-.-.-.-.-.-.-.-.-.-.-.-.-.- 
 ERROR 2016-10-18 09:34:42,184 base 660 2892 Internal Server Error: /bill/save/ 
Traceback (most recent call last):
  File "C:\Python27\lib\site-packages\django\core\handlers\base.py", line 149, in get_response
    response = self.process_exception_by_middleware(e, request)
  File "C:\Python27\lib\site-packages\django\core\handlers\base.py", line 147, in get_response
    response = wrapped_callback(request, *callback_args, **callback_kwargs)
  File "C:\Python27\lib\site-packages\django\views\decorators\csrf.py", line 58, in wrapped_view
    return view_func(*args, **kwargs)
  File "D:\Proyectos\infa web\infa_web\infa_web\apps\facturacion\views.py", line 465, in BillSave
    'vmovi': medios_pagos_total
  File "D:\Proyectos\infa web\infa_web\infa_web\apps\facturacion\views.py", line 179, in save_movideta
    movi =  Movi.objects.get(cmovi = (movideta_array['cmovi'] if not movi else (movi[0] if movi.count() > 1 else movi.cmovi)))
AttributeError: 'QuerySet' object has no attribute 'cmovi'
.-.-.-.-.-.-.-.-.-.-.-.-.-.-.-.-.-.-.-.-.-.-.-.-.-.-.-.-.-.-.-.-.-.-.-.-.-.-.-.- 
 ERROR 2016-10-18 09:34:59,947 base 444 5568 Internal Server Error: /bill/save/ 
Traceback (most recent call last):
  File "C:\Python27\lib\site-packages\django\core\handlers\base.py", line 149, in get_response
    response = self.process_exception_by_middleware(e, request)
  File "C:\Python27\lib\site-packages\django\core\handlers\base.py", line 147, in get_response
    response = wrapped_callback(request, *callback_args, **callback_kwargs)
  File "C:\Python27\lib\site-packages\django\views\decorators\csrf.py", line 58, in wrapped_view
    return view_func(*args, **kwargs)
  File "D:\Proyectos\infa web\infa_web\infa_web\apps\facturacion\views.py", line 465, in BillSave
    'vmovi': medios_pagos_total
  File "D:\Proyectos\infa web\infa_web\infa_web\apps\facturacion\views.py", line 179, in save_movideta
    movi =  Movi.objects.get(cmovi = (movideta_array['cmovi'].cmovi if not movi else (movi[0] if movi.count() > 1 else movi)))
  File "C:\Python27\lib\site-packages\django\db\models\manager.py", line 122, in manager_method
    return getattr(self.get_queryset(), name)(*args, **kwargs)
  File "C:\Python27\lib\site-packages\django\db\models\query.py", line 381, in get
    num = len(clone)
  File "C:\Python27\lib\site-packages\django\db\models\query.py", line 240, in __len__
    self._fetch_all()
  File "C:\Python27\lib\site-packages\django\db\models\query.py", line 1074, in _fetch_all
    self._result_cache = list(self.iterator())
  File "C:\Python27\lib\site-packages\django\db\models\query.py", line 52, in __iter__
    results = compiler.execute_sql()
  File "C:\Python27\lib\site-packages\django\db\models\sql\compiler.py", line 837, in execute_sql
    sql, params = self.as_sql()
  File "C:\Python27\lib\site-packages\django\db\models\sql\compiler.py", line 389, in as_sql
    where, w_params = self.compile(self.where) if self.where is not None else ("", [])
  File "C:\Python27\lib\site-packages\django\db\models\sql\compiler.py", line 366, in compile
    sql, params = node.as_sql(self, self.connection)
  File "C:\Python27\lib\site-packages\django\db\models\sql\where.py", line 79, in as_sql
    sql, params = compiler.compile(child)
  File "C:\Python27\lib\site-packages\django\db\models\sql\compiler.py", line 366, in compile
    sql, params = node.as_sql(self, self.connection)
  File "C:\Python27\lib\site-packages\django\db\models\lookups.py", line 158, in as_sql
    rhs_sql, rhs_params = self.process_rhs(compiler, connection)
  File "C:\Python27\lib\site-packages\django\db\models\lookups.py", line 88, in process_rhs
    sql, params = value._as_sql(connection=connection)
  File "C:\Python27\lib\site-packages\django\db\models\query.py", line 1139, in _as_sql
    raise ValueError("Can't do subqueries with queries on different DBs.")
ValueError: Can't do subqueries with queries on different DBs.
.-.-.-.-.-.-.-.-.-.-.-.-.-.-.-.-.-.-.-.-.-.-.-.-.-.-.-.-.-.-.-.-.-.-.-.-.-.-.-.- 
 ERROR 2016-10-18 10:22:13,795 base 3992 5560 Internal Server Error: /cartera/ 
Traceback (most recent call last):
  File "C:\Python27\lib\site-packages\django\core\handlers\base.py", line 174, in get_response
    response = self.process_exception_by_middleware(e, request)
  File "C:\Python27\lib\site-packages\django\core\handlers\base.py", line 172, in get_response
    response = response.render()
  File "C:\Python27\lib\site-packages\django\template\response.py", line 160, in render
    self.content = self.rendered_content
  File "C:\Python27\lib\site-packages\django\template\response.py", line 135, in rendered_content
    template = self._resolve_template(self.template_name)
  File "C:\Python27\lib\site-packages\django\template\response.py", line 90, in _resolve_template
    new_template = self.resolve_template(template)
  File "C:\Python27\lib\site-packages\django\template\response.py", line 80, in resolve_template
    return select_template(template, using=self.using)
  File "C:\Python27\lib\site-packages\django\template\loader.py", line 62, in select_template
    return engine.get_template(template_name, dirs)
  File "C:\Python27\lib\site-packages\django\template\backends\django.py", line 40, in get_template
    return Template(self.engine.get_template(template_name, dirs), self)
  File "C:\Python27\lib\site-packages\django\template\engine.py", line 190, in get_template
    template, origin = self.find_template(template_name, dirs)
  File "C:\Python27\lib\site-packages\django\template\engine.py", line 157, in find_template
    name, template_dirs=dirs, skip=skip,
  File "C:\Python27\lib\site-packages\django\template\loaders\base.py", line 46, in get_template
    contents, origin, origin.template_name, self.engine,
  File "C:\Python27\lib\site-packages\django\template\base.py", line 189, in __init__
    self.nodelist = self.compile_nodelist()
  File "C:\Python27\lib\site-packages\django\template\base.py", line 231, in compile_nodelist
    return parser.parse()
  File "C:\Python27\lib\site-packages\django\template\base.py", line 516, in parse
    raise self.error(token, e)
TemplateSyntaxError: Invalid filter: 'vttotal'
.-.-.-.-.-.-.-.-.-.-.-.-.-.-.-.-.-.-.-.-.-.-.-.-.-.-.-.-.-.-.-.-.-.-.-.-.-.-.-.- 
 ERROR 2016-10-18 10:30:33,713 base 1476 4952 Internal Server Error: /cartera/ 
Traceback (most recent call last):
  File "C:\Python27\lib\site-packages\django\core\handlers\base.py", line 174, in get_response
    response = self.process_exception_by_middleware(e, request)
  File "C:\Python27\lib\site-packages\django\core\handlers\base.py", line 172, in get_response
    response = response.render()
  File "C:\Python27\lib\site-packages\django\template\response.py", line 160, in render
    self.content = self.rendered_content
  File "C:\Python27\lib\site-packages\django\template\response.py", line 137, in rendered_content
    content = template.render(context, self._request)
  File "C:\Python27\lib\site-packages\django\template\backends\django.py", line 95, in render
    return self.template.render(context)
  File "C:\Python27\lib\site-packages\django\template\base.py", line 206, in render
    return self._render(context)
  File "C:\Python27\lib\site-packages\django\template\base.py", line 197, in _render
    return self.nodelist.render(context)
  File "C:\Python27\lib\site-packages\django\template\base.py", line 992, in render
    bit = node.render_annotated(context)
  File "C:\Python27\lib\site-packages\django\template\base.py", line 959, in render_annotated
    return self.render(context)
  File "C:\Python27\lib\site-packages\django\template\loader_tags.py", line 173, in render
    return compiled_parent._render(context)
  File "C:\Python27\lib\site-packages\django\template\base.py", line 197, in _render
    return self.nodelist.render(context)
  File "C:\Python27\lib\site-packages\django\template\base.py", line 992, in render
    bit = node.render_annotated(context)
  File "C:\Python27\lib\site-packages\django\template\base.py", line 959, in render_annotated
    return self.render(context)
  File "C:\Python27\lib\site-packages\django\template\loader_tags.py", line 69, in render
    result = block.nodelist.render(context)
  File "C:\Python27\lib\site-packages\django\template\base.py", line 992, in render
    bit = node.render_annotated(context)
  File "C:\Python27\lib\site-packages\django\template\base.py", line 959, in render_annotated
    return self.render(context)
  File "C:\Python27\lib\site-packages\django\template\defaulttags.py", line 168, in render
    len_values = len(values)
  File "C:\Python27\lib\site-packages\django\db\models\query.py", line 240, in __len__
    self._fetch_all()
  File "C:\Python27\lib\site-packages\django\db\models\query.py", line 1074, in _fetch_all
    self._result_cache = list(self.iterator())
  File "C:\Python27\lib\site-packages\django\db\models\query.py", line 52, in __iter__
    results = compiler.execute_sql()
  File "C:\Python27\lib\site-packages\django\db\models\sql\compiler.py", line 837, in execute_sql
    sql, params = self.as_sql()
  File "C:\Python27\lib\site-packages\django\db\models\sql\compiler.py", line 382, in as_sql
    extra_select, order_by, group_by = self.pre_sql_setup()
  File "C:\Python27\lib\site-packages\django\db\models\sql\compiler.py", line 49, in pre_sql_setup
    order_by = self.get_order_by()
  File "C:\Python27\lib\site-packages\django\db\models\sql\compiler.py", line 295, in get_order_by
    field, self.query.get_meta(), default_order=asc))
  File "C:\Python27\lib\site-packages\django\db\models\sql\compiler.py", line 566, in find_ordering_name
    field, targets, alias, joins, path, opts = self._setup_joins(pieces, opts, alias)
  File "C:\Python27\lib\site-packages\django\db\models\sql\compiler.py", line 599, in _setup_joins
    pieces, opts, alias)
  File "C:\Python27\lib\site-packages\django\db\models\sql\query.py", line 1405, in setup_joins
    names, opts, allow_many, fail_on_missing=True)
  File "C:\Python27\lib\site-packages\django\db\models\sql\query.py", line 1330, in names_to_path
    "Choices are: %s" % (name, ", ".join(available)))
FieldError: Cannot resolve keyword 'nombre_proyecto' into field. Choices are: baseiva, ccaja, ccaja_id, cesdo, cesdo_id, citerce, citerce_id, cmovi, ctimo, ctimo_id, descrimovi, detaanula, fmovi, movideta, movipago, vcambio, vch, vcred, vefe, ventre, vtar, vtdescu, vtiva, vtsuma, vttotal
.-.-.-.-.-.-.-.-.-.-.-.-.-.-.-.-.-.-.-.-.-.-.-.-.-.-.-.-.-.-.-.-.-.-.-.-.-.-.-.- 
 ERROR 2016-10-19 09:12:58,450 base 4984 3204 Internal Server Error: /cartera/ 
Traceback (most recent call last):
  File "C:\Python27\lib\site-packages\django\core\handlers\base.py", line 174, in get_response
    response = self.process_exception_by_middleware(e, request)
  File "C:\Python27\lib\site-packages\django\core\handlers\base.py", line 172, in get_response
    response = response.render()
  File "C:\Python27\lib\site-packages\django\template\response.py", line 160, in render
    self.content = self.rendered_content
  File "C:\Python27\lib\site-packages\django\template\response.py", line 135, in rendered_content
    template = self._resolve_template(self.template_name)
  File "C:\Python27\lib\site-packages\django\template\response.py", line 90, in _resolve_template
    new_template = self.resolve_template(template)
  File "C:\Python27\lib\site-packages\django\template\response.py", line 80, in resolve_template
    return select_template(template, using=self.using)
  File "C:\Python27\lib\site-packages\django\template\loader.py", line 62, in select_template
    return engine.get_template(template_name, dirs)
  File "C:\Python27\lib\site-packages\django\template\backends\django.py", line 40, in get_template
    return Template(self.engine.get_template(template_name, dirs), self)
  File "C:\Python27\lib\site-packages\django\template\engine.py", line 190, in get_template
    template, origin = self.find_template(template_name, dirs)
  File "C:\Python27\lib\site-packages\django\template\engine.py", line 157, in find_template
    name, template_dirs=dirs, skip=skip,
  File "C:\Python27\lib\site-packages\django\template\loaders\base.py", line 46, in get_template
    contents, origin, origin.template_name, self.engine,
  File "C:\Python27\lib\site-packages\django\template\base.py", line 189, in __init__
    self.nodelist = self.compile_nodelist()
  File "C:\Python27\lib\site-packages\django\template\base.py", line 231, in compile_nodelist
    return parser.parse()
  File "C:\Python27\lib\site-packages\django\template\base.py", line 516, in parse
    raise self.error(token, e)
TemplateSyntaxError: saldo_factura requires 3 arguments, 2 provided
.-.-.-.-.-.-.-.-.-.-.-.-.-.-.-.-.-.-.-.-.-.-.-.-.-.-.-.-.-.-.-.-.-.-.-.-.-.-.-.- 
 ERROR 2016-10-19 09:13:50,020 base 4984 1756 Internal Server Error: /cartera/ 
Traceback (most recent call last):
  File "C:\Python27\lib\site-packages\django\core\handlers\base.py", line 174, in get_response
    response = self.process_exception_by_middleware(e, request)
  File "C:\Python27\lib\site-packages\django\core\handlers\base.py", line 172, in get_response
    response = response.render()
  File "C:\Python27\lib\site-packages\django\template\response.py", line 160, in render
    self.content = self.rendered_content
  File "C:\Python27\lib\site-packages\django\template\response.py", line 135, in rendered_content
    template = self._resolve_template(self.template_name)
  File "C:\Python27\lib\site-packages\django\template\response.py", line 90, in _resolve_template
    new_template = self.resolve_template(template)
  File "C:\Python27\lib\site-packages\django\template\response.py", line 80, in resolve_template
    return select_template(template, using=self.using)
  File "C:\Python27\lib\site-packages\django\template\loader.py", line 62, in select_template
    return engine.get_template(template_name, dirs)
  File "C:\Python27\lib\site-packages\django\template\backends\django.py", line 40, in get_template
    return Template(self.engine.get_template(template_name, dirs), self)
  File "C:\Python27\lib\site-packages\django\template\engine.py", line 190, in get_template
    template, origin = self.find_template(template_name, dirs)
  File "C:\Python27\lib\site-packages\django\template\engine.py", line 157, in find_template
    name, template_dirs=dirs, skip=skip,
  File "C:\Python27\lib\site-packages\django\template\loaders\base.py", line 46, in get_template
    contents, origin, origin.template_name, self.engine,
  File "C:\Python27\lib\site-packages\django\template\base.py", line 189, in __init__
    self.nodelist = self.compile_nodelist()
  File "C:\Python27\lib\site-packages\django\template\base.py", line 231, in compile_nodelist
    return parser.parse()
  File "C:\Python27\lib\site-packages\django\template\base.py", line 516, in parse
    raise self.error(token, e)
TemplateSyntaxError: saldo_factura requires 3 arguments, 1 provided
.-.-.-.-.-.-.-.-.-.-.-.-.-.-.-.-.-.-.-.-.-.-.-.-.-.-.-.-.-.-.-.-.-.-.-.-.-.-.-.- 
 ERROR 2016-10-19 09:18:41,066 base 5088 2920 Internal Server Error: /cartera/ 
Traceback (most recent call last):
  File "C:\Python27\lib\site-packages\django\core\handlers\base.py", line 174, in get_response
    response = self.process_exception_by_middleware(e, request)
  File "C:\Python27\lib\site-packages\django\core\handlers\base.py", line 172, in get_response
    response = response.render()
  File "C:\Python27\lib\site-packages\django\template\response.py", line 160, in render
    self.content = self.rendered_content
  File "C:\Python27\lib\site-packages\django\template\response.py", line 135, in rendered_content
    template = self._resolve_template(self.template_name)
  File "C:\Python27\lib\site-packages\django\template\response.py", line 90, in _resolve_template
    new_template = self.resolve_template(template)
  File "C:\Python27\lib\site-packages\django\template\response.py", line 80, in resolve_template
    return select_template(template, using=self.using)
  File "C:\Python27\lib\site-packages\django\template\loader.py", line 62, in select_template
    return engine.get_template(template_name, dirs)
  File "C:\Python27\lib\site-packages\django\template\backends\django.py", line 40, in get_template
    return Template(self.engine.get_template(template_name, dirs), self)
  File "C:\Python27\lib\site-packages\django\template\engine.py", line 190, in get_template
    template, origin = self.find_template(template_name, dirs)
  File "C:\Python27\lib\site-packages\django\template\engine.py", line 157, in find_template
    name, template_dirs=dirs, skip=skip,
  File "C:\Python27\lib\site-packages\django\template\loaders\base.py", line 46, in get_template
    contents, origin, origin.template_name, self.engine,
  File "C:\Python27\lib\site-packages\django\template\base.py", line 189, in __init__
    self.nodelist = self.compile_nodelist()
  File "C:\Python27\lib\site-packages\django\template\base.py", line 231, in compile_nodelist
    return parser.parse()
  File "C:\Python27\lib\site-packages\django\template\base.py", line 516, in parse
    raise self.error(token, e)
TemplateSyntaxError: Could not parse some characters: movi.vttotal|saldo_factura:"cii="|+movi.pk+"&request_db="+request.db||intcomma
.-.-.-.-.-.-.-.-.-.-.-.-.-.-.-.-.-.-.-.-.-.-.-.-.-.-.-.-.-.-.-.-.-.-.-.-.-.-.-.- 
 ERROR 2016-10-19 09:19:13,558 base 5088 5908 Internal Server Error: /cartera/ 
Traceback (most recent call last):
  File "C:\Python27\lib\site-packages\django\core\handlers\base.py", line 174, in get_response
    response = self.process_exception_by_middleware(e, request)
  File "C:\Python27\lib\site-packages\django\core\handlers\base.py", line 172, in get_response
    response = response.render()
  File "C:\Python27\lib\site-packages\django\template\response.py", line 160, in render
    self.content = self.rendered_content
  File "C:\Python27\lib\site-packages\django\template\response.py", line 135, in rendered_content
    template = self._resolve_template(self.template_name)
  File "C:\Python27\lib\site-packages\django\template\response.py", line 90, in _resolve_template
    new_template = self.resolve_template(template)
  File "C:\Python27\lib\site-packages\django\template\response.py", line 80, in resolve_template
    return select_template(template, using=self.using)
  File "C:\Python27\lib\site-packages\django\template\loader.py", line 62, in select_template
    return engine.get_template(template_name, dirs)
  File "C:\Python27\lib\site-packages\django\template\backends\django.py", line 40, in get_template
    return Template(self.engine.get_template(template_name, dirs), self)
  File "C:\Python27\lib\site-packages\django\template\engine.py", line 190, in get_template
    template, origin = self.find_template(template_name, dirs)
  File "C:\Python27\lib\site-packages\django\template\engine.py", line 157, in find_template
    name, template_dirs=dirs, skip=skip,
  File "C:\Python27\lib\site-packages\django\template\loaders\base.py", line 46, in get_template
    contents, origin, origin.template_name, self.engine,
  File "C:\Python27\lib\site-packages\django\template\base.py", line 189, in __init__
    self.nodelist = self.compile_nodelist()
  File "C:\Python27\lib\site-packages\django\template\base.py", line 231, in compile_nodelist
    return parser.parse()
  File "C:\Python27\lib\site-packages\django\template\base.py", line 516, in parse
    raise self.error(token, e)
TemplateSyntaxError: Could not parse some characters: movi.vttotal|saldo_factura:"cii="|+movi.pk+"&request_db="+request.db||intcomma
.-.-.-.-.-.-.-.-.-.-.-.-.-.-.-.-.-.-.-.-.-.-.-.-.-.-.-.-.-.-.-.-.-.-.-.-.-.-.-.- 
 ERROR 2016-10-19 09:19:59,473 base 5088 3176 Internal Server Error: /cartera/ 
Traceback (most recent call last):
  File "C:\Python27\lib\site-packages\django\core\handlers\base.py", line 174, in get_response
    response = self.process_exception_by_middleware(e, request)
  File "C:\Python27\lib\site-packages\django\core\handlers\base.py", line 172, in get_response
    response = response.render()
  File "C:\Python27\lib\site-packages\django\template\response.py", line 160, in render
    self.content = self.rendered_content
  File "C:\Python27\lib\site-packages\django\template\response.py", line 135, in rendered_content
    template = self._resolve_template(self.template_name)
  File "C:\Python27\lib\site-packages\django\template\response.py", line 90, in _resolve_template
    new_template = self.resolve_template(template)
  File "C:\Python27\lib\site-packages\django\template\response.py", line 80, in resolve_template
    return select_template(template, using=self.using)
  File "C:\Python27\lib\site-packages\django\template\loader.py", line 62, in select_template
    return engine.get_template(template_name, dirs)
  File "C:\Python27\lib\site-packages\django\template\backends\django.py", line 40, in get_template
    return Template(self.engine.get_template(template_name, dirs), self)
  File "C:\Python27\lib\site-packages\django\template\engine.py", line 190, in get_template
    template, origin = self.find_template(template_name, dirs)
  File "C:\Python27\lib\site-packages\django\template\engine.py", line 157, in find_template
    name, template_dirs=dirs, skip=skip,
  File "C:\Python27\lib\site-packages\django\template\loaders\base.py", line 46, in get_template
    contents, origin, origin.template_name, self.engine,
  File "C:\Python27\lib\site-packages\django\template\base.py", line 189, in __init__
    self.nodelist = self.compile_nodelist()
  File "C:\Python27\lib\site-packages\django\template\base.py", line 231, in compile_nodelist
    return parser.parse()
  File "C:\Python27\lib\site-packages\django\template\base.py", line 516, in parse
    raise self.error(token, e)
TemplateSyntaxError: Could not parse the remainder: '+movi.pk+"&request_db="+request.db' from 'movi.vttotal|saldo_factura:"cii="+movi.pk+"&request_db="+request.db'
.-.-.-.-.-.-.-.-.-.-.-.-.-.-.-.-.-.-.-.-.-.-.-.-.-.-.-.-.-.-.-.-.-.-.-.-.-.-.-.- 
 ERROR 2016-10-19 09:24:15,227 base 5088 4084 Internal Server Error: /cartera/ 
Traceback (most recent call last):
  File "C:\Python27\lib\site-packages\django\core\handlers\base.py", line 174, in get_response
    response = self.process_exception_by_middleware(e, request)
  File "C:\Python27\lib\site-packages\django\core\handlers\base.py", line 172, in get_response
    response = response.render()
  File "C:\Python27\lib\site-packages\django\template\response.py", line 160, in render
    self.content = self.rendered_content
  File "C:\Python27\lib\site-packages\django\template\response.py", line 135, in rendered_content
    template = self._resolve_template(self.template_name)
  File "C:\Python27\lib\site-packages\django\template\response.py", line 90, in _resolve_template
    new_template = self.resolve_template(template)
  File "C:\Python27\lib\site-packages\django\template\response.py", line 80, in resolve_template
    return select_template(template, using=self.using)
  File "C:\Python27\lib\site-packages\django\template\loader.py", line 62, in select_template
    return engine.get_template(template_name, dirs)
  File "C:\Python27\lib\site-packages\django\template\backends\django.py", line 40, in get_template
    return Template(self.engine.get_template(template_name, dirs), self)
  File "C:\Python27\lib\site-packages\django\template\engine.py", line 190, in get_template
    template, origin = self.find_template(template_name, dirs)
  File "C:\Python27\lib\site-packages\django\template\engine.py", line 157, in find_template
    name, template_dirs=dirs, skip=skip,
  File "C:\Python27\lib\site-packages\django\template\loaders\base.py", line 46, in get_template
    contents, origin, origin.template_name, self.engine,
  File "C:\Python27\lib\site-packages\django\template\base.py", line 189, in __init__
    self.nodelist = self.compile_nodelist()
  File "C:\Python27\lib\site-packages\django\template\base.py", line 231, in compile_nodelist
    return parser.parse()
  File "C:\Python27\lib\site-packages\django\template\base.py", line 516, in parse
    raise self.error(token, e)
TemplateSyntaxError: Could not parse the remainder: '+movi.pk+"&request_db="+request.db' from 'movi.vttotal|saldo_factura:"cii="+movi.pk+"&request_db="+request.db'
.-.-.-.-.-.-.-.-.-.-.-.-.-.-.-.-.-.-.-.-.-.-.-.-.-.-.-.-.-.-.-.-.-.-.-.-.-.-.-.- 
 ERROR 2016-10-19 09:24:23,239 base 5088 692 Internal Server Error: /cartera/ 
Traceback (most recent call last):
  File "C:\Python27\lib\site-packages\django\core\handlers\base.py", line 174, in get_response
    response = self.process_exception_by_middleware(e, request)
  File "C:\Python27\lib\site-packages\django\core\handlers\base.py", line 172, in get_response
    response = response.render()
  File "C:\Python27\lib\site-packages\django\template\response.py", line 160, in render
    self.content = self.rendered_content
  File "C:\Python27\lib\site-packages\django\template\response.py", line 135, in rendered_content
    template = self._resolve_template(self.template_name)
  File "C:\Python27\lib\site-packages\django\template\response.py", line 90, in _resolve_template
    new_template = self.resolve_template(template)
  File "C:\Python27\lib\site-packages\django\template\response.py", line 80, in resolve_template
    return select_template(template, using=self.using)
  File "C:\Python27\lib\site-packages\django\template\loader.py", line 62, in select_template
    return engine.get_template(template_name, dirs)
  File "C:\Python27\lib\site-packages\django\template\backends\django.py", line 40, in get_template
    return Template(self.engine.get_template(template_name, dirs), self)
  File "C:\Python27\lib\site-packages\django\template\engine.py", line 190, in get_template
    template, origin = self.find_template(template_name, dirs)
  File "C:\Python27\lib\site-packages\django\template\engine.py", line 157, in find_template
    name, template_dirs=dirs, skip=skip,
  File "C:\Python27\lib\site-packages\django\template\loaders\base.py", line 46, in get_template
    contents, origin, origin.template_name, self.engine,
  File "C:\Python27\lib\site-packages\django\template\base.py", line 189, in __init__
    self.nodelist = self.compile_nodelist()
  File "C:\Python27\lib\site-packages\django\template\base.py", line 231, in compile_nodelist
    return parser.parse()
  File "C:\Python27\lib\site-packages\django\template\base.py", line 516, in parse
    raise self.error(token, e)
TemplateSyntaxError: Could not parse the remainder: '+movi.pk+"&request_db="+request.db' from 'movi.vttotal|saldo_factura:"cii="+movi.pk+"&request_db="+request.db'
.-.-.-.-.-.-.-.-.-.-.-.-.-.-.-.-.-.-.-.-.-.-.-.-.-.-.-.-.-.-.-.-.-.-.-.-.-.-.-.- 
 ERROR 2016-10-19 09:24:24,006 base 5088 5504 Internal Server Error: /cartera/ 
Traceback (most recent call last):
  File "C:\Python27\lib\site-packages\django\core\handlers\base.py", line 174, in get_response
    response = self.process_exception_by_middleware(e, request)
  File "C:\Python27\lib\site-packages\django\core\handlers\base.py", line 172, in get_response
    response = response.render()
  File "C:\Python27\lib\site-packages\django\template\response.py", line 160, in render
    self.content = self.rendered_content
  File "C:\Python27\lib\site-packages\django\template\response.py", line 135, in rendered_content
    template = self._resolve_template(self.template_name)
  File "C:\Python27\lib\site-packages\django\template\response.py", line 90, in _resolve_template
    new_template = self.resolve_template(template)
  File "C:\Python27\lib\site-packages\django\template\response.py", line 80, in resolve_template
    return select_template(template, using=self.using)
  File "C:\Python27\lib\site-packages\django\template\loader.py", line 62, in select_template
    return engine.get_template(template_name, dirs)
  File "C:\Python27\lib\site-packages\django\template\backends\django.py", line 40, in get_template
    return Template(self.engine.get_template(template_name, dirs), self)
  File "C:\Python27\lib\site-packages\django\template\engine.py", line 190, in get_template
    template, origin = self.find_template(template_name, dirs)
  File "C:\Python27\lib\site-packages\django\template\engine.py", line 157, in find_template
    name, template_dirs=dirs, skip=skip,
  File "C:\Python27\lib\site-packages\django\template\loaders\base.py", line 46, in get_template
    contents, origin, origin.template_name, self.engine,
  File "C:\Python27\lib\site-packages\django\template\base.py", line 189, in __init__
    self.nodelist = self.compile_nodelist()
  File "C:\Python27\lib\site-packages\django\template\base.py", line 231, in compile_nodelist
    return parser.parse()
  File "C:\Python27\lib\site-packages\django\template\base.py", line 516, in parse
    raise self.error(token, e)
TemplateSyntaxError: Could not parse the remainder: '+movi.pk+"&request_db="+request.db' from 'movi.vttotal|saldo_factura:"cii="+movi.pk+"&request_db="+request.db'
.-.-.-.-.-.-.-.-.-.-.-.-.-.-.-.-.-.-.-.-.-.-.-.-.-.-.-.-.-.-.-.-.-.-.-.-.-.-.-.- 
 ERROR 2016-10-19 09:24:58,572 base 4972 2012 Internal Server Error: /cartera/ 
Traceback (most recent call last):
  File "C:\Python27\lib\site-packages\django\core\handlers\base.py", line 174, in get_response
    response = self.process_exception_by_middleware(e, request)
  File "C:\Python27\lib\site-packages\django\core\handlers\base.py", line 172, in get_response
    response = response.render()
  File "C:\Python27\lib\site-packages\django\template\response.py", line 160, in render
    self.content = self.rendered_content
  File "C:\Python27\lib\site-packages\django\template\response.py", line 135, in rendered_content
    template = self._resolve_template(self.template_name)
  File "C:\Python27\lib\site-packages\django\template\response.py", line 90, in _resolve_template
    new_template = self.resolve_template(template)
  File "C:\Python27\lib\site-packages\django\template\response.py", line 80, in resolve_template
    return select_template(template, using=self.using)
  File "C:\Python27\lib\site-packages\django\template\loader.py", line 62, in select_template
    return engine.get_template(template_name, dirs)
  File "C:\Python27\lib\site-packages\django\template\backends\django.py", line 40, in get_template
    return Template(self.engine.get_template(template_name, dirs), self)
  File "C:\Python27\lib\site-packages\django\template\engine.py", line 190, in get_template
    template, origin = self.find_template(template_name, dirs)
  File "C:\Python27\lib\site-packages\django\template\engine.py", line 157, in find_template
    name, template_dirs=dirs, skip=skip,
  File "C:\Python27\lib\site-packages\django\template\loaders\base.py", line 46, in get_template
    contents, origin, origin.template_name, self.engine,
  File "C:\Python27\lib\site-packages\django\template\base.py", line 189, in __init__
    self.nodelist = self.compile_nodelist()
  File "C:\Python27\lib\site-packages\django\template\base.py", line 231, in compile_nodelist
    return parser.parse()
  File "C:\Python27\lib\site-packages\django\template\base.py", line 516, in parse
    raise self.error(token, e)
TemplateSyntaxError: Could not parse the remainder: '+movi.pk+"&request_db="+request.db' from 'movi.vttotal|saldo_factura:"cii="+movi.pk+"&request_db="+request.db'
.-.-.-.-.-.-.-.-.-.-.-.-.-.-.-.-.-.-.-.-.-.-.-.-.-.-.-.-.-.-.-.-.-.-.-.-.-.-.-.- 
 ERROR 2016-10-19 09:27:37,713 base 4972 5320 Internal Server Error: /cartera/ 
Traceback (most recent call last):
  File "C:\Python27\lib\site-packages\django\core\handlers\base.py", line 174, in get_response
    response = self.process_exception_by_middleware(e, request)
  File "C:\Python27\lib\site-packages\django\core\handlers\base.py", line 172, in get_response
    response = response.render()
  File "C:\Python27\lib\site-packages\django\template\response.py", line 160, in render
    self.content = self.rendered_content
  File "C:\Python27\lib\site-packages\django\template\response.py", line 135, in rendered_content
    template = self._resolve_template(self.template_name)
  File "C:\Python27\lib\site-packages\django\template\response.py", line 90, in _resolve_template
    new_template = self.resolve_template(template)
  File "C:\Python27\lib\site-packages\django\template\response.py", line 80, in resolve_template
    return select_template(template, using=self.using)
  File "C:\Python27\lib\site-packages\django\template\loader.py", line 62, in select_template
    return engine.get_template(template_name, dirs)
  File "C:\Python27\lib\site-packages\django\template\backends\django.py", line 40, in get_template
    return Template(self.engine.get_template(template_name, dirs), self)
  File "C:\Python27\lib\site-packages\django\template\engine.py", line 190, in get_template
    template, origin = self.find_template(template_name, dirs)
  File "C:\Python27\lib\site-packages\django\template\engine.py", line 157, in find_template
    name, template_dirs=dirs, skip=skip,
  File "C:\Python27\lib\site-packages\django\template\loaders\base.py", line 46, in get_template
    contents, origin, origin.template_name, self.engine,
  File "C:\Python27\lib\site-packages\django\template\base.py", line 189, in __init__
    self.nodelist = self.compile_nodelist()
  File "C:\Python27\lib\site-packages\django\template\base.py", line 231, in compile_nodelist
    return parser.parse()
  File "C:\Python27\lib\site-packages\django\template\base.py", line 516, in parse
    raise self.error(token, e)
TemplateSyntaxError: Could not parse the remainder: '+movi.pk+"&request_db="+request.db' from 'movi.vttotal|saldo_factura:"cii="+movi.pk+"&request_db="+request.db'
.-.-.-.-.-.-.-.-.-.-.-.-.-.-.-.-.-.-.-.-.-.-.-.-.-.-.-.-.-.-.-.-.-.-.-.-.-.-.-.- 
 ERROR 2016-10-19 09:27:40,996 base 4972 5068 Internal Server Error: /cartera/ 
Traceback (most recent call last):
  File "C:\Python27\lib\site-packages\django\core\handlers\base.py", line 174, in get_response
    response = self.process_exception_by_middleware(e, request)
  File "C:\Python27\lib\site-packages\django\core\handlers\base.py", line 172, in get_response
    response = response.render()
  File "C:\Python27\lib\site-packages\django\template\response.py", line 160, in render
    self.content = self.rendered_content
  File "C:\Python27\lib\site-packages\django\template\response.py", line 135, in rendered_content
    template = self._resolve_template(self.template_name)
  File "C:\Python27\lib\site-packages\django\template\response.py", line 90, in _resolve_template
    new_template = self.resolve_template(template)
  File "C:\Python27\lib\site-packages\django\template\response.py", line 80, in resolve_template
    return select_template(template, using=self.using)
  File "C:\Python27\lib\site-packages\django\template\loader.py", line 62, in select_template
    return engine.get_template(template_name, dirs)
  File "C:\Python27\lib\site-packages\django\template\backends\django.py", line 40, in get_template
    return Template(self.engine.get_template(template_name, dirs), self)
  File "C:\Python27\lib\site-packages\django\template\engine.py", line 190, in get_template
    template, origin = self.find_template(template_name, dirs)
  File "C:\Python27\lib\site-packages\django\template\engine.py", line 157, in find_template
    name, template_dirs=dirs, skip=skip,
  File "C:\Python27\lib\site-packages\django\template\loaders\base.py", line 46, in get_template
    contents, origin, origin.template_name, self.engine,
  File "C:\Python27\lib\site-packages\django\template\base.py", line 189, in __init__
    self.nodelist = self.compile_nodelist()
  File "C:\Python27\lib\site-packages\django\template\base.py", line 231, in compile_nodelist
    return parser.parse()
  File "C:\Python27\lib\site-packages\django\template\base.py", line 516, in parse
    raise self.error(token, e)
TemplateSyntaxError: Could not parse the remainder: '+movi.pk+"&request_db="+request.db' from 'movi.vttotal|saldo_factura:"cii="+movi.pk+"&request_db="+request.db'
.-.-.-.-.-.-.-.-.-.-.-.-.-.-.-.-.-.-.-.-.-.-.-.-.-.-.-.-.-.-.-.-.-.-.-.-.-.-.-.- 
 ERROR 2016-10-19 09:27:41,206 base 4972 1368 Internal Server Error: /cartera/ 
Traceback (most recent call last):
  File "C:\Python27\lib\site-packages\django\core\handlers\base.py", line 174, in get_response
    response = self.process_exception_by_middleware(e, request)
  File "C:\Python27\lib\site-packages\django\core\handlers\base.py", line 172, in get_response
    response = response.render()
  File "C:\Python27\lib\site-packages\django\template\response.py", line 160, in render
    self.content = self.rendered_content
  File "C:\Python27\lib\site-packages\django\template\response.py", line 135, in rendered_content
    template = self._resolve_template(self.template_name)
  File "C:\Python27\lib\site-packages\django\template\response.py", line 90, in _resolve_template
    new_template = self.resolve_template(template)
  File "C:\Python27\lib\site-packages\django\template\response.py", line 80, in resolve_template
    return select_template(template, using=self.using)
  File "C:\Python27\lib\site-packages\django\template\loader.py", line 62, in select_template
    return engine.get_template(template_name, dirs)
  File "C:\Python27\lib\site-packages\django\template\backends\django.py", line 40, in get_template
    return Template(self.engine.get_template(template_name, dirs), self)
  File "C:\Python27\lib\site-packages\django\template\engine.py", line 190, in get_template
    template, origin = self.find_template(template_name, dirs)
  File "C:\Python27\lib\site-packages\django\template\engine.py", line 157, in find_template
    name, template_dirs=dirs, skip=skip,
  File "C:\Python27\lib\site-packages\django\template\loaders\base.py", line 46, in get_template
    contents, origin, origin.template_name, self.engine,
  File "C:\Python27\lib\site-packages\django\template\base.py", line 189, in __init__
    self.nodelist = self.compile_nodelist()
  File "C:\Python27\lib\site-packages\django\template\base.py", line 231, in compile_nodelist
    return parser.parse()
  File "C:\Python27\lib\site-packages\django\template\base.py", line 516, in parse
    raise self.error(token, e)
TemplateSyntaxError: Could not parse the remainder: '+movi.pk+"&request_db="+request.db' from 'movi.vttotal|saldo_factura:"cii="+movi.pk+"&request_db="+request.db'
.-.-.-.-.-.-.-.-.-.-.-.-.-.-.-.-.-.-.-.-.-.-.-.-.-.-.-.-.-.-.-.-.-.-.-.-.-.-.-.- 
 ERROR 2016-10-19 09:27:41,428 base 4972 500 Internal Server Error: /cartera/ 
Traceback (most recent call last):
  File "C:\Python27\lib\site-packages\django\core\handlers\base.py", line 174, in get_response
    response = self.process_exception_by_middleware(e, request)
  File "C:\Python27\lib\site-packages\django\core\handlers\base.py", line 172, in get_response
    response = response.render()
  File "C:\Python27\lib\site-packages\django\template\response.py", line 160, in render
    self.content = self.rendered_content
  File "C:\Python27\lib\site-packages\django\template\response.py", line 135, in rendered_content
    template = self._resolve_template(self.template_name)
  File "C:\Python27\lib\site-packages\django\template\response.py", line 90, in _resolve_template
    new_template = self.resolve_template(template)
  File "C:\Python27\lib\site-packages\django\template\response.py", line 80, in resolve_template
    return select_template(template, using=self.using)
  File "C:\Python27\lib\site-packages\django\template\loader.py", line 62, in select_template
    return engine.get_template(template_name, dirs)
  File "C:\Python27\lib\site-packages\django\template\backends\django.py", line 40, in get_template
    return Template(self.engine.get_template(template_name, dirs), self)
  File "C:\Python27\lib\site-packages\django\template\engine.py", line 190, in get_template
    template, origin = self.find_template(template_name, dirs)
  File "C:\Python27\lib\site-packages\django\template\engine.py", line 157, in find_template
    name, template_dirs=dirs, skip=skip,
  File "C:\Python27\lib\site-packages\django\template\loaders\base.py", line 46, in get_template
    contents, origin, origin.template_name, self.engine,
  File "C:\Python27\lib\site-packages\django\template\base.py", line 189, in __init__
    self.nodelist = self.compile_nodelist()
  File "C:\Python27\lib\site-packages\django\template\base.py", line 231, in compile_nodelist
    return parser.parse()
  File "C:\Python27\lib\site-packages\django\template\base.py", line 516, in parse
    raise self.error(token, e)
TemplateSyntaxError: Could not parse the remainder: '+movi.pk+"&request_db="+request.db' from 'movi.vttotal|saldo_factura:"cii="+movi.pk+"&request_db="+request.db'
.-.-.-.-.-.-.-.-.-.-.-.-.-.-.-.-.-.-.-.-.-.-.-.-.-.-.-.-.-.-.-.-.-.-.-.-.-.-.-.- 
 ERROR 2016-10-19 09:27:41,595 base 4972 3300 Internal Server Error: /cartera/ 
Traceback (most recent call last):
  File "C:\Python27\lib\site-packages\django\core\handlers\base.py", line 174, in get_response
    response = self.process_exception_by_middleware(e, request)
  File "C:\Python27\lib\site-packages\django\core\handlers\base.py", line 172, in get_response
    response = response.render()
  File "C:\Python27\lib\site-packages\django\template\response.py", line 160, in render
    self.content = self.rendered_content
  File "C:\Python27\lib\site-packages\django\template\response.py", line 135, in rendered_content
    template = self._resolve_template(self.template_name)
  File "C:\Python27\lib\site-packages\django\template\response.py", line 90, in _resolve_template
    new_template = self.resolve_template(template)
  File "C:\Python27\lib\site-packages\django\template\response.py", line 80, in resolve_template
    return select_template(template, using=self.using)
  File "C:\Python27\lib\site-packages\django\template\loader.py", line 62, in select_template
    return engine.get_template(template_name, dirs)
  File "C:\Python27\lib\site-packages\django\template\backends\django.py", line 40, in get_template
    return Template(self.engine.get_template(template_name, dirs), self)
  File "C:\Python27\lib\site-packages\django\template\engine.py", line 190, in get_template
    template, origin = self.find_template(template_name, dirs)
  File "C:\Python27\lib\site-packages\django\template\engine.py", line 157, in find_template
    name, template_dirs=dirs, skip=skip,
  File "C:\Python27\lib\site-packages\django\template\loaders\base.py", line 46, in get_template
    contents, origin, origin.template_name, self.engine,
  File "C:\Python27\lib\site-packages\django\template\base.py", line 189, in __init__
    self.nodelist = self.compile_nodelist()
  File "C:\Python27\lib\site-packages\django\template\base.py", line 231, in compile_nodelist
    return parser.parse()
  File "C:\Python27\lib\site-packages\django\template\base.py", line 516, in parse
    raise self.error(token, e)
TemplateSyntaxError: Could not parse the remainder: '+movi.pk+"&request_db="+request.db' from 'movi.vttotal|saldo_factura:"cii="+movi.pk+"&request_db="+request.db'
.-.-.-.-.-.-.-.-.-.-.-.-.-.-.-.-.-.-.-.-.-.-.-.-.-.-.-.-.-.-.-.-.-.-.-.-.-.-.-.- 
 ERROR 2016-10-19 09:28:13,502 base 4972 4832 Internal Server Error: /cartera/ 
Traceback (most recent call last):
  File "C:\Python27\lib\site-packages\django\core\handlers\base.py", line 174, in get_response
    response = self.process_exception_by_middleware(e, request)
  File "C:\Python27\lib\site-packages\django\core\handlers\base.py", line 172, in get_response
    response = response.render()
  File "C:\Python27\lib\site-packages\django\template\response.py", line 160, in render
    self.content = self.rendered_content
  File "C:\Python27\lib\site-packages\django\template\response.py", line 135, in rendered_content
    template = self._resolve_template(self.template_name)
  File "C:\Python27\lib\site-packages\django\template\response.py", line 90, in _resolve_template
    new_template = self.resolve_template(template)
  File "C:\Python27\lib\site-packages\django\template\response.py", line 80, in resolve_template
    return select_template(template, using=self.using)
  File "C:\Python27\lib\site-packages\django\template\loader.py", line 62, in select_template
    return engine.get_template(template_name, dirs)
  File "C:\Python27\lib\site-packages\django\template\backends\django.py", line 40, in get_template
    return Template(self.engine.get_template(template_name, dirs), self)
  File "C:\Python27\lib\site-packages\django\template\engine.py", line 190, in get_template
    template, origin = self.find_template(template_name, dirs)
  File "C:\Python27\lib\site-packages\django\template\engine.py", line 157, in find_template
    name, template_dirs=dirs, skip=skip,
  File "C:\Python27\lib\site-packages\django\template\loaders\base.py", line 46, in get_template
    contents, origin, origin.template_name, self.engine,
  File "C:\Python27\lib\site-packages\django\template\base.py", line 189, in __init__
    self.nodelist = self.compile_nodelist()
  File "C:\Python27\lib\site-packages\django\template\base.py", line 231, in compile_nodelist
    return parser.parse()
  File "C:\Python27\lib\site-packages\django\template\base.py", line 516, in parse
    raise self.error(token, e)
TemplateSyntaxError: Could not parse the remainder: '+movi.cmovi+"&request_db=1"' from 'movi.vttotal|saldo_factura:"cii="+movi.cmovi+"&request_db=1"'
.-.-.-.-.-.-.-.-.-.-.-.-.-.-.-.-.-.-.-.-.-.-.-.-.-.-.-.-.-.-.-.-.-.-.-.-.-.-.-.- 
 ERROR 2016-10-19 09:28:13,687 base 4972 3776 Internal Server Error: /cartera/ 
Traceback (most recent call last):
  File "C:\Python27\lib\site-packages\django\core\handlers\base.py", line 174, in get_response
    response = self.process_exception_by_middleware(e, request)
  File "C:\Python27\lib\site-packages\django\core\handlers\base.py", line 172, in get_response
    response = response.render()
  File "C:\Python27\lib\site-packages\django\template\response.py", line 160, in render
    self.content = self.rendered_content
  File "C:\Python27\lib\site-packages\django\template\response.py", line 135, in rendered_content
    template = self._resolve_template(self.template_name)
  File "C:\Python27\lib\site-packages\django\template\response.py", line 90, in _resolve_template
    new_template = self.resolve_template(template)
  File "C:\Python27\lib\site-packages\django\template\response.py", line 80, in resolve_template
    return select_template(template, using=self.using)
  File "C:\Python27\lib\site-packages\django\template\loader.py", line 62, in select_template
    return engine.get_template(template_name, dirs)
  File "C:\Python27\lib\site-packages\django\template\backends\django.py", line 40, in get_template
    return Template(self.engine.get_template(template_name, dirs), self)
  File "C:\Python27\lib\site-packages\django\template\engine.py", line 190, in get_template
    template, origin = self.find_template(template_name, dirs)
  File "C:\Python27\lib\site-packages\django\template\engine.py", line 157, in find_template
    name, template_dirs=dirs, skip=skip,
  File "C:\Python27\lib\site-packages\django\template\loaders\base.py", line 46, in get_template
    contents, origin, origin.template_name, self.engine,
  File "C:\Python27\lib\site-packages\django\template\base.py", line 189, in __init__
    self.nodelist = self.compile_nodelist()
  File "C:\Python27\lib\site-packages\django\template\base.py", line 231, in compile_nodelist
    return parser.parse()
  File "C:\Python27\lib\site-packages\django\template\base.py", line 516, in parse
    raise self.error(token, e)
TemplateSyntaxError: Could not parse the remainder: '+movi.cmovi+"&request_db=1"' from 'movi.vttotal|saldo_factura:"cii="+movi.cmovi+"&request_db=1"'
.-.-.-.-.-.-.-.-.-.-.-.-.-.-.-.-.-.-.-.-.-.-.-.-.-.-.-.-.-.-.-.-.-.-.-.-.-.-.-.- 
 ERROR 2016-10-19 09:28:14,006 base 4972 3316 Internal Server Error: /cartera/ 
Traceback (most recent call last):
  File "C:\Python27\lib\site-packages\django\core\handlers\base.py", line 174, in get_response
    response = self.process_exception_by_middleware(e, request)
  File "C:\Python27\lib\site-packages\django\core\handlers\base.py", line 172, in get_response
    response = response.render()
  File "C:\Python27\lib\site-packages\django\template\response.py", line 160, in render
    self.content = self.rendered_content
  File "C:\Python27\lib\site-packages\django\template\response.py", line 135, in rendered_content
    template = self._resolve_template(self.template_name)
  File "C:\Python27\lib\site-packages\django\template\response.py", line 90, in _resolve_template
    new_template = self.resolve_template(template)
  File "C:\Python27\lib\site-packages\django\template\response.py", line 80, in resolve_template
    return select_template(template, using=self.using)
  File "C:\Python27\lib\site-packages\django\template\loader.py", line 62, in select_template
    return engine.get_template(template_name, dirs)
  File "C:\Python27\lib\site-packages\django\template\backends\django.py", line 40, in get_template
    return Template(self.engine.get_template(template_name, dirs), self)
  File "C:\Python27\lib\site-packages\django\template\engine.py", line 190, in get_template
    template, origin = self.find_template(template_name, dirs)
  File "C:\Python27\lib\site-packages\django\template\engine.py", line 157, in find_template
    name, template_dirs=dirs, skip=skip,
  File "C:\Python27\lib\site-packages\django\template\loaders\base.py", line 46, in get_template
    contents, origin, origin.template_name, self.engine,
  File "C:\Python27\lib\site-packages\django\template\base.py", line 189, in __init__
    self.nodelist = self.compile_nodelist()
  File "C:\Python27\lib\site-packages\django\template\base.py", line 231, in compile_nodelist
    return parser.parse()
  File "C:\Python27\lib\site-packages\django\template\base.py", line 516, in parse
    raise self.error(token, e)
TemplateSyntaxError: Could not parse the remainder: '+movi.cmovi+"&request_db=1"' from 'movi.vttotal|saldo_factura:"cii="+movi.cmovi+"&request_db=1"'
.-.-.-.-.-.-.-.-.-.-.-.-.-.-.-.-.-.-.-.-.-.-.-.-.-.-.-.-.-.-.-.-.-.-.-.-.-.-.-.- 
 ERROR 2016-10-19 09:30:43,753 base 4972 5192 Internal Server Error: /cartera/ 
Traceback (most recent call last):
  File "C:\Python27\lib\site-packages\django\core\handlers\base.py", line 174, in get_response
    response = self.process_exception_by_middleware(e, request)
  File "C:\Python27\lib\site-packages\django\core\handlers\base.py", line 172, in get_response
    response = response.render()
  File "C:\Python27\lib\site-packages\django\template\response.py", line 160, in render
    self.content = self.rendered_content
  File "C:\Python27\lib\site-packages\django\template\response.py", line 135, in rendered_content
    template = self._resolve_template(self.template_name)
  File "C:\Python27\lib\site-packages\django\template\response.py", line 90, in _resolve_template
    new_template = self.resolve_template(template)
  File "C:\Python27\lib\site-packages\django\template\response.py", line 80, in resolve_template
    return select_template(template, using=self.using)
  File "C:\Python27\lib\site-packages\django\template\loader.py", line 62, in select_template
    return engine.get_template(template_name, dirs)
  File "C:\Python27\lib\site-packages\django\template\backends\django.py", line 40, in get_template
    return Template(self.engine.get_template(template_name, dirs), self)
  File "C:\Python27\lib\site-packages\django\template\engine.py", line 190, in get_template
    template, origin = self.find_template(template_name, dirs)
  File "C:\Python27\lib\site-packages\django\template\engine.py", line 157, in find_template
    name, template_dirs=dirs, skip=skip,
  File "C:\Python27\lib\site-packages\django\template\loaders\base.py", line 46, in get_template
    contents, origin, origin.template_name, self.engine,
  File "C:\Python27\lib\site-packages\django\template\base.py", line 189, in __init__
    self.nodelist = self.compile_nodelist()
  File "C:\Python27\lib\site-packages\django\template\base.py", line 231, in compile_nodelist
    return parser.parse()
  File "C:\Python27\lib\site-packages\django\template\base.py", line 516, in parse
    raise self.error(token, e)
TemplateSyntaxError: Could not parse the remainder: '+movi.cmovi+"&request_db=1"' from 'movi.vttotal|saldo_factura:"cii="+movi.cmovi+"&request_db=1"'
.-.-.-.-.-.-.-.-.-.-.-.-.-.-.-.-.-.-.-.-.-.-.-.-.-.-.-.-.-.-.-.-.-.-.-.-.-.-.-.- 
 ERROR 2016-10-19 09:32:00,977 base 4972 5800 Internal Server Error: /cartera/ 
Traceback (most recent call last):
  File "C:\Python27\lib\site-packages\django\core\handlers\base.py", line 174, in get_response
    response = self.process_exception_by_middleware(e, request)
  File "C:\Python27\lib\site-packages\django\core\handlers\base.py", line 172, in get_response
    response = response.render()
  File "C:\Python27\lib\site-packages\django\template\response.py", line 160, in render
    self.content = self.rendered_content
  File "C:\Python27\lib\site-packages\django\template\response.py", line 135, in rendered_content
    template = self._resolve_template(self.template_name)
  File "C:\Python27\lib\site-packages\django\template\response.py", line 90, in _resolve_template
    new_template = self.resolve_template(template)
  File "C:\Python27\lib\site-packages\django\template\response.py", line 80, in resolve_template
    return select_template(template, using=self.using)
  File "C:\Python27\lib\site-packages\django\template\loader.py", line 62, in select_template
    return engine.get_template(template_name, dirs)
  File "C:\Python27\lib\site-packages\django\template\backends\django.py", line 40, in get_template
    return Template(self.engine.get_template(template_name, dirs), self)
  File "C:\Python27\lib\site-packages\django\template\engine.py", line 190, in get_template
    template, origin = self.find_template(template_name, dirs)
  File "C:\Python27\lib\site-packages\django\template\engine.py", line 157, in find_template
    name, template_dirs=dirs, skip=skip,
  File "C:\Python27\lib\site-packages\django\template\loaders\base.py", line 46, in get_template
    contents, origin, origin.template_name, self.engine,
  File "C:\Python27\lib\site-packages\django\template\base.py", line 189, in __init__
    self.nodelist = self.compile_nodelist()
  File "C:\Python27\lib\site-packages\django\template\base.py", line 231, in compile_nodelist
    return parser.parse()
  File "C:\Python27\lib\site-packages\django\template\base.py", line 516, in parse
    raise self.error(token, e)
TemplateSyntaxError: Could not parse the remainder: 'request.db' from 'movi.vttotal|saldo_factura:"cii=j&request_db="request.db'
.-.-.-.-.-.-.-.-.-.-.-.-.-.-.-.-.-.-.-.-.-.-.-.-.-.-.-.-.-.-.-.-.-.-.-.-.-.-.-.- 
 ERROR 2016-10-19 09:32:29,618 base 4972 5308 Internal Server Error: /cartera/ 
Traceback (most recent call last):
  File "C:\Python27\lib\site-packages\django\core\handlers\base.py", line 174, in get_response
    response = self.process_exception_by_middleware(e, request)
  File "C:\Python27\lib\site-packages\django\core\handlers\base.py", line 172, in get_response
    response = response.render()
  File "C:\Python27\lib\site-packages\django\template\response.py", line 160, in render
    self.content = self.rendered_content
  File "C:\Python27\lib\site-packages\django\template\response.py", line 135, in rendered_content
    template = self._resolve_template(self.template_name)
  File "C:\Python27\lib\site-packages\django\template\response.py", line 90, in _resolve_template
    new_template = self.resolve_template(template)
  File "C:\Python27\lib\site-packages\django\template\response.py", line 80, in resolve_template
    return select_template(template, using=self.using)
  File "C:\Python27\lib\site-packages\django\template\loader.py", line 62, in select_template
    return engine.get_template(template_name, dirs)
  File "C:\Python27\lib\site-packages\django\template\backends\django.py", line 40, in get_template
    return Template(self.engine.get_template(template_name, dirs), self)
  File "C:\Python27\lib\site-packages\django\template\engine.py", line 190, in get_template
    template, origin = self.find_template(template_name, dirs)
  File "C:\Python27\lib\site-packages\django\template\engine.py", line 157, in find_template
    name, template_dirs=dirs, skip=skip,
  File "C:\Python27\lib\site-packages\django\template\loaders\base.py", line 46, in get_template
    contents, origin, origin.template_name, self.engine,
  File "C:\Python27\lib\site-packages\django\template\base.py", line 189, in __init__
    self.nodelist = self.compile_nodelist()
  File "C:\Python27\lib\site-packages\django\template\base.py", line 231, in compile_nodelist
    return parser.parse()
  File "C:\Python27\lib\site-packages\django\template\base.py", line 516, in parse
    raise self.error(token, e)
TemplateSyntaxError: Could not parse the remainder: '.request.db' from 'movi.vttotal|saldo_factura:"cii=j&request_db=".request.db'
.-.-.-.-.-.-.-.-.-.-.-.-.-.-.-.-.-.-.-.-.-.-.-.-.-.-.-.-.-.-.-.-.-.-.-.-.-.-.-.- 
 ERROR 2016-10-19 09:33:34,111 base 4972 3700 Internal Server Error: /cartera/ 
Traceback (most recent call last):
  File "C:\Python27\lib\site-packages\django\core\handlers\base.py", line 174, in get_response
    response = self.process_exception_by_middleware(e, request)
  File "C:\Python27\lib\site-packages\django\core\handlers\base.py", line 172, in get_response
    response = response.render()
  File "C:\Python27\lib\site-packages\django\template\response.py", line 160, in render
    self.content = self.rendered_content
  File "C:\Python27\lib\site-packages\django\template\response.py", line 135, in rendered_content
    template = self._resolve_template(self.template_name)
  File "C:\Python27\lib\site-packages\django\template\response.py", line 90, in _resolve_template
    new_template = self.resolve_template(template)
  File "C:\Python27\lib\site-packages\django\template\response.py", line 80, in resolve_template
    return select_template(template, using=self.using)
  File "C:\Python27\lib\site-packages\django\template\loader.py", line 62, in select_template
    return engine.get_template(template_name, dirs)
  File "C:\Python27\lib\site-packages\django\template\backends\django.py", line 40, in get_template
    return Template(self.engine.get_template(template_name, dirs), self)
  File "C:\Python27\lib\site-packages\django\template\engine.py", line 190, in get_template
    template, origin = self.find_template(template_name, dirs)
  File "C:\Python27\lib\site-packages\django\template\engine.py", line 157, in find_template
    name, template_dirs=dirs, skip=skip,
  File "C:\Python27\lib\site-packages\django\template\loaders\base.py", line 46, in get_template
    contents, origin, origin.template_name, self.engine,
  File "C:\Python27\lib\site-packages\django\template\base.py", line 189, in __init__
    self.nodelist = self.compile_nodelist()
  File "C:\Python27\lib\site-packages\django\template\base.py", line 231, in compile_nodelist
    return parser.parse()
  File "C:\Python27\lib\site-packages\django\template\base.py", line 516, in parse
    raise self.error(token, e)
TemplateSyntaxError: Could not parse the remainder: '+request.db' from 'movi.vttotal|saldo_factura:"cii=j&request_db="+request.db'
.-.-.-.-.-.-.-.-.-.-.-.-.-.-.-.-.-.-.-.-.-.-.-.-.-.-.-.-.-.-.-.-.-.-.-.-.-.-.-.- 
 ERROR 2016-10-19 10:06:38,302 base 4840 3480 Internal Server Error: /cartera/ 
Traceback (most recent call last):
  File "C:\Python27\lib\site-packages\django\core\handlers\base.py", line 174, in get_response
    response = self.process_exception_by_middleware(e, request)
  File "C:\Python27\lib\site-packages\django\core\handlers\base.py", line 172, in get_response
    response = response.render()
  File "C:\Python27\lib\site-packages\django\template\response.py", line 160, in render
    self.content = self.rendered_content
  File "C:\Python27\lib\site-packages\django\template\response.py", line 137, in rendered_content
    content = template.render(context, self._request)
  File "C:\Python27\lib\site-packages\django\template\backends\django.py", line 95, in render
    return self.template.render(context)
  File "C:\Python27\lib\site-packages\django\template\base.py", line 206, in render
    return self._render(context)
  File "C:\Python27\lib\site-packages\django\template\base.py", line 197, in _render
    return self.nodelist.render(context)
  File "C:\Python27\lib\site-packages\django\template\base.py", line 992, in render
    bit = node.render_annotated(context)
  File "C:\Python27\lib\site-packages\django\template\base.py", line 959, in render_annotated
    return self.render(context)
  File "C:\Python27\lib\site-packages\django\template\loader_tags.py", line 173, in render
    return compiled_parent._render(context)
  File "C:\Python27\lib\site-packages\django\template\base.py", line 197, in _render
    return self.nodelist.render(context)
  File "C:\Python27\lib\site-packages\django\template\base.py", line 992, in render
    bit = node.render_annotated(context)
  File "C:\Python27\lib\site-packages\django\template\base.py", line 959, in render_annotated
    return self.render(context)
  File "C:\Python27\lib\site-packages\django\template\loader_tags.py", line 69, in render
    result = block.nodelist.render(context)
  File "C:\Python27\lib\site-packages\django\template\base.py", line 992, in render
    bit = node.render_annotated(context)
  File "C:\Python27\lib\site-packages\django\template\base.py", line 959, in render_annotated
    return self.render(context)
  File "C:\Python27\lib\site-packages\django\template\defaulttags.py", line 220, in render
    nodelist.append(node.render_annotated(context))
  File "C:\Python27\lib\site-packages\django\template\base.py", line 959, in render_annotated
    return self.render(context)
  File "C:\Python27\lib\site-packages\django\template\base.py", line 1043, in render
    output = self.filter_expression.resolve(context)
  File "C:\Python27\lib\site-packages\django\template\base.py", line 736, in resolve
    new_obj = func(obj, *arg_vals)
  File "D:\Proyectos\infa web\infa_web\infa_web\apps\base\templatetags\date_appen.py", line 83, in saldo_factura
    ab = Movideta.objects.using(request_db).filter(docrefe = cmovi).aggregate(tot_ab = sum('vmovi'))
TypeError: unsupported operand type(s) for +: 'int' and 'str'
.-.-.-.-.-.-.-.-.-.-.-.-.-.-.-.-.-.-.-.-.-.-.-.-.-.-.-.-.-.-.-.-.-.-.-.-.-.-.-.- 
 ERROR 2016-10-19 10:07:45,917 base 4872 4520 Internal Server Error: /cartera/ 
Traceback (most recent call last):
  File "C:\Python27\lib\site-packages\django\core\handlers\base.py", line 174, in get_response
    response = self.process_exception_by_middleware(e, request)
  File "C:\Python27\lib\site-packages\django\core\handlers\base.py", line 172, in get_response
    response = response.render()
  File "C:\Python27\lib\site-packages\django\template\response.py", line 160, in render
    self.content = self.rendered_content
  File "C:\Python27\lib\site-packages\django\template\response.py", line 137, in rendered_content
    content = template.render(context, self._request)
  File "C:\Python27\lib\site-packages\django\template\backends\django.py", line 95, in render
    return self.template.render(context)
  File "C:\Python27\lib\site-packages\django\template\base.py", line 206, in render
    return self._render(context)
  File "C:\Python27\lib\site-packages\django\template\base.py", line 197, in _render
    return self.nodelist.render(context)
  File "C:\Python27\lib\site-packages\django\template\base.py", line 992, in render
    bit = node.render_annotated(context)
  File "C:\Python27\lib\site-packages\django\template\base.py", line 959, in render_annotated
    return self.render(context)
  File "C:\Python27\lib\site-packages\django\template\loader_tags.py", line 173, in render
    return compiled_parent._render(context)
  File "C:\Python27\lib\site-packages\django\template\base.py", line 197, in _render
    return self.nodelist.render(context)
  File "C:\Python27\lib\site-packages\django\template\base.py", line 992, in render
    bit = node.render_annotated(context)
  File "C:\Python27\lib\site-packages\django\template\base.py", line 959, in render_annotated
    return self.render(context)
  File "C:\Python27\lib\site-packages\django\template\loader_tags.py", line 69, in render
    result = block.nodelist.render(context)
  File "C:\Python27\lib\site-packages\django\template\base.py", line 992, in render
    bit = node.render_annotated(context)
  File "C:\Python27\lib\site-packages\django\template\base.py", line 959, in render_annotated
    return self.render(context)
  File "C:\Python27\lib\site-packages\django\template\defaulttags.py", line 220, in render
    nodelist.append(node.render_annotated(context))
  File "C:\Python27\lib\site-packages\django\template\base.py", line 959, in render_annotated
    return self.render(context)
  File "C:\Python27\lib\site-packages\django\template\base.py", line 1043, in render
    output = self.filter_expression.resolve(context)
  File "C:\Python27\lib\site-packages\django\template\base.py", line 736, in resolve
    new_obj = func(obj, *arg_vals)
  File "D:\Proyectos\infa web\infa_web\infa_web\apps\base\templatetags\date_appen.py", line 83, in saldo_factura
    ab = Movideta.objects.using(request_db).filter(docrefe = cmovi).aggregate(tot_ab = sum('vmovi'))
TypeError: unsupported operand type(s) for +: 'int' and 'str'
.-.-.-.-.-.-.-.-.-.-.-.-.-.-.-.-.-.-.-.-.-.-.-.-.-.-.-.-.-.-.-.-.-.-.-.-.-.-.-.- 
 ERROR 2016-10-19 10:08:58,453 base 2996 4012 Internal Server Error: /cartera/ 
Traceback (most recent call last):
  File "C:\Python27\lib\site-packages\django\core\handlers\base.py", line 174, in get_response
    response = self.process_exception_by_middleware(e, request)
  File "C:\Python27\lib\site-packages\django\core\handlers\base.py", line 172, in get_response
    response = response.render()
  File "C:\Python27\lib\site-packages\django\template\response.py", line 160, in render
    self.content = self.rendered_content
  File "C:\Python27\lib\site-packages\django\template\response.py", line 137, in rendered_content
    content = template.render(context, self._request)
  File "C:\Python27\lib\site-packages\django\template\backends\django.py", line 95, in render
    return self.template.render(context)
  File "C:\Python27\lib\site-packages\django\template\base.py", line 206, in render
    return self._render(context)
  File "C:\Python27\lib\site-packages\django\template\base.py", line 197, in _render
    return self.nodelist.render(context)
  File "C:\Python27\lib\site-packages\django\template\base.py", line 992, in render
    bit = node.render_annotated(context)
  File "C:\Python27\lib\site-packages\django\template\base.py", line 959, in render_annotated
    return self.render(context)
  File "C:\Python27\lib\site-packages\django\template\loader_tags.py", line 173, in render
    return compiled_parent._render(context)
  File "C:\Python27\lib\site-packages\django\template\base.py", line 197, in _render
    return self.nodelist.render(context)
  File "C:\Python27\lib\site-packages\django\template\base.py", line 992, in render
    bit = node.render_annotated(context)
  File "C:\Python27\lib\site-packages\django\template\base.py", line 959, in render_annotated
    return self.render(context)
  File "C:\Python27\lib\site-packages\django\template\loader_tags.py", line 69, in render
    result = block.nodelist.render(context)
  File "C:\Python27\lib\site-packages\django\template\base.py", line 992, in render
    bit = node.render_annotated(context)
  File "C:\Python27\lib\site-packages\django\template\base.py", line 959, in render_annotated
    return self.render(context)
  File "C:\Python27\lib\site-packages\django\template\defaulttags.py", line 220, in render
    nodelist.append(node.render_annotated(context))
  File "C:\Python27\lib\site-packages\django\template\base.py", line 959, in render_annotated
    return self.render(context)
  File "C:\Python27\lib\site-packages\django\template\base.py", line 1043, in render
    output = self.filter_expression.resolve(context)
  File "C:\Python27\lib\site-packages\django\template\base.py", line 736, in resolve
    new_obj = func(obj, *arg_vals)
  File "D:\Proyectos\infa web\infa_web\infa_web\apps\base\templatetags\date_appen.py", line 83, in saldo_factura
    ab = Movideta.objects.using(request_db).filter(docrefe = cmovi).aggregate(tot_ab = sum('vmovi'))
TypeError: unsupported operand type(s) for +: 'int' and 'str'
.-.-.-.-.-.-.-.-.-.-.-.-.-.-.-.-.-.-.-.-.-.-.-.-.-.-.-.-.-.-.-.-.-.-.-.-.-.-.-.- 
 ERROR 2016-10-19 10:18:53,823 base 4436 1932 Internal Server Error: /bill/save/ 
Traceback (most recent call last):
  File "C:\Python27\lib\site-packages\django\core\handlers\base.py", line 149, in get_response
    response = self.process_exception_by_middleware(e, request)
  File "C:\Python27\lib\site-packages\django\core\handlers\base.py", line 147, in get_response
    response = wrapped_callback(request, *callback_args, **callback_kwargs)
  File "C:\Python27\lib\site-packages\django\views\decorators\csrf.py", line 58, in wrapped_view
    return view_func(*args, **kwargs)
  File "D:\Proyectos\infa web\infa_web\infa_web\apps\facturacion\views.py", line 413, in BillSave
    'vtdescu': float(data['vdescu'])
  File "D:\Proyectos\infa web\infa_web\infa_web\apps\facturacion\views.py", line 166, in save_movi
    movi.save(using = request_db)
  File "C:\Python27\lib\site-packages\django\db\models\base.py", line 708, in save
    force_update=force_update, update_fields=update_fields)
  File "C:\Python27\lib\site-packages\django\db\models\base.py", line 736, in save_base
    updated = self._save_table(raw, cls, force_insert, force_update, using, update_fields)
  File "C:\Python27\lib\site-packages\django\db\models\base.py", line 820, in _save_table
    result = self._do_insert(cls._base_manager, using, fields, update_pk, raw)
  File "C:\Python27\lib\site-packages\django\db\models\base.py", line 859, in _do_insert
    using=using, raw=raw)
  File "C:\Python27\lib\site-packages\django\db\models\manager.py", line 122, in manager_method
    return getattr(self.get_queryset(), name)(*args, **kwargs)
  File "C:\Python27\lib\site-packages\django\db\models\query.py", line 1039, in _insert
    return query.get_compiler(using=using).execute_sql(return_id)
  File "C:\Python27\lib\site-packages\django\db\models\sql\compiler.py", line 1060, in execute_sql
    cursor.execute(sql, params)
  File "C:\Python27\lib\site-packages\django\db\backends\utils.py", line 79, in execute
    return super(CursorDebugWrapper, self).execute(sql, params)
  File "C:\Python27\lib\site-packages\django\db\backends\utils.py", line 64, in execute
    return self.cursor.execute(sql, params)
  File "C:\Python27\lib\site-packages\django\db\utils.py", line 95, in __exit__
    six.reraise(dj_exc_type, dj_exc_value, traceback)
  File "C:\Python27\lib\site-packages\django\db\backends\utils.py", line 64, in execute
    return self.cursor.execute(sql, params)
DataError: el valor es demasiado largo para el tipo character varying(10)

.-.-.-.-.-.-.-.-.-.-.-.-.-.-.-.-.-.-.-.-.-.-.-.-.-.-.-.-.-.-.-.-.-.-.-.-.-.-.-.- 
 ERROR 2016-10-19 10:19:06,046 base 4436 4124 Internal Server Error: /bill/save/ 
Traceback (most recent call last):
  File "C:\Python27\lib\site-packages\django\core\handlers\base.py", line 149, in get_response
    response = self.process_exception_by_middleware(e, request)
  File "C:\Python27\lib\site-packages\django\core\handlers\base.py", line 147, in get_response
    response = wrapped_callback(request, *callback_args, **callback_kwargs)
  File "C:\Python27\lib\site-packages\django\views\decorators\csrf.py", line 58, in wrapped_view
    return view_func(*args, **kwargs)
  File "D:\Proyectos\infa web\infa_web\infa_web\apps\facturacion\views.py", line 413, in BillSave
    'vtdescu': float(data['vdescu'])
  File "D:\Proyectos\infa web\infa_web\infa_web\apps\facturacion\views.py", line 166, in save_movi
    movi.save(using = request_db)
  File "C:\Python27\lib\site-packages\django\db\models\base.py", line 708, in save
    force_update=force_update, update_fields=update_fields)
  File "C:\Python27\lib\site-packages\django\db\models\base.py", line 736, in save_base
    updated = self._save_table(raw, cls, force_insert, force_update, using, update_fields)
  File "C:\Python27\lib\site-packages\django\db\models\base.py", line 820, in _save_table
    result = self._do_insert(cls._base_manager, using, fields, update_pk, raw)
  File "C:\Python27\lib\site-packages\django\db\models\base.py", line 859, in _do_insert
    using=using, raw=raw)
  File "C:\Python27\lib\site-packages\django\db\models\manager.py", line 122, in manager_method
    return getattr(self.get_queryset(), name)(*args, **kwargs)
  File "C:\Python27\lib\site-packages\django\db\models\query.py", line 1039, in _insert
    return query.get_compiler(using=using).execute_sql(return_id)
  File "C:\Python27\lib\site-packages\django\db\models\sql\compiler.py", line 1060, in execute_sql
    cursor.execute(sql, params)
  File "C:\Python27\lib\site-packages\django\db\backends\utils.py", line 79, in execute
    return super(CursorDebugWrapper, self).execute(sql, params)
  File "C:\Python27\lib\site-packages\django\db\backends\utils.py", line 64, in execute
    return self.cursor.execute(sql, params)
  File "C:\Python27\lib\site-packages\django\db\utils.py", line 95, in __exit__
    six.reraise(dj_exc_type, dj_exc_value, traceback)
  File "C:\Python27\lib\site-packages\django\db\backends\utils.py", line 64, in execute
    return self.cursor.execute(sql, params)
DataError: el valor es demasiado largo para el tipo character varying(10)

.-.-.-.-.-.-.-.-.-.-.-.-.-.-.-.-.-.-.-.-.-.-.-.-.-.-.-.-.-.-.-.-.-.-.-.-.-.-.-.- 
 ERROR 2016-10-19 10:57:47,075 base 4320 5068 Internal Server Error: /cartera/ 
Traceback (most recent call last):
  File "C:\Python27\lib\site-packages\django\core\handlers\base.py", line 174, in get_response
    response = self.process_exception_by_middleware(e, request)
  File "C:\Python27\lib\site-packages\django\core\handlers\base.py", line 172, in get_response
    response = response.render()
  File "C:\Python27\lib\site-packages\django\template\response.py", line 160, in render
    self.content = self.rendered_content
  File "C:\Python27\lib\site-packages\django\template\response.py", line 137, in rendered_content
    content = template.render(context, self._request)
  File "C:\Python27\lib\site-packages\django\template\backends\django.py", line 95, in render
    return self.template.render(context)
  File "C:\Python27\lib\site-packages\django\template\base.py", line 206, in render
    return self._render(context)
  File "C:\Python27\lib\site-packages\django\template\base.py", line 197, in _render
    return self.nodelist.render(context)
  File "C:\Python27\lib\site-packages\django\template\base.py", line 992, in render
    bit = node.render_annotated(context)
  File "C:\Python27\lib\site-packages\django\template\base.py", line 959, in render_annotated
    return self.render(context)
  File "C:\Python27\lib\site-packages\django\template\loader_tags.py", line 173, in render
    return compiled_parent._render(context)
  File "C:\Python27\lib\site-packages\django\template\base.py", line 197, in _render
    return self.nodelist.render(context)
  File "C:\Python27\lib\site-packages\django\template\base.py", line 992, in render
    bit = node.render_annotated(context)
  File "C:\Python27\lib\site-packages\django\template\base.py", line 959, in render_annotated
    return self.render(context)
  File "C:\Python27\lib\site-packages\django\template\loader_tags.py", line 69, in render
    result = block.nodelist.render(context)
  File "C:\Python27\lib\site-packages\django\template\base.py", line 992, in render
    bit = node.render_annotated(context)
  File "C:\Python27\lib\site-packages\django\template\base.py", line 959, in render_annotated
    return self.render(context)
  File "C:\Python27\lib\site-packages\django\template\defaulttags.py", line 220, in render
    nodelist.append(node.render_annotated(context))
  File "C:\Python27\lib\site-packages\django\template\base.py", line 959, in render_annotated
    return self.render(context)
  File "C:\Python27\lib\site-packages\django\template\base.py", line 1043, in render
    output = self.filter_expression.resolve(context)
  File "C:\Python27\lib\site-packages\django\template\base.py", line 736, in resolve
    new_obj = func(obj, *arg_vals)
  File "D:\Proyectos\infa web\infa_web\infa_web\apps\base\templatetags\date_appen.py", line 86, in saldo_factura
    ctimo_ab = ctimo_billing('ctimo_ab_billing')
TypeError: ctimo_billing() takes exactly 2 arguments (1 given)
.-.-.-.-.-.-.-.-.-.-.-.-.-.-.-.-.-.-.-.-.-.-.-.-.-.-.-.-.-.-.-.-.-.-.-.-.-.-.-.- 
 ERROR 2016-10-19 10:57:49,789 base 4320 4256 Internal Server Error: /cartera/ 
Traceback (most recent call last):
  File "C:\Python27\lib\site-packages\django\core\handlers\base.py", line 174, in get_response
    response = self.process_exception_by_middleware(e, request)
  File "C:\Python27\lib\site-packages\django\core\handlers\base.py", line 172, in get_response
    response = response.render()
  File "C:\Python27\lib\site-packages\django\template\response.py", line 160, in render
    self.content = self.rendered_content
  File "C:\Python27\lib\site-packages\django\template\response.py", line 137, in rendered_content
    content = template.render(context, self._request)
  File "C:\Python27\lib\site-packages\django\template\backends\django.py", line 95, in render
    return self.template.render(context)
  File "C:\Python27\lib\site-packages\django\template\base.py", line 206, in render
    return self._render(context)
  File "C:\Python27\lib\site-packages\django\template\base.py", line 197, in _render
    return self.nodelist.render(context)
  File "C:\Python27\lib\site-packages\django\template\base.py", line 992, in render
    bit = node.render_annotated(context)
  File "C:\Python27\lib\site-packages\django\template\base.py", line 959, in render_annotated
    return self.render(context)
  File "C:\Python27\lib\site-packages\django\template\loader_tags.py", line 173, in render
    return compiled_parent._render(context)
  File "C:\Python27\lib\site-packages\django\template\base.py", line 197, in _render
    return self.nodelist.render(context)
  File "C:\Python27\lib\site-packages\django\template\base.py", line 992, in render
    bit = node.render_annotated(context)
  File "C:\Python27\lib\site-packages\django\template\base.py", line 959, in render_annotated
    return self.render(context)
  File "C:\Python27\lib\site-packages\django\template\loader_tags.py", line 69, in render
    result = block.nodelist.render(context)
  File "C:\Python27\lib\site-packages\django\template\base.py", line 992, in render
    bit = node.render_annotated(context)
  File "C:\Python27\lib\site-packages\django\template\base.py", line 959, in render_annotated
    return self.render(context)
  File "C:\Python27\lib\site-packages\django\template\defaulttags.py", line 220, in render
    nodelist.append(node.render_annotated(context))
  File "C:\Python27\lib\site-packages\django\template\base.py", line 959, in render_annotated
    return self.render(context)
  File "C:\Python27\lib\site-packages\django\template\base.py", line 1043, in render
    output = self.filter_expression.resolve(context)
  File "C:\Python27\lib\site-packages\django\template\base.py", line 736, in resolve
    new_obj = func(obj, *arg_vals)
  File "D:\Proyectos\infa web\infa_web\infa_web\apps\base\templatetags\date_appen.py", line 86, in saldo_factura
    ctimo_ab = ctimo_billing('ctimo_ab_billing')
TypeError: ctimo_billing() takes exactly 2 arguments (1 given)
.-.-.-.-.-.-.-.-.-.-.-.-.-.-.-.-.-.-.-.-.-.-.-.-.-.-.-.-.-.-.-.-.-.-.-.-.-.-.-.- 
 ERROR 2016-10-19 10:58:14,437 base 4320 3840 Internal Server Error: /cartera/ 
Traceback (most recent call last):
  File "C:\Python27\lib\site-packages\django\core\handlers\base.py", line 174, in get_response
    response = self.process_exception_by_middleware(e, request)
  File "C:\Python27\lib\site-packages\django\core\handlers\base.py", line 172, in get_response
    response = response.render()
  File "C:\Python27\lib\site-packages\django\template\response.py", line 160, in render
    self.content = self.rendered_content
  File "C:\Python27\lib\site-packages\django\template\response.py", line 137, in rendered_content
    content = template.render(context, self._request)
  File "C:\Python27\lib\site-packages\django\template\backends\django.py", line 95, in render
    return self.template.render(context)
  File "C:\Python27\lib\site-packages\django\template\base.py", line 206, in render
    return self._render(context)
  File "C:\Python27\lib\site-packages\django\template\base.py", line 197, in _render
    return self.nodelist.render(context)
  File "C:\Python27\lib\site-packages\django\template\base.py", line 992, in render
    bit = node.render_annotated(context)
  File "C:\Python27\lib\site-packages\django\template\base.py", line 959, in render_annotated
    return self.render(context)
  File "C:\Python27\lib\site-packages\django\template\loader_tags.py", line 173, in render
    return compiled_parent._render(context)
  File "C:\Python27\lib\site-packages\django\template\base.py", line 197, in _render
    return self.nodelist.render(context)
  File "C:\Python27\lib\site-packages\django\template\base.py", line 992, in render
    bit = node.render_annotated(context)
  File "C:\Python27\lib\site-packages\django\template\base.py", line 959, in render_annotated
    return self.render(context)
  File "C:\Python27\lib\site-packages\django\template\loader_tags.py", line 69, in render
    result = block.nodelist.render(context)
  File "C:\Python27\lib\site-packages\django\template\base.py", line 992, in render
    bit = node.render_annotated(context)
  File "C:\Python27\lib\site-packages\django\template\base.py", line 959, in render_annotated
    return self.render(context)
  File "C:\Python27\lib\site-packages\django\template\defaulttags.py", line 220, in render
    nodelist.append(node.render_annotated(context))
  File "C:\Python27\lib\site-packages\django\template\base.py", line 959, in render_annotated
    return self.render(context)
  File "C:\Python27\lib\site-packages\django\template\base.py", line 1043, in render
    output = self.filter_expression.resolve(context)
  File "C:\Python27\lib\site-packages\django\template\base.py", line 736, in resolve
    new_obj = func(obj, *arg_vals)
  File "D:\Proyectos\infa web\infa_web\infa_web\apps\base\templatetags\date_appen.py", line 86, in saldo_factura
    ctimo_ab = ctimo_billing('ctimo_ab_billing')
TypeError: ctimo_billing() takes exactly 2 arguments (1 given)
.-.-.-.-.-.-.-.-.-.-.-.-.-.-.-.-.-.-.-.-.-.-.-.-.-.-.-.-.-.-.-.-.-.-.-.-.-.-.-.- 
 ERROR 2016-10-19 10:58:16,888 base 4320 1100 Internal Server Error: /cartera/ 
Traceback (most recent call last):
  File "C:\Python27\lib\site-packages\django\core\handlers\base.py", line 174, in get_response
    response = self.process_exception_by_middleware(e, request)
  File "C:\Python27\lib\site-packages\django\core\handlers\base.py", line 172, in get_response
    response = response.render()
  File "C:\Python27\lib\site-packages\django\template\response.py", line 160, in render
    self.content = self.rendered_content
  File "C:\Python27\lib\site-packages\django\template\response.py", line 137, in rendered_content
    content = template.render(context, self._request)
  File "C:\Python27\lib\site-packages\django\template\backends\django.py", line 95, in render
    return self.template.render(context)
  File "C:\Python27\lib\site-packages\django\template\base.py", line 206, in render
    return self._render(context)
  File "C:\Python27\lib\site-packages\django\template\base.py", line 197, in _render
    return self.nodelist.render(context)
  File "C:\Python27\lib\site-packages\django\template\base.py", line 992, in render
    bit = node.render_annotated(context)
  File "C:\Python27\lib\site-packages\django\template\base.py", line 959, in render_annotated
    return self.render(context)
  File "C:\Python27\lib\site-packages\django\template\loader_tags.py", line 173, in render
    return compiled_parent._render(context)
  File "C:\Python27\lib\site-packages\django\template\base.py", line 197, in _render
    return self.nodelist.render(context)
  File "C:\Python27\lib\site-packages\django\template\base.py", line 992, in render
    bit = node.render_annotated(context)
  File "C:\Python27\lib\site-packages\django\template\base.py", line 959, in render_annotated
    return self.render(context)
  File "C:\Python27\lib\site-packages\django\template\loader_tags.py", line 69, in render
    result = block.nodelist.render(context)
  File "C:\Python27\lib\site-packages\django\template\base.py", line 992, in render
    bit = node.render_annotated(context)
  File "C:\Python27\lib\site-packages\django\template\base.py", line 959, in render_annotated
    return self.render(context)
  File "C:\Python27\lib\site-packages\django\template\defaulttags.py", line 220, in render
    nodelist.append(node.render_annotated(context))
  File "C:\Python27\lib\site-packages\django\template\base.py", line 959, in render_annotated
    return self.render(context)
  File "C:\Python27\lib\site-packages\django\template\base.py", line 1043, in render
    output = self.filter_expression.resolve(context)
  File "C:\Python27\lib\site-packages\django\template\base.py", line 736, in resolve
    new_obj = func(obj, *arg_vals)
  File "D:\Proyectos\infa web\infa_web\infa_web\apps\base\templatetags\date_appen.py", line 86, in saldo_factura
    ctimo_ab = ctimo_billing('ctimo_ab_billing')
TypeError: ctimo_billing() takes exactly 2 arguments (1 given)
.-.-.-.-.-.-.-.-.-.-.-.-.-.-.-.-.-.-.-.-.-.-.-.-.-.-.-.-.-.-.-.-.-.-.-.-.-.-.-.- 
 ERROR 2016-10-19 10:59:54,947 base 4544 5508 Internal Server Error: /cartera/ 
Traceback (most recent call last):
  File "C:\Python27\lib\site-packages\django\core\handlers\base.py", line 174, in get_response
    response = self.process_exception_by_middleware(e, request)
  File "C:\Python27\lib\site-packages\django\core\handlers\base.py", line 172, in get_response
    response = response.render()
  File "C:\Python27\lib\site-packages\django\template\response.py", line 160, in render
    self.content = self.rendered_content
  File "C:\Python27\lib\site-packages\django\template\response.py", line 137, in rendered_content
    content = template.render(context, self._request)
  File "C:\Python27\lib\site-packages\django\template\backends\django.py", line 95, in render
    return self.template.render(context)
  File "C:\Python27\lib\site-packages\django\template\base.py", line 206, in render
    return self._render(context)
  File "C:\Python27\lib\site-packages\django\template\base.py", line 197, in _render
    return self.nodelist.render(context)
  File "C:\Python27\lib\site-packages\django\template\base.py", line 992, in render
    bit = node.render_annotated(context)
  File "C:\Python27\lib\site-packages\django\template\base.py", line 959, in render_annotated
    return self.render(context)
  File "C:\Python27\lib\site-packages\django\template\loader_tags.py", line 173, in render
    return compiled_parent._render(context)
  File "C:\Python27\lib\site-packages\django\template\base.py", line 197, in _render
    return self.nodelist.render(context)
  File "C:\Python27\lib\site-packages\django\template\base.py", line 992, in render
    bit = node.render_annotated(context)
  File "C:\Python27\lib\site-packages\django\template\base.py", line 959, in render_annotated
    return self.render(context)
  File "C:\Python27\lib\site-packages\django\template\loader_tags.py", line 69, in render
    result = block.nodelist.render(context)
  File "C:\Python27\lib\site-packages\django\template\base.py", line 992, in render
    bit = node.render_annotated(context)
  File "C:\Python27\lib\site-packages\django\template\base.py", line 959, in render_annotated
    return self.render(context)
  File "C:\Python27\lib\site-packages\django\template\defaulttags.py", line 220, in render
    nodelist.append(node.render_annotated(context))
  File "C:\Python27\lib\site-packages\django\template\base.py", line 959, in render_annotated
    return self.render(context)
  File "C:\Python27\lib\site-packages\django\template\base.py", line 1043, in render
    output = self.filter_expression.resolve(context)
  File "C:\Python27\lib\site-packages\django\template\base.py", line 736, in resolve
    new_obj = func(obj, *arg_vals)
  File "D:\Proyectos\infa web\infa_web\infa_web\apps\base\templatetags\date_appen.py", line 87, in saldo_factura
    ab = int(Movideta.objects.using(request_db).filter(docrefe = cmovi, cmovi__ctimo = ctimo_ab.pk).aggregate(ab_tot = Sum('vmovi')).ab_tot)
AttributeError: 'dict' object has no attribute 'ab_tot'
.-.-.-.-.-.-.-.-.-.-.-.-.-.-.-.-.-.-.-.-.-.-.-.-.-.-.-.-.-.-.-.-.-.-.-.-.-.-.-.- 
 ERROR 2016-10-19 10:59:58,056 base 4544 4956 Internal Server Error: /cartera/ 
Traceback (most recent call last):
  File "C:\Python27\lib\site-packages\django\core\handlers\base.py", line 174, in get_response
    response = self.process_exception_by_middleware(e, request)
  File "C:\Python27\lib\site-packages\django\core\handlers\base.py", line 172, in get_response
    response = response.render()
  File "C:\Python27\lib\site-packages\django\template\response.py", line 160, in render
    self.content = self.rendered_content
  File "C:\Python27\lib\site-packages\django\template\response.py", line 137, in rendered_content
    content = template.render(context, self._request)
  File "C:\Python27\lib\site-packages\django\template\backends\django.py", line 95, in render
    return self.template.render(context)
  File "C:\Python27\lib\site-packages\django\template\base.py", line 206, in render
    return self._render(context)
  File "C:\Python27\lib\site-packages\django\template\base.py", line 197, in _render
    return self.nodelist.render(context)
  File "C:\Python27\lib\site-packages\django\template\base.py", line 992, in render
    bit = node.render_annotated(context)
  File "C:\Python27\lib\site-packages\django\template\base.py", line 959, in render_annotated
    return self.render(context)
  File "C:\Python27\lib\site-packages\django\template\loader_tags.py", line 173, in render
    return compiled_parent._render(context)
  File "C:\Python27\lib\site-packages\django\template\base.py", line 197, in _render
    return self.nodelist.render(context)
  File "C:\Python27\lib\site-packages\django\template\base.py", line 992, in render
    bit = node.render_annotated(context)
  File "C:\Python27\lib\site-packages\django\template\base.py", line 959, in render_annotated
    return self.render(context)
  File "C:\Python27\lib\site-packages\django\template\loader_tags.py", line 69, in render
    result = block.nodelist.render(context)
  File "C:\Python27\lib\site-packages\django\template\base.py", line 992, in render
    bit = node.render_annotated(context)
  File "C:\Python27\lib\site-packages\django\template\base.py", line 959, in render_annotated
    return self.render(context)
  File "C:\Python27\lib\site-packages\django\template\defaulttags.py", line 220, in render
    nodelist.append(node.render_annotated(context))
  File "C:\Python27\lib\site-packages\django\template\base.py", line 959, in render_annotated
    return self.render(context)
  File "C:\Python27\lib\site-packages\django\template\base.py", line 1043, in render
    output = self.filter_expression.resolve(context)
  File "C:\Python27\lib\site-packages\django\template\base.py", line 736, in resolve
    new_obj = func(obj, *arg_vals)
  File "D:\Proyectos\infa web\infa_web\infa_web\apps\base\templatetags\date_appen.py", line 87, in saldo_factura
    ab = int(Movideta.objects.using(request_db).filter(docrefe = cmovi, cmovi__ctimo = ctimo_ab.pk).aggregate(ab_tot = Sum('vmovi')).ab_tot)
AttributeError: 'dict' object has no attribute 'ab_tot'
.-.-.-.-.-.-.-.-.-.-.-.-.-.-.-.-.-.-.-.-.-.-.-.-.-.-.-.-.-.-.-.-.-.-.-.-.-.-.-.- 
 ERROR 2016-10-19 11:00:29,015 base 4312 2800 Internal Server Error: /cartera/ 
Traceback (most recent call last):
  File "C:\Python27\lib\site-packages\django\core\handlers\base.py", line 174, in get_response
    response = self.process_exception_by_middleware(e, request)
  File "C:\Python27\lib\site-packages\django\core\handlers\base.py", line 172, in get_response
    response = response.render()
  File "C:\Python27\lib\site-packages\django\template\response.py", line 160, in render
    self.content = self.rendered_content
  File "C:\Python27\lib\site-packages\django\template\response.py", line 137, in rendered_content
    content = template.render(context, self._request)
  File "C:\Python27\lib\site-packages\django\template\backends\django.py", line 95, in render
    return self.template.render(context)
  File "C:\Python27\lib\site-packages\django\template\base.py", line 206, in render
    return self._render(context)
  File "C:\Python27\lib\site-packages\django\template\base.py", line 197, in _render
    return self.nodelist.render(context)
  File "C:\Python27\lib\site-packages\django\template\base.py", line 992, in render
    bit = node.render_annotated(context)
  File "C:\Python27\lib\site-packages\django\template\base.py", line 959, in render_annotated
    return self.render(context)
  File "C:\Python27\lib\site-packages\django\template\loader_tags.py", line 173, in render
    return compiled_parent._render(context)
  File "C:\Python27\lib\site-packages\django\template\base.py", line 197, in _render
    return self.nodelist.render(context)
  File "C:\Python27\lib\site-packages\django\template\base.py", line 992, in render
    bit = node.render_annotated(context)
  File "C:\Python27\lib\site-packages\django\template\base.py", line 959, in render_annotated
    return self.render(context)
  File "C:\Python27\lib\site-packages\django\template\loader_tags.py", line 69, in render
    result = block.nodelist.render(context)
  File "C:\Python27\lib\site-packages\django\template\base.py", line 992, in render
    bit = node.render_annotated(context)
  File "C:\Python27\lib\site-packages\django\template\base.py", line 959, in render_annotated
    return self.render(context)
  File "C:\Python27\lib\site-packages\django\template\defaulttags.py", line 220, in render
    nodelist.append(node.render_annotated(context))
  File "C:\Python27\lib\site-packages\django\template\base.py", line 959, in render_annotated
    return self.render(context)
  File "C:\Python27\lib\site-packages\django\template\base.py", line 1043, in render
    output = self.filter_expression.resolve(context)
  File "C:\Python27\lib\site-packages\django\template\base.py", line 736, in resolve
    new_obj = func(obj, *arg_vals)
  File "D:\Proyectos\infa web\infa_web\infa_web\apps\base\templatetags\date_appen.py", line 87, in saldo_factura
    ab = int(Movideta.objects.using(request_db).filter(docrefe = cmovi, cmovi__ctimo = ctimo_ab.pk).aggregate(ab_tot = Sum('vmovi'))['ab_tot'])
TypeError: int() argument must be a string or a number, not 'NoneType'
.-.-.-.-.-.-.-.-.-.-.-.-.-.-.-.-.-.-.-.-.-.-.-.-.-.-.-.-.-.-.-.-.-.-.-.-.-.-.-.- 
 ERROR 2016-10-19 11:03:00,447 base 5544 2432 Internal Server Error: /cartera/ 
Traceback (most recent call last):
  File "C:\Python27\lib\site-packages\django\core\handlers\base.py", line 174, in get_response
    response = self.process_exception_by_middleware(e, request)
  File "C:\Python27\lib\site-packages\django\core\handlers\base.py", line 172, in get_response
    response = response.render()
  File "C:\Python27\lib\site-packages\django\template\response.py", line 160, in render
    self.content = self.rendered_content
  File "C:\Python27\lib\site-packages\django\template\response.py", line 137, in rendered_content
    content = template.render(context, self._request)
  File "C:\Python27\lib\site-packages\django\template\backends\django.py", line 95, in render
    return self.template.render(context)
  File "C:\Python27\lib\site-packages\django\template\base.py", line 206, in render
    return self._render(context)
  File "C:\Python27\lib\site-packages\django\template\base.py", line 197, in _render
    return self.nodelist.render(context)
  File "C:\Python27\lib\site-packages\django\template\base.py", line 992, in render
    bit = node.render_annotated(context)
  File "C:\Python27\lib\site-packages\django\template\base.py", line 959, in render_annotated
    return self.render(context)
  File "C:\Python27\lib\site-packages\django\template\loader_tags.py", line 173, in render
    return compiled_parent._render(context)
  File "C:\Python27\lib\site-packages\django\template\base.py", line 197, in _render
    return self.nodelist.render(context)
  File "C:\Python27\lib\site-packages\django\template\base.py", line 992, in render
    bit = node.render_annotated(context)
  File "C:\Python27\lib\site-packages\django\template\base.py", line 959, in render_annotated
    return self.render(context)
  File "C:\Python27\lib\site-packages\django\template\loader_tags.py", line 69, in render
    result = block.nodelist.render(context)
  File "C:\Python27\lib\site-packages\django\template\base.py", line 992, in render
    bit = node.render_annotated(context)
  File "C:\Python27\lib\site-packages\django\template\base.py", line 959, in render_annotated
    return self.render(context)
  File "C:\Python27\lib\site-packages\django\template\defaulttags.py", line 220, in render
    nodelist.append(node.render_annotated(context))
  File "C:\Python27\lib\site-packages\django\template\base.py", line 959, in render_annotated
    return self.render(context)
  File "C:\Python27\lib\site-packages\django\template\base.py", line 1043, in render
    output = self.filter_expression.resolve(context)
  File "C:\Python27\lib\site-packages\django\template\base.py", line 736, in resolve
    new_obj = func(obj, *arg_vals)
  File "D:\Proyectos\infa web\infa_web\infa_web\apps\base\templatetags\date_appen.py", line 85, in saldo_factura
    movi = Movi.objects.using(request_db).get(cmomi = cmovi)
  File "C:\Python27\lib\site-packages\django\db\models\query.py", line 378, in get
    clone = self.filter(*args, **kwargs)
  File "C:\Python27\lib\site-packages\django\db\models\query.py", line 790, in filter
    return self._filter_or_exclude(False, *args, **kwargs)
  File "C:\Python27\lib\site-packages\django\db\models\query.py", line 808, in _filter_or_exclude
    clone.query.add_q(Q(*args, **kwargs))
  File "C:\Python27\lib\site-packages\django\db\models\sql\query.py", line 1243, in add_q
    clause, _ = self._add_q(q_object, self.used_aliases)
  File "C:\Python27\lib\site-packages\django\db\models\sql\query.py", line 1269, in _add_q
    allow_joins=allow_joins, split_subq=split_subq,
  File "C:\Python27\lib\site-packages\django\db\models\sql\query.py", line 1149, in build_filter
    lookups, parts, reffed_expression = self.solve_lookup_type(arg)
  File "C:\Python27\lib\site-packages\django\db\models\sql\query.py", line 1035, in solve_lookup_type
    _, field, _, lookup_parts = self.names_to_path(lookup_splitted, self.get_meta())
  File "C:\Python27\lib\site-packages\django\db\models\sql\query.py", line 1330, in names_to_path
    "Choices are: %s" % (name, ", ".join(available)))
FieldError: Cannot resolve keyword 'cmomi' into field. Choices are: baseiva, ccaja, ccaja_id, cesdo, cesdo_id, citerce, citerce_id, cmovi, ctimo, ctimo_id, descrimovi, detaanula, fmovi, movideta, movipago, vcambio, vch, vcred, vefe, ventre, vtar, vtdescu, vtiva, vtsuma, vttotal
.-.-.-.-.-.-.-.-.-.-.-.-.-.-.-.-.-.-.-.-.-.-.-.-.-.-.-.-.-.-.-.-.-.-.-.-.-.-.-.- 
 ERROR 2016-10-19 11:03:04,894 base 5544 5616 Internal Server Error: /cartera/ 
Traceback (most recent call last):
  File "C:\Python27\lib\site-packages\django\core\handlers\base.py", line 174, in get_response
    response = self.process_exception_by_middleware(e, request)
  File "C:\Python27\lib\site-packages\django\core\handlers\base.py", line 172, in get_response
    response = response.render()
  File "C:\Python27\lib\site-packages\django\template\response.py", line 160, in render
    self.content = self.rendered_content
  File "C:\Python27\lib\site-packages\django\template\response.py", line 137, in rendered_content
    content = template.render(context, self._request)
  File "C:\Python27\lib\site-packages\django\template\backends\django.py", line 95, in render
    return self.template.render(context)
  File "C:\Python27\lib\site-packages\django\template\base.py", line 206, in render
    return self._render(context)
  File "C:\Python27\lib\site-packages\django\template\base.py", line 197, in _render
    return self.nodelist.render(context)
  File "C:\Python27\lib\site-packages\django\template\base.py", line 992, in render
    bit = node.render_annotated(context)
  File "C:\Python27\lib\site-packages\django\template\base.py", line 959, in render_annotated
    return self.render(context)
  File "C:\Python27\lib\site-packages\django\template\loader_tags.py", line 173, in render
    return compiled_parent._render(context)
  File "C:\Python27\lib\site-packages\django\template\base.py", line 197, in _render
    return self.nodelist.render(context)
  File "C:\Python27\lib\site-packages\django\template\base.py", line 992, in render
    bit = node.render_annotated(context)
  File "C:\Python27\lib\site-packages\django\template\base.py", line 959, in render_annotated
    return self.render(context)
  File "C:\Python27\lib\site-packages\django\template\loader_tags.py", line 69, in render
    result = block.nodelist.render(context)
  File "C:\Python27\lib\site-packages\django\template\base.py", line 992, in render
    bit = node.render_annotated(context)
  File "C:\Python27\lib\site-packages\django\template\base.py", line 959, in render_annotated
    return self.render(context)
  File "C:\Python27\lib\site-packages\django\template\defaulttags.py", line 220, in render
    nodelist.append(node.render_annotated(context))
  File "C:\Python27\lib\site-packages\django\template\base.py", line 959, in render_annotated
    return self.render(context)
  File "C:\Python27\lib\site-packages\django\template\base.py", line 1043, in render
    output = self.filter_expression.resolve(context)
  File "C:\Python27\lib\site-packages\django\template\base.py", line 736, in resolve
    new_obj = func(obj, *arg_vals)
  File "D:\Proyectos\infa web\infa_web\infa_web\apps\base\templatetags\date_appen.py", line 85, in saldo_factura
    movi = Movi.objects.using(request_db).get(cmomi = cmovi)
  File "C:\Python27\lib\site-packages\django\db\models\query.py", line 378, in get
    clone = self.filter(*args, **kwargs)
  File "C:\Python27\lib\site-packages\django\db\models\query.py", line 790, in filter
    return self._filter_or_exclude(False, *args, **kwargs)
  File "C:\Python27\lib\site-packages\django\db\models\query.py", line 808, in _filter_or_exclude
    clone.query.add_q(Q(*args, **kwargs))
  File "C:\Python27\lib\site-packages\django\db\models\sql\query.py", line 1243, in add_q
    clause, _ = self._add_q(q_object, self.used_aliases)
  File "C:\Python27\lib\site-packages\django\db\models\sql\query.py", line 1269, in _add_q
    allow_joins=allow_joins, split_subq=split_subq,
  File "C:\Python27\lib\site-packages\django\db\models\sql\query.py", line 1149, in build_filter
    lookups, parts, reffed_expression = self.solve_lookup_type(arg)
  File "C:\Python27\lib\site-packages\django\db\models\sql\query.py", line 1035, in solve_lookup_type
    _, field, _, lookup_parts = self.names_to_path(lookup_splitted, self.get_meta())
  File "C:\Python27\lib\site-packages\django\db\models\sql\query.py", line 1330, in names_to_path
    "Choices are: %s" % (name, ", ".join(available)))
FieldError: Cannot resolve keyword 'cmomi' into field. Choices are: baseiva, ccaja, ccaja_id, cesdo, cesdo_id, citerce, citerce_id, cmovi, ctimo, ctimo_id, descrimovi, detaanula, fmovi, movideta, movipago, vcambio, vch, vcred, vefe, ventre, vtar, vtdescu, vtiva, vtsuma, vttotal
.-.-.-.-.-.-.-.-.-.-.-.-.-.-.-.-.-.-.-.-.-.-.-.-.-.-.-.-.-.-.-.-.-.-.-.-.-.-.-.- 
 ERROR 2016-10-19 11:03:15,242 base 2152 2444 Internal Server Error: /cartera/ 
Traceback (most recent call last):
  File "C:\Python27\lib\site-packages\django\core\handlers\base.py", line 174, in get_response
    response = self.process_exception_by_middleware(e, request)
  File "C:\Python27\lib\site-packages\django\core\handlers\base.py", line 172, in get_response
    response = response.render()
  File "C:\Python27\lib\site-packages\django\template\response.py", line 160, in render
    self.content = self.rendered_content
  File "C:\Python27\lib\site-packages\django\template\response.py", line 137, in rendered_content
    content = template.render(context, self._request)
  File "C:\Python27\lib\site-packages\django\template\backends\django.py", line 95, in render
    return self.template.render(context)
  File "C:\Python27\lib\site-packages\django\template\base.py", line 206, in render
    return self._render(context)
  File "C:\Python27\lib\site-packages\django\template\base.py", line 197, in _render
    return self.nodelist.render(context)
  File "C:\Python27\lib\site-packages\django\template\base.py", line 992, in render
    bit = node.render_annotated(context)
  File "C:\Python27\lib\site-packages\django\template\base.py", line 959, in render_annotated
    return self.render(context)
  File "C:\Python27\lib\site-packages\django\template\loader_tags.py", line 173, in render
    return compiled_parent._render(context)
  File "C:\Python27\lib\site-packages\django\template\base.py", line 197, in _render
    return self.nodelist.render(context)
  File "C:\Python27\lib\site-packages\django\template\base.py", line 992, in render
    bit = node.render_annotated(context)
  File "C:\Python27\lib\site-packages\django\template\base.py", line 959, in render_annotated
    return self.render(context)
  File "C:\Python27\lib\site-packages\django\template\loader_tags.py", line 69, in render
    result = block.nodelist.render(context)
  File "C:\Python27\lib\site-packages\django\template\base.py", line 992, in render
    bit = node.render_annotated(context)
  File "C:\Python27\lib\site-packages\django\template\base.py", line 959, in render_annotated
    return self.render(context)
  File "C:\Python27\lib\site-packages\django\template\defaulttags.py", line 220, in render
    nodelist.append(node.render_annotated(context))
  File "C:\Python27\lib\site-packages\django\template\base.py", line 959, in render_annotated
    return self.render(context)
  File "C:\Python27\lib\site-packages\django\template\base.py", line 1043, in render
    output = self.filter_expression.resolve(context)
  File "C:\Python27\lib\site-packages\django\template\base.py", line 736, in resolve
    new_obj = func(obj, *arg_vals)
  File "D:\Proyectos\infa web\infa_web\infa_web\apps\base\templatetags\date_appen.py", line 88, in saldo_factura
    ab = movi.vttotal - float(ab if ab is not None else 0)
TypeError: unsupported operand type(s) for -: 'Decimal' and 'float'
=======
  File "/home/midas/Documentos/infa_web_folder/InfaWeb/infa_web/apps/facturacion/views.py", line 325, in BillSave
    value_vttotal = float(data['vttotal'])
ValueError: could not convert string to float: %24+11%2C000
>>>>>>> 741fbd4327bf04c4460b4a4d50217e42424d4c23
