.-.-.-.-.-.-.-.-.-.-.-.-.-.-.-.-.-.-.-.-.-.-.-.-.-.-.-.-.-.-.-.-.-.-.-.-.-.-.-.- 
 ERROR 2016-10-25 09:46:59,739 base 11772 140296150144768 Internal Server Error: /bill/billing/ 
Traceback (most recent call last):
  File "/home/midas/Documentos/infa_web_folder/dev_env/local/lib/python2.7/site-packages/django/core/handlers/base.py", line 174, in get_response
    response = self.process_exception_by_middleware(e, request)
  File "/home/midas/Documentos/infa_web_folder/dev_env/local/lib/python2.7/site-packages/django/core/handlers/base.py", line 172, in get_response
    response = response.render()
  File "/home/midas/Documentos/infa_web_folder/dev_env/local/lib/python2.7/site-packages/django/template/response.py", line 160, in render
    self.content = self.rendered_content
  File "/home/midas/Documentos/infa_web_folder/dev_env/local/lib/python2.7/site-packages/django/template/response.py", line 135, in rendered_content
    template = self._resolve_template(self.template_name)
  File "/home/midas/Documentos/infa_web_folder/dev_env/local/lib/python2.7/site-packages/django/template/response.py", line 90, in _resolve_template
    new_template = self.resolve_template(template)
  File "/home/midas/Documentos/infa_web_folder/dev_env/local/lib/python2.7/site-packages/django/template/response.py", line 80, in resolve_template
    return select_template(template, using=self.using)
  File "/home/midas/Documentos/infa_web_folder/dev_env/local/lib/python2.7/site-packages/django/template/loader.py", line 55, in select_template
    engines = _engine_list(using)
  File "/home/midas/Documentos/infa_web_folder/dev_env/local/lib/python2.7/site-packages/django/template/loader.py", line 143, in _engine_list
    return engines.all() if using is None else [engines[using]]
  File "/home/midas/Documentos/infa_web_folder/dev_env/local/lib/python2.7/site-packages/django/template/utils.py", line 110, in all
    return [self[alias] for alias in self]
  File "/home/midas/Documentos/infa_web_folder/dev_env/local/lib/python2.7/site-packages/django/template/utils.py", line 101, in __getitem__
    engine = engine_cls(params)
  File "/home/midas/Documentos/infa_web_folder/dev_env/local/lib/python2.7/site-packages/django/template/backends/django.py", line 31, in __init__
    options['libraries'] = self.get_templatetag_libraries(libraries)
  File "/home/midas/Documentos/infa_web_folder/dev_env/local/lib/python2.7/site-packages/django/template/backends/django.py", line 49, in get_templatetag_libraries
    libraries = get_installed_libraries()
  File "/home/midas/Documentos/infa_web_folder/dev_env/local/lib/python2.7/site-packages/django/template/backends/django.py", line 142, in get_installed_libraries
    for name in get_package_libraries(pkg):
  File "/home/midas/Documentos/infa_web_folder/dev_env/local/lib/python2.7/site-packages/django/template/backends/django.py", line 155, in get_package_libraries
    module = import_module(entry[1])
  File "/usr/lib/python2.7/importlib/__init__.py", line 37, in import_module
    __import__(name)
  File "/home/midas/Documentos/infa_web_folder/InfaWeb/infa_web/apps/base/templatetags/tags_appem.py", line 3, in <module>
    register = template.Library()
NameError: name 'template' is not defined
.-.-.-.-.-.-.-.-.-.-.-.-.-.-.-.-.-.-.-.-.-.-.-.-.-.-.-.-.-.-.-.-.-.-.-.-.-.-.-.- 
 ERROR 2016-10-25 09:47:08,699 base 11772 140296150144768 Internal Server Error: /bill/billing/ 
Traceback (most recent call last):
  File "/home/midas/Documentos/infa_web_folder/dev_env/local/lib/python2.7/site-packages/django/core/handlers/base.py", line 174, in get_response
    response = self.process_exception_by_middleware(e, request)
  File "/home/midas/Documentos/infa_web_folder/dev_env/local/lib/python2.7/site-packages/django/core/handlers/base.py", line 172, in get_response
    response = response.render()
  File "/home/midas/Documentos/infa_web_folder/dev_env/local/lib/python2.7/site-packages/django/template/response.py", line 160, in render
    self.content = self.rendered_content
  File "/home/midas/Documentos/infa_web_folder/dev_env/local/lib/python2.7/site-packages/django/template/response.py", line 135, in rendered_content
    template = self._resolve_template(self.template_name)
  File "/home/midas/Documentos/infa_web_folder/dev_env/local/lib/python2.7/site-packages/django/template/response.py", line 90, in _resolve_template
    new_template = self.resolve_template(template)
  File "/home/midas/Documentos/infa_web_folder/dev_env/local/lib/python2.7/site-packages/django/template/response.py", line 80, in resolve_template
    return select_template(template, using=self.using)
  File "/home/midas/Documentos/infa_web_folder/dev_env/local/lib/python2.7/site-packages/django/template/loader.py", line 55, in select_template
    engines = _engine_list(using)
  File "/home/midas/Documentos/infa_web_folder/dev_env/local/lib/python2.7/site-packages/django/template/loader.py", line 143, in _engine_list
    return engines.all() if using is None else [engines[using]]
  File "/home/midas/Documentos/infa_web_folder/dev_env/local/lib/python2.7/site-packages/django/template/utils.py", line 110, in all
    return [self[alias] for alias in self]
  File "/home/midas/Documentos/infa_web_folder/dev_env/local/lib/python2.7/site-packages/django/template/utils.py", line 101, in __getitem__
    engine = engine_cls(params)
  File "/home/midas/Documentos/infa_web_folder/dev_env/local/lib/python2.7/site-packages/django/template/backends/django.py", line 31, in __init__
    options['libraries'] = self.get_templatetag_libraries(libraries)
  File "/home/midas/Documentos/infa_web_folder/dev_env/local/lib/python2.7/site-packages/django/template/backends/django.py", line 49, in get_templatetag_libraries
    libraries = get_installed_libraries()
  File "/home/midas/Documentos/infa_web_folder/dev_env/local/lib/python2.7/site-packages/django/template/backends/django.py", line 142, in get_installed_libraries
    for name in get_package_libraries(pkg):
  File "/home/midas/Documentos/infa_web_folder/dev_env/local/lib/python2.7/site-packages/django/template/backends/django.py", line 155, in get_package_libraries
    module = import_module(entry[1])
  File "/usr/lib/python2.7/importlib/__init__.py", line 37, in import_module
    __import__(name)
  File "/home/midas/Documentos/infa_web_folder/InfaWeb/infa_web/apps/base/templatetags/tags_appem.py", line 3, in <module>
    register = template.Library()
NameError: name 'template' is not defined
.-.-.-.-.-.-.-.-.-.-.-.-.-.-.-.-.-.-.-.-.-.-.-.-.-.-.-.-.-.-.-.-.-.-.-.-.-.-.-.- 
 ERROR 2016-10-25 09:47:18,377 base 11772 140296139917056 Internal Server Error: / 
Traceback (most recent call last):
  File "/home/midas/Documentos/infa_web_folder/dev_env/local/lib/python2.7/site-packages/django/core/handlers/base.py", line 174, in get_response
    response = self.process_exception_by_middleware(e, request)
  File "/home/midas/Documentos/infa_web_folder/dev_env/local/lib/python2.7/site-packages/django/core/handlers/base.py", line 172, in get_response
    response = response.render()
  File "/home/midas/Documentos/infa_web_folder/dev_env/local/lib/python2.7/site-packages/django/template/response.py", line 160, in render
    self.content = self.rendered_content
  File "/home/midas/Documentos/infa_web_folder/dev_env/local/lib/python2.7/site-packages/django/template/response.py", line 135, in rendered_content
    template = self._resolve_template(self.template_name)
  File "/home/midas/Documentos/infa_web_folder/dev_env/local/lib/python2.7/site-packages/django/template/response.py", line 90, in _resolve_template
    new_template = self.resolve_template(template)
  File "/home/midas/Documentos/infa_web_folder/dev_env/local/lib/python2.7/site-packages/django/template/response.py", line 80, in resolve_template
    return select_template(template, using=self.using)
  File "/home/midas/Documentos/infa_web_folder/dev_env/local/lib/python2.7/site-packages/django/template/loader.py", line 55, in select_template
    engines = _engine_list(using)
  File "/home/midas/Documentos/infa_web_folder/dev_env/local/lib/python2.7/site-packages/django/template/loader.py", line 143, in _engine_list
    return engines.all() if using is None else [engines[using]]
  File "/home/midas/Documentos/infa_web_folder/dev_env/local/lib/python2.7/site-packages/django/template/utils.py", line 110, in all
    return [self[alias] for alias in self]
  File "/home/midas/Documentos/infa_web_folder/dev_env/local/lib/python2.7/site-packages/django/template/utils.py", line 101, in __getitem__
    engine = engine_cls(params)
  File "/home/midas/Documentos/infa_web_folder/dev_env/local/lib/python2.7/site-packages/django/template/backends/django.py", line 31, in __init__
    options['libraries'] = self.get_templatetag_libraries(libraries)
  File "/home/midas/Documentos/infa_web_folder/dev_env/local/lib/python2.7/site-packages/django/template/backends/django.py", line 49, in get_templatetag_libraries
    libraries = get_installed_libraries()
  File "/home/midas/Documentos/infa_web_folder/dev_env/local/lib/python2.7/site-packages/django/template/backends/django.py", line 142, in get_installed_libraries
    for name in get_package_libraries(pkg):
  File "/home/midas/Documentos/infa_web_folder/dev_env/local/lib/python2.7/site-packages/django/template/backends/django.py", line 155, in get_package_libraries
    module = import_module(entry[1])
  File "/usr/lib/python2.7/importlib/__init__.py", line 37, in import_module
    __import__(name)
  File "/home/midas/Documentos/infa_web_folder/InfaWeb/infa_web/apps/base/templatetags/tags_appem.py", line 3, in <module>
    register = template.Library()
NameError: name 'template' is not defined
.-.-.-.-.-.-.-.-.-.-.-.-.-.-.-.-.-.-.-.-.-.-.-.-.-.-.-.-.-.-.-.-.-.-.-.-.-.-.-.- 
 ERROR 2016-10-25 09:47:25,689 base 11772 140296150144768 Internal Server Error: / 
Traceback (most recent call last):
  File "/home/midas/Documentos/infa_web_folder/dev_env/local/lib/python2.7/site-packages/django/core/handlers/base.py", line 174, in get_response
    response = self.process_exception_by_middleware(e, request)
  File "/home/midas/Documentos/infa_web_folder/dev_env/local/lib/python2.7/site-packages/django/core/handlers/base.py", line 172, in get_response
    response = response.render()
  File "/home/midas/Documentos/infa_web_folder/dev_env/local/lib/python2.7/site-packages/django/template/response.py", line 160, in render
    self.content = self.rendered_content
  File "/home/midas/Documentos/infa_web_folder/dev_env/local/lib/python2.7/site-packages/django/template/response.py", line 135, in rendered_content
    template = self._resolve_template(self.template_name)
  File "/home/midas/Documentos/infa_web_folder/dev_env/local/lib/python2.7/site-packages/django/template/response.py", line 90, in _resolve_template
    new_template = self.resolve_template(template)
  File "/home/midas/Documentos/infa_web_folder/dev_env/local/lib/python2.7/site-packages/django/template/response.py", line 80, in resolve_template
    return select_template(template, using=self.using)
  File "/home/midas/Documentos/infa_web_folder/dev_env/local/lib/python2.7/site-packages/django/template/loader.py", line 55, in select_template
    engines = _engine_list(using)
  File "/home/midas/Documentos/infa_web_folder/dev_env/local/lib/python2.7/site-packages/django/template/loader.py", line 143, in _engine_list
    return engines.all() if using is None else [engines[using]]
  File "/home/midas/Documentos/infa_web_folder/dev_env/local/lib/python2.7/site-packages/django/template/utils.py", line 110, in all
    return [self[alias] for alias in self]
  File "/home/midas/Documentos/infa_web_folder/dev_env/local/lib/python2.7/site-packages/django/template/utils.py", line 101, in __getitem__
    engine = engine_cls(params)
  File "/home/midas/Documentos/infa_web_folder/dev_env/local/lib/python2.7/site-packages/django/template/backends/django.py", line 31, in __init__
    options['libraries'] = self.get_templatetag_libraries(libraries)
  File "/home/midas/Documentos/infa_web_folder/dev_env/local/lib/python2.7/site-packages/django/template/backends/django.py", line 49, in get_templatetag_libraries
    libraries = get_installed_libraries()
  File "/home/midas/Documentos/infa_web_folder/dev_env/local/lib/python2.7/site-packages/django/template/backends/django.py", line 142, in get_installed_libraries
    for name in get_package_libraries(pkg):
  File "/home/midas/Documentos/infa_web_folder/dev_env/local/lib/python2.7/site-packages/django/template/backends/django.py", line 155, in get_package_libraries
    module = import_module(entry[1])
  File "/usr/lib/python2.7/importlib/__init__.py", line 37, in import_module
    __import__(name)
  File "/home/midas/Documentos/infa_web_folder/InfaWeb/infa_web/apps/base/templatetags/tags_appem.py", line 3, in <module>
    register = template.Library()
NameError: name 'template' is not defined
.-.-.-.-.-.-.-.-.-.-.-.-.-.-.-.-.-.-.-.-.-.-.-.-.-.-.-.-.-.-.-.-.-.-.-.-.-.-.-.- 
 ERROR 2016-10-25 09:47:51,451 base 11891 139779509319424 Internal Server Error: / 
Traceback (most recent call last):
  File "/home/midas/Documentos/infa_web_folder/dev_env/local/lib/python2.7/site-packages/django/core/handlers/base.py", line 174, in get_response
    response = self.process_exception_by_middleware(e, request)
  File "/home/midas/Documentos/infa_web_folder/dev_env/local/lib/python2.7/site-packages/django/core/handlers/base.py", line 172, in get_response
    response = response.render()
  File "/home/midas/Documentos/infa_web_folder/dev_env/local/lib/python2.7/site-packages/django/template/response.py", line 160, in render
    self.content = self.rendered_content
  File "/home/midas/Documentos/infa_web_folder/dev_env/local/lib/python2.7/site-packages/django/template/response.py", line 135, in rendered_content
    template = self._resolve_template(self.template_name)
  File "/home/midas/Documentos/infa_web_folder/dev_env/local/lib/python2.7/site-packages/django/template/response.py", line 90, in _resolve_template
    new_template = self.resolve_template(template)
  File "/home/midas/Documentos/infa_web_folder/dev_env/local/lib/python2.7/site-packages/django/template/response.py", line 80, in resolve_template
    return select_template(template, using=self.using)
  File "/home/midas/Documentos/infa_web_folder/dev_env/local/lib/python2.7/site-packages/django/template/loader.py", line 55, in select_template
    engines = _engine_list(using)
  File "/home/midas/Documentos/infa_web_folder/dev_env/local/lib/python2.7/site-packages/django/template/loader.py", line 143, in _engine_list
    return engines.all() if using is None else [engines[using]]
  File "/home/midas/Documentos/infa_web_folder/dev_env/local/lib/python2.7/site-packages/django/template/utils.py", line 110, in all
    return [self[alias] for alias in self]
  File "/home/midas/Documentos/infa_web_folder/dev_env/local/lib/python2.7/site-packages/django/template/utils.py", line 101, in __getitem__
    engine = engine_cls(params)
  File "/home/midas/Documentos/infa_web_folder/dev_env/local/lib/python2.7/site-packages/django/template/backends/django.py", line 31, in __init__
    options['libraries'] = self.get_templatetag_libraries(libraries)
  File "/home/midas/Documentos/infa_web_folder/dev_env/local/lib/python2.7/site-packages/django/template/backends/django.py", line 49, in get_templatetag_libraries
    libraries = get_installed_libraries()
  File "/home/midas/Documentos/infa_web_folder/dev_env/local/lib/python2.7/site-packages/django/template/backends/django.py", line 142, in get_installed_libraries
    for name in get_package_libraries(pkg):
  File "/home/midas/Documentos/infa_web_folder/dev_env/local/lib/python2.7/site-packages/django/template/backends/django.py", line 155, in get_package_libraries
    module = import_module(entry[1])
  File "/usr/lib/python2.7/importlib/__init__.py", line 37, in import_module
    __import__(name)
  File "/home/midas/Documentos/infa_web_folder/InfaWeb/infa_web/apps/base/templatetags/tags_appem.py", line 3, in <module>
    register = template.Library()
NameError: name 'template' is not defined
.-.-.-.-.-.-.-.-.-.-.-.-.-.-.-.-.-.-.-.-.-.-.-.-.-.-.-.-.-.-.-.-.-.-.-.-.-.-.-.- 
 ERROR 2016-10-25 09:47:58,594 base 11891 139779500926720 Internal Server Error: /parameters/ 
Traceback (most recent call last):
  File "/home/midas/Documentos/infa_web_folder/dev_env/local/lib/python2.7/site-packages/django/core/handlers/base.py", line 149, in get_response
    response = self.process_exception_by_middleware(e, request)
  File "/home/midas/Documentos/infa_web_folder/dev_env/local/lib/python2.7/site-packages/django/core/handlers/base.py", line 147, in get_response
    response = wrapped_callback(request, *callback_args, **callback_kwargs)
<<<<<<< HEAD
  File "/home/jsandoval86/ProjectsDev/Appem/env/local/lib/python2.7/site-packages/django/views/decorators/csrf.py", line 58, in wrapped_view
    return view_func(*args, **kwargs)
  File "/home/jsandoval86/ProjectsDev/Appem/appem/infa_web/apps/facturacion/views.py", line 298, in BillSave
    data['femi'] = data['femi'] + " " + today.strftime("%H:%M:%S")
KeyError: 'femi'
=======
TypeError: int() argument must be a string or a number, not 'Esdo'
>>>>>>> 80aaf54b7872818c3b8df1785cc846c7b7e2e0fc
.-.-.-.-.-.-.-.-.-.-.-.-.-.-.-.-.-.-.-.-.-.-.-.-.-.-.-.-.-.-.-.-.-.-.-.-.-.-.-.- 
 ERROR 2016-10-25 09:43:46,884 base 9789 140232789120768 Internal Server Error: /m/search-client 
Traceback (most recent call last):
  File "/home/jsandoval86/ProjectsDev/Appem/env/local/lib/python2.7/site-packages/django/core/handlers/base.py", line 149, in get_response
    response = self.process_exception_by_middleware(e, request)
  File "/home/jsandoval86/ProjectsDev/Appem/env/local/lib/python2.7/site-packages/django/core/handlers/base.py", line 147, in get_response
    response = wrapped_callback(request, *callback_args, **callback_kwargs)
  File "/home/jsandoval86/ProjectsDev/Appem/appem/infa_web/apps/m/views.py", line 88, in mFacSearchClient
    return render(request, 'm/m_fac_search_client.html', context)
  File "/home/jsandoval86/ProjectsDev/Appem/env/local/lib/python2.7/site-packages/django/shortcuts.py", line 67, in render
    template_name, context, request=request, using=using)
  File "/home/jsandoval86/ProjectsDev/Appem/env/local/lib/python2.7/site-packages/django/template/loader.py", line 97, in render_to_string
    return template.render(context, request)
  File "/home/jsandoval86/ProjectsDev/Appem/env/local/lib/python2.7/site-packages/django/template/backends/django.py", line 95, in render
    return self.template.render(context)
  File "/home/jsandoval86/ProjectsDev/Appem/env/local/lib/python2.7/site-packages/django/template/base.py", line 206, in render
    return self._render(context)
  File "/home/jsandoval86/ProjectsDev/Appem/env/local/lib/python2.7/site-packages/django/template/base.py", line 197, in _render
    return self.nodelist.render(context)
  File "/home/jsandoval86/ProjectsDev/Appem/env/local/lib/python2.7/site-packages/django/template/base.py", line 992, in render
    bit = node.render_annotated(context)
  File "/home/jsandoval86/ProjectsDev/Appem/env/local/lib/python2.7/site-packages/django/template/base.py", line 959, in render_annotated
    return self.render(context)
  File "/home/jsandoval86/ProjectsDev/Appem/env/local/lib/python2.7/site-packages/django/template/loader_tags.py", line 173, in render
    return compiled_parent._render(context)
  File "/home/jsandoval86/ProjectsDev/Appem/env/local/lib/python2.7/site-packages/django/template/base.py", line 197, in _render
    return self.nodelist.render(context)
  File "/home/jsandoval86/ProjectsDev/Appem/env/local/lib/python2.7/site-packages/django/template/base.py", line 992, in render
    bit = node.render_annotated(context)
  File "/home/jsandoval86/ProjectsDev/Appem/env/local/lib/python2.7/site-packages/django/template/base.py", line 959, in render_annotated
    return self.render(context)
  File "/home/jsandoval86/ProjectsDev/Appem/env/local/lib/python2.7/site-packages/django/template/loader_tags.py", line 69, in render
    result = block.nodelist.render(context)
  File "/home/jsandoval86/ProjectsDev/Appem/env/local/lib/python2.7/site-packages/django/template/base.py", line 992, in render
    bit = node.render_annotated(context)
  File "/home/jsandoval86/ProjectsDev/Appem/env/local/lib/python2.7/site-packages/django/template/base.py", line 959, in render_annotated
    return self.render(context)
  File "/home/jsandoval86/ProjectsDev/Appem/env/local/lib/python2.7/site-packages/django/template/defaulttags.py", line 168, in render
    len_values = len(values)
  File "/home/jsandoval86/ProjectsDev/Appem/env/local/lib/python2.7/site-packages/django/db/models/query.py", line 240, in __len__
    self._fetch_all()
  File "/home/jsandoval86/ProjectsDev/Appem/env/local/lib/python2.7/site-packages/django/db/models/query.py", line 1074, in _fetch_all
    self._result_cache = list(self.iterator())
  File "/home/jsandoval86/ProjectsDev/Appem/env/local/lib/python2.7/site-packages/django/db/models/query.py", line 52, in __iter__
    results = compiler.execute_sql()
  File "/home/jsandoval86/ProjectsDev/Appem/env/local/lib/python2.7/site-packages/django/db/models/sql/compiler.py", line 846, in execute_sql
    cursor = self.connection.cursor()
  File "/home/jsandoval86/ProjectsDev/Appem/env/local/lib/python2.7/site-packages/django/db/backends/base/base.py", line 231, in cursor
    cursor = self.make_debug_cursor(self._cursor())
  File "/home/jsandoval86/ProjectsDev/Appem/env/local/lib/python2.7/site-packages/django/db/backends/base/base.py", line 204, in _cursor
    self.ensure_connection()
  File "/home/jsandoval86/ProjectsDev/Appem/env/local/lib/python2.7/site-packages/django/db/backends/base/base.py", line 199, in ensure_connection
    self.connect()
  File "/home/jsandoval86/ProjectsDev/Appem/env/local/lib/python2.7/site-packages/django/db/utils.py", line 95, in __exit__
    six.reraise(dj_exc_type, dj_exc_value, traceback)
  File "/home/jsandoval86/ProjectsDev/Appem/env/local/lib/python2.7/site-packages/django/db/backends/base/base.py", line 199, in ensure_connection
    self.connect()
  File "/home/jsandoval86/ProjectsDev/Appem/env/local/lib/python2.7/site-packages/django/db/backends/base/base.py", line 171, in connect
    self.connection = self.get_new_connection(conn_params)
  File "/home/jsandoval86/ProjectsDev/Appem/env/local/lib/python2.7/site-packages/django/db/backends/postgresql/base.py", line 175, in get_new_connection
    connection = Database.connect(**conn_params)
  File "/home/jsandoval86/ProjectsDev/Appem/env/local/lib/python2.7/site-packages/psycopg2/__init__.py", line 164, in connect
    conn = _connect(dsn, connection_factory=connection_factory, async=async)
OperationalError: FATAL:  password authentication failed for user "root"
FATAL:  password authentication failed for user "root"

.-.-.-.-.-.-.-.-.-.-.-.-.-.-.-.-.-.-.-.-.-.-.-.-.-.-.-.-.-.-.-.-.-.-.-.-.-.-.-.- 
 ERROR 2016-10-25 09:45:54,053 base 10239 139738790016768 Internal Server Error: /m/search-client 
Traceback (most recent call last):
  File "/home/jsandoval86/ProjectsDev/Appem/env/local/lib/python2.7/site-packages/django/core/handlers/base.py", line 149, in get_response
    response = self.process_exception_by_middleware(e, request)
  File "/home/jsandoval86/ProjectsDev/Appem/env/local/lib/python2.7/site-packages/django/core/handlers/base.py", line 147, in get_response
    response = wrapped_callback(request, *callback_args, **callback_kwargs)
  File "/home/jsandoval86/ProjectsDev/Appem/appem/infa_web/apps/m/views.py", line 88, in mFacSearchClient
    return render(request, 'm/m_fac_search_client.html', context)
  File "/home/jsandoval86/ProjectsDev/Appem/env/local/lib/python2.7/site-packages/django/shortcuts.py", line 67, in render
    template_name, context, request=request, using=using)
  File "/home/jsandoval86/ProjectsDev/Appem/env/local/lib/python2.7/site-packages/django/template/loader.py", line 97, in render_to_string
    return template.render(context, request)
  File "/home/jsandoval86/ProjectsDev/Appem/env/local/lib/python2.7/site-packages/django/template/backends/django.py", line 95, in render
    return self.template.render(context)
  File "/home/jsandoval86/ProjectsDev/Appem/env/local/lib/python2.7/site-packages/django/template/base.py", line 206, in render
    return self._render(context)
  File "/home/jsandoval86/ProjectsDev/Appem/env/local/lib/python2.7/site-packages/django/template/base.py", line 197, in _render
    return self.nodelist.render(context)
  File "/home/jsandoval86/ProjectsDev/Appem/env/local/lib/python2.7/site-packages/django/template/base.py", line 992, in render
    bit = node.render_annotated(context)
  File "/home/jsandoval86/ProjectsDev/Appem/env/local/lib/python2.7/site-packages/django/template/base.py", line 959, in render_annotated
    return self.render(context)
  File "/home/jsandoval86/ProjectsDev/Appem/env/local/lib/python2.7/site-packages/django/template/loader_tags.py", line 173, in render
    return compiled_parent._render(context)
  File "/home/jsandoval86/ProjectsDev/Appem/env/local/lib/python2.7/site-packages/django/template/base.py", line 197, in _render
    return self.nodelist.render(context)
  File "/home/jsandoval86/ProjectsDev/Appem/env/local/lib/python2.7/site-packages/django/template/base.py", line 992, in render
    bit = node.render_annotated(context)
  File "/home/jsandoval86/ProjectsDev/Appem/env/local/lib/python2.7/site-packages/django/template/base.py", line 959, in render_annotated
    return self.render(context)
  File "/home/jsandoval86/ProjectsDev/Appem/env/local/lib/python2.7/site-packages/django/template/loader_tags.py", line 69, in render
    result = block.nodelist.render(context)
  File "/home/jsandoval86/ProjectsDev/Appem/env/local/lib/python2.7/site-packages/django/template/base.py", line 992, in render
    bit = node.render_annotated(context)
  File "/home/jsandoval86/ProjectsDev/Appem/env/local/lib/python2.7/site-packages/django/template/base.py", line 959, in render_annotated
    return self.render(context)
  File "/home/jsandoval86/ProjectsDev/Appem/env/local/lib/python2.7/site-packages/django/template/defaulttags.py", line 168, in render
    len_values = len(values)
  File "/home/jsandoval86/ProjectsDev/Appem/env/local/lib/python2.7/site-packages/django/db/models/query.py", line 240, in __len__
    self._fetch_all()
  File "/home/jsandoval86/ProjectsDev/Appem/env/local/lib/python2.7/site-packages/django/db/models/query.py", line 1074, in _fetch_all
    self._result_cache = list(self.iterator())
  File "/home/jsandoval86/ProjectsDev/Appem/env/local/lib/python2.7/site-packages/django/db/models/query.py", line 52, in __iter__
    results = compiler.execute_sql()
  File "/home/jsandoval86/ProjectsDev/Appem/env/local/lib/python2.7/site-packages/django/db/models/sql/compiler.py", line 846, in execute_sql
    cursor = self.connection.cursor()
  File "/home/jsandoval86/ProjectsDev/Appem/env/local/lib/python2.7/site-packages/django/db/backends/base/base.py", line 231, in cursor
    cursor = self.make_debug_cursor(self._cursor())
  File "/home/jsandoval86/ProjectsDev/Appem/env/local/lib/python2.7/site-packages/django/db/backends/base/base.py", line 204, in _cursor
    self.ensure_connection()
  File "/home/jsandoval86/ProjectsDev/Appem/env/local/lib/python2.7/site-packages/django/db/backends/base/base.py", line 199, in ensure_connection
    self.connect()
  File "/home/jsandoval86/ProjectsDev/Appem/env/local/lib/python2.7/site-packages/django/db/utils.py", line 95, in __exit__
    six.reraise(dj_exc_type, dj_exc_value, traceback)
  File "/home/jsandoval86/ProjectsDev/Appem/env/local/lib/python2.7/site-packages/django/db/backends/base/base.py", line 199, in ensure_connection
    self.connect()
  File "/home/jsandoval86/ProjectsDev/Appem/env/local/lib/python2.7/site-packages/django/db/backends/base/base.py", line 171, in connect
    self.connection = self.get_new_connection(conn_params)
  File "/home/jsandoval86/ProjectsDev/Appem/env/local/lib/python2.7/site-packages/django/db/backends/postgresql/base.py", line 175, in get_new_connection
    connection = Database.connect(**conn_params)
  File "/home/jsandoval86/ProjectsDev/Appem/env/local/lib/python2.7/site-packages/psycopg2/__init__.py", line 164, in connect
    conn = _connect(dsn, connection_factory=connection_factory, async=async)
OperationalError: FATAL:  password authentication failed for user "postgres"
FATAL:  password authentication failed for user "postgres"

.-.-.-.-.-.-.-.-.-.-.-.-.-.-.-.-.-.-.-.-.-.-.-.-.-.-.-.-.-.-.-.-.-.-.-.-.-.-.-.- 
 ERROR 2016-10-25 09:51:32,776 base 10369 140519889377024 Internal Server Error: /m/articles/list 
Traceback (most recent call last):
  File "/home/jsandoval86/ProjectsDev/Appem/env/local/lib/python2.7/site-packages/django/core/handlers/base.py", line 149, in get_response
    response = self.process_exception_by_middleware(e, request)
  File "/home/jsandoval86/ProjectsDev/Appem/env/local/lib/python2.7/site-packages/django/core/handlers/base.py", line 147, in get_response
    response = wrapped_callback(request, *callback_args, **callback_kwargs)
  File "/home/jsandoval86/ProjectsDev/Appem/env/local/lib/python2.7/site-packages/django/views/decorators/csrf.py", line 58, in wrapped_view
    return view_func(*args, **kwargs)
  File "/home/jsandoval86/ProjectsDev/Appem/appem/infa_web/apps/m/views.py", line 157, in mArticlesList
    Q(carlos=query) | Q(ncorto__contains=query)
  File "/home/jsandoval86/ProjectsDev/Appem/env/local/lib/python2.7/site-packages/django/db/models/query.py", line 790, in filter
    return self._filter_or_exclude(False, *args, **kwargs)
  File "/home/jsandoval86/ProjectsDev/Appem/env/local/lib/python2.7/site-packages/django/db/models/query.py", line 808, in _filter_or_exclude
    clone.query.add_q(Q(*args, **kwargs))
  File "/home/jsandoval86/ProjectsDev/Appem/env/local/lib/python2.7/site-packages/django/db/models/sql/query.py", line 1243, in add_q
    clause, _ = self._add_q(q_object, self.used_aliases)
  File "/home/jsandoval86/ProjectsDev/Appem/env/local/lib/python2.7/site-packages/django/db/models/sql/query.py", line 1263, in _add_q
    current_negated, allow_joins, split_subq)
  File "/home/jsandoval86/ProjectsDev/Appem/env/local/lib/python2.7/site-packages/django/db/models/sql/query.py", line 1269, in _add_q
    allow_joins=allow_joins, split_subq=split_subq,
  File "/home/jsandoval86/ProjectsDev/Appem/env/local/lib/python2.7/site-packages/django/db/models/sql/query.py", line 1203, in build_filter
    condition = self.build_lookup(lookups, col, value)
  File "/home/jsandoval86/ProjectsDev/Appem/env/local/lib/python2.7/site-packages/django/db/models/sql/query.py", line 1099, in build_lookup
    return final_lookup(lhs, rhs)
  File "/home/jsandoval86/ProjectsDev/Appem/env/local/lib/python2.7/site-packages/django/db/models/lookups.py", line 19, in __init__
    self.rhs = self.get_prep_lookup()
  File "/home/jsandoval86/ProjectsDev/Appem/env/local/lib/python2.7/site-packages/django/db/models/lookups.py", line 57, in get_prep_lookup
    return self.lhs.output_field.get_prep_lookup(self.lookup_name, self.rhs)
  File "/home/jsandoval86/ProjectsDev/Appem/env/local/lib/python2.7/site-packages/django/db/models/fields/__init__.py", line 1860, in get_prep_lookup
    return super(IntegerField, self).get_prep_lookup(lookup_type, value)
  File "/home/jsandoval86/ProjectsDev/Appem/env/local/lib/python2.7/site-packages/django/db/models/fields/__init__.py", line 744, in get_prep_lookup
    return self.get_prep_value(value)
  File "/home/jsandoval86/ProjectsDev/Appem/env/local/lib/python2.7/site-packages/django/db/models/fields/__init__.py", line 1854, in get_prep_value
    return int(value)
ValueError: invalid literal for int() with base 10: 'moto'
.-.-.-.-.-.-.-.-.-.-.-.-.-.-.-.-.-.-.-.-.-.-.-.-.-.-.-.-.-.-.-.-.-.-.-.-.-.-.-.- 
 ERROR 2016-10-25 09:51:34,638 base 10369 140519889377024 Internal Server Error: /m/articles/list 
Traceback (most recent call last):
  File "/home/jsandoval86/ProjectsDev/Appem/env/local/lib/python2.7/site-packages/django/core/handlers/base.py", line 149, in get_response
    response = self.process_exception_by_middleware(e, request)
  File "/home/jsandoval86/ProjectsDev/Appem/env/local/lib/python2.7/site-packages/django/core/handlers/base.py", line 147, in get_response
    response = wrapped_callback(request, *callback_args, **callback_kwargs)
  File "/home/jsandoval86/ProjectsDev/Appem/env/local/lib/python2.7/site-packages/django/views/decorators/csrf.py", line 58, in wrapped_view
    return view_func(*args, **kwargs)
  File "/home/jsandoval86/ProjectsDev/Appem/appem/infa_web/apps/m/views.py", line 157, in mArticlesList
    Q(carlos=query) | Q(ncorto__contains=query)
  File "/home/jsandoval86/ProjectsDev/Appem/env/local/lib/python2.7/site-packages/django/db/models/query.py", line 790, in filter
    return self._filter_or_exclude(False, *args, **kwargs)
  File "/home/jsandoval86/ProjectsDev/Appem/env/local/lib/python2.7/site-packages/django/db/models/query.py", line 808, in _filter_or_exclude
    clone.query.add_q(Q(*args, **kwargs))
  File "/home/jsandoval86/ProjectsDev/Appem/env/local/lib/python2.7/site-packages/django/db/models/sql/query.py", line 1243, in add_q
    clause, _ = self._add_q(q_object, self.used_aliases)
  File "/home/jsandoval86/ProjectsDev/Appem/env/local/lib/python2.7/site-packages/django/db/models/sql/query.py", line 1263, in _add_q
    current_negated, allow_joins, split_subq)
  File "/home/jsandoval86/ProjectsDev/Appem/env/local/lib/python2.7/site-packages/django/db/models/sql/query.py", line 1269, in _add_q
    allow_joins=allow_joins, split_subq=split_subq,
  File "/home/jsandoval86/ProjectsDev/Appem/env/local/lib/python2.7/site-packages/django/db/models/sql/query.py", line 1203, in build_filter
    condition = self.build_lookup(lookups, col, value)
  File "/home/jsandoval86/ProjectsDev/Appem/env/local/lib/python2.7/site-packages/django/db/models/sql/query.py", line 1099, in build_lookup
    return final_lookup(lhs, rhs)
  File "/home/jsandoval86/ProjectsDev/Appem/env/local/lib/python2.7/site-packages/django/db/models/lookups.py", line 19, in __init__
    self.rhs = self.get_prep_lookup()
  File "/home/jsandoval86/ProjectsDev/Appem/env/local/lib/python2.7/site-packages/django/db/models/lookups.py", line 57, in get_prep_lookup
    return self.lhs.output_field.get_prep_lookup(self.lookup_name, self.rhs)
  File "/home/jsandoval86/ProjectsDev/Appem/env/local/lib/python2.7/site-packages/django/db/models/fields/__init__.py", line 1860, in get_prep_lookup
    return super(IntegerField, self).get_prep_lookup(lookup_type, value)
  File "/home/jsandoval86/ProjectsDev/Appem/env/local/lib/python2.7/site-packages/django/db/models/fields/__init__.py", line 744, in get_prep_lookup
    return self.get_prep_value(value)
  File "/home/jsandoval86/ProjectsDev/Appem/env/local/lib/python2.7/site-packages/django/db/models/fields/__init__.py", line 1854, in get_prep_value
    return int(value)
ValueError: invalid literal for int() with base 10: 'motoro'
.-.-.-.-.-.-.-.-.-.-.-.-.-.-.-.-.-.-.-.-.-.-.-.-.-.-.-.-.-.-.-.-.-.-.-.-.-.-.-.- 
 ERROR 2016-10-25 09:51:42,702 base 10369 140519889377024 Internal Server Error: /m/articles/list 
Traceback (most recent call last):
  File "/home/jsandoval86/ProjectsDev/Appem/env/local/lib/python2.7/site-packages/django/core/handlers/base.py", line 149, in get_response
    response = self.process_exception_by_middleware(e, request)
  File "/home/jsandoval86/ProjectsDev/Appem/env/local/lib/python2.7/site-packages/django/core/handlers/base.py", line 147, in get_response
    response = wrapped_callback(request, *callback_args, **callback_kwargs)
  File "/home/jsandoval86/ProjectsDev/Appem/env/local/lib/python2.7/site-packages/django/views/decorators/csrf.py", line 58, in wrapped_view
    return view_func(*args, **kwargs)
  File "/home/jsandoval86/ProjectsDev/Appem/appem/infa_web/apps/m/views.py", line 157, in mArticlesList
    Q(carlos=query) | Q(ncorto__contains=query)
  File "/home/jsandoval86/ProjectsDev/Appem/env/local/lib/python2.7/site-packages/django/db/models/query.py", line 790, in filter
    return self._filter_or_exclude(False, *args, **kwargs)
  File "/home/jsandoval86/ProjectsDev/Appem/env/local/lib/python2.7/site-packages/django/db/models/query.py", line 808, in _filter_or_exclude
    clone.query.add_q(Q(*args, **kwargs))
  File "/home/jsandoval86/ProjectsDev/Appem/env/local/lib/python2.7/site-packages/django/db/models/sql/query.py", line 1243, in add_q
    clause, _ = self._add_q(q_object, self.used_aliases)
  File "/home/jsandoval86/ProjectsDev/Appem/env/local/lib/python2.7/site-packages/django/db/models/sql/query.py", line 1263, in _add_q
    current_negated, allow_joins, split_subq)
  File "/home/jsandoval86/ProjectsDev/Appem/env/local/lib/python2.7/site-packages/django/db/models/sql/query.py", line 1269, in _add_q
    allow_joins=allow_joins, split_subq=split_subq,
  File "/home/jsandoval86/ProjectsDev/Appem/env/local/lib/python2.7/site-packages/django/db/models/sql/query.py", line 1203, in build_filter
    condition = self.build_lookup(lookups, col, value)
  File "/home/jsandoval86/ProjectsDev/Appem/env/local/lib/python2.7/site-packages/django/db/models/sql/query.py", line 1099, in build_lookup
    return final_lookup(lhs, rhs)
  File "/home/jsandoval86/ProjectsDev/Appem/env/local/lib/python2.7/site-packages/django/db/models/lookups.py", line 19, in __init__
    self.rhs = self.get_prep_lookup()
  File "/home/jsandoval86/ProjectsDev/Appem/env/local/lib/python2.7/site-packages/django/db/models/lookups.py", line 57, in get_prep_lookup
    return self.lhs.output_field.get_prep_lookup(self.lookup_name, self.rhs)
  File "/home/jsandoval86/ProjectsDev/Appem/env/local/lib/python2.7/site-packages/django/db/models/fields/__init__.py", line 1860, in get_prep_lookup
    return super(IntegerField, self).get_prep_lookup(lookup_type, value)
  File "/home/jsandoval86/ProjectsDev/Appem/env/local/lib/python2.7/site-packages/django/db/models/fields/__init__.py", line 744, in get_prep_lookup
    return self.get_prep_value(value)
  File "/home/jsandoval86/ProjectsDev/Appem/env/local/lib/python2.7/site-packages/django/db/models/fields/__init__.py", line 1854, in get_prep_value
    return int(value)
ValueError: invalid literal for int() with base 10: 'motor'
.-.-.-.-.-.-.-.-.-.-.-.-.-.-.-.-.-.-.-.-.-.-.-.-.-.-.-.-.-.-.-.-.-.-.-.-.-.-.-.- 
 ERROR 2016-10-25 10:03:06,872 base 10899 139857132615424 Internal Server Error: /bill/save/ 
Traceback (most recent call last):
  File "/home/jsandoval86/ProjectsDev/Appem/env/local/lib/python2.7/site-packages/django/core/handlers/base.py", line 149, in get_response
    response = self.process_exception_by_middleware(e, request)
  File "/home/jsandoval86/ProjectsDev/Appem/env/local/lib/python2.7/site-packages/django/core/handlers/base.py", line 147, in get_response
    response = wrapped_callback(request, *callback_args, **callback_kwargs)
  File "/home/jsandoval86/ProjectsDev/Appem/env/local/lib/python2.7/site-packages/django/views/decorators/csrf.py", line 58, in wrapped_view
    return view_func(*args, **kwargs)
  File "/home/jsandoval86/ProjectsDev/Appem/appem/infa_web/apps/facturacion/views.py", line 299, in BillSave
    data['femi'] = data['femi'] + " " + today.strftime("%H:%M:%S")
KeyError: 'femi'
=======
  File "/home/midas/Documentos/infa_web_folder/InfaWeb/infa_web/apps/base/views.py", line 158, in ParametersList
    return render_to_response("parametros/parameters.html",context)
  File "/home/midas/Documentos/infa_web_folder/dev_env/local/lib/python2.7/site-packages/django/shortcuts.py", line 39, in render_to_response
    content = loader.render_to_string(template_name, context, using=using)
  File "/home/midas/Documentos/infa_web_folder/dev_env/local/lib/python2.7/site-packages/django/template/loader.py", line 96, in render_to_string
    template = get_template(template_name, using=using)
  File "/home/midas/Documentos/infa_web_folder/dev_env/local/lib/python2.7/site-packages/django/template/loader.py", line 26, in get_template
    engines = _engine_list(using)
  File "/home/midas/Documentos/infa_web_folder/dev_env/local/lib/python2.7/site-packages/django/template/loader.py", line 143, in _engine_list
    return engines.all() if using is None else [engines[using]]
  File "/home/midas/Documentos/infa_web_folder/dev_env/local/lib/python2.7/site-packages/django/template/utils.py", line 110, in all
    return [self[alias] for alias in self]
  File "/home/midas/Documentos/infa_web_folder/dev_env/local/lib/python2.7/site-packages/django/template/utils.py", line 101, in __getitem__
    engine = engine_cls(params)
  File "/home/midas/Documentos/infa_web_folder/dev_env/local/lib/python2.7/site-packages/django/template/backends/django.py", line 31, in __init__
    options['libraries'] = self.get_templatetag_libraries(libraries)
  File "/home/midas/Documentos/infa_web_folder/dev_env/local/lib/python2.7/site-packages/django/template/backends/django.py", line 49, in get_templatetag_libraries
    libraries = get_installed_libraries()
  File "/home/midas/Documentos/infa_web_folder/dev_env/local/lib/python2.7/site-packages/django/template/backends/django.py", line 142, in get_installed_libraries
    for name in get_package_libraries(pkg):
  File "/home/midas/Documentos/infa_web_folder/dev_env/local/lib/python2.7/site-packages/django/template/backends/django.py", line 155, in get_package_libraries
    module = import_module(entry[1])
  File "/usr/lib/python2.7/importlib/__init__.py", line 37, in import_module
    __import__(name)
  File "/home/midas/Documentos/infa_web_folder/InfaWeb/infa_web/apps/base/templatetags/tags_appem.py", line 3, in <module>
    register = template.Library()
NameError: name 'template' is not defined
>>>>>>> efae654f4b16b2de233d66921eb420a6663121af
.-.-.-.-.-.-.-.-.-.-.-.-.-.-.-.-.-.-.-.-.-.-.-.-.-.-.-.-.-.-.-.-.-.-.-.-.-.-.-.- 
<<<<<<< HEAD
 ERROR 2016-10-25 10:29:30,135 base 14591 139642824529664 Internal Server Error: /bill/save/3/ 
Traceback (most recent call last):
  File "/home/midas/Documentos/infa_web_folder/dev_env/local/lib/python2.7/site-packages/django/core/handlers/base.py", line 149, in get_response
    response = self.process_exception_by_middleware(e, request)
  File "/home/midas/Documentos/infa_web_folder/dev_env/local/lib/python2.7/site-packages/django/core/handlers/base.py", line 147, in get_response
    response = wrapped_callback(request, *callback_args, **callback_kwargs)
  File "/home/midas/Documentos/infa_web_folder/dev_env/local/lib/python2.7/site-packages/django/views/decorators/csrf.py", line 58, in wrapped_view
    return view_func(*args, **kwargs)
  File "/home/midas/Documentos/infa_web_folder/InfaWeb/infa_web/apps/facturacion/views.py", line 656, in BillUpdate
    response['movi'][ctimo.prefijo]['movideta'] = {}
KeyError: 'movi'
.-.-.-.-.-.-.-.-.-.-.-.-.-.-.-.-.-.-.-.-.-.-.-.-.-.-.-.-.-.-.-.-.-.-.-.-.-.-.-.- 
 ERROR 2016-10-25 10:29:47,720 base 14591 139642858100480 Internal Server Error: /bill/save/3/ 
Traceback (most recent call last):
  File "/home/midas/Documentos/infa_web_folder/dev_env/local/lib/python2.7/site-packages/django/core/handlers/base.py", line 149, in get_response
    response = self.process_exception_by_middleware(e, request)
  File "/home/midas/Documentos/infa_web_folder/dev_env/local/lib/python2.7/site-packages/django/core/handlers/base.py", line 147, in get_response
    response = wrapped_callback(request, *callback_args, **callback_kwargs)
  File "/home/midas/Documentos/infa_web_folder/dev_env/local/lib/python2.7/site-packages/django/views/decorators/csrf.py", line 58, in wrapped_view
    return view_func(*args, **kwargs)
  File "/home/midas/Documentos/infa_web_folder/InfaWeb/infa_web/apps/facturacion/views.py", line 656, in BillUpdate
    response['movi'][ctimo.prefijo]['movideta'] = {}
KeyError: 'movi'
.-.-.-.-.-.-.-.-.-.-.-.-.-.-.-.-.-.-.-.-.-.-.-.-.-.-.-.-.-.-.-.-.-.-.-.-.-.-.-.- 
 ERROR 2016-10-25 10:30:19,982 base 14852 139636607534848 Internal Server Error: /bill/save/3/ 
Traceback (most recent call last):
  File "/home/midas/Documentos/infa_web_folder/dev_env/local/lib/python2.7/site-packages/django/core/handlers/base.py", line 149, in get_response
    response = self.process_exception_by_middleware(e, request)
  File "/home/midas/Documentos/infa_web_folder/dev_env/local/lib/python2.7/site-packages/django/core/handlers/base.py", line 147, in get_response
    response = wrapped_callback(request, *callback_args, **callback_kwargs)
  File "/home/midas/Documentos/infa_web_folder/dev_env/local/lib/python2.7/site-packages/django/views/decorators/csrf.py", line 58, in wrapped_view
    return view_func(*args, **kwargs)
  File "/home/midas/Documentos/infa_web_folder/InfaWeb/infa_web/apps/facturacion/views.py", line 656, in BillUpdate
    response['movi'][ctimo.prefijo]['movideta'] = {}
KeyError: 'movi'
=======
 ERROR 2016-10-25 10:43:22,028 base 5696 5748 Internal Server Error: /bill/list/ 
Traceback (most recent call last):
  File "C:\Python27\lib\site-packages\django\core\handlers\base.py", line 123, in get_response
    response = middleware_method(request)
  File "D:\Proyectos\infa web\infa_web\infa_web\apps\base\middleware.py", line 24, in process_request
    manageParameters.set_param_object("date_appen",current_date_format)
  File "D:\Proyectos\infa web\infa_web\infa_web\parameters.py", line 42, in set_param_object
    parameters = json.load(json_data)
  File "C:\Python27\lib\json\__init__.py", line 291, in load
    **kw)
  File "C:\Python27\lib\json\__init__.py", line 339, in loads
    return _default_decoder.decode(s)
  File "C:\Python27\lib\json\decoder.py", line 364, in decode
    obj, end = self.raw_decode(s, idx=_w(s, 0).end())
  File "C:\Python27\lib\json\decoder.py", line 380, in raw_decode
    obj, end = self.scan_once(s, idx)
ValueError: Expecting property name: line 49 column 1 (char 1326)
.-.-.-.-.-.-.-.-.-.-.-.-.-.-.-.-.-.-.-.-.-.-.-.-.-.-.-.-.-.-.-.-.-.-.-.-.-.-.-.- 
 ERROR 2016-10-25 10:43:39,701 base 5696 6120 Internal Server Error: /bill/list/ 
Traceback (most recent call last):
  File "C:\Python27\lib\site-packages\django\core\handlers\base.py", line 123, in get_response
    response = middleware_method(request)
  File "D:\Proyectos\infa web\infa_web\infa_web\apps\base\middleware.py", line 24, in process_request
    manageParameters.set_param_object("date_appen",current_date_format)
  File "D:\Proyectos\infa web\infa_web\infa_web\parameters.py", line 42, in set_param_object
    parameters = json.load(json_data)
  File "C:\Python27\lib\json\__init__.py", line 291, in load
    **kw)
  File "C:\Python27\lib\json\__init__.py", line 339, in loads
    return _default_decoder.decode(s)
  File "C:\Python27\lib\json\decoder.py", line 364, in decode
    obj, end = self.raw_decode(s, idx=_w(s, 0).end())
  File "C:\Python27\lib\json\decoder.py", line 380, in raw_decode
    obj, end = self.scan_once(s, idx)
ValueError: Expecting property name: line 49 column 1 (char 1326)
.-.-.-.-.-.-.-.-.-.-.-.-.-.-.-.-.-.-.-.-.-.-.-.-.-.-.-.-.-.-.-.-.-.-.-.-.-.-.-.- 
 ERROR 2016-10-25 10:44:17,591 base 5696 5108 Internal Server Error: /bill/list/ 
Traceback (most recent call last):
  File "C:\Python27\lib\site-packages\django\core\handlers\base.py", line 174, in get_response
    response = self.process_exception_by_middleware(e, request)
  File "C:\Python27\lib\site-packages\django\core\handlers\base.py", line 172, in get_response
    response = response.render()
  File "C:\Python27\lib\site-packages\django\template\response.py", line 160, in render
    self.content = self.rendered_content
  File "C:\Python27\lib\site-packages\django\template\response.py", line 137, in rendered_content
    content = template.render(context, self._request)
  File "C:\Python27\lib\site-packages\django\template\backends\django.py", line 95, in render
    return self.template.render(context)
  File "C:\Python27\lib\site-packages\django\template\base.py", line 206, in render
    return self._render(context)
  File "C:\Python27\lib\site-packages\django\template\base.py", line 197, in _render
    return self.nodelist.render(context)
  File "C:\Python27\lib\site-packages\django\template\base.py", line 992, in render
    bit = node.render_annotated(context)
  File "C:\Python27\lib\site-packages\django\template\base.py", line 959, in render_annotated
    return self.render(context)
  File "C:\Python27\lib\site-packages\django\template\loader_tags.py", line 173, in render
    return compiled_parent._render(context)
  File "C:\Python27\lib\site-packages\django\template\base.py", line 197, in _render
    return self.nodelist.render(context)
  File "C:\Python27\lib\site-packages\django\template\base.py", line 992, in render
    bit = node.render_annotated(context)
  File "C:\Python27\lib\site-packages\django\template\base.py", line 959, in render_annotated
    return self.render(context)
  File "C:\Python27\lib\site-packages\django\template\loader_tags.py", line 69, in render
    result = block.nodelist.render(context)
  File "C:\Python27\lib\site-packages\django\template\base.py", line 992, in render
    bit = node.render_annotated(context)
  File "C:\Python27\lib\site-packages\django\template\base.py", line 959, in render_annotated
    return self.render(context)
  File "C:\Python27\lib\site-packages\django\template\defaulttags.py", line 168, in render
    len_values = len(values)
  File "C:\Python27\lib\site-packages\django\db\models\query.py", line 240, in __len__
    self._fetch_all()
  File "C:\Python27\lib\site-packages\django\db\models\query.py", line 1074, in _fetch_all
    self._result_cache = list(self.iterator())
  File "C:\Python27\lib\site-packages\django\db\models\query.py", line 52, in __iter__
    results = compiler.execute_sql()
  File "C:\Python27\lib\site-packages\django\db\models\sql\compiler.py", line 846, in execute_sql
    cursor = self.connection.cursor()
  File "C:\Python27\lib\site-packages\django\db\backends\base\base.py", line 231, in cursor
    cursor = self.make_debug_cursor(self._cursor())
  File "C:\Python27\lib\site-packages\django\db\backends\base\base.py", line 204, in _cursor
    self.ensure_connection()
  File "C:\Python27\lib\site-packages\django\db\backends\base\base.py", line 199, in ensure_connection
    self.connect()
  File "C:\Python27\lib\site-packages\django\db\utils.py", line 95, in __exit__
    six.reraise(dj_exc_type, dj_exc_value, traceback)
  File "C:\Python27\lib\site-packages\django\db\backends\base\base.py", line 199, in ensure_connection
    self.connect()
  File "C:\Python27\lib\site-packages\django\db\backends\base\base.py", line 171, in connect
    self.connection = self.get_new_connection(conn_params)
  File "C:\Python27\lib\site-packages\django\db\backends\postgresql\base.py", line 175, in get_new_connection
    connection = Database.connect(**conn_params)
  File "C:\Python27\lib\site-packages\psycopg2\__init__.py", line 164, in connect
    conn = _connect(dsn, connection_factory=connection_factory, async=async)
OperationalError: FATAL:  la autentificación password falló para el usuario «postgres»

.-.-.-.-.-.-.-.-.-.-.-.-.-.-.-.-.-.-.-.-.-.-.-.-.-.-.-.-.-.-.-.-.-.-.-.-.-.-.-.- 
 ERROR 2016-10-25 10:44:25,161 base 5696 6060 Internal Server Error: /bill/list/ 
Traceback (most recent call last):
  File "C:\Python27\lib\site-packages\django\core\handlers\base.py", line 174, in get_response
    response = self.process_exception_by_middleware(e, request)
  File "C:\Python27\lib\site-packages\django\core\handlers\base.py", line 172, in get_response
    response = response.render()
  File "C:\Python27\lib\site-packages\django\template\response.py", line 160, in render
    self.content = self.rendered_content
  File "C:\Python27\lib\site-packages\django\template\response.py", line 137, in rendered_content
    content = template.render(context, self._request)
  File "C:\Python27\lib\site-packages\django\template\backends\django.py", line 95, in render
    return self.template.render(context)
  File "C:\Python27\lib\site-packages\django\template\base.py", line 206, in render
    return self._render(context)
  File "C:\Python27\lib\site-packages\django\template\base.py", line 197, in _render
    return self.nodelist.render(context)
  File "C:\Python27\lib\site-packages\django\template\base.py", line 992, in render
    bit = node.render_annotated(context)
  File "C:\Python27\lib\site-packages\django\template\base.py", line 959, in render_annotated
    return self.render(context)
  File "C:\Python27\lib\site-packages\django\template\loader_tags.py", line 173, in render
    return compiled_parent._render(context)
  File "C:\Python27\lib\site-packages\django\template\base.py", line 197, in _render
    return self.nodelist.render(context)
  File "C:\Python27\lib\site-packages\django\template\base.py", line 992, in render
    bit = node.render_annotated(context)
  File "C:\Python27\lib\site-packages\django\template\base.py", line 959, in render_annotated
    return self.render(context)
  File "C:\Python27\lib\site-packages\django\template\loader_tags.py", line 69, in render
    result = block.nodelist.render(context)
  File "C:\Python27\lib\site-packages\django\template\base.py", line 992, in render
    bit = node.render_annotated(context)
  File "C:\Python27\lib\site-packages\django\template\base.py", line 959, in render_annotated
    return self.render(context)
  File "C:\Python27\lib\site-packages\django\template\defaulttags.py", line 168, in render
    len_values = len(values)
  File "C:\Python27\lib\site-packages\django\db\models\query.py", line 240, in __len__
    self._fetch_all()
  File "C:\Python27\lib\site-packages\django\db\models\query.py", line 1074, in _fetch_all
    self._result_cache = list(self.iterator())
  File "C:\Python27\lib\site-packages\django\db\models\query.py", line 52, in __iter__
    results = compiler.execute_sql()
  File "C:\Python27\lib\site-packages\django\db\models\sql\compiler.py", line 846, in execute_sql
    cursor = self.connection.cursor()
  File "C:\Python27\lib\site-packages\django\db\backends\base\base.py", line 231, in cursor
    cursor = self.make_debug_cursor(self._cursor())
  File "C:\Python27\lib\site-packages\django\db\backends\base\base.py", line 204, in _cursor
    self.ensure_connection()
  File "C:\Python27\lib\site-packages\django\db\backends\base\base.py", line 199, in ensure_connection
    self.connect()
  File "C:\Python27\lib\site-packages\django\db\utils.py", line 95, in __exit__
    six.reraise(dj_exc_type, dj_exc_value, traceback)
  File "C:\Python27\lib\site-packages\django\db\backends\base\base.py", line 199, in ensure_connection
    self.connect()
  File "C:\Python27\lib\site-packages\django\db\backends\base\base.py", line 171, in connect
    self.connection = self.get_new_connection(conn_params)
  File "C:\Python27\lib\site-packages\django\db\backends\postgresql\base.py", line 175, in get_new_connection
    connection = Database.connect(**conn_params)
  File "C:\Python27\lib\site-packages\psycopg2\__init__.py", line 164, in connect
    conn = _connect(dsn, connection_factory=connection_factory, async=async)
OperationalError: FATAL:  la autentificación password falló para el usuario «postgres»

.-.-.-.-.-.-.-.-.-.-.-.-.-.-.-.-.-.-.-.-.-.-.-.-.-.-.-.-.-.-.-.-.-.-.-.-.-.-.-.- 
 ERROR 2016-10-25 10:44:29,710 base 5696 3784 Internal Server Error: /bill/list/ 
Traceback (most recent call last):
  File "C:\Python27\lib\site-packages\django\core\handlers\base.py", line 174, in get_response
    response = self.process_exception_by_middleware(e, request)
  File "C:\Python27\lib\site-packages\django\core\handlers\base.py", line 172, in get_response
    response = response.render()
  File "C:\Python27\lib\site-packages\django\template\response.py", line 160, in render
    self.content = self.rendered_content
  File "C:\Python27\lib\site-packages\django\template\response.py", line 137, in rendered_content
    content = template.render(context, self._request)
  File "C:\Python27\lib\site-packages\django\template\backends\django.py", line 95, in render
    return self.template.render(context)
  File "C:\Python27\lib\site-packages\django\template\base.py", line 206, in render
    return self._render(context)
  File "C:\Python27\lib\site-packages\django\template\base.py", line 197, in _render
    return self.nodelist.render(context)
  File "C:\Python27\lib\site-packages\django\template\base.py", line 992, in render
    bit = node.render_annotated(context)
  File "C:\Python27\lib\site-packages\django\template\base.py", line 959, in render_annotated
    return self.render(context)
  File "C:\Python27\lib\site-packages\django\template\loader_tags.py", line 173, in render
    return compiled_parent._render(context)
  File "C:\Python27\lib\site-packages\django\template\base.py", line 197, in _render
    return self.nodelist.render(context)
  File "C:\Python27\lib\site-packages\django\template\base.py", line 992, in render
    bit = node.render_annotated(context)
  File "C:\Python27\lib\site-packages\django\template\base.py", line 959, in render_annotated
    return self.render(context)
  File "C:\Python27\lib\site-packages\django\template\loader_tags.py", line 69, in render
    result = block.nodelist.render(context)
  File "C:\Python27\lib\site-packages\django\template\base.py", line 992, in render
    bit = node.render_annotated(context)
  File "C:\Python27\lib\site-packages\django\template\base.py", line 959, in render_annotated
    return self.render(context)
  File "C:\Python27\lib\site-packages\django\template\defaulttags.py", line 168, in render
    len_values = len(values)
  File "C:\Python27\lib\site-packages\django\db\models\query.py", line 240, in __len__
    self._fetch_all()
  File "C:\Python27\lib\site-packages\django\db\models\query.py", line 1074, in _fetch_all
    self._result_cache = list(self.iterator())
  File "C:\Python27\lib\site-packages\django\db\models\query.py", line 52, in __iter__
    results = compiler.execute_sql()
  File "C:\Python27\lib\site-packages\django\db\models\sql\compiler.py", line 846, in execute_sql
    cursor = self.connection.cursor()
  File "C:\Python27\lib\site-packages\django\db\backends\base\base.py", line 231, in cursor
    cursor = self.make_debug_cursor(self._cursor())
  File "C:\Python27\lib\site-packages\django\db\backends\base\base.py", line 204, in _cursor
    self.ensure_connection()
  File "C:\Python27\lib\site-packages\django\db\backends\base\base.py", line 199, in ensure_connection
    self.connect()
  File "C:\Python27\lib\site-packages\django\db\utils.py", line 95, in __exit__
    six.reraise(dj_exc_type, dj_exc_value, traceback)
  File "C:\Python27\lib\site-packages\django\db\backends\base\base.py", line 199, in ensure_connection
    self.connect()
  File "C:\Python27\lib\site-packages\django\db\backends\base\base.py", line 171, in connect
    self.connection = self.get_new_connection(conn_params)
  File "C:\Python27\lib\site-packages\django\db\backends\postgresql\base.py", line 175, in get_new_connection
    connection = Database.connect(**conn_params)
  File "C:\Python27\lib\site-packages\psycopg2\__init__.py", line 164, in connect
    conn = _connect(dsn, connection_factory=connection_factory, async=async)
OperationalError: FATAL:  la autentificación password falló para el usuario «postgres»

.-.-.-.-.-.-.-.-.-.-.-.-.-.-.-.-.-.-.-.-.-.-.-.-.-.-.-.-.-.-.-.-.-.-.-.-.-.-.-.- 
 ERROR 2016-10-25 10:44:33,818 base 5696 928 Internal Server Error: /bill/billing/ 
Traceback (most recent call last):
  File "C:\Python27\lib\site-packages\django\core\handlers\base.py", line 174, in get_response
    response = self.process_exception_by_middleware(e, request)
  File "C:\Python27\lib\site-packages\django\core\handlers\base.py", line 172, in get_response
    response = response.render()
  File "C:\Python27\lib\site-packages\django\template\response.py", line 160, in render
    self.content = self.rendered_content
  File "C:\Python27\lib\site-packages\django\template\response.py", line 137, in rendered_content
    content = template.render(context, self._request)
  File "C:\Python27\lib\site-packages\django\template\backends\django.py", line 95, in render
    return self.template.render(context)
  File "C:\Python27\lib\site-packages\django\template\base.py", line 206, in render
    return self._render(context)
  File "C:\Python27\lib\site-packages\django\template\base.py", line 197, in _render
    return self.nodelist.render(context)
  File "C:\Python27\lib\site-packages\django\template\base.py", line 992, in render
    bit = node.render_annotated(context)
  File "C:\Python27\lib\site-packages\django\template\base.py", line 959, in render_annotated
    return self.render(context)
  File "C:\Python27\lib\site-packages\django\template\loader_tags.py", line 173, in render
    return compiled_parent._render(context)
  File "C:\Python27\lib\site-packages\django\template\base.py", line 197, in _render
    return self.nodelist.render(context)
  File "C:\Python27\lib\site-packages\django\template\base.py", line 992, in render
    bit = node.render_annotated(context)
  File "C:\Python27\lib\site-packages\django\template\base.py", line 959, in render_annotated
    return self.render(context)
  File "C:\Python27\lib\site-packages\django\template\loader_tags.py", line 69, in render
    result = block.nodelist.render(context)
  File "C:\Python27\lib\site-packages\django\template\base.py", line 992, in render
    bit = node.render_annotated(context)
  File "C:\Python27\lib\site-packages\django\template\base.py", line 959, in render_annotated
    return self.render(context)
  File "C:\Python27\lib\site-packages\django\template\base.py", line 1049, in render
    return render_value_in_context(output, context)
  File "C:\Python27\lib\site-packages\django\template\base.py", line 1026, in render_value_in_context
    value = force_text(value)
  File "C:\Python27\lib\site-packages\django\utils\encoding.py", line 78, in force_text
    s = six.text_type(s)
  File "C:\Python27\lib\site-packages\django\utils\html.py", line 381, in <lambda>
    klass.__unicode__ = lambda self: mark_safe(klass_unicode(self))
  File "C:\Python27\lib\site-packages\django\forms\boundfield.py", line 43, in __str__
    return self.as_widget()
  File "C:\Python27\lib\site-packages\django\forms\boundfield.py", line 101, in as_widget
    return force_text(widget.render(name, self.value(), attrs=attrs))
  File "C:\Python27\lib\site-packages\django\forms\widgets.py", line 528, in render
    options = self.render_options(choices, [value])
  File "C:\Python27\lib\site-packages\django\forms\widgets.py", line 554, in render_options
    for option_value, option_label in chain(self.choices, choices):
  File "C:\Python27\lib\site-packages\django\forms\models.py", line 1109, in __iter__
    for obj in queryset:
  File "C:\Python27\lib\site-packages\django\db\models\query.py", line 52, in __iter__
    results = compiler.execute_sql()
  File "C:\Python27\lib\site-packages\django\db\models\sql\compiler.py", line 846, in execute_sql
    cursor = self.connection.cursor()
  File "C:\Python27\lib\site-packages\django\db\backends\base\base.py", line 231, in cursor
    cursor = self.make_debug_cursor(self._cursor())
  File "C:\Python27\lib\site-packages\django\db\backends\base\base.py", line 204, in _cursor
    self.ensure_connection()
  File "C:\Python27\lib\site-packages\django\db\backends\base\base.py", line 199, in ensure_connection
    self.connect()
  File "C:\Python27\lib\site-packages\django\db\utils.py", line 95, in __exit__
    six.reraise(dj_exc_type, dj_exc_value, traceback)
  File "C:\Python27\lib\site-packages\django\db\backends\base\base.py", line 199, in ensure_connection
    self.connect()
  File "C:\Python27\lib\site-packages\django\db\backends\base\base.py", line 171, in connect
    self.connection = self.get_new_connection(conn_params)
  File "C:\Python27\lib\site-packages\django\db\backends\postgresql\base.py", line 175, in get_new_connection
    connection = Database.connect(**conn_params)
  File "C:\Python27\lib\site-packages\psycopg2\__init__.py", line 164, in connect
    conn = _connect(dsn, connection_factory=connection_factory, async=async)
OperationalError: FATAL:  la autentificación password falló para el usuario «postgres»

.-.-.-.-.-.-.-.-.-.-.-.-.-.-.-.-.-.-.-.-.-.-.-.-.-.-.-.-.-.-.-.-.-.-.-.-.-.-.-.- 
 ERROR 2016-10-25 10:44:49,832 base 5696 5292 Internal Server Error: /bill/billing/ 
Traceback (most recent call last):
  File "C:\Python27\lib\site-packages\django\core\handlers\base.py", line 174, in get_response
    response = self.process_exception_by_middleware(e, request)
  File "C:\Python27\lib\site-packages\django\core\handlers\base.py", line 172, in get_response
    response = response.render()
  File "C:\Python27\lib\site-packages\django\template\response.py", line 160, in render
    self.content = self.rendered_content
  File "C:\Python27\lib\site-packages\django\template\response.py", line 137, in rendered_content
    content = template.render(context, self._request)
  File "C:\Python27\lib\site-packages\django\template\backends\django.py", line 95, in render
    return self.template.render(context)
  File "C:\Python27\lib\site-packages\django\template\base.py", line 206, in render
    return self._render(context)
  File "C:\Python27\lib\site-packages\django\template\base.py", line 197, in _render
    return self.nodelist.render(context)
  File "C:\Python27\lib\site-packages\django\template\base.py", line 992, in render
    bit = node.render_annotated(context)
  File "C:\Python27\lib\site-packages\django\template\base.py", line 959, in render_annotated
    return self.render(context)
  File "C:\Python27\lib\site-packages\django\template\loader_tags.py", line 173, in render
    return compiled_parent._render(context)
  File "C:\Python27\lib\site-packages\django\template\base.py", line 197, in _render
    return self.nodelist.render(context)
  File "C:\Python27\lib\site-packages\django\template\base.py", line 992, in render
    bit = node.render_annotated(context)
  File "C:\Python27\lib\site-packages\django\template\base.py", line 959, in render_annotated
    return self.render(context)
  File "C:\Python27\lib\site-packages\django\template\loader_tags.py", line 69, in render
    result = block.nodelist.render(context)
  File "C:\Python27\lib\site-packages\django\template\base.py", line 992, in render
    bit = node.render_annotated(context)
  File "C:\Python27\lib\site-packages\django\template\base.py", line 959, in render_annotated
    return self.render(context)
  File "C:\Python27\lib\site-packages\django\template\base.py", line 1049, in render
    return render_value_in_context(output, context)
  File "C:\Python27\lib\site-packages\django\template\base.py", line 1026, in render_value_in_context
    value = force_text(value)
  File "C:\Python27\lib\site-packages\django\utils\encoding.py", line 78, in force_text
    s = six.text_type(s)
  File "C:\Python27\lib\site-packages\django\utils\html.py", line 381, in <lambda>
    klass.__unicode__ = lambda self: mark_safe(klass_unicode(self))
  File "C:\Python27\lib\site-packages\django\forms\boundfield.py", line 43, in __str__
    return self.as_widget()
  File "C:\Python27\lib\site-packages\django\forms\boundfield.py", line 101, in as_widget
    return force_text(widget.render(name, self.value(), attrs=attrs))
  File "C:\Python27\lib\site-packages\django\forms\widgets.py", line 528, in render
    options = self.render_options(choices, [value])
  File "C:\Python27\lib\site-packages\django\forms\widgets.py", line 554, in render_options
    for option_value, option_label in chain(self.choices, choices):
  File "C:\Python27\lib\site-packages\django\forms\models.py", line 1109, in __iter__
    for obj in queryset:
  File "C:\Python27\lib\site-packages\django\db\models\query.py", line 52, in __iter__
    results = compiler.execute_sql()
  File "C:\Python27\lib\site-packages\django\db\models\sql\compiler.py", line 846, in execute_sql
    cursor = self.connection.cursor()
  File "C:\Python27\lib\site-packages\django\db\backends\base\base.py", line 231, in cursor
    cursor = self.make_debug_cursor(self._cursor())
  File "C:\Python27\lib\site-packages\django\db\backends\base\base.py", line 204, in _cursor
    self.ensure_connection()
  File "C:\Python27\lib\site-packages\django\db\backends\base\base.py", line 199, in ensure_connection
    self.connect()
  File "C:\Python27\lib\site-packages\django\db\utils.py", line 95, in __exit__
    six.reraise(dj_exc_type, dj_exc_value, traceback)
  File "C:\Python27\lib\site-packages\django\db\backends\base\base.py", line 199, in ensure_connection
    self.connect()
  File "C:\Python27\lib\site-packages\django\db\backends\base\base.py", line 171, in connect
    self.connection = self.get_new_connection(conn_params)
  File "C:\Python27\lib\site-packages\django\db\backends\postgresql\base.py", line 175, in get_new_connection
    connection = Database.connect(**conn_params)
  File "C:\Python27\lib\site-packages\psycopg2\__init__.py", line 164, in connect
    conn = _connect(dsn, connection_factory=connection_factory, async=async)
OperationalError: FATAL:  la autentificación password falló para el usuario «postgres»

.-.-.-.-.-.-.-.-.-.-.-.-.-.-.-.-.-.-.-.-.-.-.-.-.-.-.-.-.-.-.-.-.-.-.-.-.-.-.-.- 
 ERROR 2016-10-25 10:45:21,247 base 5696 5732 Internal Server Error: /bill/billing/ 
Traceback (most recent call last):
  File "C:\Python27\lib\site-packages\django\core\handlers\base.py", line 174, in get_response
    response = self.process_exception_by_middleware(e, request)
  File "C:\Python27\lib\site-packages\django\core\handlers\base.py", line 172, in get_response
    response = response.render()
  File "C:\Python27\lib\site-packages\django\template\response.py", line 160, in render
    self.content = self.rendered_content
  File "C:\Python27\lib\site-packages\django\template\response.py", line 137, in rendered_content
    content = template.render(context, self._request)
  File "C:\Python27\lib\site-packages\django\template\backends\django.py", line 95, in render
    return self.template.render(context)
  File "C:\Python27\lib\site-packages\django\template\base.py", line 206, in render
    return self._render(context)
  File "C:\Python27\lib\site-packages\django\template\base.py", line 197, in _render
    return self.nodelist.render(context)
  File "C:\Python27\lib\site-packages\django\template\base.py", line 992, in render
    bit = node.render_annotated(context)
  File "C:\Python27\lib\site-packages\django\template\base.py", line 959, in render_annotated
    return self.render(context)
  File "C:\Python27\lib\site-packages\django\template\loader_tags.py", line 173, in render
    return compiled_parent._render(context)
  File "C:\Python27\lib\site-packages\django\template\base.py", line 197, in _render
    return self.nodelist.render(context)
  File "C:\Python27\lib\site-packages\django\template\base.py", line 992, in render
    bit = node.render_annotated(context)
  File "C:\Python27\lib\site-packages\django\template\base.py", line 959, in render_annotated
    return self.render(context)
  File "C:\Python27\lib\site-packages\django\template\loader_tags.py", line 69, in render
    result = block.nodelist.render(context)
  File "C:\Python27\lib\site-packages\django\template\base.py", line 992, in render
    bit = node.render_annotated(context)
  File "C:\Python27\lib\site-packages\django\template\base.py", line 959, in render_annotated
    return self.render(context)
  File "C:\Python27\lib\site-packages\django\template\base.py", line 1049, in render
    return render_value_in_context(output, context)
  File "C:\Python27\lib\site-packages\django\template\base.py", line 1026, in render_value_in_context
    value = force_text(value)
  File "C:\Python27\lib\site-packages\django\utils\encoding.py", line 78, in force_text
    s = six.text_type(s)
  File "C:\Python27\lib\site-packages\django\utils\html.py", line 381, in <lambda>
    klass.__unicode__ = lambda self: mark_safe(klass_unicode(self))
  File "C:\Python27\lib\site-packages\django\forms\boundfield.py", line 43, in __str__
    return self.as_widget()
  File "C:\Python27\lib\site-packages\django\forms\boundfield.py", line 101, in as_widget
    return force_text(widget.render(name, self.value(), attrs=attrs))
  File "C:\Python27\lib\site-packages\django\forms\widgets.py", line 528, in render
    options = self.render_options(choices, [value])
  File "C:\Python27\lib\site-packages\django\forms\widgets.py", line 554, in render_options
    for option_value, option_label in chain(self.choices, choices):
  File "C:\Python27\lib\site-packages\django\forms\models.py", line 1109, in __iter__
    for obj in queryset:
  File "C:\Python27\lib\site-packages\django\db\models\query.py", line 52, in __iter__
    results = compiler.execute_sql()
  File "C:\Python27\lib\site-packages\django\db\models\sql\compiler.py", line 846, in execute_sql
    cursor = self.connection.cursor()
  File "C:\Python27\lib\site-packages\django\db\backends\base\base.py", line 231, in cursor
    cursor = self.make_debug_cursor(self._cursor())
  File "C:\Python27\lib\site-packages\django\db\backends\base\base.py", line 204, in _cursor
    self.ensure_connection()
  File "C:\Python27\lib\site-packages\django\db\backends\base\base.py", line 199, in ensure_connection
    self.connect()
  File "C:\Python27\lib\site-packages\django\db\utils.py", line 95, in __exit__
    six.reraise(dj_exc_type, dj_exc_value, traceback)
  File "C:\Python27\lib\site-packages\django\db\backends\base\base.py", line 199, in ensure_connection
    self.connect()
  File "C:\Python27\lib\site-packages\django\db\backends\base\base.py", line 171, in connect
    self.connection = self.get_new_connection(conn_params)
  File "C:\Python27\lib\site-packages\django\db\backends\postgresql\base.py", line 175, in get_new_connection
    connection = Database.connect(**conn_params)
  File "C:\Python27\lib\site-packages\psycopg2\__init__.py", line 164, in connect
    conn = _connect(dsn, connection_factory=connection_factory, async=async)
OperationalError: FATAL:  la autentificación password falló para el usuario «postgres»

.-.-.-.-.-.-.-.-.-.-.-.-.-.-.-.-.-.-.-.-.-.-.-.-.-.-.-.-.-.-.-.-.-.-.-.-.-.-.-.- 
 ERROR 2016-10-25 10:45:45,056 base 5696 4064 Internal Server Error: /bill/billing/ 
Traceback (most recent call last):
  File "C:\Python27\lib\site-packages\django\core\handlers\base.py", line 174, in get_response
    response = self.process_exception_by_middleware(e, request)
  File "C:\Python27\lib\site-packages\django\core\handlers\base.py", line 172, in get_response
    response = response.render()
  File "C:\Python27\lib\site-packages\django\template\response.py", line 160, in render
    self.content = self.rendered_content
  File "C:\Python27\lib\site-packages\django\template\response.py", line 137, in rendered_content
    content = template.render(context, self._request)
  File "C:\Python27\lib\site-packages\django\template\backends\django.py", line 95, in render
    return self.template.render(context)
  File "C:\Python27\lib\site-packages\django\template\base.py", line 206, in render
    return self._render(context)
  File "C:\Python27\lib\site-packages\django\template\base.py", line 197, in _render
    return self.nodelist.render(context)
  File "C:\Python27\lib\site-packages\django\template\base.py", line 992, in render
    bit = node.render_annotated(context)
  File "C:\Python27\lib\site-packages\django\template\base.py", line 959, in render_annotated
    return self.render(context)
  File "C:\Python27\lib\site-packages\django\template\loader_tags.py", line 173, in render
    return compiled_parent._render(context)
  File "C:\Python27\lib\site-packages\django\template\base.py", line 197, in _render
    return self.nodelist.render(context)
  File "C:\Python27\lib\site-packages\django\template\base.py", line 992, in render
    bit = node.render_annotated(context)
  File "C:\Python27\lib\site-packages\django\template\base.py", line 959, in render_annotated
    return self.render(context)
  File "C:\Python27\lib\site-packages\django\template\loader_tags.py", line 69, in render
    result = block.nodelist.render(context)
  File "C:\Python27\lib\site-packages\django\template\base.py", line 992, in render
    bit = node.render_annotated(context)
  File "C:\Python27\lib\site-packages\django\template\base.py", line 959, in render_annotated
    return self.render(context)
  File "C:\Python27\lib\site-packages\django\template\base.py", line 1049, in render
    return render_value_in_context(output, context)
  File "C:\Python27\lib\site-packages\django\template\base.py", line 1026, in render_value_in_context
    value = force_text(value)
  File "C:\Python27\lib\site-packages\django\utils\encoding.py", line 78, in force_text
    s = six.text_type(s)
  File "C:\Python27\lib\site-packages\django\utils\html.py", line 381, in <lambda>
    klass.__unicode__ = lambda self: mark_safe(klass_unicode(self))
  File "C:\Python27\lib\site-packages\django\forms\boundfield.py", line 43, in __str__
    return self.as_widget()
  File "C:\Python27\lib\site-packages\django\forms\boundfield.py", line 101, in as_widget
    return force_text(widget.render(name, self.value(), attrs=attrs))
  File "C:\Python27\lib\site-packages\django\forms\widgets.py", line 528, in render
    options = self.render_options(choices, [value])
  File "C:\Python27\lib\site-packages\django\forms\widgets.py", line 554, in render_options
    for option_value, option_label in chain(self.choices, choices):
  File "C:\Python27\lib\site-packages\django\forms\models.py", line 1109, in __iter__
    for obj in queryset:
  File "C:\Python27\lib\site-packages\django\db\models\query.py", line 52, in __iter__
    results = compiler.execute_sql()
  File "C:\Python27\lib\site-packages\django\db\models\sql\compiler.py", line 846, in execute_sql
    cursor = self.connection.cursor()
  File "C:\Python27\lib\site-packages\django\db\backends\base\base.py", line 231, in cursor
    cursor = self.make_debug_cursor(self._cursor())
  File "C:\Python27\lib\site-packages\django\db\backends\base\base.py", line 204, in _cursor
    self.ensure_connection()
  File "C:\Python27\lib\site-packages\django\db\backends\base\base.py", line 199, in ensure_connection
    self.connect()
  File "C:\Python27\lib\site-packages\django\db\utils.py", line 95, in __exit__
    six.reraise(dj_exc_type, dj_exc_value, traceback)
  File "C:\Python27\lib\site-packages\django\db\backends\base\base.py", line 199, in ensure_connection
    self.connect()
  File "C:\Python27\lib\site-packages\django\db\backends\base\base.py", line 171, in connect
    self.connection = self.get_new_connection(conn_params)
  File "C:\Python27\lib\site-packages\django\db\backends\postgresql\base.py", line 175, in get_new_connection
    connection = Database.connect(**conn_params)
  File "C:\Python27\lib\site-packages\psycopg2\__init__.py", line 164, in connect
    conn = _connect(dsn, connection_factory=connection_factory, async=async)
OperationalError: FATAL:  la autentificación password falló para el usuario «postgres»

.-.-.-.-.-.-.-.-.-.-.-.-.-.-.-.-.-.-.-.-.-.-.-.-.-.-.-.-.-.-.-.-.-.-.-.-.-.-.-.- 
 ERROR 2016-10-25 10:46:42,971 base 1900 5756 Internal Server Error: /bill/billing/ 
Traceback (most recent call last):
  File "C:\Python27\lib\site-packages\django\core\handlers\base.py", line 174, in get_response
    response = self.process_exception_by_middleware(e, request)
  File "C:\Python27\lib\site-packages\django\core\handlers\base.py", line 172, in get_response
    response = response.render()
  File "C:\Python27\lib\site-packages\django\template\response.py", line 160, in render
    self.content = self.rendered_content
  File "C:\Python27\lib\site-packages\django\template\response.py", line 137, in rendered_content
    content = template.render(context, self._request)
  File "C:\Python27\lib\site-packages\django\template\backends\django.py", line 95, in render
    return self.template.render(context)
  File "C:\Python27\lib\site-packages\django\template\base.py", line 206, in render
    return self._render(context)
  File "C:\Python27\lib\site-packages\django\template\base.py", line 197, in _render
    return self.nodelist.render(context)
  File "C:\Python27\lib\site-packages\django\template\base.py", line 992, in render
    bit = node.render_annotated(context)
  File "C:\Python27\lib\site-packages\django\template\base.py", line 959, in render_annotated
    return self.render(context)
  File "C:\Python27\lib\site-packages\django\template\loader_tags.py", line 173, in render
    return compiled_parent._render(context)
  File "C:\Python27\lib\site-packages\django\template\base.py", line 197, in _render
    return self.nodelist.render(context)
  File "C:\Python27\lib\site-packages\django\template\base.py", line 992, in render
    bit = node.render_annotated(context)
  File "C:\Python27\lib\site-packages\django\template\base.py", line 959, in render_annotated
    return self.render(context)
  File "C:\Python27\lib\site-packages\django\template\loader_tags.py", line 69, in render
    result = block.nodelist.render(context)
  File "C:\Python27\lib\site-packages\django\template\base.py", line 992, in render
    bit = node.render_annotated(context)
  File "C:\Python27\lib\site-packages\django\template\base.py", line 959, in render_annotated
    return self.render(context)
  File "C:\Python27\lib\site-packages\django\template\base.py", line 1049, in render
    return render_value_in_context(output, context)
  File "C:\Python27\lib\site-packages\django\template\base.py", line 1026, in render_value_in_context
    value = force_text(value)
  File "C:\Python27\lib\site-packages\django\utils\encoding.py", line 78, in force_text
    s = six.text_type(s)
  File "C:\Python27\lib\site-packages\django\utils\html.py", line 381, in <lambda>
    klass.__unicode__ = lambda self: mark_safe(klass_unicode(self))
  File "C:\Python27\lib\site-packages\django\forms\boundfield.py", line 43, in __str__
    return self.as_widget()
  File "C:\Python27\lib\site-packages\django\forms\boundfield.py", line 101, in as_widget
    return force_text(widget.render(name, self.value(), attrs=attrs))
  File "C:\Python27\lib\site-packages\django\forms\widgets.py", line 528, in render
    options = self.render_options(choices, [value])
  File "C:\Python27\lib\site-packages\django\forms\widgets.py", line 554, in render_options
    for option_value, option_label in chain(self.choices, choices):
  File "C:\Python27\lib\site-packages\django\forms\models.py", line 1109, in __iter__
    for obj in queryset:
  File "C:\Python27\lib\site-packages\django\db\models\query.py", line 52, in __iter__
    results = compiler.execute_sql()
  File "C:\Python27\lib\site-packages\django\db\models\sql\compiler.py", line 846, in execute_sql
    cursor = self.connection.cursor()
  File "C:\Python27\lib\site-packages\django\db\backends\base\base.py", line 231, in cursor
    cursor = self.make_debug_cursor(self._cursor())
  File "C:\Python27\lib\site-packages\django\db\backends\base\base.py", line 204, in _cursor
    self.ensure_connection()
  File "C:\Python27\lib\site-packages\django\db\backends\base\base.py", line 199, in ensure_connection
    self.connect()
  File "C:\Python27\lib\site-packages\django\db\utils.py", line 95, in __exit__
    six.reraise(dj_exc_type, dj_exc_value, traceback)
  File "C:\Python27\lib\site-packages\django\db\backends\base\base.py", line 199, in ensure_connection
    self.connect()
  File "C:\Python27\lib\site-packages\django\db\backends\base\base.py", line 171, in connect
    self.connection = self.get_new_connection(conn_params)
  File "C:\Python27\lib\site-packages\django\db\backends\postgresql\base.py", line 175, in get_new_connection
    connection = Database.connect(**conn_params)
  File "C:\Python27\lib\site-packages\psycopg2\__init__.py", line 164, in connect
    conn = _connect(dsn, connection_factory=connection_factory, async=async)
OperationalError: FATAL:  la autentificación password falló para el usuario «postgres»

.-.-.-.-.-.-.-.-.-.-.-.-.-.-.-.-.-.-.-.-.-.-.-.-.-.-.-.-.-.-.-.-.-.-.-.-.-.-.-.- 
 ERROR 2016-10-25 10:47:28,757 base 3140 2000 Internal Server Error: /bill/billing/ 
Traceback (most recent call last):
  File "C:\Python27\lib\site-packages\django\core\handlers\base.py", line 174, in get_response
    response = self.process_exception_by_middleware(e, request)
  File "C:\Python27\lib\site-packages\django\core\handlers\base.py", line 172, in get_response
    response = response.render()
  File "C:\Python27\lib\site-packages\django\template\response.py", line 160, in render
    self.content = self.rendered_content
  File "C:\Python27\lib\site-packages\django\template\response.py", line 137, in rendered_content
    content = template.render(context, self._request)
  File "C:\Python27\lib\site-packages\django\template\backends\django.py", line 95, in render
    return self.template.render(context)
  File "C:\Python27\lib\site-packages\django\template\base.py", line 206, in render
    return self._render(context)
  File "C:\Python27\lib\site-packages\django\template\base.py", line 197, in _render
    return self.nodelist.render(context)
  File "C:\Python27\lib\site-packages\django\template\base.py", line 992, in render
    bit = node.render_annotated(context)
  File "C:\Python27\lib\site-packages\django\template\base.py", line 959, in render_annotated
    return self.render(context)
  File "C:\Python27\lib\site-packages\django\template\loader_tags.py", line 173, in render
    return compiled_parent._render(context)
  File "C:\Python27\lib\site-packages\django\template\base.py", line 197, in _render
    return self.nodelist.render(context)
  File "C:\Python27\lib\site-packages\django\template\base.py", line 992, in render
    bit = node.render_annotated(context)
  File "C:\Python27\lib\site-packages\django\template\base.py", line 959, in render_annotated
    return self.render(context)
  File "C:\Python27\lib\site-packages\django\template\loader_tags.py", line 69, in render
    result = block.nodelist.render(context)
  File "C:\Python27\lib\site-packages\django\template\base.py", line 992, in render
    bit = node.render_annotated(context)
  File "C:\Python27\lib\site-packages\django\template\base.py", line 959, in render_annotated
    return self.render(context)
  File "C:\Python27\lib\site-packages\django\template\base.py", line 1049, in render
    return render_value_in_context(output, context)
  File "C:\Python27\lib\site-packages\django\template\base.py", line 1026, in render_value_in_context
    value = force_text(value)
  File "C:\Python27\lib\site-packages\django\utils\encoding.py", line 78, in force_text
    s = six.text_type(s)
  File "C:\Python27\lib\site-packages\django\utils\html.py", line 381, in <lambda>
    klass.__unicode__ = lambda self: mark_safe(klass_unicode(self))
  File "C:\Python27\lib\site-packages\django\forms\boundfield.py", line 43, in __str__
    return self.as_widget()
  File "C:\Python27\lib\site-packages\django\forms\boundfield.py", line 101, in as_widget
    return force_text(widget.render(name, self.value(), attrs=attrs))
  File "C:\Python27\lib\site-packages\django\forms\widgets.py", line 528, in render
    options = self.render_options(choices, [value])
  File "C:\Python27\lib\site-packages\django\forms\widgets.py", line 554, in render_options
    for option_value, option_label in chain(self.choices, choices):
  File "C:\Python27\lib\site-packages\django\forms\models.py", line 1109, in __iter__
    for obj in queryset:
  File "C:\Python27\lib\site-packages\django\db\models\query.py", line 52, in __iter__
    results = compiler.execute_sql()
  File "C:\Python27\lib\site-packages\django\db\models\sql\compiler.py", line 846, in execute_sql
    cursor = self.connection.cursor()
  File "C:\Python27\lib\site-packages\django\db\backends\base\base.py", line 231, in cursor
    cursor = self.make_debug_cursor(self._cursor())
  File "C:\Python27\lib\site-packages\django\db\backends\base\base.py", line 204, in _cursor
    self.ensure_connection()
  File "C:\Python27\lib\site-packages\django\db\backends\base\base.py", line 199, in ensure_connection
    self.connect()
  File "C:\Python27\lib\site-packages\django\db\utils.py", line 95, in __exit__
    six.reraise(dj_exc_type, dj_exc_value, traceback)
  File "C:\Python27\lib\site-packages\django\db\backends\base\base.py", line 199, in ensure_connection
    self.connect()
  File "C:\Python27\lib\site-packages\django\db\backends\base\base.py", line 171, in connect
    self.connection = self.get_new_connection(conn_params)
  File "C:\Python27\lib\site-packages\django\db\backends\postgresql\base.py", line 175, in get_new_connection
    connection = Database.connect(**conn_params)
  File "C:\Python27\lib\site-packages\psycopg2\__init__.py", line 164, in connect
    conn = _connect(dsn, connection_factory=connection_factory, async=async)
OperationalError: FATAL:  la autentificación password falló para el usuario «postgres»

.-.-.-.-.-.-.-.-.-.-.-.-.-.-.-.-.-.-.-.-.-.-.-.-.-.-.-.-.-.-.-.-.-.-.-.-.-.-.-.- 
 ERROR 2016-10-25 10:49:23,723 base 4472 3952 Internal Server Error: /bill/save/164/ 
Traceback (most recent call last):
  File "C:\Python27\lib\site-packages\django\core\handlers\base.py", line 149, in get_response
    response = self.process_exception_by_middleware(e, request)
  File "C:\Python27\lib\site-packages\django\core\handlers\base.py", line 147, in get_response
    response = wrapped_callback(request, *callback_args, **callback_kwargs)
  File "C:\Python27\lib\site-packages\django\views\decorators\csrf.py", line 58, in wrapped_view
    return view_func(*args, **kwargs)
  File "D:\Proyectos\infa web\infa_web\infa_web\apps\facturacion\views.py", line 657, in BillUpdate
    response['movi'][ctimo.prefijo]['movideta'] = {}
KeyError: u'IA'
>>>>>>> a33de2ef11d4c724b2e2e7468e15a54528bf3b44
.-.-.-.-.-.-.-.-.-.-.-.-.-.-.-.-.-.-.-.-.-.-.-.-.-.-.-.-.-.-.-.-.-.-.-.-.-.-.-.- 
 ERROR 2016-10-25 11:15:11,950 base 5120 3784 Internal Server Error: /bill/save/164/ 
Traceback (most recent call last):
  File "C:\Python27\lib\site-packages\django\core\handlers\base.py", line 149, in get_response
    response = self.process_exception_by_middleware(e, request)
  File "C:\Python27\lib\site-packages\django\core\handlers\base.py", line 147, in get_response
    response = wrapped_callback(request, *callback_args, **callback_kwargs)
  File "C:\Python27\lib\site-packages\django\views\decorators\csrf.py", line 58, in wrapped_view
    return view_func(*args, **kwargs)
  File "D:\Proyectos\infa web\infa_web\infa_web\apps\facturacion\views.py", line 725, in BillUpdate
    response['movi'][ctimo.prefijo]['vttotal'] = (vefe_t + vtar_t + vch_t)
KeyError: u'IA'
.-.-.-.-.-.-.-.-.-.-.-.-.-.-.-.-.-.-.-.-.-.-.-.-.-.-.-.-.-.-.-.-.-.-.-.-.-.-.-.- 
 ERROR 2016-10-25 11:18:27,190 base 5604 968 Internal Server Error: /bill/save/164/ 
Traceback (most recent call last):
  File "C:\Python27\lib\site-packages\django\core\handlers\base.py", line 149, in get_response
    response = self.process_exception_by_middleware(e, request)
  File "C:\Python27\lib\site-packages\django\core\handlers\base.py", line 147, in get_response
    response = wrapped_callback(request, *callback_args, **callback_kwargs)
  File "C:\Python27\lib\site-packages\django\views\decorators\csrf.py", line 58, in wrapped_view
    return view_func(*args, **kwargs)
  File "D:\Proyectos\infa web\infa_web\infa_web\apps\facturacion\views.py", line 728, in BillUpdate
    response['movi'].appen(response_movi)
AttributeError: 'list' object has no attribute 'appen'
.-.-.-.-.-.-.-.-.-.-.-.-.-.-.-.-.-.-.-.-.-.-.-.-.-.-.-.-.-.-.-.-.-.-.-.-.-.-.-.- 
 ERROR 2016-10-25 11:32:26,992 base 4472 4344 Internal Server Error: /bill/save/164/ 
Traceback (most recent call last):
  File "C:\Python27\lib\site-packages\django\core\handlers\base.py", line 149, in get_response
    response = self.process_exception_by_middleware(e, request)
  File "C:\Python27\lib\site-packages\django\core\handlers\base.py", line 147, in get_response
    response = wrapped_callback(request, *callback_args, **callback_kwargs)
  File "C:\Python27\lib\site-packages\django\views\decorators\csrf.py", line 58, in wrapped_view
    return view_func(*args, **kwargs)
  File "D:\Proyectos\infa web\infa_web\infa_web\apps\facturacion\views.py", line 692, in BillUpdate
    response_fac['medios_pago'] = []
NameError: global name 'response_fac' is not defined
.-.-.-.-.-.-.-.-.-.-.-.-.-.-.-.-.-.-.-.-.-.-.-.-.-.-.-.-.-.-.-.-.-.-.-.-.-.-.-.- 
 ERROR 2016-10-25 11:32:53,977 base 3808 3820 Internal Server Error: /bill/save/164/ 
Traceback (most recent call last):
  File "C:\Python27\lib\site-packages\django\core\handlers\base.py", line 149, in get_response
    response = self.process_exception_by_middleware(e, request)
  File "C:\Python27\lib\site-packages\django\core\handlers\base.py", line 147, in get_response
    response = wrapped_callback(request, *callback_args, **callback_kwargs)
  File "C:\Python27\lib\site-packages\django\views\decorators\csrf.py", line 58, in wrapped_view
    return view_func(*args, **kwargs)
  File "D:\Proyectos\infa web\infa_web\infa_web\apps\facturacion\views.py", line 718, in BillUpdate
    response['fac'].append(response_fac)
AttributeError: 'dict' object has no attribute 'append'
.-.-.-.-.-.-.-.-.-.-.-.-.-.-.-.-.-.-.-.-.-.-.-.-.-.-.-.-.-.-.-.-.-.-.-.-.-.-.-.- 
 ERROR 2016-10-25 11:45:27,575 base 4168 2504 Internal Server Error: /bill/save/164/ 
Traceback (most recent call last):
  File "C:\Python27\lib\site-packages\django\core\handlers\base.py", line 149, in get_response
    response = self.process_exception_by_middleware(e, request)
  File "C:\Python27\lib\site-packages\django\core\handlers\base.py", line 147, in get_response
    response = wrapped_callback(request, *callback_args, **callback_kwargs)
  File "C:\Python27\lib\site-packages\django\views\decorators\csrf.py", line 58, in wrapped_view
    return view_func(*args, **kwargs)
  File "D:\Proyectos\infa web\infa_web\infa_web\apps\facturacion\views.py", line 653, in BillUpdate
    response_fac['medios_pago'].append(auxfac)
KeyError: 'medios_pago'
.-.-.-.-.-.-.-.-.-.-.-.-.-.-.-.-.-.-.-.-.-.-.-.-.-.-.-.-.-.-.-.-.-.-.-.-.-.-.-.- 
 ERROR 2016-10-25 11:46:32,318 base 964 6056 Internal Server Error: /bill/save/164/ 
Traceback (most recent call last):
  File "C:\Python27\lib\site-packages\django\core\handlers\base.py", line 149, in get_response
    response = self.process_exception_by_middleware(e, request)
  File "C:\Python27\lib\site-packages\django\core\handlers\base.py", line 147, in get_response
    response = wrapped_callback(request, *callback_args, **callback_kwargs)
  File "C:\Python27\lib\site-packages\django\views\decorators\csrf.py", line 58, in wrapped_view
    return view_func(*args, **kwargs)
  File "D:\Proyectos\infa web\infa_web\infa_web\apps\facturacion\views.py", line 810, in BillUpdate
    response['fac']['fac_deta'][fac_deta.pk] = {}
TypeError: list indices must be integers, not str
.-.-.-.-.-.-.-.-.-.-.-.-.-.-.-.-.-.-.-.-.-.-.-.-.-.-.-.-.-.-.-.-.-.-.-.-.-.-.-.- 
 ERROR 2016-10-25 11:49:24,773 base 5492 2160 Internal Server Error: /bill/save/164/ 
Traceback (most recent call last):
  File "C:\Python27\lib\site-packages\django\core\handlers\base.py", line 149, in get_response
    response = self.process_exception_by_middleware(e, request)
  File "C:\Python27\lib\site-packages\django\core\handlers\base.py", line 147, in get_response
    response = wrapped_callback(request, *callback_args, **callback_kwargs)
  File "C:\Python27\lib\site-packages\django\views\decorators\csrf.py", line 58, in wrapped_view
    return view_func(*args, **kwargs)
  File "D:\Proyectos\infa web\infa_web\infa_web\apps\facturacion\views.py", line 712, in BillUpdate
    response_fac['medios_pago'].append(auxdetapago)
KeyError: 'medios_pago'
.-.-.-.-.-.-.-.-.-.-.-.-.-.-.-.-.-.-.-.-.-.-.-.-.-.-.-.-.-.-.-.-.-.-.-.-.-.-.-.- 
 ERROR 2016-10-25 11:50:32,068 base 5236 1324 Internal Server Error: /bill/save/164/ 
Traceback (most recent call last):
  File "C:\Python27\lib\site-packages\django\core\handlers\base.py", line 149, in get_response
    response = self.process_exception_by_middleware(e, request)
  File "C:\Python27\lib\site-packages\django\core\handlers\base.py", line 147, in get_response
    response = wrapped_callback(request, *callback_args, **callback_kwargs)
  File "C:\Python27\lib\site-packages\django\views\decorators\csrf.py", line 58, in wrapped_view
    return view_func(*args, **kwargs)
  File "D:\Proyectos\infa web\infa_web\infa_web\apps\facturacion\views.py", line 713, in BillUpdate
    response_fac['medios_pago'].append(auxdetapago)
AttributeError: 'dict' object has no attribute 'append'
.-.-.-.-.-.-.-.-.-.-.-.-.-.-.-.-.-.-.-.-.-.-.-.-.-.-.-.-.-.-.-.-.-.-.-.-.-.-.-.- 
 ERROR 2016-10-25 11:51:00,229 base 2648 6060 Internal Server Error: /bill/save/164/ 
Traceback (most recent call last):
  File "C:\Python27\lib\site-packages\django\core\handlers\base.py", line 149, in get_response
    response = self.process_exception_by_middleware(e, request)
  File "C:\Python27\lib\site-packages\django\core\handlers\base.py", line 147, in get_response
    response = wrapped_callback(request, *callback_args, **callback_kwargs)
  File "C:\Python27\lib\site-packages\django\views\decorators\csrf.py", line 58, in wrapped_view
    return view_func(*args, **kwargs)
  File "D:\Proyectos\infa web\infa_web\infa_web\apps\facturacion\views.py", line 713, in BillUpdate
    response_fac['medios_pago'].append(auxdetapago)
AttributeError: 'dict' object has no attribute 'append'
.-.-.-.-.-.-.-.-.-.-.-.-.-.-.-.-.-.-.-.-.-.-.-.-.-.-.-.-.-.-.-.-.-.-.-.-.-.-.-.- 
 ERROR 2016-10-25 11:51:32,312 base 5976 5120 Internal Server Error: /bill/save/164/ 
Traceback (most recent call last):
  File "C:\Python27\lib\site-packages\django\core\handlers\base.py", line 149, in get_response
    response = self.process_exception_by_middleware(e, request)
  File "C:\Python27\lib\site-packages\django\core\handlers\base.py", line 147, in get_response
    response = wrapped_callback(request, *callback_args, **callback_kwargs)
  File "C:\Python27\lib\site-packages\django\views\decorators\csrf.py", line 58, in wrapped_view
    return view_func(*args, **kwargs)
  File "D:\Proyectos\infa web\infa_web\infa_web\apps\facturacion\views.py", line 730, in BillUpdate
    response_movi['movideta'].append(auxdetamovi)
KeyError: 'movideta'
.-.-.-.-.-.-.-.-.-.-.-.-.-.-.-.-.-.-.-.-.-.-.-.-.-.-.-.-.-.-.-.-.-.-.-.-.-.-.-.- 
 ERROR 2016-10-25 11:52:11,440 base 4836 4404 Internal Server Error: /bill/save/164/ 
Traceback (most recent call last):
  File "C:\Python27\lib\site-packages\django\core\handlers\base.py", line 149, in get_response
    response = self.process_exception_by_middleware(e, request)
  File "C:\Python27\lib\site-packages\django\core\handlers\base.py", line 147, in get_response
    response = wrapped_callback(request, *callback_args, **callback_kwargs)
  File "C:\Python27\lib\site-packages\django\views\decorators\csrf.py", line 58, in wrapped_view
    return view_func(*args, **kwargs)
  File "D:\Proyectos\infa web\infa_web\infa_web\apps\facturacion\views.py", line 812, in BillUpdate
    response['fac']['fac_deta'][fac_deta.pk] = {}
TypeError: list indices must be integers, not str
.-.-.-.-.-.-.-.-.-.-.-.-.-.-.-.-.-.-.-.-.-.-.-.-.-.-.-.-.-.-.-.-.-.-.-.-.-.-.-.- 
 ERROR 2016-10-25 11:54:57,486 base 6124 4832 Internal Server Error: /bill/save/164/ 
Traceback (most recent call last):
  File "C:\Python27\lib\site-packages\django\core\handlers\base.py", line 149, in get_response
    response = self.process_exception_by_middleware(e, request)
  File "C:\Python27\lib\site-packages\django\core\handlers\base.py", line 147, in get_response
    response = wrapped_callback(request, *callback_args, **callback_kwargs)
  File "C:\Python27\lib\site-packages\django\views\decorators\csrf.py", line 58, in wrapped_view
    return view_func(*args, **kwargs)
  File "D:\Proyectos\infa web\infa_web\infa_web\apps\facturacion\views.py", line 812, in BillUpdate
    response['fac']['fac_deta'][fac_deta.pk] = {}
TypeError: list indices must be integers, not str
.-.-.-.-.-.-.-.-.-.-.-.-.-.-.-.-.-.-.-.-.-.-.-.-.-.-.-.-.-.-.-.-.-.-.-.-.-.-.-.- 
 ERROR 2016-10-25 11:57:15,803 base 4424 2516 Internal Server Error: /bill/save/164/ 
Traceback (most recent call last):
  File "C:\Python27\lib\site-packages\django\core\handlers\base.py", line 149, in get_response
    response = self.process_exception_by_middleware(e, request)
  File "C:\Python27\lib\site-packages\django\core\handlers\base.py", line 147, in get_response
    response = wrapped_callback(request, *callback_args, **callback_kwargs)
  File "C:\Python27\lib\site-packages\django\views\decorators\csrf.py", line 58, in wrapped_view
    return view_func(*args, **kwargs)
  File "D:\Proyectos\infa web\infa_web\infa_web\apps\facturacion\views.py", line 820, in BillUpdate
    response_fac['facdeta'].append(auxdetafac)
KeyError: 'facdeta'
.-.-.-.-.-.-.-.-.-.-.-.-.-.-.-.-.-.-.-.-.-.-.-.-.-.-.-.-.-.-.-.-.-.-.-.-.-.-.-.- 
 ERROR 2016-10-25 11:57:51,826 base 6272 6348 Internal Server Error: /bill/save/164/ 
Traceback (most recent call last):
  File "C:\Python27\lib\site-packages\django\core\handlers\base.py", line 149, in get_response
    response = self.process_exception_by_middleware(e, request)
  File "C:\Python27\lib\site-packages\django\core\handlers\base.py", line 147, in get_response
    response = wrapped_callback(request, *callback_args, **callback_kwargs)
  File "C:\Python27\lib\site-packages\django\views\decorators\csrf.py", line 58, in wrapped_view
    return view_func(*args, **kwargs)
  File "D:\Proyectos\infa web\infa_web\infa_web\apps\facturacion\views.py", line 842, in BillUpdate
    response_mvsa['mvsadeta'].append(auxdetamvsa)
KeyError: 'mvsadeta'
.-.-.-.-.-.-.-.-.-.-.-.-.-.-.-.-.-.-.-.-.-.-.-.-.-.-.-.-.-.-.-.-.-.-.-.-.-.-.-.- 
 ERROR 2016-10-25 11:59:23,973 base 6608 6732 Internal Server Error: /bill/save/164/ 
Traceback (most recent call last):
  File "C:\Python27\lib\site-packages\django\core\handlers\base.py", line 149, in get_response
    response = self.process_exception_by_middleware(e, request)
  File "C:\Python27\lib\site-packages\django\core\handlers\base.py", line 147, in get_response
    response = wrapped_callback(request, *callback_args, **callback_kwargs)
  File "C:\Python27\lib\site-packages\django\views\decorators\csrf.py", line 58, in wrapped_view
    return view_func(*args, **kwargs)
  File "D:\Proyectos\infa web\infa_web\infa_web\apps\facturacion\views.py", line 843, in BillUpdate
    response_mvsa['mvsadeta'].append(auxdetamvsa)
KeyError: 'mvsadeta'
.-.-.-.-.-.-.-.-.-.-.-.-.-.-.-.-.-.-.-.-.-.-.-.-.-.-.-.-.-.-.-.-.-.-.-.-.-.-.-.- 
 ERROR 2016-10-25 11:59:56,556 base 6888 6956 Internal Server Error: /bill/save/164/ 
Traceback (most recent call last):
  File "C:\Python27\lib\site-packages\django\core\handlers\base.py", line 149, in get_response
    response = self.process_exception_by_middleware(e, request)
  File "C:\Python27\lib\site-packages\django\core\handlers\base.py", line 147, in get_response
    response = wrapped_callback(request, *callback_args, **callback_kwargs)
  File "C:\Python27\lib\site-packages\django\views\decorators\csrf.py", line 58, in wrapped_view
    return view_func(*args, **kwargs)
  File "D:\Proyectos\infa web\infa_web\infa_web\apps\facturacion\views.py", line 849, in BillUpdate
    response['fac']['fac_deta']['num_delete'] = fac_deta.count()
TypeError: list indices must be integers, not str
