.-.-.-.-.-.-.-.-.-.-.-.-.-.-.-.-.-.-.-.-.-.-.-.-.-.-.-.-.-.-.-.-.-.-.-.-.-.-.-.- 
 ERROR 2016-10-08 15:45:04,077 base 9475 140618974099200 Internal Server Error: /bill/save/ 
Traceback (most recent call last):
  File "/home/adriann/Project_django/appem/dev_env/local/lib/python2.7/site-packages/django/core/handlers/base.py", line 149, in get_response
    response = self.process_exception_by_middleware(e, request)
  File "/home/adriann/Project_django/appem/dev_env/local/lib/python2.7/site-packages/django/core/handlers/base.py", line 147, in get_response
    response = wrapped_callback(request, *callback_args, **callback_kwargs)
  File "/home/adriann/Project_django/appem/dev_env/local/lib/python2.7/site-packages/django/views/decorators/csrf.py", line 58, in wrapped_view
    return view_func(*args, **kwargs)
  File "/home/adriann/Project_django/appem/appem/infa_web/apps/facturacion/views.py", line 161, in BillSave
    cesdo = Esdo.objects.using(request.db).get(pk = data['cesdo'])
  File "/home/adriann/Project_django/appem/dev_env/local/lib/python2.7/site-packages/django/db/models/query.py", line 387, in get
    self.model._meta.object_name
DoesNotExist: Esdo matching query does not exist.
.-.-.-.-.-.-.-.-.-.-.-.-.-.-.-.-.-.-.-.-.-.-.-.-.-.-.-.-.-.-.-.-.-.-.-.-.-.-.-.- 
 ERROR 2016-10-08 15:45:15,674 base 9475 140618974099200 Internal Server Error: /bill/save/ 
Traceback (most recent call last):
  File "/home/adriann/Project_django/appem/dev_env/local/lib/python2.7/site-packages/django/core/handlers/base.py", line 149, in get_response
    response = self.process_exception_by_middleware(e, request)
  File "/home/adriann/Project_django/appem/dev_env/local/lib/python2.7/site-packages/django/core/handlers/base.py", line 147, in get_response
    response = wrapped_callback(request, *callback_args, **callback_kwargs)
  File "/home/adriann/Project_django/appem/dev_env/local/lib/python2.7/site-packages/django/views/decorators/csrf.py", line 58, in wrapped_view
    return view_func(*args, **kwargs)
  File "/home/adriann/Project_django/appem/appem/infa_web/apps/facturacion/views.py", line 161, in BillSave
    cesdo = Esdo.objects.using(request.db).get(pk = data['cesdo'])
  File "/home/adriann/Project_django/appem/dev_env/local/lib/python2.7/site-packages/django/db/models/query.py", line 387, in get
    self.model._meta.object_name
DoesNotExist: Esdo matching query does not exist.
.-.-.-.-.-.-.-.-.-.-.-.-.-.-.-.-.-.-.-.-.-.-.-.-.-.-.-.-.-.-.-.-.-.-.-.-.-.-.-.- 
 ERROR 2016-10-08 16:02:15,324 base 10319 140093669914368 Internal Server Error: /bill/billing/ 
Traceback (most recent call last):
  File "/home/adriann/Project_django/appem/dev_env/local/lib/python2.7/site-packages/django/core/handlers/base.py", line 174, in get_response
    response = self.process_exception_by_middleware(e, request)
  File "/home/adriann/Project_django/appem/dev_env/local/lib/python2.7/site-packages/django/core/handlers/base.py", line 172, in get_response
    response = response.render()
  File "/home/adriann/Project_django/appem/dev_env/local/lib/python2.7/site-packages/django/template/response.py", line 160, in render
    self.content = self.rendered_content
  File "/home/adriann/Project_django/appem/dev_env/local/lib/python2.7/site-packages/django/template/response.py", line 137, in rendered_content
    content = template.render(context, self._request)
  File "/home/adriann/Project_django/appem/dev_env/local/lib/python2.7/site-packages/django/template/backends/django.py", line 95, in render
    return self.template.render(context)
  File "/home/adriann/Project_django/appem/dev_env/local/lib/python2.7/site-packages/django/template/base.py", line 206, in render
    return self._render(context)
  File "/home/adriann/Project_django/appem/dev_env/local/lib/python2.7/site-packages/django/template/base.py", line 197, in _render
    return self.nodelist.render(context)
  File "/home/adriann/Project_django/appem/dev_env/local/lib/python2.7/site-packages/django/template/base.py", line 992, in render
    bit = node.render_annotated(context)
  File "/home/adriann/Project_django/appem/dev_env/local/lib/python2.7/site-packages/django/template/base.py", line 959, in render_annotated
    return self.render(context)
  File "/home/adriann/Project_django/appem/dev_env/local/lib/python2.7/site-packages/django/template/loader_tags.py", line 173, in render
    return compiled_parent._render(context)
  File "/home/adriann/Project_django/appem/dev_env/local/lib/python2.7/site-packages/django/template/base.py", line 197, in _render
    return self.nodelist.render(context)
  File "/home/adriann/Project_django/appem/dev_env/local/lib/python2.7/site-packages/django/template/base.py", line 992, in render
    bit = node.render_annotated(context)
  File "/home/adriann/Project_django/appem/dev_env/local/lib/python2.7/site-packages/django/template/base.py", line 959, in render_annotated
    return self.render(context)
  File "/home/adriann/Project_django/appem/dev_env/local/lib/python2.7/site-packages/django/template/loader_tags.py", line 69, in render
    result = block.nodelist.render(context)
  File "/home/adriann/Project_django/appem/dev_env/local/lib/python2.7/site-packages/django/template/base.py", line 992, in render
    bit = node.render_annotated(context)
  File "/home/adriann/Project_django/appem/dev_env/local/lib/python2.7/site-packages/django/template/base.py", line 959, in render_annotated
    return self.render(context)
  File "/home/adriann/Project_django/appem/dev_env/local/lib/python2.7/site-packages/django/template/base.py", line 1049, in render
    return render_value_in_context(output, context)
  File "/home/adriann/Project_django/appem/dev_env/local/lib/python2.7/site-packages/django/template/base.py", line 1026, in render_value_in_context
    value = force_text(value)
  File "/home/adriann/Project_django/appem/dev_env/local/lib/python2.7/site-packages/django/utils/encoding.py", line 78, in force_text
    s = six.text_type(s)
  File "/home/adriann/Project_django/appem/dev_env/local/lib/python2.7/site-packages/django/utils/html.py", line 381, in <lambda>
    klass.__unicode__ = lambda self: mark_safe(klass_unicode(self))
  File "/home/adriann/Project_django/appem/dev_env/local/lib/python2.7/site-packages/django/forms/boundfield.py", line 43, in __str__
    return self.as_widget()
  File "/home/adriann/Project_django/appem/dev_env/local/lib/python2.7/site-packages/django/forms/boundfield.py", line 101, in as_widget
    return force_text(widget.render(name, self.value(), attrs=attrs))
  File "/home/adriann/Project_django/appem/dev_env/local/lib/python2.7/site-packages/django/forms/widgets.py", line 528, in render
    options = self.render_options(choices, [value])
  File "/home/adriann/Project_django/appem/dev_env/local/lib/python2.7/site-packages/django/forms/widgets.py", line 554, in render_options
    for option_value, option_label in chain(self.choices, choices):
  File "/home/adriann/Project_django/appem/dev_env/local/lib/python2.7/site-packages/django/forms/models.py", line 1109, in __iter__
    for obj in queryset:
  File "/home/adriann/Project_django/appem/dev_env/local/lib/python2.7/site-packages/django/db/models/query.py", line 52, in __iter__
    results = compiler.execute_sql()
  File "/home/adriann/Project_django/appem/dev_env/local/lib/python2.7/site-packages/django/db/models/sql/compiler.py", line 848, in execute_sql
    cursor.execute(sql, params)
  File "/home/adriann/Project_django/appem/dev_env/local/lib/python2.7/site-packages/django/db/backends/utils.py", line 79, in execute
    return super(CursorDebugWrapper, self).execute(sql, params)
  File "/home/adriann/Project_django/appem/dev_env/local/lib/python2.7/site-packages/django/db/backends/utils.py", line 64, in execute
    return self.cursor.execute(sql, params)
  File "/home/adriann/Project_django/appem/dev_env/local/lib/python2.7/site-packages/django/db/utils.py", line 95, in __exit__
    six.reraise(dj_exc_type, dj_exc_value, traceback)
  File "/home/adriann/Project_django/appem/dev_env/local/lib/python2.7/site-packages/django/db/backends/utils.py", line 64, in execute
    return self.cursor.execute(sql, params)
ProgrammingError: relation "terceros_vende" does not exist
LINE 1: ...nde"."porventa", "terceros_vende"."cesdo_id" FROM "terceros_...
                                                             ^

.-.-.-.-.-.-.-.-.-.-.-.-.-.-.-.-.-.-.-.-.-.-.-.-.-.-.-.-.-.-.-.-.-.-.-.-.-.-.-.- 
 ERROR 2016-10-10 08:02:00,747 base 5611 139699448444672 Internal Server Error: /bill/save/ 
Traceback (most recent call last):
  File "/home/midas/Documentos/infa_web_folder/dev_env/local/lib/python2.7/site-packages/django/core/handlers/base.py", line 149, in get_response
    response = self.process_exception_by_middleware(e, request)
  File "/home/midas/Documentos/infa_web_folder/dev_env/local/lib/python2.7/site-packages/django/core/handlers/base.py", line 147, in get_response
    response = wrapped_callback(request, *callback_args, **callback_kwargs)
  File "/home/midas/Documentos/infa_web_folder/dev_env/local/lib/python2.7/site-packages/django/views/decorators/csrf.py", line 58, in wrapped_view
    return view_func(*args, **kwargs)
  File "/home/midas/Documentos/infa_web_folder/InfaWeb/infa_web/apps/facturacion/views.py", line 233, in BillSave
    movi_pk = code_generate(Movi, ccaja, 'cmovi', request.db)
  File "/home/midas/Documentos/infa_web_folder/InfaWeb/infa_web/apps/facturacion/views.py", line 41, in code_generate
    value = str(Model.objects.using(request_db).latest(value_get))
  File "/home/midas/Documentos/infa_web_folder/dev_env/local/lib/python2.7/site-packages/django/db/models/query.py", line 544, in latest
    return self._earliest_or_latest(field_name=field_name, direction="-")
  File "/home/midas/Documentos/infa_web_folder/dev_env/local/lib/python2.7/site-packages/django/db/models/query.py", line 538, in _earliest_or_latest
    return obj.get()
  File "/home/midas/Documentos/infa_web_folder/dev_env/local/lib/python2.7/site-packages/django/db/models/query.py", line 387, in get
    self.model._meta.object_name
DoesNotExist: Movi matching query does not exist.
.-.-.-.-.-.-.-.-.-.-.-.-.-.-.-.-.-.-.-.-.-.-.-.-.-.-.-.-.-.-.-.-.-.-.-.-.-.-.-.- 
 ERROR 2016-10-10 08:02:56,007 base 5611 139699448444672 Internal Server Error: /bill/save/ 
Traceback (most recent call last):
  File "/home/midas/Documentos/infa_web_folder/dev_env/local/lib/python2.7/site-packages/django/core/handlers/base.py", line 149, in get_response
    response = self.process_exception_by_middleware(e, request)
  File "/home/midas/Documentos/infa_web_folder/dev_env/local/lib/python2.7/site-packages/django/core/handlers/base.py", line 147, in get_response
    response = wrapped_callback(request, *callback_args, **callback_kwargs)
  File "/home/midas/Documentos/infa_web_folder/dev_env/local/lib/python2.7/site-packages/django/views/decorators/csrf.py", line 58, in wrapped_view
    return view_func(*args, **kwargs)
  File "/home/midas/Documentos/infa_web_folder/InfaWeb/infa_web/apps/facturacion/views.py", line 233, in BillSave
    movi_pk = code_generate(Movi, ccaja, 'cmovi', request.db)
  File "/home/midas/Documentos/infa_web_folder/InfaWeb/infa_web/apps/facturacion/views.py", line 41, in code_generate
    value = str(Model.objects.using(request_db).latest(value_get))
  File "/home/midas/Documentos/infa_web_folder/dev_env/local/lib/python2.7/site-packages/django/db/models/query.py", line 544, in latest
    return self._earliest_or_latest(field_name=field_name, direction="-")
  File "/home/midas/Documentos/infa_web_folder/dev_env/local/lib/python2.7/site-packages/django/db/models/query.py", line 538, in _earliest_or_latest
    return obj.get()
  File "/home/midas/Documentos/infa_web_folder/dev_env/local/lib/python2.7/site-packages/django/db/models/query.py", line 387, in get
    self.model._meta.object_name
DoesNotExist: Movi matching query does not exist.
.-.-.-.-.-.-.-.-.-.-.-.-.-.-.-.-.-.-.-.-.-.-.-.-.-.-.-.-.-.-.-.-.-.-.-.-.-.-.-.- 
 ERROR 2016-10-10 08:06:00,707 base 6250 140456293820160 Internal Server Error: /bill/print/ 
Traceback (most recent call last):
  File "/home/midas/Documentos/infa_web_folder/dev_env/local/lib/python2.7/site-packages/django/core/handlers/base.py", line 149, in get_response
    response = self.process_exception_by_middleware(e, request)
  File "/home/midas/Documentos/infa_web_folder/dev_env/local/lib/python2.7/site-packages/django/core/handlers/base.py", line 147, in get_response
    response = wrapped_callback(request, *callback_args, **callback_kwargs)
  File "/home/midas/Documentos/infa_web_folder/dev_env/local/lib/python2.7/site-packages/django/views/generic/base.py", line 68, in view
    return self.dispatch(request, *args, **kwargs)
  File "/home/midas/Documentos/infa_web_folder/dev_env/local/lib/python2.7/site-packages/django/views/generic/base.py", line 88, in dispatch
    return handler(request, *args, **kwargs)
  File "/home/midas/Documentos/infa_web_folder/dev_env/local/lib/python2.7/site-packages/easy_pdf/views.py", line 80, in get
    context = self.get_context_data(**kwargs)
  File "/home/midas/Documentos/infa_web_folder/InfaWeb/infa_web/apps/facturacion/views.py", line 806, in get_context_data
    factura = Fac.objects.using(self.request.db).get(cfac=cfac)
  File "/home/midas/Documentos/infa_web_folder/dev_env/local/lib/python2.7/site-packages/django/db/models/query.py", line 387, in get
    self.model._meta.object_name
DoesNotExist: Fac matching query does not exist.
.-.-.-.-.-.-.-.-.-.-.-.-.-.-.-.-.-.-.-.-.-.-.-.-.-.-.-.-.-.-.-.-.-.-.-.-.-.-.-.- 
<<<<<<< HEAD
 ERROR 2016-10-10 09:10:56,207 base 2264 5804 Internal Server Error: /bill/save/ 
Traceback (most recent call last):
  File "C:\Python27\lib\site-packages\django\core\handlers\base.py", line 149, in get_response
    response = self.process_exception_by_middleware(e, request)
  File "C:\Python27\lib\site-packages\django\core\handlers\base.py", line 147, in get_response
    response = wrapped_callback(request, *callback_args, **callback_kwargs)
  File "C:\Python27\lib\site-packages\django\views\decorators\csrf.py", line 58, in wrapped_view
    return view_func(*args, **kwargs)
  File "D:\Proyectos\infa web\infa_web\infa_web\apps\facturacion\views.py", line 318, in BillSave
    'vtdescu': float(data['vdescu'])
  File "D:\Proyectos\infa web\infa_web\infa_web\apps\facturacion\views.py", line 151, in save_movi
    cmovi = movi_array['cmovi'],
KeyError: 'cmovi'
.-.-.-.-.-.-.-.-.-.-.-.-.-.-.-.-.-.-.-.-.-.-.-.-.-.-.-.-.-.-.-.-.-.-.-.-.-.-.-.- 
 ERROR 2016-10-10 09:42:06,579 base 3860 180 Internal Server Error: /bill/save/ 
Traceback (most recent call last):
  File "C:\Python27\lib\site-packages\django\core\handlers\base.py", line 149, in get_response
    response = self.process_exception_by_middleware(e, request)
  File "C:\Python27\lib\site-packages\django\core\handlers\base.py", line 147, in get_response
    response = wrapped_callback(request, *callback_args, **callback_kwargs)
  File "C:\Python27\lib\site-packages\django\views\decorators\csrf.py", line 58, in wrapped_view
    return view_func(*args, **kwargs)
  File "D:\Proyectos\infa web\infa_web\infa_web\apps\facturacion\views.py", line 385, in BillSave
    'vmpago': float(data_facpago['vmpago'])
  File "D:\Proyectos\infa web\infa_web\infa_web\apps\facturacion\views.py", line 199, in save_fac_pago
    fac_pago = get_or_none(Facpago, request_db, fac = fac_pago_array['fac'], it = fac_pago_array['it'])
KeyError: 'fac'
.-.-.-.-.-.-.-.-.-.-.-.-.-.-.-.-.-.-.-.-.-.-.-.-.-.-.-.-.-.-.-.-.-.-.-.-.-.-.-.- 
 ERROR 2016-10-10 09:42:51,838 base 5124 5512 Internal Server Error: /bill/save/ 
Traceback (most recent call last):
  File "C:\Python27\lib\site-packages\django\core\handlers\base.py", line 149, in get_response
    response = self.process_exception_by_middleware(e, request)
  File "C:\Python27\lib\site-packages\django\core\handlers\base.py", line 147, in get_response
    response = wrapped_callback(request, *callback_args, **callback_kwargs)
  File "C:\Python27\lib\site-packages\django\views\decorators\csrf.py", line 58, in wrapped_view
    return view_func(*args, **kwargs)
  File "D:\Proyectos\infa web\infa_web\infa_web\apps\facturacion\views.py", line 385, in BillSave
    'vmpago': float(data_facpago['vmpago'])
  File "D:\Proyectos\infa web\infa_web\infa_web\apps\facturacion\views.py", line 199, in save_fac_pago
    fac_pago = get_or_none(Facpago, request_db, fac = fac_pago_array['fac'].pk, it = fac_pago_array['it'])
KeyError: 'fac'
.-.-.-.-.-.-.-.-.-.-.-.-.-.-.-.-.-.-.-.-.-.-.-.-.-.-.-.-.-.-.-.-.-.-.-.-.-.-.-.- 
 ERROR 2016-10-10 09:43:21,013 base 2140 5612 Internal Server Error: /bill/save/ 
Traceback (most recent call last):
  File "C:\Python27\lib\site-packages\django\core\handlers\base.py", line 149, in get_response
    response = self.process_exception_by_middleware(e, request)
  File "C:\Python27\lib\site-packages\django\core\handlers\base.py", line 147, in get_response
    response = wrapped_callback(request, *callback_args, **callback_kwargs)
  File "C:\Python27\lib\site-packages\django\views\decorators\csrf.py", line 58, in wrapped_view
    return view_func(*args, **kwargs)
  File "D:\Proyectos\infa web\infa_web\infa_web\apps\facturacion\views.py", line 385, in BillSave
    'vmpago': float(data_facpago['vmpago'])
  File "D:\Proyectos\infa web\infa_web\infa_web\apps\facturacion\views.py", line 199, in save_fac_pago
    fac_pago = get_or_none(Facpago, request_db, cfac = fac_pago_array['fac'].pk, it = fac_pago_array['it'])
KeyError: 'fac'
.-.-.-.-.-.-.-.-.-.-.-.-.-.-.-.-.-.-.-.-.-.-.-.-.-.-.-.-.-.-.-.-.-.-.-.-.-.-.-.- 
 ERROR 2016-10-10 09:43:47,493 base 5120 4592 Internal Server Error: /bill/save/ 
Traceback (most recent call last):
  File "C:\Python27\lib\site-packages\django\core\handlers\base.py", line 149, in get_response
    response = self.process_exception_by_middleware(e, request)
  File "C:\Python27\lib\site-packages\django\core\handlers\base.py", line 147, in get_response
    response = wrapped_callback(request, *callback_args, **callback_kwargs)
  File "C:\Python27\lib\site-packages\django\views\decorators\csrf.py", line 58, in wrapped_view
    return view_func(*args, **kwargs)
  File "D:\Proyectos\infa web\infa_web\infa_web\apps\facturacion\views.py", line 409, in BillSave
    'vmovi': medios_pagos_total
TypeError: save_movideta() takes exactly 2 arguments (3 given)
.-.-.-.-.-.-.-.-.-.-.-.-.-.-.-.-.-.-.-.-.-.-.-.-.-.-.-.-.-.-.-.-.-.-.-.-.-.-.-.- 
 ERROR 2016-10-10 10:08:14,901 base 3504 4504 Internal Server Error: /bill/save/ 
Traceback (most recent call last):
  File "C:\Python27\lib\site-packages\django\core\handlers\base.py", line 149, in get_response
    response = self.process_exception_by_middleware(e, request)
  File "C:\Python27\lib\site-packages\django\core\handlers\base.py", line 147, in get_response
    response = wrapped_callback(request, *callback_args, **callback_kwargs)
  File "C:\Python27\lib\site-packages\django\views\decorators\csrf.py", line 58, in wrapped_view
    return view_func(*args, **kwargs)
  File "D:\Proyectos\infa web\infa_web\infa_web\apps\facturacion\views.py", line 528, in BillSave
    'vtotal': float((vt + viva))
  File "D:\Proyectos\infa web\infa_web\infa_web\apps\facturacion\views.py", line 276, in save_mvsa_deta
    mvsa_deta = get_or_none(Mvsadeta, request_db, cmvsa = mvsa_deta_array['mvsa'].pk, carlos = mvsa_deta_array['carlos'].pk)
KeyError: 'mvsa'
.-.-.-.-.-.-.-.-.-.-.-.-.-.-.-.-.-.-.-.-.-.-.-.-.-.-.-.-.-.-.-.-.-.-.-.-.-.-.-.- 
 ERROR 2016-10-10 10:19:20,457 base 3600 1872 Internal Server Error: /bill/save/82/ 
Traceback (most recent call last):
  File "C:\Python27\lib\site-packages\django\core\handlers\base.py", line 149, in get_response
    response = self.process_exception_by_middleware(e, request)
  File "C:\Python27\lib\site-packages\django\core\handlers\base.py", line 147, in get_response
    response = wrapped_callback(request, *callback_args, **callback_kwargs)
  File "C:\Python27\lib\site-packages\django\views\decorators\csrf.py", line 58, in wrapped_view
    return view_func(*args, **kwargs)
  File "D:\Proyectos\infa web\infa_web\infa_web\apps\facturacion\views.py", line 592, in BillUpdate
    'vrtefte': float(data['vrtefte']),
  File "D:\Proyectos\infa web\infa_web\infa_web\apps\facturacion\views.py", line 60, in save_fac
    fac.descri = fac_array['descri']
KeyError: 'descri'
.-.-.-.-.-.-.-.-.-.-.-.-.-.-.-.-.-.-.-.-.-.-.-.-.-.-.-.-.-.-.-.-.-.-.-.-.-.-.-.- 
 ERROR 2016-10-10 10:21:44,802 base 4752 2580 Internal Server Error: /bill/save/82/ 
Traceback (most recent call last):
  File "C:\Python27\lib\site-packages\django\core\handlers\base.py", line 149, in get_response
    response = self.process_exception_by_middleware(e, request)
  File "C:\Python27\lib\site-packages\django\core\handlers\base.py", line 147, in get_response
    response = wrapped_callback(request, *callback_args, **callback_kwargs)
  File "C:\Python27\lib\site-packages\django\views\decorators\csrf.py", line 58, in wrapped_view
    return view_func(*args, **kwargs)
  File "D:\Proyectos\infa web\infa_web\infa_web\apps\facturacion\views.py", line 593, in BillUpdate
    'vrtefte': float(data['vrtefte']),
  File "D:\Proyectos\infa web\infa_web\infa_web\apps\facturacion\views.py", line 70, in save_fac
    fac.tpordes = fac_array['tpordes']
KeyError: 'tpordes'
.-.-.-.-.-.-.-.-.-.-.-.-.-.-.-.-.-.-.-.-.-.-.-.-.-.-.-.-.-.-.-.-.-.-.-.-.-.-.-.- 
 ERROR 2016-10-10 10:45:03,131 base 5096 5808 Internal Server Error: /bill/save/ 
Traceback (most recent call last):
  File "C:\Python27\lib\site-packages\django\core\handlers\base.py", line 149, in get_response
    response = self.process_exception_by_middleware(e, request)
  File "C:\Python27\lib\site-packages\django\core\handlers\base.py", line 147, in get_response
    response = wrapped_callback(request, *callback_args, **callback_kwargs)
  File "C:\Python27\lib\site-packages\django\views\decorators\csrf.py", line 58, in wrapped_view
    return view_func(*args, **kwargs)
  File "D:\Proyectos\infa web\infa_web\infa_web\apps\facturacion\views.py", line 468, in BillSave
    'vmovi': medios_pagos_total
  File "D:\Proyectos\infa web\infa_web\infa_web\apps\facturacion\views.py", line 188, in save_movideta
    cmovi = movi[0],
  File "C:\Python27\lib\site-packages\django\db\models\query.py", line 280, in __getitem__
    return self._result_cache[k]
IndexError: list index out of range
.-.-.-.-.-.-.-.-.-.-.-.-.-.-.-.-.-.-.-.-.-.-.-.-.-.-.-.-.-.-.-.-.-.-.-.-.-.-.-.- 
 ERROR 2016-10-10 10:47:04,401 base 4800 6048 Internal Server Error: /bill/save/82/ 
Traceback (most recent call last):
  File "C:\Python27\lib\site-packages\django\core\handlers\base.py", line 149, in get_response
    response = self.process_exception_by_middleware(e, request)
  File "C:\Python27\lib\site-packages\django\core\handlers\base.py", line 147, in get_response
    response = wrapped_callback(request, *callback_args, **callback_kwargs)
  File "C:\Python27\lib\site-packages\django\views\decorators\csrf.py", line 58, in wrapped_view
    return view_func(*args, **kwargs)
  File "D:\Proyectos\infa web\infa_web\infa_web\apps\facturacion\views.py", line 550, in BillUpdate
    ctimo_cxc_billing = manageParameters.get_param_value('ctimo_cxc_billing')
NameError: global name 'manageParameters' is not defined
.-.-.-.-.-.-.-.-.-.-.-.-.-.-.-.-.-.-.-.-.-.-.-.-.-.-.-.-.-.-.-.-.-.-.-.-.-.-.-.- 
 ERROR 2016-10-10 11:30:44,329 base 4632 2640 Internal Server Error: /bill/save/ 
Traceback (most recent call last):
  File "C:\Python27\lib\site-packages\django\core\handlers\base.py", line 149, in get_response
    response = self.process_exception_by_middleware(e, request)
  File "C:\Python27\lib\site-packages\django\core\handlers\base.py", line 147, in get_response
    response = wrapped_callback(request, *callback_args, **callback_kwargs)
  File "C:\Python27\lib\site-packages\django\views\decorators\csrf.py", line 58, in wrapped_view
    return view_func(*args, **kwargs)
  File "D:\Proyectos\infa web\infa_web\infa_web\apps\facturacion\views.py", line 413, in BillSave
    'vtdescu': float(data['vdescu'])
  File "D:\Proyectos\infa web\infa_web\infa_web\apps\facturacion\views.py", line 130, in save_movi
    movi = movi_find(movi_array['cfac'], request_db, movi_array['ctimo'])
  File "D:\Proyectos\infa web\infa_web\infa_web\apps\facturacion\views.py", line 171, in movi_find
    return movi_find.filter(ctimo__pk = ctimo_billing)
  File "C:\Python27\lib\site-packages\django\db\models\query.py", line 790, in filter
    return self._filter_or_exclude(False, *args, **kwargs)
  File "C:\Python27\lib\site-packages\django\db\models\query.py", line 808, in _filter_or_exclude
    clone.query.add_q(Q(*args, **kwargs))
  File "C:\Python27\lib\site-packages\django\db\models\sql\query.py", line 1243, in add_q
    clause, _ = self._add_q(q_object, self.used_aliases)
  File "C:\Python27\lib\site-packages\django\db\models\sql\query.py", line 1269, in _add_q
    allow_joins=allow_joins, split_subq=split_subq,
  File "C:\Python27\lib\site-packages\django\db\models\sql\query.py", line 1203, in build_filter
    condition = self.build_lookup(lookups, col, value)
  File "C:\Python27\lib\site-packages\django\db\models\sql\query.py", line 1099, in build_lookup
    return final_lookup(lhs, rhs)
  File "C:\Python27\lib\site-packages\django\db\models\lookups.py", line 19, in __init__
    self.rhs = self.get_prep_lookup()
  File "C:\Python27\lib\site-packages\django\db\models\lookups.py", line 57, in get_prep_lookup
    return self.lhs.output_field.get_prep_lookup(self.lookup_name, self.rhs)
  File "C:\Python27\lib\site-packages\django\db\models\fields\__init__.py", line 1860, in get_prep_lookup
    return super(IntegerField, self).get_prep_lookup(lookup_type, value)
  File "C:\Python27\lib\site-packages\django\db\models\fields\__init__.py", line 744, in get_prep_lookup
    return self.get_prep_value(value)
  File "C:\Python27\lib\site-packages\django\db\models\fields\__init__.py", line 1854, in get_prep_value
    return int(value)
TypeError: int() argument must be a string or a number, not 'Timo'
.-.-.-.-.-.-.-.-.-.-.-.-.-.-.-.-.-.-.-.-.-.-.-.-.-.-.-.-.-.-.-.-.-.-.-.-.-.-.-.- 
 ERROR 2016-10-10 11:31:55,003 base 1076 1696 Internal Server Error: /bill/save/84/ 
Traceback (most recent call last):
  File "C:\Python27\lib\site-packages\django\core\handlers\base.py", line 149, in get_response
    response = self.process_exception_by_middleware(e, request)
  File "C:\Python27\lib\site-packages\django\core\handlers\base.py", line 147, in get_response
    response = wrapped_callback(request, *callback_args, **callback_kwargs)
  File "C:\Python27\lib\site-packages\django\views\decorators\csrf.py", line 58, in wrapped_view
    return view_func(*args, **kwargs)
  File "D:\Proyectos\infa web\infa_web\infa_web\apps\facturacion\views.py", line 619, in BillUpdate
    'vmpago': float(data_facpago['vmpago'])
  File "D:\Proyectos\infa web\infa_web\infa_web\apps\facturacion\views.py", line 195, in save_fac_pago
    fac_pago = get_or_none(Facpago, request_db, cfac = fac_pago_array['cfac'].pk, it = fac_pago_array['it'])
AttributeError: 'int' object has no attribute 'pk'
.-.-.-.-.-.-.-.-.-.-.-.-.-.-.-.-.-.-.-.-.-.-.-.-.-.-.-.-.-.-.-.-.-.-.-.-.-.-.-.- 
 ERROR 2016-10-10 11:33:01,678 base 5128 5812 Internal Server Error: /bill/save/84/ 
Traceback (most recent call last):
  File "C:\Python27\lib\site-packages\django\core\handlers\base.py", line 149, in get_response
    response = self.process_exception_by_middleware(e, request)
  File "C:\Python27\lib\site-packages\django\core\handlers\base.py", line 147, in get_response
    response = wrapped_callback(request, *callback_args, **callback_kwargs)
  File "C:\Python27\lib\site-packages\django\views\decorators\csrf.py", line 58, in wrapped_view
    return view_func(*args, **kwargs)
  File "D:\Proyectos\infa web\infa_web\infa_web\apps\facturacion\views.py", line 630, in BillUpdate
    'vmovi': float(data_facpago['vmpago'])
  File "D:\Proyectos\infa web\infa_web\infa_web\apps\facturacion\views.py", line 181, in save_movideta
    movideta = movi[0].movideta_set.using(request.db).get(itmovi = movideta_array['itmovi'])
NameError: global name 'request' is not defined
=======
 ERROR 2016-10-10 08:17:02,800 base 7008 140242978907904 Internal Server Error: /bill/print/ 
Traceback (most recent call last):
  File "/home/midas/Documentos/infa_web_folder/dev_env/local/lib/python2.7/site-packages/django/core/handlers/base.py", line 149, in get_response
    response = self.process_exception_by_middleware(e, request)
  File "/home/midas/Documentos/infa_web_folder/dev_env/local/lib/python2.7/site-packages/django/core/handlers/base.py", line 147, in get_response
    response = wrapped_callback(request, *callback_args, **callback_kwargs)
  File "/home/midas/Documentos/infa_web_folder/dev_env/local/lib/python2.7/site-packages/django/views/generic/base.py", line 68, in view
    return self.dispatch(request, *args, **kwargs)
  File "/home/midas/Documentos/infa_web_folder/dev_env/local/lib/python2.7/site-packages/django/views/generic/base.py", line 88, in dispatch
    return handler(request, *args, **kwargs)
  File "/home/midas/Documentos/infa_web_folder/dev_env/local/lib/python2.7/site-packages/easy_pdf/views.py", line 80, in get
    context = self.get_context_data(**kwargs)
  File "/home/midas/Documentos/infa_web_folder/InfaWeb/infa_web/apps/facturacion/views.py", line 804, in get_context_data
    factura = Fac.objects.using(self.request.db).get(cfac=cfac)
  File "/home/midas/Documentos/infa_web_folder/dev_env/local/lib/python2.7/site-packages/django/db/models/query.py", line 387, in get
    self.model._meta.object_name
DoesNotExist: Fac matching query does not exist.
.-.-.-.-.-.-.-.-.-.-.-.-.-.-.-.-.-.-.-.-.-.-.-.-.-.-.-.-.-.-.-.-.-.-.-.-.-.-.-.- 
 ERROR 2016-10-10 08:21:35,176 base 7008 140242978907904 Internal Server Error: /bill/print/ 
Traceback (most recent call last):
  File "/home/midas/Documentos/infa_web_folder/dev_env/local/lib/python2.7/site-packages/django/core/handlers/base.py", line 149, in get_response
    response = self.process_exception_by_middleware(e, request)
  File "/home/midas/Documentos/infa_web_folder/dev_env/local/lib/python2.7/site-packages/django/core/handlers/base.py", line 147, in get_response
    response = wrapped_callback(request, *callback_args, **callback_kwargs)
  File "/home/midas/Documentos/infa_web_folder/dev_env/local/lib/python2.7/site-packages/django/views/generic/base.py", line 68, in view
    return self.dispatch(request, *args, **kwargs)
  File "/home/midas/Documentos/infa_web_folder/dev_env/local/lib/python2.7/site-packages/django/views/generic/base.py", line 88, in dispatch
    return handler(request, *args, **kwargs)
  File "/home/midas/Documentos/infa_web_folder/dev_env/local/lib/python2.7/site-packages/easy_pdf/views.py", line 80, in get
    context = self.get_context_data(**kwargs)
  File "/home/midas/Documentos/infa_web_folder/InfaWeb/infa_web/apps/facturacion/views.py", line 804, in get_context_data
    factura = Fac.objects.using(self.request.db).get(cfac=cfac)
  File "/home/midas/Documentos/infa_web_folder/dev_env/local/lib/python2.7/site-packages/django/db/models/query.py", line 387, in get
    self.model._meta.object_name
DoesNotExist: Fac matching query does not exist.
.-.-.-.-.-.-.-.-.-.-.-.-.-.-.-.-.-.-.-.-.-.-.-.-.-.-.-.-.-.-.-.-.-.-.-.-.-.-.-.- 
 ERROR 2016-10-10 09:26:35,299 base 9184 140417930417920 Internal Server Error: /bill/reports/view/ventas 
Traceback (most recent call last):
  File "/home/midas/Documentos/infa_web_folder/dev_env/local/lib/python2.7/site-packages/django/core/handlers/base.py", line 149, in get_response
    response = self.process_exception_by_middleware(e, request)
  File "/home/midas/Documentos/infa_web_folder/dev_env/local/lib/python2.7/site-packages/django/core/handlers/base.py", line 147, in get_response
    response = wrapped_callback(request, *callback_args, **callback_kwargs)
TypeError: __init__() takes exactly 1 argument (2 given)
.-.-.-.-.-.-.-.-.-.-.-.-.-.-.-.-.-.-.-.-.-.-.-.-.-.-.-.-.-.-.-.-.-.-.-.-.-.-.-.- 
 ERROR 2016-10-10 09:27:06,034 base 9308 140217414924032 Internal Server Error: /bill/reports/view/ventas 
Traceback (most recent call last):
  File "/home/midas/Documentos/infa_web_folder/dev_env/local/lib/python2.7/site-packages/django/core/handlers/base.py", line 149, in get_response
    response = self.process_exception_by_middleware(e, request)
  File "/home/midas/Documentos/infa_web_folder/dev_env/local/lib/python2.7/site-packages/django/core/handlers/base.py", line 147, in get_response
    response = wrapped_callback(request, *callback_args, **callback_kwargs)
  File "/home/midas/Documentos/infa_web_folder/dev_env/local/lib/python2.7/site-packages/django/views/generic/base.py", line 68, in view
    return self.dispatch(request, *args, **kwargs)
  File "/home/midas/Documentos/infa_web_folder/dev_env/local/lib/python2.7/site-packages/django/views/generic/base.py", line 88, in dispatch
    return handler(request, *args, **kwargs)
  File "/home/midas/Documentos/infa_web_folder/dev_env/local/lib/python2.7/site-packages/easy_pdf/views.py", line 80, in get
    context = self.get_context_data(**kwargs)
  File "/home/midas/Documentos/infa_web_folder/InfaWeb/infa_web/apps/facturacion/views.py", line 857, in get_context_data
    context = super(BillPrint, self).get_context_data(**kwargs)
TypeError: super(type, obj): obj must be an instance or subtype of type
.-.-.-.-.-.-.-.-.-.-.-.-.-.-.-.-.-.-.-.-.-.-.-.-.-.-.-.-.-.-.-.-.-.-.-.-.-.-.-.- 
 ERROR 2016-10-10 09:32:39,769 base 9539 140357141010176 Internal Server Error: /bill/reports/view/ventas 
Traceback (most recent call last):
  File "/home/midas/Documentos/infa_web_folder/dev_env/local/lib/python2.7/site-packages/django/core/handlers/base.py", line 149, in get_response
    response = self.process_exception_by_middleware(e, request)
  File "/home/midas/Documentos/infa_web_folder/dev_env/local/lib/python2.7/site-packages/django/core/handlers/base.py", line 147, in get_response
    response = wrapped_callback(request, *callback_args, **callback_kwargs)
  File "/home/midas/Documentos/infa_web_folder/InfaWeb/infa_web/apps/facturacion/views.py", line 850, in report_view_bill
    form = ReportVentaForm(request.db)
  File "/home/midas/Documentos/infa_web_folder/InfaWeb/infa_web/apps/facturacion/forms.py", line 186, in __init__
    manageParameters = ManageParameters(name_db)
NameError: global name 'ManageParameters' is not defined
.-.-.-.-.-.-.-.-.-.-.-.-.-.-.-.-.-.-.-.-.-.-.-.-.-.-.-.-.-.-.-.-.-.-.-.-.-.-.-.- 
 ERROR 2016-10-10 09:33:27,041 base 9572 140564390262528 Internal Server Error: /bill/reports/view/ventas 
Traceback (most recent call last):
  File "/home/midas/Documentos/infa_web_folder/dev_env/local/lib/python2.7/site-packages/django/core/handlers/base.py", line 149, in get_response
    response = self.process_exception_by_middleware(e, request)
  File "/home/midas/Documentos/infa_web_folder/dev_env/local/lib/python2.7/site-packages/django/core/handlers/base.py", line 147, in get_response
    response = wrapped_callback(request, *callback_args, **callback_kwargs)
  File "/home/midas/Documentos/infa_web_folder/InfaWeb/infa_web/apps/facturacion/views.py", line 850, in report_view_bill
    form = ReportVentaForm(request.db)
  File "/home/midas/Documentos/infa_web_folder/InfaWeb/infa_web/apps/facturacion/forms.py", line 192, in __init__
    except Invinicab.DoesNotExist:
NameError: global name 'Invinicab' is not defined
.-.-.-.-.-.-.-.-.-.-.-.-.-.-.-.-.-.-.-.-.-.-.-.-.-.-.-.-.-.-.-.-.-.-.-.-.-.-.-.- 
 ERROR 2016-10-10 09:49:47,699 base 10242 140296190727936 Internal Server Error: /bill/reports/fn/ventas 
Traceback (most recent call last):
  File "/home/midas/Documentos/infa_web_folder/dev_env/local/lib/python2.7/site-packages/django/core/handlers/base.py", line 149, in get_response
    response = self.process_exception_by_middleware(e, request)
  File "/home/midas/Documentos/infa_web_folder/dev_env/local/lib/python2.7/site-packages/django/core/handlers/base.py", line 147, in get_response
    response = wrapped_callback(request, *callback_args, **callback_kwargs)
  File "/home/midas/Documentos/infa_web_folder/dev_env/local/lib/python2.7/site-packages/django/views/generic/base.py", line 68, in view
    return self.dispatch(request, *args, **kwargs)
  File "/home/midas/Documentos/infa_web_folder/dev_env/local/lib/python2.7/site-packages/django/views/generic/base.py", line 88, in dispatch
    return handler(request, *args, **kwargs)
  File "/home/midas/Documentos/infa_web_folder/dev_env/local/lib/python2.7/site-packages/easy_pdf/views.py", line 81, in get
    return self.render_to_response(context)
  File "/home/midas/Documentos/infa_web_folder/dev_env/local/lib/python2.7/site-packages/easy_pdf/views.py", line 63, in render_to_response
    return self.get_pdf_response(context, **response_kwargs)
  File "/home/midas/Documentos/infa_web_folder/dev_env/local/lib/python2.7/site-packages/easy_pdf/views.py", line 59, in get_pdf_response
    **self.get_pdf_kwargs()
  File "/home/midas/Documentos/infa_web_folder/dev_env/local/lib/python2.7/site-packages/easy_pdf/rendering.py", line 166, in render_to_pdf_response
    pdf = render_to_pdf(template, context, encoding=encoding, **kwargs)
  File "/home/midas/Documentos/infa_web_folder/dev_env/local/lib/python2.7/site-packages/easy_pdf/rendering.py", line 138, in render_to_pdf
    content = loader.render_to_string(template, context)
  File "/home/midas/Documentos/infa_web_folder/dev_env/local/lib/python2.7/site-packages/django/template/loader.py", line 94, in render_to_string
    template = select_template(template_name, using=using)
  File "/home/midas/Documentos/infa_web_folder/dev_env/local/lib/python2.7/site-packages/django/template/loader.py", line 62, in select_template
    return engine.get_template(template_name, dirs)
  File "/home/midas/Documentos/infa_web_folder/dev_env/local/lib/python2.7/site-packages/django/template/backends/django.py", line 40, in get_template
    return Template(self.engine.get_template(template_name, dirs), self)
  File "/home/midas/Documentos/infa_web_folder/dev_env/local/lib/python2.7/site-packages/django/template/engine.py", line 190, in get_template
    template, origin = self.find_template(template_name, dirs)
  File "/home/midas/Documentos/infa_web_folder/dev_env/local/lib/python2.7/site-packages/django/template/engine.py", line 157, in find_template
    name, template_dirs=dirs, skip=skip,
  File "/home/midas/Documentos/infa_web_folder/dev_env/local/lib/python2.7/site-packages/django/template/loaders/base.py", line 46, in get_template
    contents, origin, origin.template_name, self.engine,
  File "/home/midas/Documentos/infa_web_folder/dev_env/local/lib/python2.7/site-packages/django/template/base.py", line 189, in __init__
    self.nodelist = self.compile_nodelist()
  File "/home/midas/Documentos/infa_web_folder/dev_env/local/lib/python2.7/site-packages/django/template/base.py", line 231, in compile_nodelist
    return parser.parse()
  File "/home/midas/Documentos/infa_web_folder/dev_env/local/lib/python2.7/site-packages/django/template/base.py", line 516, in parse
    raise self.error(token, e)
TemplateSyntaxError: Empty variable tag on line 25
.-.-.-.-.-.-.-.-.-.-.-.-.-.-.-.-.-.-.-.-.-.-.-.-.-.-.-.-.-.-.-.-.-.-.-.-.-.-.-.- 
 ERROR 2016-10-10 09:54:45,716 base 11387 139901344990976 Internal Server Error: /bill/reports/fn/ventas 
Traceback (most recent call last):
  File "/home/midas/Documentos/infa_web_folder/dev_env/local/lib/python2.7/site-packages/django/core/handlers/base.py", line 149, in get_response
    response = self.process_exception_by_middleware(e, request)
  File "/home/midas/Documentos/infa_web_folder/dev_env/local/lib/python2.7/site-packages/django/core/handlers/base.py", line 147, in get_response
    response = wrapped_callback(request, *callback_args, **callback_kwargs)
  File "/home/midas/Documentos/infa_web_folder/dev_env/local/lib/python2.7/site-packages/django/views/generic/base.py", line 68, in view
    return self.dispatch(request, *args, **kwargs)
  File "/home/midas/Documentos/infa_web_folder/dev_env/local/lib/python2.7/site-packages/django/views/generic/base.py", line 88, in dispatch
    return handler(request, *args, **kwargs)
  File "/home/midas/Documentos/infa_web_folder/dev_env/local/lib/python2.7/site-packages/easy_pdf/views.py", line 80, in get
    context = self.get_context_data(**kwargs)
  File "/home/midas/Documentos/infa_web_folder/InfaWeb/infa_web/apps/facturacion/views.py", line 869, in get_context_data
    data.totales.subtotal = 0
AttributeError: 'dict' object has no attribute 'subtotal'
.-.-.-.-.-.-.-.-.-.-.-.-.-.-.-.-.-.-.-.-.-.-.-.-.-.-.-.-.-.-.-.-.-.-.-.-.-.-.-.- 
 ERROR 2016-10-10 09:55:24,916 base 11431 139766609979136 Internal Server Error: /bill/reports/fn/ventas 
Traceback (most recent call last):
  File "/home/midas/Documentos/infa_web_folder/dev_env/local/lib/python2.7/site-packages/django/core/handlers/base.py", line 149, in get_response
    response = self.process_exception_by_middleware(e, request)
  File "/home/midas/Documentos/infa_web_folder/dev_env/local/lib/python2.7/site-packages/django/core/handlers/base.py", line 147, in get_response
    response = wrapped_callback(request, *callback_args, **callback_kwargs)
  File "/home/midas/Documentos/infa_web_folder/dev_env/local/lib/python2.7/site-packages/django/views/generic/base.py", line 68, in view
    return self.dispatch(request, *args, **kwargs)
  File "/home/midas/Documentos/infa_web_folder/dev_env/local/lib/python2.7/site-packages/django/views/generic/base.py", line 88, in dispatch
    return handler(request, *args, **kwargs)
  File "/home/midas/Documentos/infa_web_folder/dev_env/local/lib/python2.7/site-packages/easy_pdf/views.py", line 80, in get
    context = self.get_context_data(**kwargs)
  File "/home/midas/Documentos/infa_web_folder/InfaWeb/infa_web/apps/facturacion/views.py", line 860, in get_context_data
    data["totales"] = {}
  File "/home/midas/Documentos/infa_web_folder/dev_env/local/lib/python2.7/site-packages/django/http/request.py", line 407, in __setitem__
    self._assert_mutable()
  File "/home/midas/Documentos/infa_web_folder/dev_env/local/lib/python2.7/site-packages/django/http/request.py", line 404, in _assert_mutable
    raise AttributeError("This QueryDict instance is immutable")
AttributeError: This QueryDict instance is immutable
.-.-.-.-.-.-.-.-.-.-.-.-.-.-.-.-.-.-.-.-.-.-.-.-.-.-.-.-.-.-.-.-.-.-.-.-.-.-.-.- 
 ERROR 2016-10-10 10:21:26,759 base 12856 140221085644544 Internal Server Error: /bill/reports/view/ventas 
Traceback (most recent call last):
  File "/home/midas/Documentos/infa_web_folder/dev_env/local/lib/python2.7/site-packages/django/core/handlers/base.py", line 149, in get_response
    response = self.process_exception_by_middleware(e, request)
  File "/home/midas/Documentos/infa_web_folder/dev_env/local/lib/python2.7/site-packages/django/core/handlers/base.py", line 147, in get_response
    response = wrapped_callback(request, *callback_args, **callback_kwargs)
  File "/home/midas/Documentos/infa_web_folder/InfaWeb/infa_web/apps/facturacion/views.py", line 848, in report_view_bill
    form_common = CommonForm(request.db)
  File "/home/midas/Documentos/infa_web_folder/InfaWeb/infa_web/apps/base/forms.py", line 185, in __init__
    self.fields['vendedor'].queryset = Vende.objects.using(name_db).all()
KeyError: 'vendedor'
.-.-.-.-.-.-.-.-.-.-.-.-.-.-.-.-.-.-.-.-.-.-.-.-.-.-.-.-.-.-.-.-.-.-.-.-.-.-.-.- 
 ERROR 2016-10-10 10:21:29,760 base 12856 140221085644544 Internal Server Error: /bill/reports/view/ventas 
Traceback (most recent call last):
  File "/home/midas/Documentos/infa_web_folder/dev_env/local/lib/python2.7/site-packages/django/core/handlers/base.py", line 149, in get_response
    response = self.process_exception_by_middleware(e, request)
  File "/home/midas/Documentos/infa_web_folder/dev_env/local/lib/python2.7/site-packages/django/core/handlers/base.py", line 147, in get_response
    response = wrapped_callback(request, *callback_args, **callback_kwargs)
  File "/home/midas/Documentos/infa_web_folder/InfaWeb/infa_web/apps/facturacion/views.py", line 848, in report_view_bill
    form_common = CommonForm(request.db)
  File "/home/midas/Documentos/infa_web_folder/InfaWeb/infa_web/apps/base/forms.py", line 185, in __init__
    self.fields['vendedor'].queryset = Vende.objects.using(name_db).all()
KeyError: 'vendedor'
.-.-.-.-.-.-.-.-.-.-.-.-.-.-.-.-.-.-.-.-.-.-.-.-.-.-.-.-.-.-.-.-.-.-.-.-.-.-.-.- 
 ERROR 2016-10-10 10:27:52,176 base 13468 139734699050752 Internal Server Error: /bill/reports/view/ventas 
Traceback (most recent call last):
  File "/home/midas/Documentos/infa_web_folder/dev_env/local/lib/python2.7/site-packages/django/core/handlers/base.py", line 149, in get_response
    response = self.process_exception_by_middleware(e, request)
  File "/home/midas/Documentos/infa_web_folder/dev_env/local/lib/python2.7/site-packages/django/core/handlers/base.py", line 147, in get_response
    response = wrapped_callback(request, *callback_args, **callback_kwargs)
  File "/home/midas/Documentos/infa_web_folder/InfaWeb/infa_web/apps/facturacion/views.py", line 848, in report_view_bill
    form_common = CommonForm(request.db)
  File "/home/midas/Documentos/infa_web_folder/InfaWeb/infa_web/apps/base/forms.py", line 185, in __init__
    self.fields['select_vendedor'].widgets.attrs["name"] = "hola"
AttributeError: 'ModelChoiceField' object has no attribute 'widgets'
.-.-.-.-.-.-.-.-.-.-.-.-.-.-.-.-.-.-.-.-.-.-.-.-.-.-.-.-.-.-.-.-.-.-.-.-.-.-.-.- 
 ERROR 2016-10-10 10:33:37,740 base 14133 140280063616768 Internal Server Error: /bill/reports/view/ventas 
Traceback (most recent call last):
  File "/home/midas/Documentos/infa_web_folder/dev_env/local/lib/python2.7/site-packages/django/core/handlers/base.py", line 149, in get_response
    response = self.process_exception_by_middleware(e, request)
  File "/home/midas/Documentos/infa_web_folder/dev_env/local/lib/python2.7/site-packages/django/core/handlers/base.py", line 147, in get_response
    response = wrapped_callback(request, *callback_args, **callback_kwargs)
  File "/home/midas/Documentos/infa_web_folder/InfaWeb/infa_web/apps/facturacion/views.py", line 847, in report_view_bill
    form = ReportVentaForm(request.db)
  File "/home/midas/Documentos/infa_web_folder/InfaWeb/infa_web/apps/facturacion/forms.py", line 186, in __init__
    self.fields['cvende'].queryset = Vende.objects.using(name_db).all()
UnboundLocalError: local variable 'name_db' referenced before assignment
.-.-.-.-.-.-.-.-.-.-.-.-.-.-.-.-.-.-.-.-.-.-.-.-.-.-.-.-.-.-.-.-.-.-.-.-.-.-.-.- 
 ERROR 2016-10-10 10:40:57,726 base 15015 140323007997696 Internal Server Error: /bill/reports/fn/ventas 
Traceback (most recent call last):
  File "/home/midas/Documentos/infa_web_folder/dev_env/local/lib/python2.7/site-packages/django/core/handlers/base.py", line 149, in get_response
    response = self.process_exception_by_middleware(e, request)
  File "/home/midas/Documentos/infa_web_folder/dev_env/local/lib/python2.7/site-packages/django/core/handlers/base.py", line 147, in get_response
    response = wrapped_callback(request, *callback_args, **callback_kwargs)
  File "/home/midas/Documentos/infa_web_folder/dev_env/local/lib/python2.7/site-packages/django/views/generic/base.py", line 68, in view
    return self.dispatch(request, *args, **kwargs)
  File "/home/midas/Documentos/infa_web_folder/dev_env/local/lib/python2.7/site-packages/django/views/generic/base.py", line 88, in dispatch
    return handler(request, *args, **kwargs)
  File "/home/midas/Documentos/infa_web_folder/dev_env/local/lib/python2.7/site-packages/easy_pdf/views.py", line 80, in get
    context = self.get_context_data(**kwargs)
  File "/home/midas/Documentos/infa_web_folder/InfaWeb/infa_web/apps/facturacion/views.py", line 860, in get_context_data
    print data.cvende
AttributeError: 'QueryDict' object has no attribute 'cvende'
.-.-.-.-.-.-.-.-.-.-.-.-.-.-.-.-.-.-.-.-.-.-.-.-.-.-.-.-.-.-.-.-.-.-.-.-.-.-.-.- 
 ERROR 2016-10-10 10:48:30,178 base 15711 140347451635456 Internal Server Error: /bill/reports/fn/ventas 
Traceback (most recent call last):
  File "/home/midas/Documentos/infa_web_folder/dev_env/local/lib/python2.7/site-packages/django/core/handlers/base.py", line 149, in get_response
    response = self.process_exception_by_middleware(e, request)
  File "/home/midas/Documentos/infa_web_folder/dev_env/local/lib/python2.7/site-packages/django/core/handlers/base.py", line 147, in get_response
    response = wrapped_callback(request, *callback_args, **callback_kwargs)
  File "/home/midas/Documentos/infa_web_folder/dev_env/local/lib/python2.7/site-packages/django/views/generic/base.py", line 68, in view
    return self.dispatch(request, *args, **kwargs)
  File "/home/midas/Documentos/infa_web_folder/dev_env/local/lib/python2.7/site-packages/django/views/generic/base.py", line 88, in dispatch
    return handler(request, *args, **kwargs)
  File "/home/midas/Documentos/infa_web_folder/dev_env/local/lib/python2.7/site-packages/easy_pdf/views.py", line 80, in get
    context = self.get_context_data(**kwargs)
  File "/home/midas/Documentos/infa_web_folder/InfaWeb/infa_web/apps/facturacion/views.py", line 878, in get_context_data
    "Vendedor" : Vende.objects.using(self.request.db).get(cvende=cvende).nvede
  File "/home/midas/Documentos/infa_web_folder/dev_env/local/lib/python2.7/site-packages/django/db/models/query.py", line 387, in get
    self.model._meta.object_name
DoesNotExist: Vende matching query does not exist.
.-.-.-.-.-.-.-.-.-.-.-.-.-.-.-.-.-.-.-.-.-.-.-.-.-.-.-.-.-.-.-.-.-.-.-.-.-.-.-.- 
 ERROR 2016-10-10 10:48:36,945 base 15711 140347443242752 Internal Server Error: /bill/reports/fn/ventas 
Traceback (most recent call last):
  File "/home/midas/Documentos/infa_web_folder/dev_env/local/lib/python2.7/site-packages/django/core/handlers/base.py", line 149, in get_response
    response = self.process_exception_by_middleware(e, request)
  File "/home/midas/Documentos/infa_web_folder/dev_env/local/lib/python2.7/site-packages/django/core/handlers/base.py", line 147, in get_response
    response = wrapped_callback(request, *callback_args, **callback_kwargs)
  File "/home/midas/Documentos/infa_web_folder/dev_env/local/lib/python2.7/site-packages/django/views/generic/base.py", line 68, in view
    return self.dispatch(request, *args, **kwargs)
  File "/home/midas/Documentos/infa_web_folder/dev_env/local/lib/python2.7/site-packages/django/views/generic/base.py", line 88, in dispatch
    return handler(request, *args, **kwargs)
  File "/home/midas/Documentos/infa_web_folder/dev_env/local/lib/python2.7/site-packages/easy_pdf/views.py", line 80, in get
    context = self.get_context_data(**kwargs)
  File "/home/midas/Documentos/infa_web_folder/InfaWeb/infa_web/apps/facturacion/views.py", line 878, in get_context_data
    "Vendedor" : Vende.objects.using(self.request.db).get(cvende=cvende).nvede
AttributeError: 'Vende' object has no attribute 'nvede'
.-.-.-.-.-.-.-.-.-.-.-.-.-.-.-.-.-.-.-.-.-.-.-.-.-.-.-.-.-.-.-.-.-.-.-.-.-.-.-.- 
 ERROR 2016-10-10 10:48:36,974 base 15711 140347451635456 Internal Server Error: /bill/reports/fn/ventas 
Traceback (most recent call last):
  File "/home/midas/Documentos/infa_web_folder/dev_env/local/lib/python2.7/site-packages/django/core/handlers/base.py", line 149, in get_response
    response = self.process_exception_by_middleware(e, request)
  File "/home/midas/Documentos/infa_web_folder/dev_env/local/lib/python2.7/site-packages/django/core/handlers/base.py", line 147, in get_response
    response = wrapped_callback(request, *callback_args, **callback_kwargs)
  File "/home/midas/Documentos/infa_web_folder/dev_env/local/lib/python2.7/site-packages/django/views/generic/base.py", line 68, in view
    return self.dispatch(request, *args, **kwargs)
  File "/home/midas/Documentos/infa_web_folder/dev_env/local/lib/python2.7/site-packages/django/views/generic/base.py", line 88, in dispatch
    return handler(request, *args, **kwargs)
  File "/home/midas/Documentos/infa_web_folder/dev_env/local/lib/python2.7/site-packages/easy_pdf/views.py", line 80, in get
    context = self.get_context_data(**kwargs)
  File "/home/midas/Documentos/infa_web_folder/InfaWeb/infa_web/apps/facturacion/views.py", line 878, in get_context_data
    "Vendedor" : Vende.objects.using(self.request.db).get(cvende=cvende).nvede
AttributeError: 'Vende' object has no attribute 'nvede'
.-.-.-.-.-.-.-.-.-.-.-.-.-.-.-.-.-.-.-.-.-.-.-.-.-.-.-.-.-.-.-.-.-.-.-.-.-.-.-.- 
 ERROR 2016-10-10 11:05:26,782 base 17003 139691153430272 Internal Server Error: /bill/reports/fn/ventas 
Traceback (most recent call last):
  File "/home/midas/Documentos/infa_web_folder/dev_env/local/lib/python2.7/site-packages/django/core/handlers/base.py", line 149, in get_response
    response = self.process_exception_by_middleware(e, request)
  File "/home/midas/Documentos/infa_web_folder/dev_env/local/lib/python2.7/site-packages/django/core/handlers/base.py", line 147, in get_response
    response = wrapped_callback(request, *callback_args, **callback_kwargs)
  File "/home/midas/Documentos/infa_web_folder/dev_env/local/lib/python2.7/site-packages/django/views/generic/base.py", line 68, in view
    return self.dispatch(request, *args, **kwargs)
  File "/home/midas/Documentos/infa_web_folder/dev_env/local/lib/python2.7/site-packages/django/views/generic/base.py", line 88, in dispatch
    return handler(request, *args, **kwargs)
  File "/home/midas/Documentos/infa_web_folder/dev_env/local/lib/python2.7/site-packages/easy_pdf/views.py", line 80, in get
    context = self.get_context_data(**kwargs)
  File "/home/midas/Documentos/infa_web_folder/InfaWeb/infa_web/apps/facturacion/views.py", line 865, in get_context_data
    "Fecha Inicial" : data.start_date,
AttributeError: 'QueryDict' object has no attribute 'start_date'
.-.-.-.-.-.-.-.-.-.-.-.-.-.-.-.-.-.-.-.-.-.-.-.-.-.-.-.-.-.-.-.-.-.-.-.-.-.-.-.- 
 ERROR 2016-10-10 11:05:49,265 base 17037 140490147337984 Internal Server Error: /bill/reports/fn/ventas 
Traceback (most recent call last):
  File "/home/midas/Documentos/infa_web_folder/dev_env/local/lib/python2.7/site-packages/django/core/handlers/base.py", line 149, in get_response
    response = self.process_exception_by_middleware(e, request)
  File "/home/midas/Documentos/infa_web_folder/dev_env/local/lib/python2.7/site-packages/django/core/handlers/base.py", line 147, in get_response
    response = wrapped_callback(request, *callback_args, **callback_kwargs)
  File "/home/midas/Documentos/infa_web_folder/dev_env/local/lib/python2.7/site-packages/django/views/generic/base.py", line 68, in view
    return self.dispatch(request, *args, **kwargs)
  File "/home/midas/Documentos/infa_web_folder/dev_env/local/lib/python2.7/site-packages/django/views/generic/base.py", line 88, in dispatch
    return handler(request, *args, **kwargs)
  File "/home/midas/Documentos/infa_web_folder/dev_env/local/lib/python2.7/site-packages/easy_pdf/views.py", line 80, in get
    context = self.get_context_data(**kwargs)
<<<<<<< HEAD
  File "/home/jsandoval86/ProjectsDev/Appem/appem/infa_web/apps/facturacion/views.py", line 720, in get_context_data
    factura = Fac.objects.using(self.request.db).get(cfac=cfac)
  File "/home/jsandoval86/ProjectsDev/Appem/env/local/lib/python2.7/site-packages/django/db/models/query.py", line 387, in get
    self.model._meta.object_name
DoesNotExist: Fac matching query does not exist.
.-.-.-.-.-.-.-.-.-.-.-.-.-.-.-.-.-.-.-.-.-.-.-.-.-.-.-.-.-.-.-.-.-.-.-.-.-.-.-.- 
 ERROR 2016-10-10 09:20:37,846 base 7924 139718489835264 Internal Server Error: /m/search-client 
Traceback (most recent call last):
  File "/home/jsandoval86/ProjectsDev/Appem/env/local/lib/python2.7/site-packages/django/core/handlers/base.py", line 123, in get_response
    response = middleware_method(request)
  File "/home/jsandoval86/ProjectsDev/Appem/appem/infa_web/apps/base/middleware.py", line 18, in process_request
    request.session['empresa_actual'] = ""
  File "/home/jsandoval86/ProjectsDev/Appem/env/local/lib/python2.7/site-packages/django/contrib/sessions/backends/base.py", line 53, in __setitem__
    self._session[key] = value
  File "/home/jsandoval86/ProjectsDev/Appem/env/local/lib/python2.7/site-packages/django/contrib/sessions/backends/base.py", line 201, in _get_session
    self._session_cache = self.load()
  File "/home/jsandoval86/ProjectsDev/Appem/env/local/lib/python2.7/site-packages/django/contrib/sessions/backends/db.py", line 33, in load
    expire_date__gt=timezone.now()
  File "/home/jsandoval86/ProjectsDev/Appem/env/local/lib/python2.7/site-packages/django/db/models/manager.py", line 122, in manager_method
    return getattr(self.get_queryset(), name)(*args, **kwargs)
  File "/home/jsandoval86/ProjectsDev/Appem/env/local/lib/python2.7/site-packages/django/db/models/query.py", line 381, in get
    num = len(clone)
  File "/home/jsandoval86/ProjectsDev/Appem/env/local/lib/python2.7/site-packages/django/db/models/query.py", line 240, in __len__
    self._fetch_all()
  File "/home/jsandoval86/ProjectsDev/Appem/env/local/lib/python2.7/site-packages/django/db/models/query.py", line 1074, in _fetch_all
    self._result_cache = list(self.iterator())
  File "/home/jsandoval86/ProjectsDev/Appem/env/local/lib/python2.7/site-packages/django/db/models/query.py", line 52, in __iter__
    results = compiler.execute_sql()
  File "/home/jsandoval86/ProjectsDev/Appem/env/local/lib/python2.7/site-packages/django/db/models/sql/compiler.py", line 846, in execute_sql
    cursor = self.connection.cursor()
  File "/home/jsandoval86/ProjectsDev/Appem/env/local/lib/python2.7/site-packages/django/db/backends/base/base.py", line 231, in cursor
    cursor = self.make_debug_cursor(self._cursor())
  File "/home/jsandoval86/ProjectsDev/Appem/env/local/lib/python2.7/site-packages/django/db/backends/base/base.py", line 204, in _cursor
    self.ensure_connection()
  File "/home/jsandoval86/ProjectsDev/Appem/env/local/lib/python2.7/site-packages/django/db/backends/base/base.py", line 199, in ensure_connection
    self.connect()
  File "/home/jsandoval86/ProjectsDev/Appem/env/local/lib/python2.7/site-packages/django/db/utils.py", line 95, in __exit__
    six.reraise(dj_exc_type, dj_exc_value, traceback)
  File "/home/jsandoval86/ProjectsDev/Appem/env/local/lib/python2.7/site-packages/django/db/backends/base/base.py", line 199, in ensure_connection
    self.connect()
  File "/home/jsandoval86/ProjectsDev/Appem/env/local/lib/python2.7/site-packages/django/db/backends/base/base.py", line 171, in connect
    self.connection = self.get_new_connection(conn_params)
  File "/home/jsandoval86/ProjectsDev/Appem/env/local/lib/python2.7/site-packages/django/db/backends/postgresql/base.py", line 175, in get_new_connection
    connection = Database.connect(**conn_params)
  File "/home/jsandoval86/ProjectsDev/Appem/env/local/lib/python2.7/site-packages/psycopg2/__init__.py", line 164, in connect
    conn = _connect(dsn, connection_factory=connection_factory, async=async)
OperationalError: could not translate host name "ec2-54-243-52-209.compute-1.amazonaws.com" to address: Name or service not known

.-.-.-.-.-.-.-.-.-.-.-.-.-.-.-.-.-.-.-.-.-.-.-.-.-.-.-.-.-.-.-.-.-.-.-.-.-.-.-.- 
 ERROR 2016-10-10 09:20:40,078 base 7924 139718489835264 Internal Server Error: /m/search-client 
Traceback (most recent call last):
  File "/home/jsandoval86/ProjectsDev/Appem/env/local/lib/python2.7/site-packages/django/core/handlers/base.py", line 123, in get_response
    response = middleware_method(request)
  File "/home/jsandoval86/ProjectsDev/Appem/appem/infa_web/apps/base/middleware.py", line 18, in process_request
    request.session['empresa_actual'] = ""
  File "/home/jsandoval86/ProjectsDev/Appem/env/local/lib/python2.7/site-packages/django/contrib/sessions/backends/base.py", line 53, in __setitem__
    self._session[key] = value
  File "/home/jsandoval86/ProjectsDev/Appem/env/local/lib/python2.7/site-packages/django/contrib/sessions/backends/base.py", line 201, in _get_session
    self._session_cache = self.load()
  File "/home/jsandoval86/ProjectsDev/Appem/env/local/lib/python2.7/site-packages/django/contrib/sessions/backends/db.py", line 33, in load
    expire_date__gt=timezone.now()
  File "/home/jsandoval86/ProjectsDev/Appem/env/local/lib/python2.7/site-packages/django/db/models/manager.py", line 122, in manager_method
    return getattr(self.get_queryset(), name)(*args, **kwargs)
  File "/home/jsandoval86/ProjectsDev/Appem/env/local/lib/python2.7/site-packages/django/db/models/query.py", line 381, in get
    num = len(clone)
  File "/home/jsandoval86/ProjectsDev/Appem/env/local/lib/python2.7/site-packages/django/db/models/query.py", line 240, in __len__
    self._fetch_all()
  File "/home/jsandoval86/ProjectsDev/Appem/env/local/lib/python2.7/site-packages/django/db/models/query.py", line 1074, in _fetch_all
    self._result_cache = list(self.iterator())
  File "/home/jsandoval86/ProjectsDev/Appem/env/local/lib/python2.7/site-packages/django/db/models/query.py", line 52, in __iter__
    results = compiler.execute_sql()
  File "/home/jsandoval86/ProjectsDev/Appem/env/local/lib/python2.7/site-packages/django/db/models/sql/compiler.py", line 846, in execute_sql
    cursor = self.connection.cursor()
  File "/home/jsandoval86/ProjectsDev/Appem/env/local/lib/python2.7/site-packages/django/db/backends/base/base.py", line 231, in cursor
    cursor = self.make_debug_cursor(self._cursor())
  File "/home/jsandoval86/ProjectsDev/Appem/env/local/lib/python2.7/site-packages/django/db/backends/base/base.py", line 204, in _cursor
    self.ensure_connection()
  File "/home/jsandoval86/ProjectsDev/Appem/env/local/lib/python2.7/site-packages/django/db/backends/base/base.py", line 199, in ensure_connection
    self.connect()
  File "/home/jsandoval86/ProjectsDev/Appem/env/local/lib/python2.7/site-packages/django/db/utils.py", line 95, in __exit__
    six.reraise(dj_exc_type, dj_exc_value, traceback)
  File "/home/jsandoval86/ProjectsDev/Appem/env/local/lib/python2.7/site-packages/django/db/backends/base/base.py", line 199, in ensure_connection
    self.connect()
  File "/home/jsandoval86/ProjectsDev/Appem/env/local/lib/python2.7/site-packages/django/db/backends/base/base.py", line 171, in connect
    self.connection = self.get_new_connection(conn_params)
  File "/home/jsandoval86/ProjectsDev/Appem/env/local/lib/python2.7/site-packages/django/db/backends/postgresql/base.py", line 175, in get_new_connection
    connection = Database.connect(**conn_params)
  File "/home/jsandoval86/ProjectsDev/Appem/env/local/lib/python2.7/site-packages/psycopg2/__init__.py", line 164, in connect
    conn = _connect(dsn, connection_factory=connection_factory, async=async)
OperationalError: could not translate host name "ec2-54-243-52-209.compute-1.amazonaws.com" to address: Name or service not known

.-.-.-.-.-.-.-.-.-.-.-.-.-.-.-.-.-.-.-.-.-.-.-.-.-.-.-.-.-.-.-.-.-.-.-.-.-.-.-.- 
 ERROR 2016-10-10 10:47:16,568 base 12374 139732325299968 Internal Server Error: /m/order2 
Traceback (most recent call last):
  File "/home/jsandoval86/ProjectsDev/Appem/env/local/lib/python2.7/site-packages/django/core/handlers/base.py", line 149, in get_response
    response = self.process_exception_by_middleware(e, request)
  File "/home/jsandoval86/ProjectsDev/Appem/env/local/lib/python2.7/site-packages/django/core/handlers/base.py", line 147, in get_response
    response = wrapped_callback(request, *callback_args, **callback_kwargs)
  File "/home/jsandoval86/ProjectsDev/Appem/appem/infa_web/apps/m/views.py", line 16, in mFacOrder2
    return render(request, 'm/m_fac_order2.html')
  File "/home/jsandoval86/ProjectsDev/Appem/env/local/lib/python2.7/site-packages/django/shortcuts.py", line 67, in render
    template_name, context, request=request, using=using)
  File "/home/jsandoval86/ProjectsDev/Appem/env/local/lib/python2.7/site-packages/django/template/loader.py", line 97, in render_to_string
    return template.render(context, request)
  File "/home/jsandoval86/ProjectsDev/Appem/env/local/lib/python2.7/site-packages/django/template/backends/django.py", line 95, in render
    return self.template.render(context)
  File "/home/jsandoval86/ProjectsDev/Appem/env/local/lib/python2.7/site-packages/django/template/base.py", line 206, in render
    return self._render(context)
  File "/home/jsandoval86/ProjectsDev/Appem/env/local/lib/python2.7/site-packages/django/template/base.py", line 197, in _render
    return self.nodelist.render(context)
  File "/home/jsandoval86/ProjectsDev/Appem/env/local/lib/python2.7/site-packages/django/template/base.py", line 992, in render
    bit = node.render_annotated(context)
  File "/home/jsandoval86/ProjectsDev/Appem/env/local/lib/python2.7/site-packages/django/template/base.py", line 959, in render_annotated
    return self.render(context)
  File "/home/jsandoval86/ProjectsDev/Appem/env/local/lib/python2.7/site-packages/django/template/loader_tags.py", line 173, in render
    return compiled_parent._render(context)
  File "/home/jsandoval86/ProjectsDev/Appem/env/local/lib/python2.7/site-packages/django/template/base.py", line 197, in _render
    return self.nodelist.render(context)
  File "/home/jsandoval86/ProjectsDev/Appem/env/local/lib/python2.7/site-packages/django/template/base.py", line 992, in render
    bit = node.render_annotated(context)
  File "/home/jsandoval86/ProjectsDev/Appem/env/local/lib/python2.7/site-packages/django/template/base.py", line 959, in render_annotated
    return self.render(context)
  File "/home/jsandoval86/ProjectsDev/Appem/env/local/lib/python2.7/site-packages/django/template/loader_tags.py", line 69, in render
    result = block.nodelist.render(context)
  File "/home/jsandoval86/ProjectsDev/Appem/env/local/lib/python2.7/site-packages/django/template/base.py", line 992, in render
    bit = node.render_annotated(context)
  File "/home/jsandoval86/ProjectsDev/Appem/env/local/lib/python2.7/site-packages/django/template/base.py", line 959, in render_annotated
    return self.render(context)
  File "/home/jsandoval86/ProjectsDev/Appem/env/local/lib/python2.7/site-packages/django/template/defaulttags.py", line 513, in render
    six.reraise(*exc_info)
  File "/home/jsandoval86/ProjectsDev/Appem/env/local/lib/python2.7/site-packages/django/template/defaulttags.py", line 499, in render
    url = reverse(view_name, args=args, kwargs=kwargs, current_app=current_app)
  File "/home/jsandoval86/ProjectsDev/Appem/env/local/lib/python2.7/site-packages/django/core/urlresolvers.py", line 600, in reverse
    return force_text(iri_to_uri(resolver._reverse_with_prefix(view, prefix, *args, **kwargs)))
  File "/home/jsandoval86/ProjectsDev/Appem/env/local/lib/python2.7/site-packages/django/core/urlresolvers.py", line 508, in _reverse_with_prefix
    (lookup_view_s, args, kwargs, len(patterns), patterns))
NoReverseMatch: Reverse for 'fac_pay' with arguments '()' and keyword arguments '{}' not found. 0 pattern(s) tried: []
.-.-.-.-.-.-.-.-.-.-.-.-.-.-.-.-.-.-.-.-.-.-.-.-.-.-.-.-.-.-.-.-.-.-.-.-.-.-.-.- 
 ERROR 2016-10-10 10:47:26,936 base 12374 139732325299968 Internal Server Error: /m/order2 
Traceback (most recent call last):
  File "/home/jsandoval86/ProjectsDev/Appem/env/local/lib/python2.7/site-packages/django/core/handlers/base.py", line 149, in get_response
    response = self.process_exception_by_middleware(e, request)
  File "/home/jsandoval86/ProjectsDev/Appem/env/local/lib/python2.7/site-packages/django/core/handlers/base.py", line 147, in get_response
    response = wrapped_callback(request, *callback_args, **callback_kwargs)
  File "/home/jsandoval86/ProjectsDev/Appem/appem/infa_web/apps/m/views.py", line 16, in mFacOrder2
    return render(request, 'm/m_fac_order2.html')
  File "/home/jsandoval86/ProjectsDev/Appem/env/local/lib/python2.7/site-packages/django/shortcuts.py", line 67, in render
    template_name, context, request=request, using=using)
  File "/home/jsandoval86/ProjectsDev/Appem/env/local/lib/python2.7/site-packages/django/template/loader.py", line 97, in render_to_string
    return template.render(context, request)
  File "/home/jsandoval86/ProjectsDev/Appem/env/local/lib/python2.7/site-packages/django/template/backends/django.py", line 95, in render
    return self.template.render(context)
  File "/home/jsandoval86/ProjectsDev/Appem/env/local/lib/python2.7/site-packages/django/template/base.py", line 206, in render
    return self._render(context)
  File "/home/jsandoval86/ProjectsDev/Appem/env/local/lib/python2.7/site-packages/django/template/base.py", line 197, in _render
    return self.nodelist.render(context)
  File "/home/jsandoval86/ProjectsDev/Appem/env/local/lib/python2.7/site-packages/django/template/base.py", line 992, in render
    bit = node.render_annotated(context)
  File "/home/jsandoval86/ProjectsDev/Appem/env/local/lib/python2.7/site-packages/django/template/base.py", line 959, in render_annotated
    return self.render(context)
  File "/home/jsandoval86/ProjectsDev/Appem/env/local/lib/python2.7/site-packages/django/template/loader_tags.py", line 173, in render
    return compiled_parent._render(context)
  File "/home/jsandoval86/ProjectsDev/Appem/env/local/lib/python2.7/site-packages/django/template/base.py", line 197, in _render
    return self.nodelist.render(context)
  File "/home/jsandoval86/ProjectsDev/Appem/env/local/lib/python2.7/site-packages/django/template/base.py", line 992, in render
    bit = node.render_annotated(context)
  File "/home/jsandoval86/ProjectsDev/Appem/env/local/lib/python2.7/site-packages/django/template/base.py", line 959, in render_annotated
    return self.render(context)
  File "/home/jsandoval86/ProjectsDev/Appem/env/local/lib/python2.7/site-packages/django/template/loader_tags.py", line 69, in render
    result = block.nodelist.render(context)
  File "/home/jsandoval86/ProjectsDev/Appem/env/local/lib/python2.7/site-packages/django/template/base.py", line 992, in render
    bit = node.render_annotated(context)
  File "/home/jsandoval86/ProjectsDev/Appem/env/local/lib/python2.7/site-packages/django/template/base.py", line 959, in render_annotated
    return self.render(context)
  File "/home/jsandoval86/ProjectsDev/Appem/env/local/lib/python2.7/site-packages/django/template/defaulttags.py", line 513, in render
    six.reraise(*exc_info)
  File "/home/jsandoval86/ProjectsDev/Appem/env/local/lib/python2.7/site-packages/django/template/defaulttags.py", line 499, in render
    url = reverse(view_name, args=args, kwargs=kwargs, current_app=current_app)
  File "/home/jsandoval86/ProjectsDev/Appem/env/local/lib/python2.7/site-packages/django/core/urlresolvers.py", line 600, in reverse
    return force_text(iri_to_uri(resolver._reverse_with_prefix(view, prefix, *args, **kwargs)))
  File "/home/jsandoval86/ProjectsDev/Appem/env/local/lib/python2.7/site-packages/django/core/urlresolvers.py", line 508, in _reverse_with_prefix
    (lookup_view_s, args, kwargs, len(patterns), patterns))
NoReverseMatch: Reverse for 'm_fac_pay' with arguments '()' and keyword arguments '{}' not found. 0 pattern(s) tried: []
=======
  File "/home/midas/Documentos/infa_web_folder/InfaWeb/infa_web/apps/facturacion/views.py", line 865, in get_context_data
    "Fecha Inicial" : data["start_date"],
  File "/home/midas/Documentos/infa_web_folder/dev_env/local/lib/python2.7/site-packages/django/utils/datastructures.py", line 85, in __getitem__
    raise MultiValueDictKeyError(repr(key))
MultiValueDictKeyError: "'start_date'"
>>>>>>> 4d19cfc6d16e42e08ea2888237b5188bdc629ba9
>>>>>>> 72784f9972ecdbc56e45aa014c4acd74268a743c
.-.-.-.-.-.-.-.-.-.-.-.-.-.-.-.-.-.-.-.-.-.-.-.-.-.-.-.-.-.-.-.-.-.-.-.-.-.-.-.- 
 ERROR 2016-10-10 14:13:52,911 base 3360 140575765526272 Internal Server Error: /bill/print/ 
Traceback (most recent call last):
  File "/home/midas/Documentos/infa_web_folder/dev_env/local/lib/python2.7/site-packages/django/core/handlers/base.py", line 149, in get_response
    response = self.process_exception_by_middleware(e, request)
  File "/home/midas/Documentos/infa_web_folder/dev_env/local/lib/python2.7/site-packages/django/core/handlers/base.py", line 147, in get_response
    response = wrapped_callback(request, *callback_args, **callback_kwargs)
  File "/home/midas/Documentos/infa_web_folder/dev_env/local/lib/python2.7/site-packages/django/views/generic/base.py", line 68, in view
    return self.dispatch(request, *args, **kwargs)
  File "/home/midas/Documentos/infa_web_folder/dev_env/local/lib/python2.7/site-packages/django/views/generic/base.py", line 88, in dispatch
    return handler(request, *args, **kwargs)
  File "/home/midas/Documentos/infa_web_folder/dev_env/local/lib/python2.7/site-packages/easy_pdf/views.py", line 80, in get
    context = self.get_context_data(**kwargs)
  File "/home/midas/Documentos/infa_web_folder/InfaWeb/infa_web/apps/facturacion/views.py", line 992, in get_context_data
    factura = Fac.objects.using(self.request.db).get(cfac=cfac)
  File "/home/midas/Documentos/infa_web_folder/dev_env/local/lib/python2.7/site-packages/django/db/models/query.py", line 387, in get
    self.model._meta.object_name
DoesNotExist: Fac matching query does not exist.
.-.-.-.-.-.-.-.-.-.-.-.-.-.-.-.-.-.-.-.-.-.-.-.-.-.-.-.-.-.-.-.-.-.-.-.-.-.-.-.- 
 ERROR 2016-10-10 14:34:07,717 base 3360 140575773132544 Internal Server Error: /bill/reports/fn/ventas 
Traceback (most recent call last):
  File "/home/midas/Documentos/infa_web_folder/dev_env/local/lib/python2.7/site-packages/django/core/handlers/base.py", line 149, in get_response
    response = self.process_exception_by_middleware(e, request)
  File "/home/midas/Documentos/infa_web_folder/dev_env/local/lib/python2.7/site-packages/django/core/handlers/base.py", line 147, in get_response
    response = wrapped_callback(request, *callback_args, **callback_kwargs)
  File "/home/midas/Documentos/infa_web_folder/dev_env/local/lib/python2.7/site-packages/django/views/generic/base.py", line 68, in view
    return self.dispatch(request, *args, **kwargs)
  File "/home/midas/Documentos/infa_web_folder/dev_env/local/lib/python2.7/site-packages/django/views/generic/base.py", line 88, in dispatch
    return handler(request, *args, **kwargs)
  File "/home/midas/Documentos/infa_web_folder/dev_env/local/lib/python2.7/site-packages/easy_pdf/views.py", line 80, in get
    context = self.get_context_data(**kwargs)
  File "/home/midas/Documentos/infa_web_folder/InfaWeb/infa_web/apps/facturacion/views.py", line 1055, in get_context_data
    "Rango de Fechas" : data["fecha_inicial"] + " - " + data["fecha_final"],
  File "/home/midas/Documentos/infa_web_folder/dev_env/local/lib/python2.7/site-packages/django/utils/datastructures.py", line 85, in __getitem__
    raise MultiValueDictKeyError(repr(key))
MultiValueDictKeyError: "'fecha_inicial'"
.-.-.-.-.-.-.-.-.-.-.-.-.-.-.-.-.-.-.-.-.-.-.-.-.-.-.-.-.-.-.-.-.-.-.-.-.-.-.-.- 
 ERROR 2016-10-10 14:34:41,529 base 3360 140575773132544 Internal Server Error: /bill/reports/fn/ventas 
Traceback (most recent call last):
  File "/home/midas/Documentos/infa_web_folder/dev_env/local/lib/python2.7/site-packages/django/core/handlers/base.py", line 149, in get_response
    response = self.process_exception_by_middleware(e, request)
  File "/home/midas/Documentos/infa_web_folder/dev_env/local/lib/python2.7/site-packages/django/core/handlers/base.py", line 147, in get_response
    response = wrapped_callback(request, *callback_args, **callback_kwargs)
  File "/home/midas/Documentos/infa_web_folder/dev_env/local/lib/python2.7/site-packages/django/views/generic/base.py", line 68, in view
    return self.dispatch(request, *args, **kwargs)
  File "/home/midas/Documentos/infa_web_folder/dev_env/local/lib/python2.7/site-packages/django/views/generic/base.py", line 88, in dispatch
    return handler(request, *args, **kwargs)
  File "/home/midas/Documentos/infa_web_folder/dev_env/local/lib/python2.7/site-packages/easy_pdf/views.py", line 80, in get
    context = self.get_context_data(**kwargs)
  File "/home/midas/Documentos/infa_web_folder/InfaWeb/infa_web/apps/facturacion/views.py", line 1055, in get_context_data
    "Rango de Fechas" : data["fecha_inicial"] + " - " + data["fecha_final"],
  File "/home/midas/Documentos/infa_web_folder/dev_env/local/lib/python2.7/site-packages/django/utils/datastructures.py", line 85, in __getitem__
    raise MultiValueDictKeyError(repr(key))
MultiValueDictKeyError: "'fecha_inicial'"
.-.-.-.-.-.-.-.-.-.-.-.-.-.-.-.-.-.-.-.-.-.-.-.-.-.-.-.-.-.-.-.-.-.-.-.-.-.-.-.- 
 ERROR 2016-10-10 14:51:37,341 base 6011 139944482912000 Internal Server Error: /parameters/ 
Traceback (most recent call last):
  File "/home/midas/Documentos/infa_web_folder/dev_env/local/lib/python2.7/site-packages/django/core/handlers/base.py", line 123, in get_response
    response = middleware_method(request)
  File "/home/midas/Documentos/infa_web_folder/InfaWeb/infa_web/apps/base/middleware.py", line 21, in process_request
    print type(manageParameters.to_dict())
TypeError: to_dict() takes exactly 2 arguments (1 given)
.-.-.-.-.-.-.-.-.-.-.-.-.-.-.-.-.-.-.-.-.-.-.-.-.-.-.-.-.-.-.-.-.-.-.-.-.-.-.-.- 
 ERROR 2016-10-10 15:23:34,401 base 7830 140058135901952 Internal Server Error: /articles/add/ 
Traceback (most recent call last):
  File "/home/midas/Documentos/infa_web_folder/dev_env/local/lib/python2.7/site-packages/django/core/handlers/base.py", line 174, in get_response
    response = self.process_exception_by_middleware(e, request)
  File "/home/midas/Documentos/infa_web_folder/dev_env/local/lib/python2.7/site-packages/django/core/handlers/base.py", line 172, in get_response
    response = response.render()
  File "/home/midas/Documentos/infa_web_folder/dev_env/local/lib/python2.7/site-packages/django/template/response.py", line 160, in render
    self.content = self.rendered_content
  File "/home/midas/Documentos/infa_web_folder/dev_env/local/lib/python2.7/site-packages/django/template/response.py", line 137, in rendered_content
    content = template.render(context, self._request)
  File "/home/midas/Documentos/infa_web_folder/dev_env/local/lib/python2.7/site-packages/django/template/backends/django.py", line 95, in render
    return self.template.render(context)
  File "/home/midas/Documentos/infa_web_folder/dev_env/local/lib/python2.7/site-packages/django/template/base.py", line 206, in render
    return self._render(context)
  File "/home/midas/Documentos/infa_web_folder/dev_env/local/lib/python2.7/site-packages/django/template/base.py", line 197, in _render
    return self.nodelist.render(context)
  File "/home/midas/Documentos/infa_web_folder/dev_env/local/lib/python2.7/site-packages/django/template/base.py", line 992, in render
    bit = node.render_annotated(context)
  File "/home/midas/Documentos/infa_web_folder/dev_env/local/lib/python2.7/site-packages/django/template/base.py", line 959, in render_annotated
    return self.render(context)
  File "/home/midas/Documentos/infa_web_folder/dev_env/local/lib/python2.7/site-packages/django/template/loader_tags.py", line 173, in render
    return compiled_parent._render(context)
  File "/home/midas/Documentos/infa_web_folder/dev_env/local/lib/python2.7/site-packages/django/template/base.py", line 197, in _render
    return self.nodelist.render(context)
  File "/home/midas/Documentos/infa_web_folder/dev_env/local/lib/python2.7/site-packages/django/template/base.py", line 992, in render
    bit = node.render_annotated(context)
  File "/home/midas/Documentos/infa_web_folder/dev_env/local/lib/python2.7/site-packages/django/template/base.py", line 959, in render_annotated
    return self.render(context)
  File "/home/midas/Documentos/infa_web_folder/dev_env/local/lib/python2.7/site-packages/django/template/loader_tags.py", line 69, in render
    result = block.nodelist.render(context)
  File "/home/midas/Documentos/infa_web_folder/dev_env/local/lib/python2.7/site-packages/django/template/base.py", line 992, in render
    bit = node.render_annotated(context)
  File "/home/midas/Documentos/infa_web_folder/dev_env/local/lib/python2.7/site-packages/django/template/base.py", line 959, in render_annotated
    return self.render(context)
  File "/home/midas/Documentos/infa_web_folder/dev_env/local/lib/python2.7/site-packages/django/template/base.py", line 1049, in render
    return render_value_in_context(output, context)
  File "/home/midas/Documentos/infa_web_folder/dev_env/local/lib/python2.7/site-packages/django/template/base.py", line 1026, in render_value_in_context
    value = force_text(value)
  File "/home/midas/Documentos/infa_web_folder/dev_env/local/lib/python2.7/site-packages/django/utils/encoding.py", line 78, in force_text
    s = six.text_type(s)
  File "/home/midas/Documentos/infa_web_folder/dev_env/local/lib/python2.7/site-packages/django/utils/html.py", line 381, in <lambda>
    klass.__unicode__ = lambda self: mark_safe(klass_unicode(self))
  File "/home/midas/Documentos/infa_web_folder/dev_env/local/lib/python2.7/site-packages/django/forms/boundfield.py", line 43, in __str__
    return self.as_widget()
  File "/home/midas/Documentos/infa_web_folder/dev_env/local/lib/python2.7/site-packages/django/forms/boundfield.py", line 101, in as_widget
    return force_text(widget.render(name, self.value(), attrs=attrs))
  File "/home/midas/Documentos/infa_web_folder/dev_env/local/lib/python2.7/site-packages/django/forms/widgets.py", line 528, in render
    options = self.render_options(choices, [value])
  File "/home/midas/Documentos/infa_web_folder/dev_env/local/lib/python2.7/site-packages/django/forms/widgets.py", line 554, in render_options
    for option_value, option_label in chain(self.choices, choices):
  File "/home/midas/Documentos/infa_web_folder/dev_env/local/lib/python2.7/site-packages/django/forms/models.py", line 1109, in __iter__
    for obj in queryset:
  File "/home/midas/Documentos/infa_web_folder/dev_env/local/lib/python2.7/site-packages/django/db/models/query.py", line 52, in __iter__
    results = compiler.execute_sql()
  File "/home/midas/Documentos/infa_web_folder/dev_env/local/lib/python2.7/site-packages/django/db/models/sql/compiler.py", line 846, in execute_sql
    cursor = self.connection.cursor()
  File "/home/midas/Documentos/infa_web_folder/dev_env/local/lib/python2.7/site-packages/django/db/backends/base/base.py", line 231, in cursor
    cursor = self.make_debug_cursor(self._cursor())
  File "/home/midas/Documentos/infa_web_folder/dev_env/local/lib/python2.7/site-packages/django/db/backends/base/base.py", line 204, in _cursor
    self.ensure_connection()
  File "/home/midas/Documentos/infa_web_folder/dev_env/local/lib/python2.7/site-packages/django/db/backends/base/base.py", line 199, in ensure_connection
    self.connect()
  File "/home/midas/Documentos/infa_web_folder/dev_env/local/lib/python2.7/site-packages/django/db/utils.py", line 95, in __exit__
    six.reraise(dj_exc_type, dj_exc_value, traceback)
  File "/home/midas/Documentos/infa_web_folder/dev_env/local/lib/python2.7/site-packages/django/db/backends/base/base.py", line 199, in ensure_connection
    self.connect()
  File "/home/midas/Documentos/infa_web_folder/dev_env/local/lib/python2.7/site-packages/django/db/backends/base/base.py", line 171, in connect
    self.connection = self.get_new_connection(conn_params)
  File "/home/midas/Documentos/infa_web_folder/dev_env/local/lib/python2.7/site-packages/django/db/backends/postgresql/base.py", line 175, in get_new_connection
    connection = Database.connect(**conn_params)
  File "/home/midas/Documentos/infa_web_folder/dev_env/local/lib/python2.7/site-packages/psycopg2/__init__.py", line 164, in connect
    conn = _connect(dsn, connection_factory=connection_factory, async=async)
OperationalError: FATAL:  database "stzef" does not exist

