.-.-.-.-.-.-.-.-.-.-.-.-.-.-.-.-.-.-.-.-.-.-.-.-.-.-.-.-.-.-.-.-.-.-.-.-.-.-.-.- 
 ERROR 2016-10-24 07:52:29,162 base 6796 140448339203840 Internal Server Error: /cartera/ 
Traceback (most recent call last):
  File "/home/midas/Documentos/infa_web_folder/dev_env/local/lib/python2.7/site-packages/django/core/handlers/base.py", line 149, in get_response
    response = self.process_exception_by_middleware(e, request)
  File "/home/midas/Documentos/infa_web_folder/dev_env/local/lib/python2.7/site-packages/django/core/handlers/base.py", line 147, in get_response
    response = wrapped_callback(request, *callback_args, **callback_kwargs)
  File "/home/midas/Documentos/infa_web_folder/dev_env/local/lib/python2.7/site-packages/django/views/generic/base.py", line 68, in view
    return self.dispatch(request, *args, **kwargs)
  File "/home/midas/Documentos/infa_web_folder/dev_env/local/lib/python2.7/site-packages/django/views/generic/base.py", line 88, in dispatch
    return handler(request, *args, **kwargs)
  File "/home/midas/Documentos/infa_web_folder/dev_env/local/lib/python2.7/site-packages/django/views/generic/list.py", line 159, in get
    self.object_list = self.get_queryset()
  File "/home/midas/Documentos/infa_web_folder/InfaWeb/infa_web/apps/movimientos/views.py", line 58, in get_queryset
    queryset = super(CarteraList, self).get_queryset().order_by('fmovi').filter(ctimo = ctimo_billing('ctimo_cxc_billing', self.request.db).pk)
  File "/home/midas/Documentos/infa_web_folder/InfaWeb/infa_web/apps/facturacion/views.py", line 176, in ctimo_billing
    return Timo.objects.using(request_db).get(pk = ctimo_billing)
  File "/home/midas/Documentos/infa_web_folder/dev_env/local/lib/python2.7/site-packages/django/db/models/query.py", line 381, in get
    num = len(clone)
  File "/home/midas/Documentos/infa_web_folder/dev_env/local/lib/python2.7/site-packages/django/db/models/query.py", line 240, in __len__
    self._fetch_all()
  File "/home/midas/Documentos/infa_web_folder/dev_env/local/lib/python2.7/site-packages/django/db/models/query.py", line 1074, in _fetch_all
    self._result_cache = list(self.iterator())
  File "/home/midas/Documentos/infa_web_folder/dev_env/local/lib/python2.7/site-packages/django/db/models/query.py", line 52, in __iter__
    results = compiler.execute_sql()
  File "/home/midas/Documentos/infa_web_folder/dev_env/local/lib/python2.7/site-packages/django/db/models/sql/compiler.py", line 846, in execute_sql
    cursor = self.connection.cursor()
  File "/home/midas/Documentos/infa_web_folder/dev_env/local/lib/python2.7/site-packages/django/db/backends/base/base.py", line 231, in cursor
    cursor = self.make_debug_cursor(self._cursor())
  File "/home/midas/Documentos/infa_web_folder/dev_env/local/lib/python2.7/site-packages/django/db/backends/base/base.py", line 204, in _cursor
    self.ensure_connection()
  File "/home/midas/Documentos/infa_web_folder/dev_env/local/lib/python2.7/site-packages/django/db/backends/base/base.py", line 199, in ensure_connection
    self.connect()
  File "/home/midas/Documentos/infa_web_folder/dev_env/local/lib/python2.7/site-packages/django/db/utils.py", line 95, in __exit__
    six.reraise(dj_exc_type, dj_exc_value, traceback)
  File "/home/midas/Documentos/infa_web_folder/dev_env/local/lib/python2.7/site-packages/django/db/backends/base/base.py", line 199, in ensure_connection
    self.connect()
  File "/home/midas/Documentos/infa_web_folder/dev_env/local/lib/python2.7/site-packages/django/db/backends/base/base.py", line 171, in connect
    self.connection = self.get_new_connection(conn_params)
  File "/home/midas/Documentos/infa_web_folder/dev_env/local/lib/python2.7/site-packages/django/db/backends/postgresql/base.py", line 175, in get_new_connection
    connection = Database.connect(**conn_params)
  File "/home/midas/Documentos/infa_web_folder/dev_env/local/lib/python2.7/site-packages/psycopg2/__init__.py", line 164, in connect
    conn = _connect(dsn, connection_factory=connection_factory, async=async)
OperationalError: FATAL:  database "stzef" does not exist

.-.-.-.-.-.-.-.-.-.-.-.-.-.-.-.-.-.-.-.-.-.-.-.-.-.-.-.-.-.-.-.-.-.-.-.-.-.-.-.- 
 ERROR 2016-10-24 07:55:40,311 base 6987 140543220799232 Internal Server Error: /cartera/ 
Traceback (most recent call last):
  File "/home/midas/Documentos/infa_web_folder/dev_env/local/lib/python2.7/site-packages/django/core/handlers/base.py", line 149, in get_response
    response = self.process_exception_by_middleware(e, request)
  File "/home/midas/Documentos/infa_web_folder/dev_env/local/lib/python2.7/site-packages/django/core/handlers/base.py", line 147, in get_response
    response = wrapped_callback(request, *callback_args, **callback_kwargs)
  File "/home/midas/Documentos/infa_web_folder/dev_env/local/lib/python2.7/site-packages/django/views/generic/base.py", line 68, in view
    return self.dispatch(request, *args, **kwargs)
  File "/home/midas/Documentos/infa_web_folder/dev_env/local/lib/python2.7/site-packages/django/views/generic/base.py", line 88, in dispatch
    return handler(request, *args, **kwargs)
  File "/home/midas/Documentos/infa_web_folder/dev_env/local/lib/python2.7/site-packages/django/views/generic/list.py", line 159, in get
    self.object_list = self.get_queryset()
  File "/home/midas/Documentos/infa_web_folder/InfaWeb/infa_web/apps/movimientos/views.py", line 58, in get_queryset
    queryset = super(CarteraList, self).get_queryset().order_by('fmovi').filter(ctimo = ctimo_billing('ctimo_cxc_billing', self.request.db).pk)
  File "/home/midas/Documentos/infa_web_folder/InfaWeb/infa_web/apps/facturacion/views.py", line 176, in ctimo_billing
    return Timo.objects.using(request_db).get(pk = ctimo_billing)
  File "/home/midas/Documentos/infa_web_folder/dev_env/local/lib/python2.7/site-packages/django/db/models/query.py", line 381, in get
    num = len(clone)
  File "/home/midas/Documentos/infa_web_folder/dev_env/local/lib/python2.7/site-packages/django/db/models/query.py", line 240, in __len__
    self._fetch_all()
  File "/home/midas/Documentos/infa_web_folder/dev_env/local/lib/python2.7/site-packages/django/db/models/query.py", line 1074, in _fetch_all
    self._result_cache = list(self.iterator())
  File "/home/midas/Documentos/infa_web_folder/dev_env/local/lib/python2.7/site-packages/django/db/models/query.py", line 49, in __iter__
    compiler = queryset.query.get_compiler(using=db)
  File "/home/midas/Documentos/infa_web_folder/dev_env/local/lib/python2.7/site-packages/django/db/models/sql/query.py", line 254, in get_compiler
    connection = connections[using]
  File "/home/midas/Documentos/infa_web_folder/dev_env/local/lib/python2.7/site-packages/django/db/utils.py", line 209, in __getitem__
    self.ensure_defaults(alias)
  File "/home/midas/Documentos/infa_web_folder/dev_env/local/lib/python2.7/site-packages/django/db/utils.py", line 179, in ensure_defaults
    raise ConnectionDoesNotExist("The connection %s doesn't exist" % alias)
ConnectionDoesNotExist: The connection db_1 doesn't exist
.-.-.-.-.-.-.-.-.-.-.-.-.-.-.-.-.-.-.-.-.-.-.-.-.-.-.-.-.-.-.-.-.-.-.-.-.-.-.-.- 
 ERROR 2016-10-24 07:56:47,753 base 7027 140495190472448 Internal Server Error: /cartera/detalle/1/ 
Traceback (most recent call last):
  File "/home/midas/Documentos/infa_web_folder/dev_env/local/lib/python2.7/site-packages/django/core/handlers/base.py", line 174, in get_response
    response = self.process_exception_by_middleware(e, request)
  File "/home/midas/Documentos/infa_web_folder/dev_env/local/lib/python2.7/site-packages/django/core/handlers/base.py", line 172, in get_response
    response = response.render()
  File "/home/midas/Documentos/infa_web_folder/dev_env/local/lib/python2.7/site-packages/django/template/response.py", line 160, in render
    self.content = self.rendered_content
  File "/home/midas/Documentos/infa_web_folder/dev_env/local/lib/python2.7/site-packages/django/template/response.py", line 137, in rendered_content
    content = template.render(context, self._request)
  File "/home/midas/Documentos/infa_web_folder/dev_env/local/lib/python2.7/site-packages/django/template/backends/django.py", line 95, in render
    return self.template.render(context)
  File "/home/midas/Documentos/infa_web_folder/dev_env/local/lib/python2.7/site-packages/django/template/base.py", line 206, in render
    return self._render(context)
  File "/home/midas/Documentos/infa_web_folder/dev_env/local/lib/python2.7/site-packages/django/template/base.py", line 197, in _render
    return self.nodelist.render(context)
  File "/home/midas/Documentos/infa_web_folder/dev_env/local/lib/python2.7/site-packages/django/template/base.py", line 992, in render
    bit = node.render_annotated(context)
  File "/home/midas/Documentos/infa_web_folder/dev_env/local/lib/python2.7/site-packages/django/template/base.py", line 959, in render_annotated
    return self.render(context)
  File "/home/midas/Documentos/infa_web_folder/dev_env/local/lib/python2.7/site-packages/django/template/loader_tags.py", line 173, in render
    return compiled_parent._render(context)
  File "/home/midas/Documentos/infa_web_folder/dev_env/local/lib/python2.7/site-packages/django/template/base.py", line 197, in _render
    return self.nodelist.render(context)
  File "/home/midas/Documentos/infa_web_folder/dev_env/local/lib/python2.7/site-packages/django/template/base.py", line 992, in render
    bit = node.render_annotated(context)
  File "/home/midas/Documentos/infa_web_folder/dev_env/local/lib/python2.7/site-packages/django/template/base.py", line 959, in render_annotated
    return self.render(context)
  File "/home/midas/Documentos/infa_web_folder/dev_env/local/lib/python2.7/site-packages/django/template/loader_tags.py", line 69, in render
    result = block.nodelist.render(context)
  File "/home/midas/Documentos/infa_web_folder/dev_env/local/lib/python2.7/site-packages/django/template/base.py", line 992, in render
    bit = node.render_annotated(context)
  File "/home/midas/Documentos/infa_web_folder/dev_env/local/lib/python2.7/site-packages/django/template/base.py", line 959, in render_annotated
    return self.render(context)
  File "/home/midas/Documentos/infa_web_folder/dev_env/local/lib/python2.7/site-packages/django/template/base.py", line 1043, in render
    output = self.filter_expression.resolve(context)
  File "/home/midas/Documentos/infa_web_folder/dev_env/local/lib/python2.7/site-packages/django/template/base.py", line 736, in resolve
    new_obj = func(obj, *arg_vals)
  File "/home/midas/Documentos/infa_web_folder/InfaWeb/infa_web/apps/base/templatetags/date_appen.py", line 113, in get_total_saldo
    value = movi_cartera - movi_abono
TypeError: unsupported operand type(s) for -: 'Decimal' and 'NoneType'
.-.-.-.-.-.-.-.-.-.-.-.-.-.-.-.-.-.-.-.-.-.-.-.-.-.-.-.-.-.-.-.-.-.-.-.-.-.-.-.- 
<<<<<<< HEAD
 ERROR 2016-10-24 11:09:41,693 base 15687 140067859322624 Internal Server Error: /bill/proccess/fn/annulment 
Traceback (most recent call last):
  File "/home/midas/Documentos/infa_web_folder/dev_env/local/lib/python2.7/site-packages/django/core/handlers/base.py", line 149, in get_response
    response = self.process_exception_by_middleware(e, request)
  File "/home/midas/Documentos/infa_web_folder/dev_env/local/lib/python2.7/site-packages/django/core/handlers/base.py", line 147, in get_response
    response = wrapped_callback(request, *callback_args, **callback_kwargs)
  File "/home/midas/Documentos/infa_web_folder/dev_env/local/lib/python2.7/site-packages/django/views/decorators/csrf.py", line 58, in wrapped_view
    return view_func(*args, **kwargs)
  File "/home/midas/Documentos/infa_web_folder/InfaWeb/infa_web/apps/facturacion/views.py", line 944, in bill_proccess_fn_annulment
    return HttpResponse(json.dumps(response), content_type="application/json",status=200)
  File "/usr/lib/python2.7/json/__init__.py", line 243, in dumps
    return _default_encoder.encode(obj)
  File "/usr/lib/python2.7/json/encoder.py", line 207, in encode
    chunks = self.iterencode(o, _one_shot=True)
  File "/usr/lib/python2.7/json/encoder.py", line 270, in iterencode
    return _iterencode(o, 0)
  File "/usr/lib/python2.7/json/encoder.py", line 184, in default
    raise TypeError(repr(o) + " is not JSON serializable")
TypeError: Decimal('4000.00') is not JSON serializable
=======
 ERROR 2016-10-24 10:01:54,530 base 4684 5624 Internal Server Error: /cartera/detalle/1/ 
Traceback (most recent call last):
  File "C:\Python27\lib\site-packages\django\core\handlers\base.py", line 174, in get_response
    response = self.process_exception_by_middleware(e, request)
  File "C:\Python27\lib\site-packages\django\core\handlers\base.py", line 172, in get_response
    response = response.render()
  File "C:\Python27\lib\site-packages\django\template\response.py", line 160, in render
    self.content = self.rendered_content
  File "C:\Python27\lib\site-packages\django\template\response.py", line 137, in rendered_content
    content = template.render(context, self._request)
  File "C:\Python27\lib\site-packages\django\template\backends\django.py", line 95, in render
    return self.template.render(context)
  File "C:\Python27\lib\site-packages\django\template\base.py", line 206, in render
    return self._render(context)
  File "C:\Python27\lib\site-packages\django\template\base.py", line 197, in _render
    return self.nodelist.render(context)
  File "C:\Python27\lib\site-packages\django\template\base.py", line 992, in render
    bit = node.render_annotated(context)
  File "C:\Python27\lib\site-packages\django\template\base.py", line 959, in render_annotated
    return self.render(context)
  File "C:\Python27\lib\site-packages\django\template\loader_tags.py", line 173, in render
    return compiled_parent._render(context)
  File "C:\Python27\lib\site-packages\django\template\base.py", line 197, in _render
    return self.nodelist.render(context)
  File "C:\Python27\lib\site-packages\django\template\base.py", line 992, in render
    bit = node.render_annotated(context)
  File "C:\Python27\lib\site-packages\django\template\base.py", line 959, in render_annotated
    return self.render(context)
  File "C:\Python27\lib\site-packages\django\template\loader_tags.py", line 69, in render
    result = block.nodelist.render(context)
  File "C:\Python27\lib\site-packages\django\template\base.py", line 992, in render
    bit = node.render_annotated(context)
  File "C:\Python27\lib\site-packages\django\template\base.py", line 959, in render_annotated
    return self.render(context)
  File "C:\Python27\lib\site-packages\django\template\base.py", line 1043, in render
    output = self.filter_expression.resolve(context)
  File "C:\Python27\lib\site-packages\django\template\base.py", line 736, in resolve
    new_obj = func(obj, *arg_vals)
  File "D:\Proyectos\infa web\infa_web\infa_web\apps\base\templatetags\date_appen.py", line 113, in get_total_saldo
    value = movi_cartera - movi_abono
TypeError: unsupported operand type(s) for -: 'NoneType' and 'NoneType'
.-.-.-.-.-.-.-.-.-.-.-.-.-.-.-.-.-.-.-.-.-.-.-.-.-.-.-.-.-.-.-.-.-.-.-.-.-.-.-.- 
 ERROR 2016-10-24 10:03:37,344 base 4684 4844 Internal Server Error: /cartera/detalle/1/ 
Traceback (most recent call last):
  File "C:\Python27\lib\site-packages\django\core\handlers\base.py", line 174, in get_response
    response = self.process_exception_by_middleware(e, request)
  File "C:\Python27\lib\site-packages\django\core\handlers\base.py", line 172, in get_response
    response = response.render()
  File "C:\Python27\lib\site-packages\django\template\response.py", line 160, in render
    self.content = self.rendered_content
  File "C:\Python27\lib\site-packages\django\template\response.py", line 137, in rendered_content
    content = template.render(context, self._request)
  File "C:\Python27\lib\site-packages\django\template\backends\django.py", line 95, in render
    return self.template.render(context)
  File "C:\Python27\lib\site-packages\django\template\base.py", line 206, in render
    return self._render(context)
  File "C:\Python27\lib\site-packages\django\template\base.py", line 197, in _render
    return self.nodelist.render(context)
  File "C:\Python27\lib\site-packages\django\template\base.py", line 992, in render
    bit = node.render_annotated(context)
  File "C:\Python27\lib\site-packages\django\template\base.py", line 959, in render_annotated
    return self.render(context)
  File "C:\Python27\lib\site-packages\django\template\loader_tags.py", line 173, in render
    return compiled_parent._render(context)
  File "C:\Python27\lib\site-packages\django\template\base.py", line 197, in _render
    return self.nodelist.render(context)
  File "C:\Python27\lib\site-packages\django\template\base.py", line 992, in render
    bit = node.render_annotated(context)
  File "C:\Python27\lib\site-packages\django\template\base.py", line 959, in render_annotated
    return self.render(context)
  File "C:\Python27\lib\site-packages\django\template\loader_tags.py", line 69, in render
    result = block.nodelist.render(context)
  File "C:\Python27\lib\site-packages\django\template\base.py", line 992, in render
    bit = node.render_annotated(context)
  File "C:\Python27\lib\site-packages\django\template\base.py", line 959, in render_annotated
    return self.render(context)
  File "C:\Python27\lib\site-packages\django\template\base.py", line 1043, in render
    output = self.filter_expression.resolve(context)
  File "C:\Python27\lib\site-packages\django\template\base.py", line 736, in resolve
    new_obj = func(obj, *arg_vals)
  File "D:\Proyectos\infa web\infa_web\infa_web\apps\base\templatetags\date_appen.py", line 113, in get_total_saldo
    value = movi_cartera - movi_abono
TypeError: unsupported operand type(s) for -: 'Decimal' and 'NoneType'
.-.-.-.-.-.-.-.-.-.-.-.-.-.-.-.-.-.-.-.-.-.-.-.-.-.-.-.-.-.-.-.-.-.-.-.-.-.-.-.- 
 ERROR 2016-10-24 10:04:52,625 base 4684 6128 Internal Server Error: /cartera/detalle/1/ 
Traceback (most recent call last):
  File "C:\Python27\lib\site-packages\django\core\handlers\base.py", line 174, in get_response
    response = self.process_exception_by_middleware(e, request)
  File "C:\Python27\lib\site-packages\django\core\handlers\base.py", line 172, in get_response
    response = response.render()
  File "C:\Python27\lib\site-packages\django\template\response.py", line 160, in render
    self.content = self.rendered_content
  File "C:\Python27\lib\site-packages\django\template\response.py", line 137, in rendered_content
    content = template.render(context, self._request)
  File "C:\Python27\lib\site-packages\django\template\backends\django.py", line 95, in render
    return self.template.render(context)
  File "C:\Python27\lib\site-packages\django\template\base.py", line 206, in render
    return self._render(context)
  File "C:\Python27\lib\site-packages\django\template\base.py", line 197, in _render
    return self.nodelist.render(context)
  File "C:\Python27\lib\site-packages\django\template\base.py", line 992, in render
    bit = node.render_annotated(context)
  File "C:\Python27\lib\site-packages\django\template\base.py", line 959, in render_annotated
    return self.render(context)
  File "C:\Python27\lib\site-packages\django\template\loader_tags.py", line 173, in render
    return compiled_parent._render(context)
  File "C:\Python27\lib\site-packages\django\template\base.py", line 197, in _render
    return self.nodelist.render(context)
  File "C:\Python27\lib\site-packages\django\template\base.py", line 992, in render
    bit = node.render_annotated(context)
  File "C:\Python27\lib\site-packages\django\template\base.py", line 959, in render_annotated
    return self.render(context)
  File "C:\Python27\lib\site-packages\django\template\loader_tags.py", line 69, in render
    result = block.nodelist.render(context)
  File "C:\Python27\lib\site-packages\django\template\base.py", line 992, in render
    bit = node.render_annotated(context)
  File "C:\Python27\lib\site-packages\django\template\base.py", line 959, in render_annotated
    return self.render(context)
  File "C:\Python27\lib\site-packages\django\template\base.py", line 1043, in render
    output = self.filter_expression.resolve(context)
  File "C:\Python27\lib\site-packages\django\template\base.py", line 736, in resolve
    new_obj = func(obj, *arg_vals)
  File "D:\Proyectos\infa web\infa_web\infa_web\apps\base\templatetags\date_appen.py", line 113, in get_total_saldo
    value = movi_cartera - movi_abono
TypeError: unsupported operand type(s) for -: 'Decimal' and 'NoneType'
.-.-.-.-.-.-.-.-.-.-.-.-.-.-.-.-.-.-.-.-.-.-.-.-.-.-.-.-.-.-.-.-.-.-.-.-.-.-.-.- 
 ERROR 2016-10-24 10:57:49,631 base 5004 664 Internal Server Error: /cartera/ 
Traceback (most recent call last):
  File "C:\Python27\lib\site-packages\django\core\handlers\base.py", line 149, in get_response
    response = self.process_exception_by_middleware(e, request)
  File "C:\Python27\lib\site-packages\django\core\handlers\base.py", line 147, in get_response
    response = wrapped_callback(request, *callback_args, **callback_kwargs)
  File "C:\Python27\lib\site-packages\django\views\generic\base.py", line 68, in view
    return self.dispatch(request, *args, **kwargs)
  File "C:\Python27\lib\site-packages\django\views\generic\base.py", line 88, in dispatch
    return handler(request, *args, **kwargs)
  File "C:\Python27\lib\site-packages\django\views\generic\list.py", line 159, in get
    self.object_list = self.get_queryset()
  File "D:\Proyectos\infa web\infa_web\infa_web\apps\movimientos\views.py", line 59, in get_queryset
    queryset = super(CarteraList, self).get_queryset().order_by('fmovi').filter(cesdo__id = CESDO_ACTIVO, ctimo = ctimo_billing('ctimo_cxc_billing', self.request.db).pk)
  File "C:\Python27\lib\site-packages\django\db\models\query.py", line 790, in filter
    return self._filter_or_exclude(False, *args, **kwargs)
  File "C:\Python27\lib\site-packages\django\db\models\query.py", line 808, in _filter_or_exclude
    clone.query.add_q(Q(*args, **kwargs))
  File "C:\Python27\lib\site-packages\django\db\models\sql\query.py", line 1243, in add_q
    clause, _ = self._add_q(q_object, self.used_aliases)
  File "C:\Python27\lib\site-packages\django\db\models\sql\query.py", line 1269, in _add_q
    allow_joins=allow_joins, split_subq=split_subq,
  File "C:\Python27\lib\site-packages\django\db\models\sql\query.py", line 1194, in build_filter
    lookup_class = field.get_lookup(lookups[0])
  File "C:\Python27\lib\site-packages\django\db\models\fields\related.py", line 693, in get_lookup
    raise TypeError('Related Field got invalid lookup: %s' % lookup_name)
TypeError: Related Field got invalid lookup: id
.-.-.-.-.-.-.-.-.-.-.-.-.-.-.-.-.-.-.-.-.-.-.-.-.-.-.-.-.-.-.-.-.-.-.-.-.-.-.-.- 
 ERROR 2016-10-24 10:57:55,512 base 5004 4480 Internal Server Error: /cartera/ 
Traceback (most recent call last):
  File "C:\Python27\lib\site-packages\django\core\handlers\base.py", line 149, in get_response
    response = self.process_exception_by_middleware(e, request)
  File "C:\Python27\lib\site-packages\django\core\handlers\base.py", line 147, in get_response
    response = wrapped_callback(request, *callback_args, **callback_kwargs)
  File "C:\Python27\lib\site-packages\django\views\generic\base.py", line 68, in view
    return self.dispatch(request, *args, **kwargs)
  File "C:\Python27\lib\site-packages\django\views\generic\base.py", line 88, in dispatch
    return handler(request, *args, **kwargs)
  File "C:\Python27\lib\site-packages\django\views\generic\list.py", line 159, in get
    self.object_list = self.get_queryset()
  File "D:\Proyectos\infa web\infa_web\infa_web\apps\movimientos\views.py", line 59, in get_queryset
    queryset = super(CarteraList, self).get_queryset().order_by('fmovi').filter(cesdo__id = CESDO_ACTIVO, ctimo = ctimo_billing('ctimo_cxc_billing', self.request.db).pk)
  File "C:\Python27\lib\site-packages\django\db\models\query.py", line 790, in filter
    return self._filter_or_exclude(False, *args, **kwargs)
  File "C:\Python27\lib\site-packages\django\db\models\query.py", line 808, in _filter_or_exclude
    clone.query.add_q(Q(*args, **kwargs))
  File "C:\Python27\lib\site-packages\django\db\models\sql\query.py", line 1243, in add_q
    clause, _ = self._add_q(q_object, self.used_aliases)
  File "C:\Python27\lib\site-packages\django\db\models\sql\query.py", line 1269, in _add_q
    allow_joins=allow_joins, split_subq=split_subq,
  File "C:\Python27\lib\site-packages\django\db\models\sql\query.py", line 1194, in build_filter
    lookup_class = field.get_lookup(lookups[0])
  File "C:\Python27\lib\site-packages\django\db\models\fields\related.py", line 693, in get_lookup
    raise TypeError('Related Field got invalid lookup: %s' % lookup_name)
TypeError: Related Field got invalid lookup: id
.-.-.-.-.-.-.-.-.-.-.-.-.-.-.-.-.-.-.-.-.-.-.-.-.-.-.-.-.-.-.-.-.-.-.-.-.-.-.-.- 
 ERROR 2016-10-24 10:58:10,598 base 2128 2652 Internal Server Error: /cartera/ 
Traceback (most recent call last):
  File "C:\Python27\lib\site-packages\django\core\handlers\base.py", line 149, in get_response
    response = self.process_exception_by_middleware(e, request)
  File "C:\Python27\lib\site-packages\django\core\handlers\base.py", line 147, in get_response
    response = wrapped_callback(request, *callback_args, **callback_kwargs)
  File "C:\Python27\lib\site-packages\django\views\generic\base.py", line 68, in view
    return self.dispatch(request, *args, **kwargs)
  File "C:\Python27\lib\site-packages\django\views\generic\base.py", line 88, in dispatch
    return handler(request, *args, **kwargs)
  File "C:\Python27\lib\site-packages\django\views\generic\list.py", line 159, in get
    self.object_list = self.get_queryset()
  File "D:\Proyectos\infa web\infa_web\infa_web\apps\movimientos\views.py", line 59, in get_queryset
    queryset = super(CarteraList, self).get_queryset().order_by('fmovi').filter(cesdo__pk = CESDO_ACTIVO, ctimo = ctimo_billing('ctimo_cxc_billing', self.request.db).pk)
  File "C:\Python27\lib\site-packages\django\db\models\query.py", line 790, in filter
    return self._filter_or_exclude(False, *args, **kwargs)
  File "C:\Python27\lib\site-packages\django\db\models\query.py", line 808, in _filter_or_exclude
    clone.query.add_q(Q(*args, **kwargs))
  File "C:\Python27\lib\site-packages\django\db\models\sql\query.py", line 1243, in add_q
    clause, _ = self._add_q(q_object, self.used_aliases)
  File "C:\Python27\lib\site-packages\django\db\models\sql\query.py", line 1269, in _add_q
    allow_joins=allow_joins, split_subq=split_subq,
  File "C:\Python27\lib\site-packages\django\db\models\sql\query.py", line 1194, in build_filter
    lookup_class = field.get_lookup(lookups[0])
  File "C:\Python27\lib\site-packages\django\db\models\fields\related.py", line 693, in get_lookup
    raise TypeError('Related Field got invalid lookup: %s' % lookup_name)
TypeError: Related Field got invalid lookup: id
.-.-.-.-.-.-.-.-.-.-.-.-.-.-.-.-.-.-.-.-.-.-.-.-.-.-.-.-.-.-.-.-.-.-.-.-.-.-.-.- 
 ERROR 2016-10-24 10:58:17,184 base 2128 1288 Internal Server Error: /cartera/ 
Traceback (most recent call last):
  File "C:\Python27\lib\site-packages\django\core\handlers\base.py", line 149, in get_response
    response = self.process_exception_by_middleware(e, request)
  File "C:\Python27\lib\site-packages\django\core\handlers\base.py", line 147, in get_response
    response = wrapped_callback(request, *callback_args, **callback_kwargs)
  File "C:\Python27\lib\site-packages\django\views\generic\base.py", line 68, in view
    return self.dispatch(request, *args, **kwargs)
  File "C:\Python27\lib\site-packages\django\views\generic\base.py", line 88, in dispatch
    return handler(request, *args, **kwargs)
  File "C:\Python27\lib\site-packages\django\views\generic\list.py", line 159, in get
    self.object_list = self.get_queryset()
  File "D:\Proyectos\infa web\infa_web\infa_web\apps\movimientos\views.py", line 59, in get_queryset
    queryset = super(CarteraList, self).get_queryset().order_by('fmovi').filter(cesdo__pk = CESDO_ACTIVO, ctimo = ctimo_billing('ctimo_cxc_billing', self.request.db).pk)
  File "C:\Python27\lib\site-packages\django\db\models\query.py", line 790, in filter
    return self._filter_or_exclude(False, *args, **kwargs)
  File "C:\Python27\lib\site-packages\django\db\models\query.py", line 808, in _filter_or_exclude
    clone.query.add_q(Q(*args, **kwargs))
  File "C:\Python27\lib\site-packages\django\db\models\sql\query.py", line 1243, in add_q
    clause, _ = self._add_q(q_object, self.used_aliases)
  File "C:\Python27\lib\site-packages\django\db\models\sql\query.py", line 1269, in _add_q
    allow_joins=allow_joins, split_subq=split_subq,
  File "C:\Python27\lib\site-packages\django\db\models\sql\query.py", line 1194, in build_filter
    lookup_class = field.get_lookup(lookups[0])
  File "C:\Python27\lib\site-packages\django\db\models\fields\related.py", line 693, in get_lookup
    raise TypeError('Related Field got invalid lookup: %s' % lookup_name)
TypeError: Related Field got invalid lookup: id
.-.-.-.-.-.-.-.-.-.-.-.-.-.-.-.-.-.-.-.-.-.-.-.-.-.-.-.-.-.-.-.-.-.-.-.-.-.-.-.- 
 ERROR 2016-10-24 11:11:38,127 base 4948 348 Internal Server Error: /cartera/ 
Traceback (most recent call last):
  File "C:\Python27\lib\site-packages\django\core\handlers\base.py", line 149, in get_response
    response = self.process_exception_by_middleware(e, request)
  File "C:\Python27\lib\site-packages\django\core\handlers\base.py", line 147, in get_response
    response = wrapped_callback(request, *callback_args, **callback_kwargs)
  File "C:\Python27\lib\site-packages\django\views\generic\base.py", line 68, in view
    return self.dispatch(request, *args, **kwargs)
  File "C:\Python27\lib\site-packages\django\views\generic\base.py", line 88, in dispatch
    return handler(request, *args, **kwargs)
  File "C:\Python27\lib\site-packages\django\views\generic\list.py", line 159, in get
    self.object_list = self.get_queryset()
  File "D:\Proyectos\infa web\infa_web\infa_web\apps\movimientos\views.py", line 60, in get_queryset
    cesdo = get_or_none(Esdo, request_db, cesdo = CESDO_ACTIVO)
NameError: global name 'request_db' is not defined
.-.-.-.-.-.-.-.-.-.-.-.-.-.-.-.-.-.-.-.-.-.-.-.-.-.-.-.-.-.-.-.-.-.-.-.-.-.-.-.- 
 ERROR 2016-10-24 11:17:32,865 base 1852 4528 Internal Server Error: /cartera/ 
Traceback (most recent call last):
  File "C:\Python27\lib\site-packages\django\core\handlers\base.py", line 174, in get_response
    response = self.process_exception_by_middleware(e, request)
  File "C:\Python27\lib\site-packages\django\core\handlers\base.py", line 172, in get_response
    response = response.render()
  File "C:\Python27\lib\site-packages\django\template\response.py", line 160, in render
    self.content = self.rendered_content
  File "C:\Python27\lib\site-packages\django\template\response.py", line 137, in rendered_content
    content = template.render(context, self._request)
  File "C:\Python27\lib\site-packages\django\template\backends\django.py", line 95, in render
    return self.template.render(context)
  File "C:\Python27\lib\site-packages\django\template\base.py", line 206, in render
    return self._render(context)
  File "C:\Python27\lib\site-packages\django\template\base.py", line 197, in _render
    return self.nodelist.render(context)
  File "C:\Python27\lib\site-packages\django\template\base.py", line 992, in render
    bit = node.render_annotated(context)
  File "C:\Python27\lib\site-packages\django\template\base.py", line 959, in render_annotated
    return self.render(context)
  File "C:\Python27\lib\site-packages\django\template\loader_tags.py", line 173, in render
    return compiled_parent._render(context)
  File "C:\Python27\lib\site-packages\django\template\base.py", line 197, in _render
    return self.nodelist.render(context)
  File "C:\Python27\lib\site-packages\django\template\base.py", line 992, in render
    bit = node.render_annotated(context)
  File "C:\Python27\lib\site-packages\django\template\base.py", line 959, in render_annotated
    return self.render(context)
  File "C:\Python27\lib\site-packages\django\template\loader_tags.py", line 69, in render
    result = block.nodelist.render(context)
  File "C:\Python27\lib\site-packages\django\template\base.py", line 992, in render
    bit = node.render_annotated(context)
  File "C:\Python27\lib\site-packages\django\template\base.py", line 959, in render_annotated
    return self.render(context)
  File "C:\Python27\lib\site-packages\django\template\defaulttags.py", line 220, in render
    nodelist.append(node.render_annotated(context))
  File "C:\Python27\lib\site-packages\django\template\base.py", line 959, in render_annotated
    return self.render(context)
  File "C:\Python27\lib\site-packages\django\template\base.py", line 1043, in render
    output = self.filter_expression.resolve(context)
  File "C:\Python27\lib\site-packages\django\template\base.py", line 736, in resolve
    new_obj = func(obj, *arg_vals)
  File "D:\Proyectos\infa web\infa_web\infa_web\apps\base\templatetags\date_appen.py", line 96, in saldo_factura
    movi_ab = movi.filter(cesdo__pk = cesdo, ctimo = ctimo_abono).aggregate(val_tot = Sum('vttotal'))['val_tot']
  File "C:\Python27\lib\site-packages\django\db\models\query.py", line 790, in filter
    return self._filter_or_exclude(False, *args, **kwargs)
  File "C:\Python27\lib\site-packages\django\db\models\query.py", line 808, in _filter_or_exclude
    clone.query.add_q(Q(*args, **kwargs))
  File "C:\Python27\lib\site-packages\django\db\models\sql\query.py", line 1243, in add_q
    clause, _ = self._add_q(q_object, self.used_aliases)
  File "C:\Python27\lib\site-packages\django\db\models\sql\query.py", line 1269, in _add_q
    allow_joins=allow_joins, split_subq=split_subq,
  File "C:\Python27\lib\site-packages\django\db\models\sql\query.py", line 1203, in build_filter
    condition = self.build_lookup(lookups, col, value)
  File "C:\Python27\lib\site-packages\django\db\models\sql\query.py", line 1099, in build_lookup
    return final_lookup(lhs, rhs)
  File "C:\Python27\lib\site-packages\django\db\models\lookups.py", line 19, in __init__
    self.rhs = self.get_prep_lookup()
  File "C:\Python27\lib\site-packages\django\db\models\lookups.py", line 57, in get_prep_lookup
    return self.lhs.output_field.get_prep_lookup(self.lookup_name, self.rhs)
  File "C:\Python27\lib\site-packages\django\db\models\fields\__init__.py", line 744, in get_prep_lookup
    return self.get_prep_value(value)
  File "C:\Python27\lib\site-packages\django\db\models\fields\__init__.py", line 976, in get_prep_value
    return int(value)
TypeError: int() argument must be a string or a number, not 'Esdo'
>>>>>>> 80aaf54b7872818c3b8df1785cc846c7b7e2e0fc
.-.-.-.-.-.-.-.-.-.-.-.-.-.-.-.-.-.-.-.-.-.-.-.-.-.-.-.-.-.-.-.-.-.-.-.-.-.-.-.- 
 ERROR 2016-10-25 07:46:14,716 base 5292 140497455757056 Internal Server Error: /parameters/ 
Traceback (most recent call last):
  File "/home/midas/Documentos/infa_web_folder/dev_env/local/lib/python2.7/site-packages/django/core/handlers/base.py", line 123, in get_response
    response = middleware_method(request)
  File "/home/midas/Documentos/infa_web_folder/InfaWeb/infa_web/apps/base/middleware.py", line 24, in process_request
    manageParameters.set_param_object("date_appen",current_date_format)
  File "/home/midas/Documentos/infa_web_folder/InfaWeb/infa_web/parameters.py", line 42, in set_param_object
    parameters = json.load(json_data)
  File "/usr/lib/python2.7/json/__init__.py", line 290, in load
    **kw)
  File "/usr/lib/python2.7/json/__init__.py", line 338, in loads
    return _default_decoder.decode(s)
  File "/usr/lib/python2.7/json/decoder.py", line 366, in decode
    obj, end = self.raw_decode(s, idx=_w(s, 0).end())
  File "/usr/lib/python2.7/json/decoder.py", line 384, in raw_decode
    raise ValueError("No JSON object could be decoded")
ValueError: No JSON object could be decoded
